Workbook
Name Eno_TM: #REF!
Name Eno_Tons: #REF!
Name Sum_T2: #REF!
Name Sum_TTM: #REF!
Name ti_tbl_50: #REF!
Name ti_tbl_69: #REF!

Sheet About
A1: SYVbT Start Year Vehicles by Technology
A3: Sources: | B3: LDVs, HDVs, Motorbikes
B4: BPS (Statistics Indonesia)
B5: Land Transportation Statistics 2019
B6: https://www.bps.go.id/publication/2020/11/20/ddce434c92536777bf07605d/statistik-transportasi-darat-2019.html
B7: Number of Cars, Buses, Trucks, Motorcycles by Province 2015-2019
B8: Table 3.3 and Appendix 8-12
B10: Aircraft
B11: BPS (Statistics Indonesia)
B12: Air Transportation Statistics 2019
B13: https://www.bps.go.id/publication/2020/11/20/231373341461207b51910a4a/statistik-transportasi-udara-2019.html
B14: The Number of Civil Aircraft Registered by Air Operator Certificate
B15: Table 3.9
B17: Ministry of Transportation
... B101: Page 9
A102: Notes
A103: BPS data only provide the number of motor vehicles by types, does not include fuel technology used
A104: Ministry of Transportation data also does not mention fuel technology used, except for trains
A105: Start year 2018

Sheet BPS LTS 2019
A1: Perkembangan Jumlah Kendaraan Bermotor Menurut Jenisnya
A2: The number of Motor Vehicles by Types
A3: Jenis Kendaraan Bermotor | B3: 2015 | C3: 2016 | D3: 2017 | E3: 2018 | F3: 2019
A4: Mobil penumpang (passenger car) | B4: 14304221 | C4: 14142958 | D4: 15968202 | E4: 16830698 | F4: 17592419 | G4: diesel/gasoline ration unknown
A5: Mobil bus (passenger bus) | B5: 296309 | C5: 304512 | D5: 313359 | E5: 322872 | F5: 331569 | G5: diesel
A6: Mobil barang (freight/truck) | B6: 4145857 | C6: 4326731 | D6: 4540902 | E6: 4797254 | F6: 5021888 | G6: diesel
A7: Sepeda motor (motorcycles) | B7: 88656931 | C7: 94531510 | D7: 100200245 | E7: 106657952 | F7: 112771136 | G7: gasoline
A8: Jumlah | B8: =SUM(B4:B7) -> 107403318 | C8: =SUM(C4:C7) -> 113305711 | D8: =SUM(D4:D7) -> 121022708 | E8: =SUM(E4:E7) -> 128608776 | F8: =SUM(F4:F7) -> 135717012
A10: Sumber | B10: Kepolisian Republik Indonesia
A11: Source | B11: Indonesian State Police

Sheet KCI Annual Report 2018
B2: Jumlah rangkaian yang beroperasi
B3: number of trainset operated
B4: 97 | C4: units
B5: (EMU: electric multiple unit)

Sheet Transjakarta Statistics
B2: Perkembangan armada bus transjakarta yang beroperasi tahun 2016-2019
B3: Number of transjakarta fleets operated 2016-2019
B5: Jenis Layanan | C5: 2016 | D5: 2017 | E5: 2018 | F5: 2019
B6: BRT | C6: 524 | D6: 581 | E6: 750 | F6: 783
B7: Mikrotrans | C7: 0 | D7: 445 | E7: 530 | F7: 1368
B8: Angkutan umum integrasi | C8: 225 | D8: 310 | E8: 480 | F8: 602
B9: Transjabodetabek | C9: 113 | D9: 106 | E9: 132 | F9: 193
B10: Rusun | C10: 14 | D10: 33 | E10: 45 | F10: 47
B11: Royaltrans | C11: 0 | D11: 0 | E11: 19 | F11: 82
B12: Bus wisata | C12: 15 | D12: 17 | E12: 21 | F12: 25
B13: Angkutan umum lain | C13: 5 | D13: 21 | E13: 6 | F13: 31
B14: Transjakarta cares | C14: 0 | D14: 7 | E14: 20 | F14: 18
B15: Total | C15: =SUM(C6:C13) -> 896 | D15: =SUM(D6:D13) -> 1513 | E15: =SUM(E6:E13) -> 1983 | F15: =SUM(F6:F13) -> 3131

Sheet EV
B2: Number of Electric Vehicles
B4: No | C4: Jenis | D4: Tahun / year
B5: No | C5: Type | D5: 2019
B6: 1 | C6: two-wheelers | D6: 0
B7: 2 | C7: three-wheelers | D7: 0
B8: 3 | C8: four-wheelers | D8: 0
B9: 4 | C9: Bus | D9: 0

Sheet BUKU IT 2019 & Statistik Transp
B1: Transportasi Jalan
B2: Land Transportatiom
B3: Jumlah Angkutan antar kota antar provinsi (AKAP) dan Pariwisata
B4: The Number of Inter city coach bus and tour bus
B5: Tabel / Table | C5: A.1.4.02 | D5: Page 1-18
B7: Tahun | C7: AKAP | D7: Pariwisata | E7: Total
B8: year | C8: inter city, inter province | D8: tour bus
B9: 2014 | C9: 22544 | D9: 19841 | E9: =D9+C9 -> 42385
B10: 2015 | C10: 23464 | D10: 21277 | E10: =D10+C10 -> 44741
B11: 2016 | C11: 22742 | D11: 22971 | E11: =D11+C11 -> 45713
B12: 2017 | C12: 16238 | D12: 24524 | E12: =D12+C12 -> 40762
B13: 2018 | C13: 16353 | D13: 24679 | E13: =D13+C13 -> 41032
B14: 2019 | C14: 12367 | D14: 12961 | E14: =D14+C14 -> 25328
B16: Jumlah Kendaraan Angkutan Alat Berat, B3, Antar-Jemput Antar Provinsi, Sewa dan Taksi Bandara
B17: Number of Heavy Equipment, Dangerous Goods Transport, Inter-provincial Shuttle Services, and Carter and Airports Taxi Service Operators
B18: Tabel / Table | C18: A.1.4.06 | D18: Page 1-21
B20: No | C20: Uraian | D20: Satuan | E20: 2014 | F20: 2015 | G20: 2016 | H20: 2017 | I20: 2018 | J20: 2019
C21: Description | D21: Unit
B22: 1 | C22: Alat Berat | D22: Unit | E22: 109 | F22: 1087 | G22: 1129 | H22: 1158 | I22: 1341 | J22: 229 | L22: passenger car | M22: =SUM(J26:J28) -> 1344
C23: Heavy Equipment | D23: Units
B24: 2 | C24: Bahan Berbahaya dan Beracun | D24: Unit | E24: 2716 | F24: 10130 | G24: 11942 | H24: 13332 | I24: 18825 | J24: 8984
C25: Dangerous Goods | D25: Units
B26: 3 | C26: Antar Jemput antar Provinsi | D26: Unit | E26: 2681 | F26: 2811 | G26: 1886 | H26: 2539 | I26: 3078 | J26: 937
C27: inter-provincial shuttle | D27: Units
B28: 4 | C28: Sewa | D28: Unit | E28: 0 | F28: 0 | G28: 0 | H28: 2341 | I28: 2495 | J28: 407
C29: Rent Services | D29: Units
B33: Jumlah Bus dan Truk Siap Operasi Perum Damri 2014-2018
B34: Number of Available-for-operation Buses & Trucks of Perum Damri 2014-2018
B35: Tabel / Table | C35: A.1.4.07 | D35: Page 1-22
B37: No | C37: Uraian | D37: Satuan | E37: 2014 | F37: 2015 | G37: 2016 | H37: 2017 | I37: 2018 | J37: 2019 | L37: freight | M37: =J51 -> 57
D38: Unit | L38: passenger | M38: =SUM(J39:J49) -> 1782
B39: 1 | C39: Bus Kota | D39: Unit | E39: 422 | F39: 405 | G39: 565 | H39: 201 | I39: 451 | J39: 436
C40: City Bus | D40: Units
B41: 2 | C41: Bus Antar Kota | D41: Unit | E41: 378 | F41: 378 | G41: 395 | H41: 406 | I41: 360 | J41: 385
C42: Intercity Bus | D42: Units
B43: 3 | C43: Bus Antar Negara | D43: Unit | E43: 11 | F43: 11 | G43: 12 | H43: 11 | I43: 8 | J43: 12
C44: Intercontinental Bus | D44: Units
B45: 4 | C45: Bus Wisata | D45: Unit | E45: 31 | F45: 26 | G45: 27 | H45: 7 | I45: 5 | J45: 15
C46: Tour Bus | D46: Units
B47: 5 | C47: Bus Perintis | D47: Unit | E47: 356 | F47: 367 | G47: 388 | H47: 741 | I47: 479 | J47: 461
...

Sheet SYVbT-passenger
A1: Number of Vehicles | B1: battery electric vehicle | C1: natural gas vehicle | D1: gasoline vehicle | E1: diesel vehicle | F1: plugin hybrid vehicle | G1: LPG vehicle | H1: hydrogen vehicle
A2: LDVs | B2: =EV!D8 -> 0 | C2: 0 | D2: ='BPS LTS 2019'!F4 -> 17592419 | E2: 0 | F2: 0 | G2: 0 | H2: 0
A3: HDVs | B3: 0 | C3: 0 | D3: 0 | E3: ='BPS LTS 2019'!F5 -> 331569 | F3: 0 | G3: 0 | H3: 0
A4: aircraft | B4: 0 | C4: 0 | D4: ='BUKU IT 2019 & Statistik Transp'!I174 -> 1197 | E4: 0 | F4: 0 | G4: 0 | H4: 0
A5: rail | B5: ='KCI Annual Report 2018'!B4 -> 97 | C5: 0 | D5: 0 | E5: ='BUKU IT 2019 & Statistik Transp'!J198+'BUKU IT 2019 & Statistik Transp'!J253+'BUKU IT 2019 & Statistik Transp'!J267+'BUKU IT 2019 & Statistik Transp'!J275 -> 667 | F5: 0 | G5: 0 | H5: 0
A6: ships | B6: 0 | C6: 0 | D6: 0 | E6: ='BUKU IT 2019 & Statistik Transp'!J149+'BUKU IT 2019 & Statistik Transp'!M105+'BUKU IT 2019 & Statistik Transp'!M88 -> 2222 | F6: 0 | G6: 0 | H6: 0
A7: motorbikes | B7: =EV!D6 -> 0 | C7: 0 | D7: ='BPS LTS 2019'!F7 -> 112771136 | E7: 0 | F7: 0 | G7: 0 | H7: 0

Sheet SYVbT-freight
A1: Number of Vehicles | B1: battery electric vehicle | C1: natural gas vehicle | D1: gasoline vehicle | E1: diesel vehicle | F1: plugin hybrid vehicle | G1: LPG vehicle | H1: hydrogen vehicle
A2: LDVs | B2: 0 | C2: 0 | D2: 0 | E2: 0 | F2: 0 | G2: 0 | H2: 0
A3: HDVs | B3: 0 | C3: 0 | D3: 0 | E3: ='BPS LTS 2019'!F6 -> 5021888 | F3: 0 | G3: 0 | H3: 0
A4: aircraft | B4: 0 | C4: 0 | D4: 0 | E4: 0 | F4: 0 | G4: 0 | H4: 0
A5: rail | B5: 0 | C5: 0 | D5: 0 | E5: 0 | F5: 0 | G5: 0 | H5: 0
A6: ships | B6: 0 | C6: 0 | D6: 0 | E6: ='BUKU IT 2019 & Statistik Transp'!J62+'BUKU IT 2019 & Statistik Transp'!J88+'BUKU IT 2019 & Statistik Transp'!J108+'BUKU IT 2019 & Statistik Transp'!J111+'BUKU IT 2019 & Statistik Transp'!J114 -> 27818 | F6: 0 | G6: 0 | H6: 0
A7: motorbikes | B7: 0 | C7: 0 | D7: 0 | E7: 0 | F7: 0 | G7: 0 | H7: 0

Sheet AEO 7
B1: ref2019.d111618a | C1: 2017 | D1: 2018 | E1: 2019 | F1: 2020 | G1: 2021 | H1: 2022 | I1: 2023 | J1: 2024 | K1: 2025 | L1: 2026 | M1: 2027 | N1: 2028 | O1: 2029 | P1: 2030 | Q1: 2031 | R1: 2032 | S1: 2033 | T1: 2034 | U1: 2035 | V1: 2036 | W1: 2037 | X1: 2038 | Y1: 2039 | Z1: 2040 | AA1: 2041 | AB1: 2042 | AC1: 2043 | AD1: 2044 | AE1: 2045 | AF1: 2046 | AG1: 2047 | AH1: 2048 | AI1: 2049 | AJ1: 2050
C3: Report | D3: Annual Energy Outlook 2019
C4: Scenario | D4: ref2019 | G4: Reference case
C5: Datekey | D5: d111618a
C6: Release Date | E6: January 2019
A10: TKI000 | B10: 7. Transportation Sector Key Indicators and Delivered Energy Consumption
AK12: 2018-
B13: Key Indicators and Consumption | C13: 2017 | D13: 2018 | E13: 2019 | F13: 2020 | G13: 2021 | H13: 2022 | I13: 2023 | J13: 2024 | K13: 2025 | L13: 2026 | M13: 2027 | N13: 2028 | O13: 2029 | P13: 2030 | Q13: 2031 | R13: 2032 | S13: 2033 | T13: 2034 | U13: 2035 | V13: 2036 | W13: 2037 | X13: 2038 | Y13: 2039 | Z13: 2040 | AA13: 2041 | AB13: 2042 | AC13: 2043 | AD13: 2044 | AE13: 2045 | AF13: 2046 | AG13: 2047 | AH13: 2048 | AI13: 2049 | AJ13: 2050 | AK13: 2050
B15: Key Indicators
B16: Travel Indicators
B17: (billion vehicle miles traveled)
A18: TKI000:ba_Light-DutyVeh | B18: Light-Duty Vehicles less than 8,501 pounds | C18: 2835.9963 | D18: 2883.0076 | E18: 2922.0107 | F18: 2951.3701 | G18: 2973.1135 | H18: 2990.5669 | I18: 3001.8533 | J18: 3009.8223 | K18: 3017.5295 | L18: 3036.9685 | M18: 3057.3228 | N18: 3077.249 | O18: 3092.1702 | P18: 3107.1677 | Q18: 3121.2544 | R18: 3134.6589 | S18: 3147.7898 | T18: 3160.5212 | U18: 3171.6843 | V18: 3188.4839 | W18: 3207.2163 | X18: 3227.2656 | Y18: 3247.8088 | Z18: 3268.6482 | AA18: 3289.6279 | AB18: 3310.8071 | AC18: 3332.4702 | AD18: 3354.2253 | AE18: 3375.4978 | AF18: 3397.093 | AG18: 3417.8025 | AH18: 3436.7725 | AI18: 3455.405 | AJ18: 3472.6509 | AK18: 0.005832
A19: TKI000:ba_CommercialLig | B19: Commercial Light Trucks 1/ | C19: 97.025139 | D19: 99.47998 | E19: 101.74947 | F19: 103.4052 | G19: 104.64126 | H19: 105.86214 | I19: 107.08696 | J19: 108.28252 | K19: 109.68753 | L19: 111.26117 | M19: 112.82363 | N19: 114.57213 | O19: 116.06745 | P19: 117.52844 | Q19: 119.13098 | R19: 120.71562 | S19: 122.31748 | T19: 123.99625 | U19: 125.76493 | V19: 127.5814 | W19: 129.47594 | X19: 131.41042 | Y19: 133.23712 | Z19: 135.04831 | AA19: 136.89467 | AB19: 138.72411 | AC19: 140.66197 | AD19: 142.69688 | AE19: 144.86681 | AF19: 147.03716 | AG19: 149.26863 | AH19: 151.51474 | AI19: 153.70024 | AJ19: 155.92755 | AK19: 0.014144
A20: TKI000:ba_FreightTrucks | B20: Freight Trucks greater than 10,000 pounds | C20: 289.55078 | D20: 297.04279 | E20: 305.55014 | F20: 309.82758 | G20: 312.85162 | H20: 316.75717 | I20: 320.85107 | J20: 324.86124 | K20: 329.14508 | L20: 333.67548 | M20: 337.54114 | N20: 341.87463 | O20: 345.66849 | P20: 349.52676 | Q20: 353.97122 | R20: 358.05899 | S20: 362.21085 | T20: 366.77152 | U20: 371.79031 | V20: 376.70877 | W20: 381.89111 | X20: 387.09091 | Y20: 391.7778 | Z20: 396.25085 | AA20: 400.73352 | AB20: 405.11423 | AC20: 409.46503 | AD20: 414.23755 | AE20: 419.31766 | AF20: 424.31128 | AG20: 429.53677 | AH20: 434.97501 | AI20: 440.03778 | AJ20: 445.35059 | AK20: 0.012736
A21: TKI000:buspassmiles | B21: (billion passenger miles traveled)
A22: TKI000:railpassmiles | B22: Bus Transportation | C22: 205.3141 | D22: 206.33447 | E22: 207.28133 | F22: 208.21898 | G22: 209.15999 | H22: 210.08101 | I22: 210.95932 | J22: 211.85976 | K22: 212.84192 | L22: 213.80716 | M22: 214.7581 | N22: 215.72217 | O22: 216.6627 | P22: 217.55475 | Q22: 218.4193 | R22: 219.26325 | S22: 220.02628 | T22: 220.74793 | U22: 221.43126 | V22: 222.08023 | W22: 222.69884 | X22: 223.28966 | Y22: 223.85547 | Z22: 224.39857 | AA22: 224.92021 | AB22: 225.42384 | AC22: 225.91266 | AD22: 226.39052 | AE22: 226.8633 | AF22: 227.33708 | AG22: 227.81938 | AH22: 228.31657 | AI22: 228.83379 | AJ22: 229.37569 | AK22: 0.003314
B23: Passenger Rail | C23: 39.645065 | D23: 39.896538 | E23: 40.432911 | F23: 40.870899 | G23: 41.314678 | H23: 41.73423 | I23: 42.149014 | J23: 42.569008 | K23: 43.00835 | L23: 43.455452 | M23: 43.862602 | N23: 44.347565 | O23: 44.702797 | P23: 45.127457 | Q23: 45.522034 | R23: 45.91967 | S23: 46.329922 | T23: 46.726559 | U23: 47.114132 | V23: 47.480175 | W23: 47.866169 | X23: 48.231972 | Y23: 48.586067 | Z23: 48.930767 | AA23: 49.274044 | AB23: 49.600204 | AC23: 49.935272 | AD23: 50.266663 | AE23: 50.58802 | AF23: 50.906265 | AG23: 51.242321 | AH23: 51.570972 | AI23: 51.911625 | AJ23: 52.242622 | AK23: 0.008461
A24: TKI000:ba_Air | B24: (billion seat miles available)
B25: Air | C25: 1173.5535 | D25: 1188.8688 | E25: 1213.5831 | F25: 1235.7582 | G25: 1255.5334 | H25: 1273.8647 | I25: 1293.121 | J25: 1313.7976 | K25: 1336.5613 | L25: 1360.6853 | M25: 1384.1838 | N25: 1413.3251 | O25: 1439.0891 | P25: 1464.7561 | Q25: 1491.2557 | R25: 1517.9093 | S25: 1544.9697 | T25: 1572.8766 | U25: 1600.8291 | V25: 1628.6422 | W25: 1656.9591 | X25: 1686.0646 | Y25: 1715.3379 | Z25: 1745.1476 | AA25: 1774.89 | AB25: 1805.4565 | AC25: 1836.7898 | AD25: 1868.7915 | AE25: 1901.8862 | AF25: 1935.8136 | AG25: 1970.7146 | AH25: 2005.9568 | AI25: 2040.9736 | AJ25: 2075.53 | AK25: 0.017565
A26: TKI000:ba_Rail | B26: (billion ton miles traveled)
A27: TKI000:ba_DomesticShipp | B27: Rail | C27: 1787.5374 | D27: 1788.7363 | E27: 1812.1239 | F27: 1776.697 | G27: 1769.3909 | H27: 1761.3311 | I27: 1760.6548 | J27: 1779.4348 | K27: 1793.8669 | L27: 1809.7041 | M27: 1816.5015 | N27: 1828.6771 | O27: 1865.3177 | P27: 1893.7076 | Q27: 1898.4255 | R27: 1901.764 | S27: 1914.6235 | T27: 1915.7354 | U27: 1929.5085 | V27: 1945.8417 | W27: 1957.7838 | X27: 1973.6379 | Y27: 1989.265 | Z27: 2003.4233 | AA27: 2016.8127 | AB27: 2027.808 | AC27: 2037.5172 | AD27: 2052.5413 | AE27: 2069.3689 | AF27: 2081.4026 | AG27: 2096.3093 | AH27: 2113.6646 | AI27: 2130.5164 | AJ27: 2149.3511 | AK27: 0.005756
B28: Domestic Shipping | C28: 447.72595 | D28: 444.52057 | E28: 435.79327 | F28: 426.55743 | G28: 415.90875 | H28: 407.28922 | I28: 397.98157 | J28: 387.66037 | K28: 377.81396 | L28: 368.69983 | M28: 359.4342 | N28: 349.28803 | O28: 339.07843 | P28: 328.70654 | Q28: 324.04404 | R28: 318.92053 | S28: 314.1752 | T28: 309.60535 | U28: 305.29675 | V28: 300.71558 | W28: 296.95438 | X28: 292.93774 | Y28: 288.72516 | Z28: 284.26468 | AA28: 282.85895 | AB28: 281.43481 | AC28: 279.57016 | AD28: 278.13324 | AE28: 276.71732 | AF28: 275.62259 | AG28: 274.33264 | AH28: 273.4216 | AI28: 271.81381 | AJ28: 270.6106 | AK28: -0.01539
B30: Energy Efficiency Indicators
A31: TKI000:ca_AvgCAFEStand | B31: (miles per gallon)
A32: TKI000:ca_CarCAFEStand | B32: New Light-Duty Vehicle CAFE Standard 2/ | C32: 33.231037 | D32: 33.824409 | E32: 34.663242 | F32: 36.011749 | G32: 37.960045 | H32: 39.711666 | I32: 41.675518 | J32: 43.356022 | K32: 45.640671 | L32: 45.687145 | M32: 45.835239 | N32: 45.955185 | O32: 46.097694 | P32: 46.204849 | Q32: 46.309845 | R32: 46.409691 | S32: 46.480145 | T32: 46.55238 | U32: 46.617996 | V32: 46.679771 | W32: 46.724213 | X32: 46.772335 | Y32: 46.816681 | Z32: 46.858173 | AA32: 46.889629 | AB32: 46.931118 | AC32: 46.960442 | AD32: 46.978397 | AE32: 46.999207 | AF32: 47.003643 | AG32: 47.005432 | AH32: 47.012489 | AI32: 47.006405 | AJ32: 46.994553 | AK32: 0.010329
A33: TKI000:ca_TwukCAFEStand | B33: New Car 2/ | C33: 38.552597 | D33: 39.421032 | E33: 40.955711 | F33: 42.739193 | G33: 44.647316 | H33: 46.77142 | I33: 49.107544 | J33: 50.479019 | K33: 53.163414 | L33: 53.165295 | M33: 53.182201 | N33: 53.182201 | O33: 53.192871 | P33: 53.192871 | Q33: 53.19289 | R33: 53.192928 | S33: 53.19294 | T33: 53.193012 | U33: 53.19305 | V33: 53.193115 | W33: 53.193115 | X33: 53.193176 | Y33: 53.194641 | Z33: 53.19503 | AA33: 53.195042 | AB33: 53.197578 | AC33: 53.197578 | AD33: 53.197578 | AE33: 53.197632 | AF33: 53.197948 | AG33: 53.19817 | AH33: 53.200935 | AI33: 53.200935 | AJ33: 53.200947 | AK33: 0.009412
A34: TKI000:ca_NewVehCred | B34: New Light Truck 2/ | C34: 28.836378 | D34: 29.179739 | E34: 29.623194 | F34: 30.619411 | G34: 32.520454 | H34: 33.934437 | I34: 35.478027 | J34: 37.151321 | K34: 38.954666 | L34: 38.965858 | M34: 38.966263 | N34: 38.96772 | O34: 38.967854 | P34: 38.969234 | Q34: 38.96973 | R34: 38.970463 | S34: 38.971207 | T34: 38.971207 | U34: 38.97168 | V34: 38.972107 | W34: 38.972855 | X34: 38.973167 | Y34: 38.973568 | Z34: 38.97398 | AA34: 38.974487 | AB34: 38.974743 | AC34: 38.975323 | AD34: 38.975731 | AE34: 38.976013 | AF34: 38.976311 | AG34: 38.976658 | AH34: 38.97686 | AI34: 38.977299 | AJ34: 38.977531 | AK34: 0.009088
A35: TKI000:ca_NewCarCred | B35: Compliance New Light-Duty Vehicle 3/ | C35: 33.453663 | D35: 33.999165 | E35: 34.852367 | F35: 36.294296 | G35: 38.366337 | H35: 40.360031 | I35: 42.344337 | J35: 43.980865 | K35: 46.242016 | L35: 46.369415 | M35: 46.563313 | N35: 46.693798 | O35: 46.881443 | P35: 47.023907 | Q35: 47.195477 | R35: 47.396988 | S35: 47.630604 | T35: 47.772404 | U35: 47.898392 | V35: 48.021744 | W35: 48.10815 | X35: 48.228577 | Y35: 48.328503 | Z35: 48.415863 | AA35: 48.528599 | AB35: 48.589287 | AC35: 48.621609 | AD35: 48.628242 | AE35: 48.712502 | AF35: 48.731789 | AG35: 48.745567 | AH35: 48.774223 | AI35: 48.780106 | AJ35: 48.78289 | AK35: 0.011346
A36: TKI000:ca_NewTwukCred | B36: New Car 3/ | C36: 39.21965 | D36: 40.208176 | E36: 41.560863 | F36: 43.481544 | G36: 45.514778 | H36: 47.57579 | I36: 49.836277 | J36: 51.162941 | K36: 53.624893 | L36: 53.706425 | M36: 53.805222 | N36: 53.878506 | O36: 54.057693 | P36: 54.205578 | Q36: 54.410496 | R36: 54.644573 | S36: 54.846699 | T36: 55.040737 | U36: 55.223377 | V36: 55.398727 | W36: 55.53233 | X36: 55.66367 | Y36: 55.798275 | Z36: 55.916218 | AA36: 55.95874 | AB36: 56.004444 | AC36: 56.03677 | AD36: 56.041607 | AE36: 56.047878 | AF36: 56.084099 | AG36: 56.117535 | AH36: 56.169254 | AI36: 56.202084 | AJ36: 56.231964 | AK36: 0.010537
A37: TKI000:ca_TestedNewVeh | B37: New Light Truck 3/ | C37: 28.781832 | D37: 28.981468 | E37: 29.56732 | F37: 30.629837 | G37: 32.641251 | H37: 34.464329 | I37: 36.083229 | J37: 37.714725 | K37: 39.624859 | L37: 39.715786 | M37: 39.738346 | N37: 39.70694 | O37: 39.659554 | P37: 39.607239 | Q37: 39.559658 | R37: 39.545506 | S37: 39.663071 | T37: 39.61974 | U37: 39.567665 | V37: 39.521477 | W37: 39.476704 | X37: 39.484936 | Y37: 39.461704 | Z37: 39.433529 | AA37: 39.534775 | AB37: 39.520966 | AC37: 39.49025 | AD37: 39.460434 | AE37: 39.564434 | AF37: 39.558979 | AG37: 39.551521 | AH37: 39.546413 | AI37: 39.541836 | AJ37: 39.546425 | AK37: 0.00976
A38: TKI000:ca_TestedNewCar | B38: Tested New Light-Duty Vehicle 4/ | C38: 32.92057 | D38: 33.597721 | E38: 34.642803 | F38: 36.290867 | G38: 38.362621 | H38: 40.356014 | I38: 42.339863 | J38: 43.975994 | K38: 46.236908 | L38: 46.364128 | M38: 46.557949 | N38: 46.688419 | O38: 46.876041 | P38: 47.018448 | Q38: 47.189926 | R38: 47.391357 | S38: 47.624954 | T38: 47.766644 | U38: 47.892525 | V38: 48.015766 | W38: 48.102093 | X38: 48.222412 | Y38: 48.322189 | Z38: 48.409386 | AA38: 48.522015 | AB38: 48.582489 | AC38: 48.614666 | AD38: 48.621155 | AE38: 48.705265 | AF38: 48.724365 | AG38: 48.737965 | AH38: 48.766415 | AI38: 48.772102 | AJ38: 48.774681 | AK38: 0.011717
A39: TKI000:ca_TestedNewTwuk | B39: New Car 4/ | C39: 38.844189 | D39: 39.84222 | E39: 41.359097 | F39: 43.479668 | G39: 45.512585 | H39: 47.573315 | I39: 49.833408 | J39: 51.159718 | K39: 53.621464 | L39: 53.702938 | M39: 53.80172 | N39: 53.874981 | O39: 54.05426 | P39: 54.202103 | Q39: 54.407009 | R39: 54.641037 | S39: 54.843136 | T39: 55.03714 | U39: 55.219742 | V39: 55.395058 | W39: 55.528614 | X39: 55.659931 | Y39: 55.794483 | Z39: 55.912376 | AA39: 55.95483 | AB39: 56.000454 | AC39: 56.032734 | AD39: 56.03751 | AE39: 56.043736 | AF39: 56.079899 | AG39: 56.113274 | AH39: 56.164932 | AI39: 56.197685 | AJ39: 56.227493 | AK39: 0.010823
A40: TKI000:ca_OnRoadNewVeh | B40: New Light Truck 4/ | C40: 28.17654 | D40: 28.57621 | E40: 29.362612 | F40: 30.6257 | G40: 32.636818 | H40: 34.45956 | I40: 36.077965 | J40: 37.708981 | K40: 39.618832 | L40: 39.709496 | M40: 39.731888 | N40: 39.700436 | O40: 39.652912 | P40: 39.600517 | Q40: 39.552765 | R40: 39.538483 | S40: 39.656025 | T40: 39.612507 | U40: 39.560276 | V40: 39.513908 | W40: 39.469017 | X40: 39.477066 | Y40: 39.453606 | Z40: 39.425179 | AA40: 39.526264 | AB40: 39.512119 | AC40: 39.481171 | AD40: 39.451141 | AE40: 39.554874 | AF40: 39.549133 | AG40: 39.541401 | AH40: 39.535969 | AI40: 39.531124 | AJ40: 39.535419 | AK40: 0.010196
A41: TKI000:ca_OnRoadNewCar | B41: On-Road New Light-Duty Vehicle 5/ | C41: 26.860435 | D41: 27.412979 | E41: 28.265438 | F41: 29.610132 | G41: 31.300692 | H41: 32.927387 | I41: 34.546352 | J41: 35.881912 | K41: 37.727074 | L41: 37.831051 | M41: 37.989754 | N41: 38.09668 | O41: 38.250278 | P41: 38.366863 | Q41: 38.507156 | R41: 38.671864 | S41: 38.86277 | T41: 38.978622 | U41: 39.081562 | V41: 39.182323 | W41: 39.252899 | X41: 39.351257 | Y41: 39.432819 | Z41: 39.504112 | AA41: 39.596188 | AB41: 39.645687 | AC41: 39.672047 | AD41: 39.67741 | AE41: 39.746174 | AF41: 39.761765 | AG41: 39.772858 | AH41: 39.796085 | AI41: 39.800686 | AJ41: 39.802731 | AK41: 0.011722
A42: TKI000:ca_OnRoadNewTwuk | B42: New Car 5/ | C42: 31.720737 | D42: 32.535744 | E42: 33.774448 | F42: 35.506138 | G42: 37.166248 | H42: 38.849072 | I42: 40.694695 | J42: 41.777779 | K42: 43.788078 | L42: 43.85461 | M42: 43.935276 | N42: 43.995106 | O42: 44.141506 | P42: 44.262238 | Q42: 44.429565 | R42: 44.620678 | S42: 44.785713 | T42: 44.944141 | U42: 45.093254 | V42: 45.23642 | W42: 45.345486 | X42: 45.452721 | Y42: 45.562599 | Z42: 45.658871 | AA42: 45.693539 | AB42: 45.730797 | AC42: 45.757156 | AD42: 45.761059 | AE42: 45.76614 | AF42: 45.795673 | AG42: 45.822926 | AH42: 45.865112 | AI42: 45.891857 | AJ42: 45.916199 | AK42: 0.010823
A43: TKI000:ca_Light-DutySto | B43: New Light Truck 5/ | C43: 22.973969 | D43: 23.299843 | E43: 23.941042 | F43: 24.970911 | G43: 26.610691 | H43: 28.09688 | I43: 29.416458 | J43: 30.746321 | K43: 32.303532 | L43: 32.377457 | M43: 32.395714 | N43: 32.370068 | O43: 32.331322 | P43: 32.288601 | Q43: 32.249664 | R43: 32.238018 | S43: 32.333858 | T43: 32.298374 | U43: 32.255791 | V43: 32.217983 | W43: 32.181381 | X43: 32.187943 | Y43: 32.168816 | Z43: 32.145638 | AA43: 32.228058 | AB43: 32.216526 | AC43: 32.191292 | AD43: 32.166805 | AE43: 32.251385 | AF43: 32.246704 | AG43: 32.240398 | AH43: 32.23597 | AI43: 32.232021 | AJ43: 32.235523 | AK43: 0.010196
... A46: TKI000:ca_FreightTruck | B46: Stock Commercial Light Truck 1/ | C46: 13.680938 | D46: 13.806588 | E46: 13.931844 | F46: 14.097829 | G46: 14.271951 | H46: 14.463296 | I46: 14.661203 | J46: 14.868921 | K46: 15.04772 | L46: 15.250485 | M46: 15.469141 | N46: 15.679131 | O46: 15.881999 | P46: 16.080351 | Q46: 16.25989 | R46: 16.421648 | S46: 16.55814 | T46: 16.673365 | U46: 16.775356 | V46: 16.865324 | W46: 16.940193 | X46: 17.005682 | Y46: 17.071365 | Z46: 17.127596 | AA46: 17.18157 | AB46: 17.229876 | AC46: 17.27033 | AD46: 17.306684 | AE46: 17.334562 | AF46: 17.348494 | AG46: 17.368992 | AH46: 17.406809 | AI46: 17.437517 | AJ46: 17.471701 | AK46: 0.007385
B47: Freight Truck | C47: 7.133016 | D47: 7.234839 | E47: 7.335194 | F47: 7.434534 | G47: 7.53856 | H47: 7.643671 | I47: 7.754342 | J47: 7.873028 | K47: 8.002402 | L47: 8.144583 | M47: 8.300921 | N47: 8.463225 | O47: 8.630606 | P47: 8.802323 | Q47: 8.97359 | R47: 9.139458 | S47: 9.299235 | T47: 9.442711 | U47: 9.568296 | V47: 9.682433 | W47: 9.784242 | X47: 9.877921 | Y47: 9.96206 | Z47: 10.051148 | AA47: 10.121845 | AB47: 10.185764 | AC47: 10.238789 | AD47: 10.28496 | AE47: 10.331643 | AF47: 10.376075 | AG47: 10.415617 | AH47: 10.453134 | AI47: 10.495623 | AJ47: 10.53261 | AK47: 0.011806
A48: TKI000:ca_Aircraft | B48: (seat miles per gallon)
B49: Aircraft | C49: 68.402603 | D49: 68.732193 | E49: 69.062111 | F49: 69.384827 | G49: 69.710152 | H49: 70.043472 | I49: 70.380814 | J49: 70.734665 | K49: 71.079346 | L49: 71.468315 | M49: 71.879921 | N49: 72.329201 | O49: 72.806061 | P49: 73.26902 | Q49: 73.724205 | R49: 74.190994 | S49: 74.669258 | T49: 75.136513 | U49: 75.61467 | V49: 76.099602 | W49: 76.587379 | X49: 77.079155 | Y49: 77.586296 | Z49: 78.09967 | AA49: 78.597786 | AB49: 79.095818 | AC49: 79.574516 | AD49: 80.036766 | AE49: 80.496498 | AF49: 80.955223 | AG49: 81.4114 | AH49: 81.874283 | AI49: 82.320076 | AJ49: 82.757706 | AK49: 0.00582
...

Sheet AEO 37
B1: ref2019.d111618a | C1: 2017 | D1: 2018 | E1: 2019 | F1: 2020 | G1: 2021 | H1: 2022 | I1: 2023 | J1: 2024 | K1: 2025 | L1: 2026 | M1: 2027 | N1: 2028 | O1: 2029 | P1: 2030 | Q1: 2031 | R1: 2032 | S1: 2033 | T1: 2034 | U1: 2035 | V1: 2036 | W1: 2037 | X1: 2038 | Y1: 2039 | Z1: 2040 | AA1: 2041 | AB1: 2042 | AC1: 2043 | AD1: 2044 | AE1: 2045 | AF1: 2046 | AG1: 2047 | AH1: 2048 | AI1: 2049 | AJ1: 2050
C3: Report | D3: Annual Energy Outlook 2019
C4: Scenario | D4: ref2019 | G4: Reference case
C5: Datekey | D5: d111618a
C6: Release Date | E6: January 2019
A10: TEF000 | B10: 37. Transportation Sector Energy Use by Fuel Type Within a Mode
B11: (trillion Btu)
AK12: 2018-
B13: Mode and Type | C13: 2017 | D13: 2018 | E13: 2019 | F13: 2020 | G13: 2021 | H13: 2022 | I13: 2023 | J13: 2024 | K13: 2025 | L13: 2026 | M13: 2027 | N13: 2028 | O13: 2029 | P13: 2030 | Q13: 2031 | R13: 2032 | S13: 2033 | T13: 2034 | U13: 2035 | V13: 2036 | W13: 2037 | X13: 2038 | Y13: 2039 | Z13: 2040 | AA13: 2041 | AB13: 2042 | AC13: 2043 | AD13: 2044 | AE13: 2045 | AF13: 2046 | AG13: 2047 | AH13: 2048 | AI13: 2049 | AJ13: 2050 | AK13: 2050
A15: TEF000:ba_Total | B15: Light-Duty Vehicle | C15: 15428.98 | D15: 15405.497 | E15: 15323.709 | F15: 15159.972 | G15: 14917.846 | H15: 14628.936 | I15: 14292.073 | J15: 13935.911 | K15: 13565.998 | L15: 13277.203 | M15: 13019.744 | N15: 12784.966 | O15: 12550.357 | P15: 12335.548 | Q15: 12134.971 | R15: 11949.124 | S15: 11778.061 | T15: 11621.788 | U15: 11477.596 | V15: 11370.867 | W15: 11287.215 | X15: 11223.201 | Y15: 11175.604 | Z15: 11142.942 | AA15: 11122.249 | AB15: 11112.763 | AC15: 11114.812 | AD15: 11125.955 | AE15: 11141.641 | AF15: 11164.967 | AG15: 11191.121 | AH15: 11216.115 | AI15: 11244.188 | AJ15: 11271.484 | AK15: -0.009717
A16: TEF000:ba_MotorGasoline | B16: Motor Gasoline excluding E85 1/ | C16: 15335.15 | D16: 15269.456 | E16: 15169.746 | F16: 14974.812 | G16: 14696.188 | H16: 14372.849 | I16: 14004.568 | J16: 13595.412 | K16: 13161.478 | L16: 12844.558 | M16: 12544.258 | N16: 12271.508 | O16: 11997.812 | P16: 11740.968 | Q16: 11512.418 | R16: 11302.258 | S16: 11104.021 | T16: 10915.162 | U16: 10746.73 | V16: 10612.404 | W16: 10502.844 | X16: 10416.009 | Y16: 10350.128 | Z16: 10299.68 | AA16: 10269.91 | AB16: 10251.455 | AC16: 10250.534 | AD16: 10253.911 | AE16: 10260.729 | AF16: 10292.284 | AG16: 10333.274 | AH16: 10360.222 | AI16: 10370.963 | AJ16: 10381.07 | AK16: -0.011986
A17: TEF000:ba_Ethanol | B17: E85 1/ | C17: 9.156984 | D17: 43.012703 | E17: 44.298954 | F17: 52.46595 | G17: 63.491283 | H17: 71.578003 | I17: 77.357468 | J17: 104.8816 | K17: 143.47879 | L17: 146.33054 | M17: 164.73543 | N17: 178.72351 | O17: 194.28662 | P17: 212.83853 | Q17: 217.02878 | R17: 218.70625 | S17: 224.12753 | T17: 235.0433 | U17: 238.4245 | V17: 244.75336 | W17: 249.60796 | X17: 251.68942 | Y17: 249.4218 | Z17: 246.1485 | AA17: 234.97339 | AB17: 224.71127 | AC17: 208.83667 | AD17: 198.04375 | AE17: 188.86974 | AF17: 162.43597 | AG17: 129.59372 | AH17: 109.98878 | AI17: 109.85819 | AJ17: 110.01675 | AK17: 0.029783
A18: TEF000:ba_Distillate(di | B18: Distillate Fuel Oil (diesel) | C18: 60.85392 | D18: 63.207066 | E18: 68.963806 | F18: 77.644913 | G18: 85.732368 | H18: 93.502289 | I18: 100.80137 | J18: 107.59821 | K18: 113.81428 | L18: 120.60284 | M18: 127.2694 | N18: 134.14171 | O18: 140.60814 | P18: 147.05969 | Q18: 153.66434 | R18: 159.30063 | S18: 164.19002 | T18: 168.79712 | U18: 172.64732 | V18: 176.17078 | W18: 179.40422 | X18: 182.19275 | Y18: 184.53606 | Z18: 187.16952 | AA18: 189.24709 | AB18: 190.37964 | AC18: 191.2065 | AD18: 191.81207 | AE18: 192.10318 | AF18: 192.42505 | AG18: 192.6785 | AH18: 192.67921 | AI18: 192.53387 | AJ18: 192.14185 | AK18: 0.035355
A19: TEF000:ba_CompressedNat | B19: Compressed/Liquefied Natural Gas | C19: 8.077009 | D19: 6.996272 | E19: 5.800754 | F19: 5.330829 | G19: 5.01966 | H19: 4.717643 | I19: 4.430637 | J19: 4.154118 | K19: 3.903601 | L19: 3.681341 | M19: 3.496768 | N19: 3.33005 | O19: 3.180697 | P19: 3.046438 | Q19: 2.936251 | R19: 2.852098 | S19: 2.782017 | T19: 2.743955 | U19: 2.715444 | V19: 2.698159 | W19: 2.68419 | X19: 2.679098 | Y19: 2.678147 | Z19: 2.679404 | AA19: 2.692208 | AB19: 2.707715 | AC19: 2.721627 | AD19: 2.735777 | AE19: 2.752394 | AF19: 2.769456 | AG19: 2.786568 | AH19: 2.804905 | AI19: 2.818092 | AJ19: 2.830572 | AK19: -0.027882
A20: TEF000:ba_LiquefiedPetr | B20: Propane | C20: 3.931244 | D20: 4.326501 | E20: 4.062418 | F20: 3.951213 | G20: 3.675384 | H20: 3.393915 | I20: 3.18454 | J20: 2.967552 | K20: 2.772993 | L20: 2.595296 | M20: 2.482469 | N20: 2.360416 | O20: 2.268101 | P20: 2.162544 | Q20: 2.067465 | R20: 2.005832 | S20: 1.952856 | T20: 1.926577 | U20: 1.90532 | V20: 1.898456 | W20: 1.891649 | X20: 1.898957 | Y20: 1.910733 | Z20: 1.925213 | AA20: 1.952184 | AB20: 1.989794 | AC20: 2.022425 | AD20: 2.056158 | AE20: 2.094924 | AF20: 2.138347 | AG20: 2.182739 | AH20: 2.232311 | AI20: 2.279563 | AJ20: 2.328814 | AK20: -0.01917
A21: TEF000:ba_Electricity | B21: Electricity | C21: 11.537136 | D21: 17.900618 | E21: 29.66337 | F21: 43.69154 | G21: 60.113934 | H21: 77.17585 | I21: 94.003891 | J21: 111.05218 | K21: 128.48337 | L21: 145.28534 | M21: 161.43393 | N21: 177.16246 | O21: 192.89389 | P21: 208.73148 | Q21: 224.82224 | R21: 240.96106 | S21: 257.17175 | T21: 273.62857 | U21: 290.11511 | V21: 307.36252 | W21: 324.78742 | X21: 342.39038 | Y21: 360.27219 | Z21: 378.38275 | AA21: 396.28464 | AB21: 414.11939 | AC21: 431.90869 | AD21: 449.65247 | AE21: 467.21533 | AF21: 484.91217 | AG21: 502.46365 | AH21: 519.88464 | AI21: 537.25446 | AJ21: 554.41638 | AK21: 0.11325
A22: TEF000:ba_LiquidHydroge | B22: Hydrogen | C22: 0.27376 | D22: 0.598766 | E22: 1.173962 | F22: 2.074811 | G22: 3.62372 | H22: 5.720049 | I22: 7.726999 | J22: 9.844712 | K22: 12.067842 | L22: 14.150493 | M22: 16.068527 | N22: 17.740499 | O22: 19.306999 | P22: 20.741417 | Q22: 22.034424 | R22: 23.0404 | S22: 23.813354 | T22: 24.48613 | U22: 25.056366 | V22: 25.579964 | W22: 25.995058 | X22: 26.341858 | Y22: 26.657215 | Z22: 26.95709 | AA22: 27.189186 | AB22: 27.399199 | AC22: 27.583216 | AD22: 27.742733 | AE22: 27.874962 | AF22: 28.002413 | AG22: 28.14126 | AH22: 28.302532 | AI22: 28.480495 | AJ22: 28.679655 | AK22: 0.128522
A24: TEF000:ca_CommercialLig | B24: Commercial Light Trucks 2/ | C24: 886.89825 | D24: 901.04919 | E24: 913.30731 | F24: 917.23218 | G24: 916.86462 | H24: 915.2868 | I24: 913.37457 | J24: 910.66724 | K24: 911.52051 | L24: 912.30298 | M24: 912.03674 | N24: 913.76532 | O24: 913.86469 | P24: 913.95062 | Q24: 916.18103 | R24: 919.2193 | S24: 923.73584 | T24: 929.93817 | U24: 937.46362 | V24: 945.92535 | W24: 955.72406 | X24: 966.26245 | Y24: 975.91791 | Z24: 985.93042 | AA24: 996.26337 | AB24: 1006.7398 | AC24: 1018.405 | AD24: 1030.9612 | AE24: 1044.9469 | AF24: 1059.7432 | AG24: 1074.549 | AH24: 1088.3407 | AI24: 1102.0864 | AJ24: 1115.8612 | AK24: 0.006704
A25: TEF000:clt_MotorGas | B25: Motor Gasoline excluding E85 1/ | C25: 606.36536 | D25: 605.30756 | E25: 607.94952 | F25: 604.1377 | G25: 596.90875 | H25: 589.81464 | I25: 582.98096 | J25: 571.22607 | K25: 558.56311 | L25: 555.41858 | M25: 547.30902 | N25: 541.48975 | O25: 534.28339 | P25: 526.78314 | Q25: 523.7121 | R25: 523.11548 | S25: 521.3371 | T25: 519.05609 | U25: 520.57098 | V25: 521.24829 | W25: 524.30823 | X25: 529.17877 | Y25: 536.13806 | Z25: 543.30438 | AA25: 554.95044 | AB25: 565.55859 | AC25: 579.68866 | AD25: 591.68262 | AE25: 603.7323 | AF25: 627.19488 | AG25: 656.53931 | AH25: 678.30609 | AI25: 686.05109 | AJ25: 693.75092 | AK25: 0.004271
A26: TEF000:clt_e85 | B26: E85 1/ | C26: 1.269456 | D26: 6.800088 | E26: 7.848506 | F26: 10.106414 | G26: 13.157337 | H26: 15.64352 | I26: 17.898479 | J26: 25.584816 | K26: 37.09631 | L26: 39.877831 | M26: 47.133904 | N26: 53.779694 | O26: 61.241974 | P26: 70.29538 | Q26: 74.829681 | R26: 79.007698 | S26: 84.767647 | T26: 93.049576 | U26: 98.679581 | V26: 105.63017 | W26: 112.19795 | X26: 117.53334 | Y26: 121.15105 | Z26: 124.08399 | AA26: 123.46315 | AB26: 123.15036 | AC26: 119.42245 | AD26: 118.49369 | AE26: 118.73388 | AF26: 107.51099 | AG26: 90.537163 | AH26: 81.026688 | AI26: 85.247459 | AJ26: 89.920685 | AK26: 0.084032
A27: TEF000:clt_Diesel | B27: Distillate Fuel Oil (diesel) | C27: 278.04269 | D27: 287.6564 | E27: 296.22836 | F27: 301.69147 | G27: 305.41623 | H27: 308.36707 | I27: 310.91235 | J27: 312.15439 | K27: 314.06976 | L27: 315.12363 | M27: 315.64606 | N27: 316.47168 | O27: 316.24033 | P27: 314.69565 | Q27: 315.3865 | R27: 314.75931 | S27: 315.19653 | T27: 315.28622 | U27: 315.54571 | V27: 316.2467 | W27: 316.27335 | X27: 316.45166 | Y27: 315.36044 | Z27: 315.10004 | AA27: 314.21469 | AB27: 314.19943 | AC27: 315.25479 | AD27: 316.50549 | AE27: 317.94644 | AF27: 320.25555 | AG27: 322.41006 | AH27: 323.64139 | AI27: 325.08737 | AJ27: 326.11346 | AK27: 0.003929
... A29: TEF000:clt_natural_gas | B29: Compressed/Liquefied Natural Gas | C29: 1.219097 | D29: 1.190767 | E29: 1.092497 | F29: 0.954232 | G29: 0.894892 | H29: 0.832107 | I29: 0.81816 | J29: 0.805134 | K29: 0.787249 | L29: 0.773612 | M29: 0.752692 | N29: 0.739955 | O29: 0.730588 | P29: 0.720062 | Q29: 0.713187 | R29: 0.708915 | S29: 0.717549 | T29: 0.734263 | U29: 0.759474 | V29: 0.791415 | W29: 0.829726 | X29: 0.877413 | Y29: 0.934525 | Z29: 0.998199 | AA29: 1.073186 | AB29: 1.155634 | AC29: 1.24983 | AD29: 1.368331 | AE29: 1.49507 | AF29: 1.610998 | AG29: 1.760768 | AH29: 1.920488 | AI29: 2.110897 | AJ29: 2.328216 | AK29: 0.021174
A30: TEF000:clt_electricity | B30: Electricity | C30: 0 | D30: 0 | E30: 0 | F30: 0.063651 | G30: 0.124021 | H30: 0.182401 | I30: 0.23847 | J30: 0.293579 | K30: 0.348081 | L30: 0.402068 | M30: 0.438809 | N30: 0.476974 | O30: 0.513499 | P30: 0.551586 | Q30: 0.58777 | R30: 0.625829 | S30: 0.664104 | T30: 0.704511 | U30: 0.745161 | V30: 0.787404 | W30: 0.831684 | X30: 0.875624 | Y30: 0.921643 | Z30: 0.966855 | AA30: 1.015562 | AB30: 1.063054 | AC30: 1.110935 | AD30: 1.162578 | AE30: 1.217335 | AF30: 1.273639 | AG30: 1.330102 | AH30: 1.391987 | AI30: 1.453642 | AJ30: 1.518894 | AK30: - -
A31: TEF000:clt_hydrogen | B31: Hydrogen | C31: 0 | D31: 0 | E31: 0 | F31: 0 | G31: 0 | H31: 0 | I31: 0 | J31: 0 | K31: 0 | L31: 0 | M31: 0 | N31: 0 | O31: 0 | P31: 0 | Q31: 0 | R31: 0 | S31: 0 | T31: 0 | U31: 0 | V31: 0 | W31: 0 | X31: 0 | Y31: 0 | Z31: 0 | AA31: 0 | AB31: 0 | AC31: 0 | AD31: 0 | AE31: 0 | AF31: 0 | AG31: 0 | AH31: 0 | AI31: 0 | AJ31: 0 | AK31: - -
A33: TEF000:da_Total | B33: Freight Trucks 3/ | C33: 5649.7139 | D33: 5725.2593 | E33: 5818.2104 | F33: 5830.04 | G33: 5814.6382 | H33: 5814.2666 | I33: 5813.0493 | J33: 5804.3057 | K33: 5792.9771 | L33: 5777.2124 | M33: 5741.1816 | N33: 5710.9766 | O33: 5669.7437 | P33: 5629.2808 | Q33: 5599.5835 | R33: 5569.5664 | S33: 5545.6562 | T33: 5537.8218 | U33: 5547.3721 | V33: 5561.834 | W33: 5587.002 | X33: 5616.1782 | Y33: 5643.7476 | Z33: 5665.542 | AA33: 5698.0361 | AB33: 5732.9048 | AC33: 5773.4688 | AD33: 5824.3999 | AE33: 5880.1401 | AF33: 5936.2446 | AG33: 5998.6572 | AH33: 6065.2212 | AI33: 6124.8315 | AJ33: 6190.8994 | AK33: 0.002447
A34: TEF000:da_MotorGasoline | B34: Motor Gasoline | C34: 524.6004 | D34: 526.05066 | E34: 531.52698 | F34: 534.25391 | G34: 536.1546 | H34: 538.6864 | I34: 542.30347 | J34: 545.79401 | K34: 547.48041 | L34: 552.80963 | M34: 555.23926 | N34: 559.45953 | O34: 565.21631 | P34: 567.23321 | Q34: 575.14087 | R34: 580.8081 | S34: 587.01581 | T34: 595.185 | U34: 604.73083 | V34: 615.77203 | W34: 626.92511 | X34: 641.21844 | Y34: 653.27844 | Z34: 668.64557 | AA34: 683.95618 | AB34: 700.56818 | AC34: 719.54102 | AD34: 737.58557 | AE34: 756.44464 | AF34: 780.32105 | AG34: 807.35449 | AH34: 832.86005 | AI34: 852.19983 | AJ34: 872.95386 | AK34: 0.015954
A35: TEF000:da_Distillate(di | B35: Distillate Fuel Oil (diesel) | C35: 5085.1343 | D35: 5153.1602 | E35: 5236.2329 | F35: 5242.0928 | G35: 5222.1313 | H35: 5216.7358 | I35: 5209.6865 | J35: 5193.999 | K35: 5176.458 | L35: 5153.0332 | M35: 5111.042 | N35: 5072.7847 | O35: 5021.7363 | P35: 4973.9824 | Q35: 4932.1289 | R35: 4891.77 | S35: 4855.564 | T35: 4831.9932 | U35: 4824.6523 | V35: 4819.5981 | W35: 4824.5913 | X35: 4829.9502 | Y35: 4835.8374 | Z35: 4831.5806 | AA35: 4838.6494 | AB35: 4845.7031 | AC35: 4856.3198 | AD35: 4875.8486 | AE35: 4897.5234 | AF35: 4917.9126 | AG35: 4942.8105 | AH35: 4969.4038 | AI35: 4989.3945 | AJ35: 5013.7705 | AK35: -0.000857
A36: TEF000:da_CompressedNat | B36: Compressed/Liquefied Natural Gas | C36: 38.148582 | D36: 41.969742 | E36: 45.182625 | F36: 47.002907 | G36: 48.040394 | H36: 48.9674 | I36: 49.663395 | J36: 50.090134 | K36: 50.380482 | L36: 50.671726 | M36: 50.900291 | N36: 51.443798 | O36: 52.070354 | P36: 53.034073 | Q36: 54.41201 | R36: 56.326271 | S36: 58.96563 | T36: 62.304535 | U36: 66.323441 | V36: 71.053864 | W36: 76.538681 | X36: 82.900162 | Y36: 90.034897 | Z36: 98.194077 | AA36: 107.21453 | AB36: 117.10681 | AC36: 128.00066 | AD36: 140.15523 | AE36: 153.60005 | AF36: 168.01939 | AG36: 183.19897 | AH36: 199.47244 | AI36: 216.06509 | AJ36: 233.0426 | AK36: 0.055032
A37: TEF000:da_LiquefiedPetr | B37: Propane | C37: 1.498156 | D37: 1.723063 | E37: 1.953256 | F37: 2.146609 | G37: 2.308614 | H37: 2.456173 | I37: 2.587135 | J37: 2.692057 | K37: 2.796156 | L37: 2.884792 | M37: 2.967321 | N37: 3.020453 | O37: 3.082369 | P37: 3.136817 | Q37: 3.175739 | R37: 3.251039 | S37: 3.326449 | T37: 3.408438 | U37: 3.512938 | V37: 3.628821 | W37: 3.759349 | X37: 3.904456 | Y37: 4.055053 | Z37: 4.221842 | AA37: 4.393282 | AB37: 4.570858 | AC37: 4.752207 | AD37: 4.947835 | AE37: 5.162933 | AF37: 5.388875 | AG37: 5.673164 | AH37: 5.882715 | AI37: 6.142014 | AJ37: 6.42971 | AK37: 0.042009
A38: TEF000:ft_eeeeeeeeeee85 | B38: E85 | C38: 0.3246 | D38: 1.628295 | E38: 1.872856 | F38: 2.416724 | G38: 3.209185 | H38: 3.917608 | I38: 4.594587 | J38: 6.818443 | K38: 10.255258 | L38: 11.512392 | M38: 14.055236 | N38: 16.588409 | O38: 19.274384 | P38: 22.838697 | Q38: 24.972017 | R38: 26.948196 | S38: 29.578747 | T38: 32.954845 | U38: 35.372707 | V38: 38.156052 | W38: 40.699623 | X38: 42.81509 | Y38: 44.225113 | Z38: 45.58128 | AA38: 45.490234 | AB38: 45.583302 | AC38: 44.42683 | AD38: 44.31554 | AE38: 44.65398 | AF38: 40.59256 | AG38: 34.289951 | AH38: 30.860264 | AI38: 32.801682 | AJ38: 34.905605 | AK38: 0.100522
A39: TEF000:ft_electricity | B39: Electricity | C39: 0.008046 | D39: 0.485918 | E39: 0.942142 | F39: 1.38731 | G39: 1.822418 | H39: 2.277648 | I39: 2.732923 | J39: 3.178591 | K39: 3.617856 | L39: 4.051343 | M39: 4.468708 | N39: 4.900696 | O39: 5.316817 | P39: 5.733423 | Q39: 6.151682 | R39: 6.574346 | S39: 7.017518 | T39: 7.477695 | U39: 7.960401 | V39: 8.470009 | W39: 8.990575 | X39: 9.533933 | Y39: 10.09076 | Z39: 10.693088 | AA39: 11.297967 | AB39: 11.913041 | AC39: 12.533807 | AD39: 13.190311 | AE39: 13.898199 | AF39: 14.634829 | AG39: 15.407668 | AH39: 16.235731 | AI39: 17.10915 | AJ39: 18.033409 | AK39: 0.11956
A40: TEF000:ft_hydrogen | B40: Hydrogen | C40: 0 | D40: 0.241363 | E40: 0.50012 | F40: 0.739795 | G40: 0.971506 | H40: 1.225471 | I40: 1.481001 | J40: 1.733284 | K40: 1.988616 | L40: 2.24914 | M40: 2.508825 | N40: 2.778879 | O40: 3.047051 | P40: 3.322155 | Q40: 3.602406 | R40: 3.888457 | S40: 4.187833 | T40: 4.498079 | U40: 4.81976 | V40: 5.155106 | W40: 5.497069 | X40: 5.856051 | Y40: 6.226105 | Z40: 6.626019 | AA40: 7.035265 | AB40: 7.459069 | AC40: 7.894515 | AD40: 8.357041 | AE40: 8.856513 | AF40: 9.375849 | AG40: 9.922225 | AH40: 10.505863 | AI40: 11.11958 | AJ40: 11.763825 | AK40: 0.129136
A43: TEF000:ea_Total | B43: Freight Rail 4/ | C43: 522.31348 | D43: 519.29571 | E43: 522.69519 | F43: 509.17395 | G43: 503.81244 | H43: 498.28558 | I43: 494.88437 | J43: 496.93982 | K43: 497.74182 | L43: 498.90024 | M43: 497.54709 | N43: 497.65418 | O43: 504.35425 | P43: 508.7308 | Q43: 506.71164 | R43: 504.3316 | S43: 504.46985 | T43: 501.50995 | U43: 501.86041 | V43: 502.84714 | W43: 502.67279 | X43: 503.47784 | Y43: 504.19418 | Z43: 504.51038 | AA43: 504.60919 | AB43: 504.09064 | AC43: 503.24023 | AD43: 503.68399 | AE43: 504.54095 | AF43: 504.20459 | AG43: 504.54315 | AH43: 505.44183 | AI43: 506.18845 | AJ43: 507.37259 | AK43: -0.000726
A44: TEF000:ea_Distillate(di | B44: Distillate Fuel Oil (diesel) | C44: 522.31348 | D44: 519.29571 | E44: 522.69519 | F44: 508.62906 | G44: 502.19608 | H44: 495.09235 | I44: 489.60803 | J44: 489.01086 | K44: 485.47165 | L44: 480.60495 | M44: 471.72385 | N44: 462.72113 | O44: 458.26724 | P44: 451.69775 | Q44: 439.62549 | R44: 427.54874 | S44: 417.86636 | T44: 405.88205 | U44: 396.84537 | V44: 388.50128 | W44: 379.45471 | X44: 371.34112 | Y44: 363.33615 | Z44: 355.22128 | AA44: 347.13797 | AB44: 338.82364 | AC44: 330.49014 | AD44: 323.1911 | AE44: 316.31207 | AF44: 308.8476 | AG44: 301.96307 | AH44: 295.55945 | AI44: 289.20377 | AJ44: 283.22842 | AK44: -0.018766
A45: TEF000:ea_ResidualOil | B45: Residual Fuel Oil | C45: 0 | D45: 0 | E45: 0 | F45: 0 | G45: 0 | H45: 0 | I45: 0 | J45: 0 | K45: 0 | L45: 0 | M45: 0 | N45: 0 | O45: 0 | P45: 0 | Q45: 0 | R45: 0 | S45: 0 | T45: 0 | U45: 0 | V45: 0 | W45: 0 | X45: 0 | Y45: 0 | Z45: 0 | AA45: 0 | AB45: 0 | AC45: 0 | AD45: 0 | AE45: 0 | AF45: 0 | AG45: 0 | AH45: 0 | AI45: 0 | AJ45: 0 | AK45: - -
A46: TEF000:ea_SeeEnGee | B46: Compressed Natural Gas | C46: 0 | D46: 0 | E46: 0 | F46: 0 | G46: 0 | H46: 0 | I46: 0 | J46: 0 | K46: 0 | L46: 0 | M46: 0 | N46: 0 | O46: 0 | P46: 0 | Q46: 0 | R46: 0 | S46: 0 | T46: 0 | U46: 0 | V46: 0 | W46: 0 | X46: 0 | Y46: 0 | Z46: 0 | AA46: 0 | AB46: 0 | AC46: 0 | AD46: 0 | AE46: 0 | AF46: 0 | AG46: 0 | AH46: 0 | AI46: 0 | AJ46: 0 | AK46: - -
A47: TEF000:ea_LiquidNG | B47: Liquefied Natural Gas | C47: 0 | D47: 0 | E47: 0 | F47: 0.544906 | G47: 1.616351 | H47: 3.193248 | I47: 5.27633 | J47: 7.928961 | K47: 12.270179 | L47: 18.2953 | M47: 25.823233 | N47: 34.933044 | O47: 46.087021 | P47: 57.033062 | Q47: 67.086143 | R47: 76.782883 | S47: 86.6035 | T47: 95.627899 | U47: 105.01504 | V47: 114.34585 | W47: 123.21808 | X47: 132.13673 | Y47: 140.85803 | Z47: 149.28909 | AA47: 157.47122 | AB47: 165.26701 | AC47: 172.75009 | AD47: 180.49289 | AE47: 188.22887 | AF47: 195.35698 | AG47: 202.58008 | AH47: 209.88238 | AI47: 216.98468 | AJ47: 224.14416 | AK47: - -
A49: TEF000:fa_Total | B49: Domestic Shipping | C49: 94.504654 | D49: 93.176033 | E49: 91.310684 | F49: 88.600655 | G49: 85.676697 | H49: 83.393082 | I49: 80.994202 | J49: 78.416794 | K49: 75.963287 | L49: 73.684006 | M49: 71.398972 | N49: 68.965057 | O49: 66.545532 | P49: 64.120544 | Q49: 62.829025 | R49: 61.462147 | S49: 60.181702 | T49: 58.948166 | U49: 57.776997 | V49: 56.567589 | W49: 55.52335 | X49: 54.441166 | Y49: 53.333256 | Z49: 52.192039 | AA49: 51.627144 | AB49: 51.063759 | AC49: 50.425755 | AD49: 49.870197 | AE49: 49.323185 | AF49: 48.837811 | AG49: 48.322044 | AH49: 47.877007 | AI49: 47.314251 | AJ49: 46.826477 | AK49: -0.021272
A50: TEF000:fa_Distillate(di | B50: Distillate Fuel Oil (diesel) | C50: 91.653206 | D50: 90.538925 | E50: 88.023674 | F50: 85.752136 | G50: 83.230179 | H50: 81.042969 | I50: 78.741394 | J50: 76.263206 | K50: 73.903214 | L50: 71.708344 | M50: 69.507538 | N50: 67.160042 | O50: 64.824844 | P50: 62.484051 | Q50: 61.24757 | R50: 59.936172 | S50: 58.708778 | T50: 57.525631 | U50: 56.401947 | V50: 55.237507 | W50: 54.235291 | X50: 53.197945 | Y50: 52.136215 | Z50: 51.012058 | AA50: 50.399712 | AB50: 49.786072 | AC50: 49.096878 | AD50: 48.484997 | AE50: 47.878189 | AF50: 47.327675 | AG50: 46.743977 | AH50: 46.224663 | AI50: 45.587563 | AJ50: 45.018429 | AK50: -0.021598
A51: TEF000:fa_ResidualOil | B51: Residual Oil | C51: 2.544341 | D51: 2.271792 | E51: 2.870655 | F51: 2.386124 | G51: 1.943896 | H51: 1.809858 | I51: 1.679463 | J51: 1.553509 | K51: 1.435882 | L51: 1.33319 | M51: 1.23104 | N51: 1.131057 | O51: 1.03578 | P51: 0.941132 | Q51: 0.86363 | R51: 0.788976 | S51: 0.716119 | T51: 0.647817 | U51: 0.583952 | V51: 0.528795 | W51: 0.472587 | X51: 0.410933 | Y51: 0.347049 | Z51: 0.29089 | AA51: 0.287727 | AB51: 0.284581 | AC51: 0.281012 | AD51: 0.277905 | AE51: 0.274842 | AF51: 0.272139 | AG51: 0.269256 | AH51: 0.266773 | AI51: 0.263622 | AJ51: 0.260896 | AK51: -0.065395
...

Sheet AEO 40
B1: ref2019.d111618a | C1: 2017 | D1: 2018 | E1: 2019 | F1: 2020 | G1: 2021 | H1: 2022 | I1: 2023 | J1: 2024 | K1: 2025 | L1: 2026 | M1: 2027 | N1: 2028 | O1: 2029 | P1: 2030 | Q1: 2031 | R1: 2032 | S1: 2033 | T1: 2034 | U1: 2035 | V1: 2036 | W1: 2037 | X1: 2038 | Y1: 2039 | Z1: 2040 | AA1: 2041 | AB1: 2042 | AC1: 2043 | AD1: 2044 | AE1: 2045 | AF1: 2046 | AG1: 2047 | AH1: 2048 | AI1: 2049 | AJ1: 2050
C3: Report | D3: Annual Energy Outlook 2019
C4: Scenario | D4: ref2019 | G4: Reference case
C5: Datekey | D5: d111618a
C6: Release Date | E6: January 2019
A10: TSK000 | B10: 40. Light-Duty Vehicle Stock by Technology Type
B11: (millions)
AK12: 2018-
B13: Technology Type | C13: 2017 | D13: 2018 | E13: 2019 | F13: 2020 | G13: 2021 | H13: 2022 | I13: 2023 | J13: 2024 | K13: 2025 | L13: 2026 | M13: 2027 | N13: 2028 | O13: 2029 | P13: 2030 | Q13: 2031 | R13: 2032 | S13: 2033 | T13: 2034 | U13: 2035 | V13: 2036 | W13: 2037 | X13: 2038 | Y13: 2039 | Z13: 2040 | AA13: 2041 | AB13: 2042 | AC13: 2043 | AD13: 2044 | AE13: 2045 | AF13: 2046 | AG13: 2047 | AH13: 2048 | AI13: 2049 | AJ13: 2050 | AK13: 2050
B15: Car Stock 1/
B16: Conventional Cars
A17: TSK000:ba_GasolineICEVe | B17: Gasoline ICE Vehicles | C17: 122.71139 | D17: 123.13561 | E17: 123.25343 | F17: 123.22289 | G17: 123.05553 | H17: 122.71806 | I17: 122.45892 | J17: 122.26625 | K17: 122.13725 | L17: 122.02596 | M17: 121.91326 | N17: 121.73737 | O17: 121.48992 | P17: 121.22288 | Q17: 121.01881 | R17: 120.82484 | S17: 120.67058 | T17: 120.57618 | U17: 120.54005 | V17: 120.56654 | W17: 120.67582 | X17: 120.89253 | Y17: 121.17606 | Z17: 121.52527 | AA17: 121.93285 | AB17: 122.37875 | AC17: 122.83848 | AD17: 123.32587 | AE17: 123.81905 | AF17: 124.2961 | AG17: 124.71469 | AH17: 125.05521 | AI17: 125.33985 | AJ17: 125.55564 | AK17: 0.000608
A18: TSK000:ba_TDIDieselICE | B18: TDI Diesel ICE | C18: 0.803633 | D18: 0.777678 | E18: 0.766264 | F18: 0.770079 | G18: 0.778114 | H18: 0.792951 | I18: 0.816763 | J18: 0.849333 | K18: 0.893797 | L18: 0.952299 | M18: 1.026648 | N18: 1.123837 | O18: 1.23531 | P18: 1.363965 | Q18: 1.498988 | R18: 1.636628 | S18: 1.771043 | T18: 1.910757 | U18: 2.043822 | V18: 2.168493 | W18: 2.287811 | X18: 2.399066 | Y18: 2.501343 | Z18: 2.594395 | AA18: 2.677506 | AB18: 2.748384 | AC18: 2.807142 | AD18: 2.85537 | AE18: 2.891941 | AF18: 2.920111 | AG18: 2.939851 | AH18: 2.950457 | AI18: 2.953688 | AJ18: 2.949322 | AK18: 0.042537
A19: TSK000:ba_TotalConventi | B19: Total Conventional Cars | C19: 123.51502 | D19: 123.91329 | E19: 124.01969 | F19: 123.99297 | G19: 123.83364 | H19: 123.51101 | I19: 123.27568 | J19: 123.11558 | K19: 123.03105 | L19: 122.97826 | M19: 122.93991 | N19: 122.86121 | O19: 122.72523 | P19: 122.58684 | Q19: 122.51779 | R19: 122.46146 | S19: 122.44162 | T19: 122.48694 | U19: 122.58387 | V19: 122.73503 | W19: 122.96363 | X19: 123.2916 | Y19: 123.67741 | Z19: 124.11967 | AA19: 124.61036 | AB19: 125.12713 | AC19: 125.64562 | AD19: 126.18124 | AE19: 126.71098 | AF19: 127.21622 | AG19: 127.65454 | AH19: 128.00566 | AI19: 128.29353 | AJ19: 128.50496 | AK19: 0.001138
B21: Alternative-Fuel Cars
A22: TSK000:ca_Ethanol-FlexF | B22: Ethanol-Flex Fuel ICE | C22: 4.813383 | D22: 4.927487 | E22: 5.0174 | F22: 5.086414 | G22: 5.130294 | H22: 5.146977 | I22: 5.139135 | J22: 5.10922 | K22: 5.056395 | L22: 4.980655 | M22: 4.887201 | N22: 4.788911 | O22: 4.689025 | P22: 4.60491 | Q22: 4.539237 | R22: 4.489612 | S22: 4.458049 | T22: 4.454955 | U22: 4.46902 | V22: 4.498343 | W22: 4.548336 | X22: 4.609901 | Y22: 4.674325 | Z22: 4.739589 | AA22: 4.797886 | AB22: 4.846465 | AC22: 4.880943 | AD22: 4.905231 | AE22: 4.919268 | AF22: 4.911937 | AG22: 4.890924 | AH22: 4.860886 | AI22: 4.825336 | AJ22: 4.78445 | AK22: -0.00092
A23: TSK000:ca_100mileEV | B23: 100 Mile Electric Vehicle | C23: 0.195882 | D23: 0.208961 | E23: 0.260034 | F23: 0.313793 | G23: 0.372325 | H23: 0.440716 | I23: 0.513588 | J23: 0.595387 | K23: 0.680871 | L23: 0.760109 | M23: 0.837168 | N23: 0.906489 | O23: 0.972457 | P23: 1.033574 | Q23: 1.092179 | R23: 1.143182 | S23: 1.191302 | T23: 1.236534 | U23: 1.278813 | V23: 1.317466 | W23: 1.351504 | X23: 1.382852 | Y23: 1.412077 | Z23: 1.439353 | AA23: 1.463613 | AB23: 1.486122 | AC23: 1.507143 | AD23: 1.527547 | AE23: 1.547346 | AF23: 1.566476 | AG23: 1.585167 | AH23: 1.604149 | AI23: 1.623101 | AJ23: 1.642135 | AK23: 0.066546
A24: TSK000:ca_ElectricVehic | B24: 200 Mile Electric Vehicle | C24: 0.134602 | D24: 0.1797 | E24: 0.346257 | F24: 0.556082 | G24: 0.776677 | H24: 1.003166 | I24: 1.249311 | J24: 1.523463 | K24: 1.820851 | L24: 2.114036 | M24: 2.406856 | N24: 2.700799 | O24: 3.004122 | P24: 3.305918 | Q24: 3.623039 | R24: 3.954119 | S24: 4.301428 | T24: 4.665046 | U24: 5.042279 | V24: 5.432127 | W24: 5.833308 | X24: 6.250597 | Y24: 6.684587 | Z24: 7.137063 | AA24: 7.591192 | AB24: 8.045319 | AC24: 8.497761 | AD24: 8.949951 | AE24: 9.400811 | AF24: 9.849263 | AG24: 10.290888 | AH24: 10.725594 | AI24: 11.15103 | AJ24: 11.564273 | AK24: 0.138985
A25: TSK000:ea_FuelCellGasol | B25: 300 Mile Electric Vehicle | C25: 0.03085 | D25: 0.166121 | E25: 0.382303 | F25: 0.664127 | G25: 1.020759 | H25: 1.3958 | I25: 1.793634 | J25: 2.201296 | K25: 2.613906 | L25: 3.02542 | M25: 3.444076 | N25: 3.875262 | O25: 4.321768 | P25: 4.798095 | Q25: 5.305131 | R25: 5.836092 | S25: 6.386522 | T25: 6.950972 | U25: 7.521293 | V25: 8.09045 | W25: 8.655412 | X25: 9.212337 | Y25: 9.756588 | Z25: 10.286201 | AA25: 10.80535 | AB25: 11.314354 | AC25: 11.817442 | AD25: 12.315123 | AE25: 12.804375 | AF25: 13.284403 | AG25: 13.750421 | AH25: 14.200466 | AI25: 14.636414 | AJ25: 15.054511 | AK25: 0.151235
A26: TSK000:ca_Plug-inGasoli | B26: Plug-in 10 Gasoline Hybrid | C26: 0.166916 | D26: 0.194989 | E26: 0.225908 | F26: 0.261096 | G26: 0.311727 | H26: 0.370292 | I26: 0.432608 | J26: 0.498413 | K26: 0.568857 | L26: 0.63855 | M26: 0.707152 | N26: 0.773436 | O26: 0.836693 | P26: 0.896938 | Q26: 0.954492 | R26: 1.009833 | S26: 1.062623 | T26: 1.113106 | U26: 1.160533 | V26: 1.205132 | W26: 1.246999 | X26: 1.284144 | Y26: 1.318235 | Z26: 1.349379 | AA26: 1.377192 | AB26: 1.401889 | AC26: 1.423813 | AD26: 1.443546 | AE26: 1.46105 | AF26: 1.476283 | AG26: 1.489851 | AH26: 1.502311 | AI26: 1.513587 | AJ26: 1.524038 | AK26: 0.066365
A27: TSK000:ca_Plug-in40Hybd | B27: Plug-in 40 Gasoline Hybrid | C27: 0.157999 | D27: 0.264722 | E27: 0.376923 | F27: 0.493695 | G27: 0.601855 | H27: 0.699711 | I27: 0.792376 | J27: 0.88319 | K27: 0.969069 | L27: 1.054026 | M27: 1.140216 | N27: 1.227819 | O27: 1.322794 | P27: 1.419631 | Q27: 1.517574 | R27: 1.615744 | S27: 1.712074 | T27: 1.807249 | U27: 1.900304 | V27: 1.993035 | W27: 2.085741 | X27: 2.179276 | Y27: 2.273645 | Z27: 2.369363 | AA27: 2.463845 | AB27: 2.557444 | AC27: 2.649464 | AD27: 2.739549 | AE27: 2.826879 | AF27: 2.910505 | AG27: 2.989496 | AH27: 3.064125 | AI27: 3.133706 | AJ27: 3.198083 | AK27: 0.080975
A28: TSK000:ca_Electric-Dies | B28: Electric-Diesel Hybrid | C28: 0 | D28: 0 | E28: 0 | F28: 0 | G28: 0 | H28: 0 | I28: 0 | J28: 0 | K28: 0 | L28: 0 | M28: 0 | N28: 0 | O28: 0 | P28: 0.001106 | Q28: 0.006045 | R28: 0.014296 | S28: 0.024435 | T28: 0.035563 | U28: 0.047097 | V28: 0.058716 | W28: 0.070455 | X28: 0.08217 | Y28: 0.093822 | Z28: 0.105484 | AA28: 0.117164 | AB28: 0.128677 | AC28: 0.139957 | AD28: 0.15096 | AE28: 0.161474 | AF28: 0.171426 | AG28: 0.180641 | AH28: 0.188912 | AI28: 0.196291 | AJ28: 0.202719 | AK28: - -
A29: TSK000:ca_Electric-Gaso | B29: Electric-Gasoline Hybrid | C29: 3.706463 | D29: 4.135645 | E29: 4.549326 | F29: 4.944612 | G29: 5.317537 | H29: 5.665772 | I29: 6.013466 | J29: 6.364937 | K29: 6.703647 | L29: 7.046333 | M29: 7.395318 | N29: 7.749272 | O29: 8.110472 | P29: 8.47981 | Q29: 8.859372 | R29: 9.236145 | S29: 9.608261 | T29: 9.971205 | U29: 10.323838 | V29: 10.665428 | W29: 10.998904 | X29: 11.323565 | Y29: 11.633993 | Z29: 11.931743 | AA29: 12.21639 | AB29: 12.484378 | AC29: 12.734292 | AD29: 12.967894 | AE29: 13.183614 | AF29: 13.379957 | AG29: 13.55348 | AH29: 13.70423 | AI29: 13.834745 | AJ29: 13.944232 | AK29: 0.038713
A30: TSK000:ca_CompressedNat | B30: Natural Gas ICE | C30: 0.029741 | D30: 0.024521 | E30: 0.019041 | F30: 0.017268 | G30: 0.01633 | H30: 0.015496 | I30: 0.014768 | J30: 0.014121 | K30: 0.013533 | L30: 0.013041 | M30: 0.012605 | N30: 0.012236 | O30: 0.011926 | P30: 0.011697 | Q30: 0.011563 | R30: 0.01148 | S30: 0.011457 | T30: 0.011497 | U30: 0.011577 | V30: 0.011685 | W30: 0.011779 | X30: 0.011888 | Y30: 0.012001 | Z30: 0.012114 | AA30: 0.01227 | AB30: 0.012376 | AC30: 0.012532 | AD30: 0.012681 | AE30: 0.012822 | AF30: 0.012952 | AG30: 0.01307 | AH30: 0.013175 | AI30: 0.013271 | AJ30: 0.013357 | AK30: -0.018804
A31: TSK000:da_CompressedNat | B31: Natural Gas Bi-fuel | C31: 0.048749 | D31: 0.047325 | E31: 0.046074 | F31: 0.044931 | G31: 0.043953 | H31: 0.043008 | I31: 0.042172 | J31: 0.041302 | K31: 0.040327 | L31: 0.039335 | M31: 0.038347 | N31: 0.037448 | O31: 0.036694 | P31: 0.036111 | Q31: 0.03575 | R31: 0.035506 | S31: 0.035422 | T31: 0.0355 | U31: 0.035655 | V31: 0.03586 | W31: 0.036056 | X31: 0.036274 | Y31: 0.036511 | Z31: 0.036762 | AA31: 0.03711 | AB31: 0.037473 | AC31: 0.037821 | AD31: 0.038169 | AE31: 0.038505 | AF31: 0.038822 | AG31: 0.039101 | AH31: 0.03934 | AI31: 0.039555 | AJ31: 0.039738 | AK31: -0.005445
A32: TSK000:da_LiquefiedPetr | B32: Propane ICE | C32: 0.004394 | D32: 0.00445 | E32: 0.004533 | F32: 0.004636 | G32: 0.004761 | H32: 0.004867 | I32: 0.004983 | J32: 0.005108 | K32: 0.005233 | L32: 0.005365 | M32: 0.005504 | N32: 0.005646 | O32: 0.005792 | P32: 0.005943 | Q32: 0.006101 | R32: 0.006253 | S32: 0.006407 | T32: 0.006562 | U32: 0.006711 | V32: 0.006855 | W32: 0.006998 | X32: 0.007137 | Y32: 0.007276 | Z32: 0.007419 | AA32: 0.007529 | AB32: 0.007673 | AC32: 0.007825 | AD32: 0.007982 | AE32: 0.008141 | AF32: 0.008301 | AG32: 0.00846 | AH32: 0.008615 | AI32: 0.008772 | AJ32: 0.008927 | AK32: 0.021997
A33: TSK000:ea_LiquefiedPetr | B33: Propane Bi-fuel | C33: 0.008613 | D33: 0.008585 | E33: 0.008586 | F33: 0.008629 | G33: 0.008718 | H33: 0.008786 | I33: 0.008874 | J33: 0.008972 | K33: 0.009068 | L33: 0.00917 | M33: 0.009277 | N33: 0.009386 | O33: 0.009503 | P33: 0.009624 | Q33: 0.00976 | R33: 0.009892 | S33: 0.010033 | T33: 0.010184 | U33: 0.010331 | V33: 0.010471 | W33: 0.010604 | X33: 0.010731 | Y33: 0.010855 | Z33: 0.01098 | AA33: 0.011036 | AB33: 0.011147 | AC33: 0.011264 | AD33: 0.011381 | AE33: 0.011495 | AF33: 0.011603 | AG33: 0.011702 | AH33: 0.011789 | AI33: 0.011869 | AJ33: 0.01194 | AK33: 0.010362
A34: TSK000:ea_FuelCellMetha | B34: Fuel Cell Methanol | C34: 0 | D34: 0 | E34: 0 | F34: 0 | G34: 0 | H34: 0 | I34: 0 | J34: 0 | K34: 0 | L34: 0 | M34: 0 | N34: 0 | O34: 0 | P34: 0 | Q34: 0 | R34: 0 | S34: 0 | T34: 0 | U34: 0 | V34: 0 | W34: 0 | X34: 0 | Y34: 0 | Z34: 0 | AA34: 0 | AB34: 0 | AC34: 0 | AD34: 0 | AE34: 0 | AF34: 0 | AG34: 0 | AH34: 0 | AI34: 0 | AJ34: 0 | AK34: - -
A35: TSK000:ea_FuelCellHydro | B35: Fuel Cell Hydrogen | C35: 0.00282 | D35: 0.005543 | E35: 0.010657 | F35: 0.019237 | G35: 0.034423 | H35: 0.056417 | I35: 0.079184 | J35: 0.104646 | K35: 0.132151 | L35: 0.159071 | M35: 0.185275 | N35: 0.209316 | O35: 0.232766 | P35: 0.255124 | Q35: 0.276566 | R35: 0.294879 | S35: 0.311813 | T35: 0.327609 | U35: 0.342043 | V35: 0.355095 | W35: 0.365934 | X35: 0.375168 | Y35: 0.38295 | Z35: 0.389479 | AA35: 0.394693 | AB35: 0.398869 | AC35: 0.402282 | AD35: 0.405169 | AE35: 0.407599 | AF35: 0.409628 | AG35: 0.411494 | AH35: 0.4135 | AI35: 0.415589 | AJ35: 0.417831 | AK35: 0.144627
A36: TSK000:ea_TotalAlternat | B36: Total Alternative Cars | C36: 9.300412 | D36: 10.168049 | E36: 11.247043 | F36: 12.414519 | G36: 13.639361 | H36: 14.851009 | I36: 16.084099 | J36: 17.350054 | K36: 18.613907 | L36: 19.84511 | M36: 21.068996 | N36: 22.296021 | O36: 23.55401 | P36: 24.858482 | Q36: 26.236809 | R36: 27.65703 | S36: 29.119825 | T36: 30.625978 | U36: 32.149498 | V36: 33.680664 | W36: 35.222031 | X36: 36.766041 | Y36: 38.296867 | Z36: 39.81493 | AA36: 41.295269 | AB36: 42.732185 | AC36: 44.12254 | AD36: 45.475185 | AE36: 46.783379 | AF36: 48.031551 | AG36: 49.214695 | AH36: 50.337093 | AI36: 51.403259 | AJ36: 52.406235 | AK36: 0.052579
A38: TSK000:fa_TotalNewCarSa | B38: Total Car Stock | C38: 132.81543 | D38: 134.08134 | E38: 135.26674 | F38: 136.40749 | G38: 137.47301 | H38: 138.36202 | I38: 139.35977 | J38: 140.46564 | K38: 141.64496 | L38: 142.82338 | M38: 144.00891 | N38: 145.15723 | O38: 146.27925 | P38: 147.44533 | Q38: 148.75461 | R38: 150.1185 | S38: 151.56145 | T38: 153.11291 | U38: 154.73337 | V38: 156.41569 | W38: 158.18567 | X38: 160.05763 | Y38: 161.97427 | Z38: 163.9346 | AA38: 165.90562 | AB38: 167.85931 | AC38: 169.76816 | AD38: 171.65643 | AE38: 173.49435 | AF38: 175.24777 | AG38: 176.86923 | AH38: 178.34276 | AI38: 179.69679 | AJ38: 180.91119 | AK38: 0.009405
B40: Light Truck Stock 1/
B41: Conventional Light Trucks
A42: TSK000:ga_GasolineICEVe | B42: Gasoline ICE Vehicles | C42: 105.13951 | D42: 105.25349 | E42: 105.41277 | F42: 105.55881 | G42: 105.75748 | H42: 105.86691 | I42: 106.05436 | J42: 106.25108 | K42: 106.37717 | L42: 106.48899 | M42: 106.44029 | N42: 106.24216 | O42: 105.84392 | P42: 105.32433 | Q42: 104.76894 | R42: 104.12988 | S42: 103.45435 | T42: 102.71626 | U42: 101.89417 | V42: 100.99657 | W42: 100.06853 | X42: 99.134407 | Y42: 98.203331 | Z42: 97.292336 | AA42: 96.440727 | AB42: 95.633842 | AC42: 94.880959 | AD42: 94.20182 | AE42: 93.576584 | AF42: 93.036606 | AG42: 92.53817 | AH42: 92.052879 | AI42: 91.603561 | AJ42: 91.180695 | AK42: -0.004475
A43: TSK000:ga_TDIDieselICE | B43: TDI Diesel ICE | C43: 0.429247 | D43: 0.494202 | E43: 0.61249 | F43: 0.777353 | G43: 0.943354 | H43: 1.108745 | I43: 1.274453 | J43: 1.436772 | K43: 1.594936 | L43: 1.745153 | M43: 1.879648 | N43: 2.000192 | O43: 2.104411 | P43: 2.194759 | Q43: 2.274534 | R43: 2.339217 | S43: 2.389884 | T43: 2.42916 | U43: 2.456599 | V43: 2.473171 | W43: 2.482533 | X43: 2.484463 | Y43: 2.479049 | Z43: 2.467787 | AA43: 2.452773 | AB43: 2.433501 | AC43: 2.411256 | AD43: 2.388016 | AE43: 2.363396 | AF43: 2.340392 | AG43: 2.318142 | AH43: 2.295082 | AI43: 2.271864 | AJ43: 2.248193 | AK43: 0.04848
A44: TSK000:ga_TotalConventi | B44: Total Conventional Light Trucks | C44: 105.56876 | D44: 105.7477 | E44: 106.02526 | F44: 106.33616 | G44: 106.70083 | H44: 106.97566 | I44: 107.32881 | J44: 107.68786 | K44: 107.97211 | L44: 108.23415 | M44: 108.31994 | N44: 108.24236 | O44: 107.94833 | P44: 107.51909 | Q44: 107.04347 | R44: 106.4691 | S44: 105.84424 | T44: 105.14542 | U44: 104.35077 | V44: 103.46974 | W44: 102.55106 | X44: 101.61887 | Y44: 100.68238 | Z44: 99.760124 | AA44: 98.893501 | AB44: 98.067345 | AC44: 97.292213 | AD44: 96.589836 | AE44: 95.93998 | AF44: 95.376999 | AG44: 94.856316 | AH44: 94.347961 | AI44: 93.875427 | AJ44: 93.428886 | AK44: -0.003863
B46: Alternative-Fuel Light Trucks
