Workbook
Name _1_year: #REF!
Name _1_yr_after_compl_yr: #REF!
Name _1_yr_after_compl_yr0: #REF!
Name _1_yr_before_compl_yr: #REF!
Name _2_year: #REF!
Name _2_year_after_compl_yr: #REF!
Name _2_years: #REF!
Name _2_yrs_before_compl_yr: #REF!
Name _20_years: #REF!
Name _22_years: #REF!
Name _25_years: #REF!
Name _3_years: #REF!
Name _3_yrs_before_compl_yr: #REF!
Name _30_years: #REF!
Name _5_years: #REF!
Name _5_yrs_after_compl_yr: #REF!
Name analysis_year: #REF!
Name Bucket: #REF!
Name capital_20_for_ipm: #REF!
Name capital_22_for_ipm: #REF!
Name capital_25_for_ipm: #REF!
Name capital_30_for_ipm: #REF!
Name capital_ct_30_for_ipm: #REF!
Name ck_310_Tm_master2: #REF!
Name ck_310_Tm_master2_ICF: #REF!
Name compl_yr: #REF!
Name compl_yr_for_ipm: #REF!
Name compliance_year_1: #REF!
Name compliance_year_2: #REF!
Name compliance_year_3: #REF!
Name compliance_year_4: #REF!
Name compliance_year_5: #REF!
Name compliance_year_6: #REF!
Name compliance_year_7: #REF!
Name compliance_year_8: #REF!
Name compliance_year_9: #REF!
Name ct_icr: #REF!
Name DeliverabilityOptions: [1]Lists!#REF!
Name discount_rate: #REF!
Name downtime_for_ipm: #REF!
Name dq_stq_facility_costs: #REF!
Name EndMonth: #REF!
Name F860_COOLING_STATUS: #REF!
Name F860_NOXCONTROL: #REF!
Name fom_for_ipm: #REF!
Name icr_costs: #REF!
Name InputUnitList: #REF!
Name IQ_CH: 110000
Name IQ_CQ: 5000
Name IQ_CY: 10000
Name IQ_DAILY: 500000
Name IQ_FH: 100000
Name IQ_FQ: 500
Name IQ_FY: 1000
Name IQ_LTM: 2000
Name IQ_MONTH: 15000
Name IQ_NTM: 6000
Name IQ_WEEK: 50000
Name IQ_YTD: 3000
Name ListCommandControVaryingDegrees: #REF!

Sheet About
A1: MCF Maximum Capacity Factor
A3: Source: | B3: Coal Adjustment
B4: The Myth of the 24/7/365 Power Plant
B5: 2019
B6: National Resources Defense Council
B7: https://www.nrdc.org/bio/rachel-fakhry/myth-247365-power-plant
B9: EPA 111 Rules
B10: EPA
B11: Analaysis of the Final Greenhouse Gas Standards and Guidelines
B12: 2024
B13: Final Rule Sens Vehicle Rules MATS and ELG (zip)
B14: Final Rule Sens Vehicle Rules MATS and ELG SSR.xlsx
A16: Notes
A17: This represents the maximum capacity factor a plant type can achieve
A18: in any given hour. This is used for non-variable plant types, including hydro. We apply
A19: a 5% penalty to represent that plants are not typically available 100% of the
A20: year due to factors like plant maintenance, based on the value for gas plants
A21: in the NRDC source above.
A23: For coal, we apply a 15% penalty based on NRDC starting in 2021. We also adjust the
A24: maximum capacity factor after 2028 based on EPA's projected impacts of their 111
A25: Rules for existing coal plants.

Sheet EPA Rules Summary
A2: EPA IPM Summary Run Results
A4: Projections for Continental U.S.
C6: Final Rule Sens Vehicle Rules MATS and ELG
A9: All costs and prices are in 2022-year dollars | C9: Values in red are rounded to zero, not equal to zero
A10: NATIONWIDE EMISSIONS | C10: 2028 | D10: 2030 | E10: 2035 | F10: 2040 | G10: 2045 | H10: 2050 | I10: 2055
A11: SO2 (million tons) | C11: 0.38178204 | D11: 0.2877666 | E11: 0.15008062 | F11: 0.13375077 | G11: 0.0136601 | H11: 0.016605887 | I11: 0.01703559
A12: NOx (million tons) | C12: 0.41680328 | D12: 0.34966976 | E12: 0.21915307 | F12: 0.17104618 | G12: 0.086862064 | H12: 0.10890104 | I12: 0.11869103
A13: CO2 (million metric tons) | C13: 1075.7036 | D13: 1007.938 | E13: 652.29001 | F13: 440.68979 | G13: 289.83436 | H13: 413.78669 | I13: 475.62131
A14: Hg (tons) | C14: 2.3622842 | D14: 2.190447 | E14: 1.8558747 | F14: 1.7549231 | G14: 1.2599124 | H14: 1.2566786 | I14: 1.2690883
A15: HCL (Mtons) | C15: 2.1144118 | D15: 1.7733223 | E15: 1.161718 | F15: 1.0492678 | G15: 0.096565891 | H15: 0.11699042 | I15: 0.11715545
A17: TOTAL COSTS | C17: 2028 | D17: 2030 | E17: 2035 | F17: 2040 | G17: 2045 | H17: 2050 | I17: 2055
A18: Total Costs (billion $) | C18: 132.75369 | D18: 141.08153 | E18: 155.02027 | F18: 160.85825 | G18: 178.0532 | H18: 190.13077 | I18: 209.2489
A20: PRICES | C20: 2028 | D20: 2030 | E20: 2035 | F20: 2040 | G20: 2045 | H20: 2050 | I20: 2055
A21: National Wholesale Electricity Price (mills/kWh) | C21: 35.598189 | D21: 39.985036 | E21: 39.047732 | F21: 33.919317 | G21: 28.962111 | H21: 39.068346 | I21: 42.898249
A22: Natural Gas Prices (2022 $/MMBtu)
A23: Henry Hub | C23: 3.0610044 | D23: 3.2856843 | E23: 3.5237571 | F23: 3.2990909 | G23: 3.4962832 | H23: 4.2861253 | I23: 4.7051272
A24: Delivered | C24: 3.1353645 | D24: 3.3594684 | E24: 3.545301 | F24: 3.2673407 | G24: 3.4817099 | H24: 4.278484 | I24: 4.6999493
A25: Minemouth Coal Prices (2022 $/MMBtu)
A26: Appalachia | C26: 1.4549263 | D26: 1.4772264 | E26: 1.4863063 | F26: 1.5516406 | G26: 2.2655175 | H26: 2.3980142 | I26: 2.3977365
A27: Imports | C27: 4.729026 | D27: 4.4503375 | E27: 4.3027965
A28: Interior | C28: 1.518363 | D28: 1.5722408 | E28: 1.7297247 | F28: 1.7859779 | G28: 1.8652331 | H28: 1.981953 | I28: 2.0035881
A29: Waste Coal | C29: 0.54324641 | D29: 0.81628239 | E29: 0.38324153 | F29: 2.0167941
A30: West | C30: 0.85137439 | D30: 0.91585383 | E30: 0.99292377 | F30: 1.0415212 | G30: 1.4784636 | H30: 1.2613479 | I30: 1.2721753
A31: National | C31: 1.0780782 | D31: 1.1725092 | E31: 1.2457788 | F31: 1.3783975 | G31: 1.6974458 | H31: 1.6369371 | I31: 1.649027
A33: TOTAL CAPACITY (Cumulative GW) | C33: 2028 | D33: 2030 | E33: 2035 | F33: 2040 | G33: 2045 | H33: 2050 | I33: 2055
A34: Hydro | C34: 102.4067 | D34: 104.50799 | E34: 108.14516 | F34: 111.82621 | G34: 112.26044 | H34: 112.26044 | I34: 112.26053
A35: Non-Hydro Renewables | C35: 428.53412 | D35: 477.61208 | E35: 738.0805 | F35: 1032.3573 | G35: 1366.2569 | H35: 1400.5869 | I35: 1492.857
A36: Biomass | C36: 0.2029 | D36: 0.2029 | E36: 0.1909 | F36: 0.1444 | G36: 0.1444 | H36: 0.1444 | I36: 0.1444
A37: Geothermal | C37: 3.21123 | D37: 3.21123 | E37: 3.21123 | F37: 3.21123 | G37: 3.28528 | H37: 3.28528 | I37: 3.28528
A38: Landfill Gas | C38: 3.1949 | D38: 3.1949 | E38: 3.0753 | F38: 3.0753 | G38: 3.0753 | H38: 4.6099926 | I38: 5.5548314
A39: Solar | C39: 184.19787 | D39: 187.34955 | E39: 303.75831 | F39: 366.91604 | G39: 540.26025 | H39: 565.94633 | I39: 604.50262
A40: Wind | C40: 237.72723 | D40: 283.6535 | E40: 427.84476 | F40: 659.01037 | G40: 819.49171 | H40: 826.60092 | I40: 879.36986
A41: Distributed Solar PV | C41: 81.438517 | D41: 92.295531 | E41: 120.51016 | F41: 151.53083 | G41: 185.35586 | H41: 223.72962 | I41: 273.9191
A42: Coal | C42: 92.528817 | D42: 63.354547 | E42: 20.016061 | F42: 18.614682 | G42: 0.91530777 | H42: 0.86830777 | I42: 0.86830777
... A140: Coal Use by Region (million tons) | C140: 77 | D140: 69.32 | E140: 66.23 | F140: 72.33 | G140: 69.83 | H140: 71.35 | I140: 70.78
A141: Power Sector
A142: Appalachia | C142: 29.145252 | D142: 31.767572 | E142: 18.949828 | F142: 18.882657
A143: Imports | C143: 0.16993139 | D143: 0.28574277 | E143: 0.0025662488
A144: Interior | C144: 32.529949 | D144: 32.335263 | E144: 25.094811 | F144: 25.052311 | G144: 0.68421884 | H144: 1.3092279 | I144: 1.3092279
A145: Waste Coal | C145: 7.2701941 | D145: 7.1457381 | E145: 3.1731807 | F145: 3.1731807
...

Sheet Coal Calculations
B1: 2028 | C1: 2030 | D1: 2035 | E1: 2040 | F1: 2045 | G1: 2050 | H1: 2055
A2: Coal without CCS Capacity Factor | B2: ='EPA Rules Summary'!C126/('EPA Rules Summary'!C43*8760)*1000 -> 0.49275096 | C2: ='EPA Rules Summary'!D126/('EPA Rules Summary'!D43*8760)*1000 -> 0.57968103 | D2: ='EPA Rules Summary'!E126/('EPA Rules Summary'!E43*8760)*1000 -> 0.62013312 | E2: ='EPA Rules Summary'!F126/('EPA Rules Summary'!F43*8760)*1000 -> 0.13938017 | F2: ='EPA Rules Summary'!G126/('EPA Rules Summary'!G43*8760)*1000 -> 0.11205077 | G2: ='EPA Rules Summary'!H126/('EPA Rules Summary'!H43*8760)*1000 -> 0.37726502 | H2: ='EPA Rules Summary'!I126/('EPA Rules Summary'!I43*8760)*1000 -> 0.42851499
A3: Coal with CCS Capacity Factor | B3: ='EPA Rules Summary'!C128/('EPA Rules Summary'!C45*8760)*1000 -> #DIV/0! | C3: ='EPA Rules Summary'!D128/('EPA Rules Summary'!D45*8760)*1000 -> 0.78338388 | D3: ='EPA Rules Summary'!E128/('EPA Rules Summary'!E45*8760)*1000 -> 0.78909278 | E3: ='EPA Rules Summary'!F128/('EPA Rules Summary'!F45*8760)*1000 -> 0.78958745 | F3: ='EPA Rules Summary'!G128/('EPA Rules Summary'!G45*8760)*1000 -> 0.61923506 | G3: ='EPA Rules Summary'!H128/('EPA Rules Summary'!H45*8760)*1000 -> 0.72106646 | H3: ='EPA Rules Summary'!I128/('EPA Rules Summary'!I45*8760)*1000 -> 0.72106646
A5: Adjusted for RAF
A6: Coal without CCS Capacity Factor | B6: =MIN(0.85,B2/'RAF-generation'!I4) -> 0.85 | C6: =MIN(0.85,C2/'RAF-generation'!J4) -> 0.85 | D6: =MIN(0.85,D2/'RAF-generation'!K4) -> 0.85 | E6: =MIN(0.85,E2/'RAF-generation'!L4) -> 0.20156329 | F6: =MIN(0.85,F2/'RAF-generation'!M4) -> 0.15984099 | G6: =MIN(0.85,G2/'RAF-generation'!N4) -> 0.53096126 | H6: =MIN(0.85,H2/'RAF-generation'!O4) -> 0.59511819
A8: Extrapolated | B8: 2021 | C8: 2022 | D8: 2023 | E8: 2024 | F8: 2025 | G8: 2026 | H8: 2027 | I8: 2028 | J8: 2029 | K8: 2030 | L8: 2031 | M8: 2032 | N8: 2033 | O8: 2034 | P8: 2035 | Q8: 2036 | R8: 2037 | S8: 2038 | T8: 2039 | U8: 2040 | V8: 2041 | W8: 2042 | X8: 2043 | Y8: 2044 | Z8: 2045 | AA8: 2046 | AB8: 2047 | AC8: 2048 | AD8: 2049 | AE8: 2050
A9: Coal without CCS Capacity Factor | B9: {=TREND($B$6:$C$6,$B$1:$C$1,B8)} -> 0.85 | C9: {=TREND($B$6:$C$6,$B$1:$C$1,C8)} -> 0.85 | D9: {=TREND($B$6:$C$6,$B$1:$C$1,D8)} -> 0.85 | E9: {=TREND($B$6:$C$6,$B$1:$C$1,E8)} -> 0.85 | F9: {=TREND($B$6:$C$6,$B$1:$C$1,F8)} -> 0.85 | G9: {=TREND($B$6:$C$6,$B$1:$C$1,G8)} -> 0.85 | H9: {=TREND($B$6:$C$6,$B$1:$C$1,H8)} -> 0.85 | I9: {=TREND($B$6:$C$6,$B$1:$C$1,I8)} -> 0.85 | ... K9: {=TREND($B$6:$C$6,$B$1:$C$1,K8)} -> 0.85 | L9: {=TREND($C$6:$D$6,$C$1:$D$1,L8)} -> 0.85 | M9: {=TREND($C$6:$D$6,$C$1:$D$1,M8)} -> 0.85 | N9: {=TREND($C$6:$D$6,$C$1:$D$1,N8)} -> 0.85 | O9: {=TREND($C$6:$D$6,$C$1:$D$1,O8)} -> 0.85 | P9: {=TREND($C$6:$D$6,$C$1:$D$1,P8)} -> 0.85 | Q9: {=TREND($D$6:$E$6,$D$1:$E$1,Q8)} -> 0.72031266 | R9: {=TREND($D$6:$E$6,$D$1:$E$1,R8)} -> 0.59062531 | S9: {=TREND($D$6:$E$6,$D$1:$E$1,S8)} -> 0.46093797 | T9: {=TREND($D$6:$E$6,$D$1:$E$1,T8)} -> 0.33125063 | U9: {=TREND($D$6:$E$6,$D$1:$E$1,U8)} -> 0.20156329 | V9: {=TREND($E$6:$F$6,$E$1:$F$1,V8)} -> 0.19321883 | W9: {=TREND($E$6:$F$6,$E$1:$F$1,W8)} -> 0.18487437 | X9: {=TREND($E$6:$F$6,$E$1:$F$1,X8)} -> 0.17652991 | Y9: {=TREND($E$6:$F$6,$E$1:$F$1,Y8)} -> 0.16818545 | Z9: {=TREND($E$6:$F$6,$E$1:$F$1,Z8)} -> 0.15984099 | AA9: {=TREND($F$6:$G$6,$F$1:$G$1,AA8)} -> 0.23406504 | AB9: {=TREND($F$6:$G$6,$F$1:$G$1,AB8)} -> 0.3082891 | AC9: {=TREND($F$6:$G$6,$F$1:$G$1,AC8)} -> 0.38251315 | AD9: {=TREND($F$6:$G$6,$F$1:$G$1,AD8)} -> 0.45673721 | AE9: {=TREND($F$6:$G$6,$F$1:$G$1,AE8)} -> 0.53096126

Sheet RAF-generation
A1: See EPA file elec/RAF
A3: Unit: dimensionless (% of capacity available) | B3: 2021 | C3: 2022 | D3: 2023 | E3: 2024 | F3: 2025 | G3: 2026 | H3: 2027 | I3: 2028 | J3: 2029 | K3: 2030 | L3: 2031 | M3: 2032 | N3: 2033 | O3: 2034 | P3: 2035 | Q3: 2036 | R3: 2037 | S3: 2038 | T3: 2039 | U3: 2040 | V3: 2041 | W3: 2042 | X3: 2043 | Y3: 2044 | Z3: 2045 | AA3: 2046 | AB3: 2047 | AC3: 2048 | AD3: 2049 | AE3: 2050
A4: hard coal | B4: 0.582 | C4: 0.5682 | D4: 0.5364 | E4: 0.55 | F4: 0.55 | G4: 0.55 | H4: 0.55 | I4: 0.57970701 | J4: 0.63084235 | K4: 0.68197768 | L4: 0.69149582 | M4: 0.70101396 | N4: 0.7105321 | O4: 0.72005023 | P4: 0.72956837 | Q4: 0.61645003 | R4: 0.55 | S4: 0.55 | T4: 0.55 | U4: 0.55 | V4: 0.55 | W4: 0.55 | X4: 0.55 | Y4: 0.55 | Z4: 0.55 | AA4: 0.55 | AB4: 0.55 | AC4: 0.55 | AD4: 0.55 | AE4: 0.55
A5: natural gas steam turbine | B5: 0.94703699 | C5: 0.89467117 | D5: 0.91474649 | E5: 0.8 | F5: 0.8 | G5: 0.8 | H5: 0.8 | I5: 0.8 | J5: 0.8 | K5: 0.8 | L5: 0.8 | M5: 0.8 | N5: 0.8 | O5: 0.8 | P5: 0.8 | Q5: 0.8 | R5: 0.8 | S5: 0.8 | T5: 0.8 | U5: 0.8 | V5: 0.8 | W5: 0.8 | X5: 0.8 | Y5: 0.8 | Z5: 0.8 | AA5: 0.8 | AB5: 0.8 | AC5: 0.8 | AD5: 0.8 | AE5: 0.8
A6: natural gas combustion turbine | B6: 0.8 | C6: 0.8 | D6: 0.8 | E6: 0.8 | F6: 0.8 | G6: 0.8 | H6: 0.8 | I6: 0.8 | J6: 0.8 | K6: 0.8 | L6: 0.8 | M6: 0.8 | N6: 0.8 | O6: 0.8 | P6: 0.8 | Q6: 0.8 | R6: 0.8 | S6: 0.8 | T6: 0.8 | U6: 0.8 | V6: 0.8 | W6: 0.8 | X6: 0.8 | Y6: 0.8 | Z6: 0.8 | AA6: 0.8 | AB6: 0.8 | AC6: 0.8 | AD6: 0.8 | AE6: 0.8
A7: nuclear | B7: 1 | C7: 1 | D7: 1 | E7: 1 | F7: 1 | G7: 1 | H7: 1 | I7: 1 | J7: 1 | K7: 1 | L7: 1 | M7: 1 | N7: 1 | O7: 1 | P7: 1 | Q7: 1 | R7: 1 | S7: 1 | T7: 1 | U7: 1 | V7: 1 | W7: 1 | X7: 1 | Y7: 1 | Z7: 1 | AA7: 1 | AB7: 1 | AC7: 1 | AD7: 1 | AE7: 1
A8: hydro | B8: 0.79849002 | C8: 0.73101616 | D8: 0.81679042 | E8: 1 | F8: 1 | G8: 1 | H8: 1 | I8: 1 | J8: 1 | K8: 1 | L8: 1 | M8: 1 | N8: 1 | O8: 1 | P8: 1 | Q8: 1 | R8: 1 | S8: 1 | T8: 1 | U8: 1 | V8: 1 | W8: 1 | X8: 1 | Y8: 1 | Z8: 1 | AA8: 1 | AB8: 1 | AC8: 1 | AD8: 1 | AE8: 1
A9: onshore wind | B9: 0.90564191 | C9: 0.96731685 | D9: 0.90477682 | E9: 1 | F9: 1 | G9: 1 | H9: 1 | I9: 1 | J9: 1 | K9: 1 | L9: 1 | M9: 1 | N9: 1 | O9: 1 | P9: 1 | Q9: 1 | R9: 1 | S9: 1 | T9: 1 | U9: 1 | V9: 1 | W9: 1 | X9: 1 | Y9: 1 | Z9: 1 | AA9: 1 | AB9: 1 | AC9: 1 | AD9: 1 | AE9: 1
A10: solar pv | B10: 0.85250074 | C10: 0.88388487 | D10: 0.83000625 | E10: 1 | F10: 1 | G10: 1 | H10: 1 | I10: 1 | J10: 1 | K10: 1 | L10: 1 | M10: 1 | N10: 1 | O10: 1 | P10: 1 | Q10: 1 | R10: 1 | S10: 1 | T10: 1 | U10: 1 | V10: 1 | W10: 1 | X10: 1 | Y10: 1 | Z10: 1 | AA10: 1 | AB10: 1 | AC10: 1 | AD10: 1 | AE10: 1
A11: solar thermal | B11: 0.94986437 | C11: 0.90591608 | D11: 0.85996562 | E11: 1 | F11: 1 | G11: 1 | H11: 1 | I11: 1 | J11: 1 | K11: 1 | L11: 1 | M11: 1 | N11: 1 | O11: 1 | P11: 1 | Q11: 1 | R11: 1 | S11: 1 | T11: 1 | U11: 1 | V11: 1 | W11: 1 | X11: 1 | Y11: 1 | Z11: 1 | AA11: 1 | AB11: 1 | AC11: 1 | AD11: 1 | AE11: 1
A12: biomass | B12: 0.85615292 | C12: 0.80255011 | D12: 0.71964187 | E12: 1 | F12: 1 | G12: 1 | H12: 1 | I12: 1 | J12: 1 | K12: 1 | L12: 1 | M12: 1 | N12: 1 | O12: 1 | P12: 1 | Q12: 1 | R12: 1 | S12: 1 | T12: 1 | U12: 1 | V12: 1 | W12: 1 | X12: 1 | Y12: 1 | Z12: 1 | AA12: 1 | AB12: 1 | AC12: 1 | AD12: 1 | AE12: 1
A13: geothermal | B13: 0.82374129 | C13: 0.84336266 | D13: 0.86301354 | E13: 1 | F13: 1 | G13: 1 | H13: 1 | I13: 1 | J13: 1 | K13: 1 | L13: 1 | M13: 1 | N13: 1 | O13: 1 | P13: 1 | Q13: 1 | R13: 1 | S13: 1 | T13: 1 | U13: 1 | V13: 1 | W13: 1 | X13: 1 | Y13: 1 | Z13: 1 | AA13: 1 | AB13: 1 | AC13: 1 | AD13: 1 | AE13: 1
A14: petroleum | B14: 0.8 | C14: 0.8 | D14: 0.8 | E14: 0.8 | F14: 0.8 | G14: 0.8 | H14: 0.8 | I14: 0.8 | J14: 0.8 | K14: 0.8 | L14: 0.8 | M14: 0.8 | N14: 0.8 | O14: 0.8 | P14: 0.8 | Q14: 0.8 | R14: 0.8 | S14: 0.8 | T14: 0.8 | U14: 0.8 | V14: 0.8 | W14: 0.8 | X14: 0.8 | Y14: 0.8 | Z14: 0.8 | AA14: 0.8 | AB14: 0.8 | AC14: 0.8 | AD14: 0.8 | AE14: 0.8
... A27: hydrogen combined cycle | B27: 0.9 | C27: 0.9 | D27: 0.9 | E27: 0.9 | F27: 0.9 | G27: 0.9 | H27: 0.9 | I27: 0.9 | J27: 0.9 | K27: 0.9 | L27: 0.9 | M27: 0.9 | N27: 0.9 | O27: 0.9 | P27: 0.9 | Q27: 0.9 | R27: 0.9 | S27: 0.9 | T27: 0.9 | U27: 0.9 | V27: 0.9 | W27: 0.9 | X27: 0.9 | Y27: 0.9 | Z27: 0.9 | AA27: 0.9 | AB27: 0.9 | AC27: 0.9 | AD27: 0.9 | AE27: 0.9

Sheet MCF
A1: Unit: dimensionless (peak time capacity factors) | B1: 2021 | C1: 2022 | D1: 2023 | E1: 2024 | F1: 2025 | G1: 2026 | H1: 2027 | I1: 2028 | J1: 2029 | K1: 2030 | L1: 2031 | M1: 2032 | N1: 2033 | O1: 2034 | P1: 2035 | Q1: 2036 | R1: 2037 | S1: 2038 | T1: 2039 | U1: 2040 | V1: 2041 | W1: 2042 | X1: 2043 | Y1: 2044 | Z1: 2045 | AA1: 2046 | AB1: 2047 | AC1: 2048 | AD1: 2049 | AE1: 2050
A2: hard coal | B2: 0.85 | C2: 0.85 | D2: 0.85 | E2: 0.85 | F2: 0.85 | G2: 0.85 | H2: 0.85 | I2: 0.85 | J2: 0.85 | K2: 0.85 | L2: 0.85 | M2: 0.85 | N2: 0.85 | O2: 0.85 | P2: 0.85 | Q2: 0.85 | R2: 0.85 | S2: 0.85 | T2: 0.85 | U2: 0.85 | V2: 0.85 | W2: 0.85 | X2: 0.85 | Y2: 0.85 | Z2: 0.85 | AA2: 0.85 | AB2: 0.85 | AC2: 0.85 | AD2: 0.85 | AE2: 0.85
A3: natural gas steam turbine | B3: 0.95 | C3: 0.95 | D3: 0.95 | E3: 0.95 | F3: 0.95 | G3: 0.95 | H3: 0.95 | I3: 0.95 | J3: 0.95 | K3: 0.95 | L3: 0.95 | M3: 0.95 | N3: 0.95 | O3: 0.95 | P3: 0.95 | Q3: 0.95 | R3: 0.95 | S3: 0.95 | T3: 0.95 | U3: 0.95 | V3: 0.95 | W3: 0.95 | X3: 0.95 | Y3: 0.95 | Z3: 0.95 | AA3: 0.95 | AB3: 0.95 | AC3: 0.95 | AD3: 0.95 | AE3: 0.95
A4: natural gas combined cycle | B4: 0.95 | C4: 0.95 | D4: 0.95 | E4: 0.95 | F4: 0.95 | G4: 0.95 | H4: 0.95 | I4: 0.95 | J4: 0.95 | K4: 0.95 | L4: 0.95 | M4: 0.95 | N4: 0.95 | O4: 0.95 | P4: 0.95 | Q4: 0.95 | R4: 0.95 | S4: 0.95 | T4: 0.95 | U4: 0.95 | V4: 0.95 | W4: 0.95 | X4: 0.95 | Y4: 0.95 | Z4: 0.95 | AA4: 0.95 | AB4: 0.95 | AC4: 0.95 | AD4: 0.95 | AE4: 0.95
A5: nuclear | B5: 0.91 | C5: 0.91 | D5: 0.91 | E5: 0.91 | F5: 0.91 | G5: 0.91 | H5: 0.91 | I5: 0.91 | J5: 0.91 | K5: 0.91 | L5: 0.91 | M5: 0.91 | N5: 0.91 | O5: 0.91 | P5: 0.91 | Q5: 0.91 | R5: 0.91 | S5: 0.91 | T5: 0.91 | U5: 0.91 | V5: 0.91 | W5: 0.91 | X5: 0.91 | Y5: 0.91 | Z5: 0.91 | AA5: 0.91 | AB5: 0.91 | AC5: 0.91 | AD5: 0.91 | AE5: 0.91
A6: hydro | B6: 0.95 | C6: 0.95 | D6: 0.95 | E6: 0.95 | F6: 0.95 | G6: 0.95 | H6: 0.95 | I6: 0.95 | J6: 0.95 | K6: 0.95 | L6: 0.95 | M6: 0.95 | N6: 0.95 | O6: 0.95 | P6: 0.95 | Q6: 0.95 | R6: 0.95 | S6: 0.95 | T6: 0.95 | U6: 0.95 | V6: 0.95 | W6: 0.95 | X6: 0.95 | Y6: 0.95 | Z6: 0.95 | AA6: 0.95 | AB6: 0.95 | AC6: 0.95 | AD6: 0.95 | AE6: 0.95
A7: onshore wind | B7: 0 | C7: 0 | D7: 0 | E7: 0 | F7: 0 | G7: 0 | H7: 0 | I7: 0 | J7: 0 | K7: 0 | L7: 0 | M7: 0 | N7: 0 | O7: 0 | P7: 0 | Q7: 0 | R7: 0 | S7: 0 | T7: 0 | U7: 0 | V7: 0 | W7: 0 | X7: 0 | Y7: 0 | Z7: 0 | AA7: 0 | AB7: 0 | AC7: 0 | AD7: 0 | AE7: 0
A8: solar pv | B8: 0 | C8: 0 | D8: 0 | E8: 0 | F8: 0 | G8: 0 | H8: 0 | I8: 0 | J8: 0 | K8: 0 | L8: 0 | M8: 0 | N8: 0 | O8: 0 | P8: 0 | Q8: 0 | R8: 0 | S8: 0 | T8: 0 | U8: 0 | V8: 0 | W8: 0 | X8: 0 | Y8: 0 | Z8: 0 | AA8: 0 | AB8: 0 | AC8: 0 | AD8: 0 | AE8: 0
A9: solar thermal | B9: 0 | C9: 0 | D9: 0 | E9: 0 | F9: 0 | G9: 0 | H9: 0 | I9: 0 | J9: 0 | K9: 0 | L9: 0 | M9: 0 | N9: 0 | O9: 0 | P9: 0 | Q9: 0 | R9: 0 | S9: 0 | T9: 0 | U9: 0 | V9: 0 | W9: 0 | X9: 0 | Y9: 0 | Z9: 0 | AA9: 0 | AB9: 0 | AC9: 0 | AD9: 0 | AE9: 0
A10: biomass | B10: 0.95 | C10: 0.95 | D10: 0.95 | E10: 0.95 | F10: 0.95 | G10: 0.95 | H10: 0.95 | I10: 0.95 | J10: 0.95 | K10: 0.95 | L10: 0.95 | M10: 0.95 | N10: 0.95 | O10: 0.95 | P10: 0.95 | Q10: 0.95 | R10: 0.95 | S10: 0.95 | T10: 0.95 | U10: 0.95 | V10: 0.95 | W10: 0.95 | X10: 0.95 | Y10: 0.95 | Z10: 0.95 | AA10: 0.95 | AB10: 0.95 | AC10: 0.95 | AD10: 0.95 | AE10: 0.95
A11: geothermal | B11: 0.95 | C11: 0.95 | D11: 0.95 | E11: 0.95 | F11: 0.95 | G11: 0.95 | H11: 0.95 | I11: 0.95 | J11: 0.95 | K11: 0.95 | L11: 0.95 | M11: 0.95 | N11: 0.95 | O11: 0.95 | P11: 0.95 | Q11: 0.95 | R11: 0.95 | S11: 0.95 | T11: 0.95 | U11: 0.95 | V11: 0.95 | W11: 0.95 | X11: 0.95 | Y11: 0.95 | Z11: 0.95 | AA11: 0.95 | AB11: 0.95 | AC11: 0.95 | AD11: 0.95 | AE11: 0.95
A12: petroleum | B12: 0.95 | C12: 0.95 | D12: 0.95 | E12: 0.95 | F12: 0.95 | G12: 0.95 | H12: 0.95 | I12: 0.95 | J12: 0.95 | K12: 0.95 | L12: 0.95 | M12: 0.95 | N12: 0.95 | O12: 0.95 | P12: 0.95 | Q12: 0.95 | R12: 0.95 | S12: 0.95 | T12: 0.95 | U12: 0.95 | V12: 0.95 | W12: 0.95 | X12: 0.95 | Y12: 0.95 | Z12: 0.95 | AA12: 0.95 | AB12: 0.95 | AC12: 0.95 | AD12: 0.95 | AE12: 0.95
... A18: municipal solid waste | B18: 0.95 | C18: 0.95 | D18: 0.95 | E18: 0.95 | F18: 0.95 | G18: 0.95 | H18: 0.95 | I18: 0.95 | J18: 0.95 | K18: 0.95 | L18: 0.95 | M18: 0.95 | N18: 0.95 | O18: 0.95 | P18: 0.95 | Q18: 0.95 | R18: 0.95 | S18: 0.95 | T18: 0.95 | U18: 0.95 | V18: 0.95 | W18: 0.95 | X18: 0.95 | Y18: 0.95 | Z18: 0.95 | AA18: 0.95 | AB18: 0.95 | AC18: 0.95 | AD18: 0.95 | AE18: 0.95
A19: hard coal w CCS | B19: =B2 -> 0.85 | C19: =C2 -> 0.85 | D19: =D2 -> 0.85 | E19: =E2 -> 0.85 | F19: =F2 -> 0.85 | G19: =G2 -> 0.85 | H19: =H2 -> 0.85 | I19: =I2 -> 0.85 | ... AE19: =AE2 -> 0.85
A20: natural gas combined cycle w CCS | B20: =B4 -> 0.95 | C20: =C4 -> 0.95 | D20: =D4 -> 0.95 | E20: =E4 -> 0.95 | F20: =F4 -> 0.95 | G20: =G4 -> 0.95 | H20: =H4 -> 0.95 | I20: =I4 -> 0.95 | ... AE20: =AE4 -> 0.95
A21: biomass w CCS | B21: =B10 -> 0.95 | C21: =C10 -> 0.95 | D21: =D10 -> 0.95 | E21: =E10 -> 0.95 | F21: =F10 -> 0.95 | G21: =G10 -> 0.95 | H21: =H10 -> 0.95 | I21: =I10 -> 0.95 | ... AE21: =AE10 -> 0.95
A22: lignite w CCS | B22: =B14 -> 0.95 | C22: =C14 -> 0.95 | D22: =D14 -> 0.95 | E22: =E14 -> 0.95 | F22: =F14 -> 0.95 | G22: =G14 -> 0.95 | H22: =H14 -> 0.95 | I22: =I14 -> 0.95 | ... AE22: =AE14 -> 0.95
A23: small modular reactor | B23: =B5 -> 0.91 | C23: =C5 -> 0.91 | D23: =D5 -> 0.91 | E23: =E5 -> 0.91 | F23: =F5 -> 0.91 | G23: =G5 -> 0.91 | H23: =H5 -> 0.91 | I23: =I5 -> 0.91 | ... AE23: =AE5 -> 0.91
A24: hydrogen combustion turbine | B24: =B4 -> 0.95 | C24: =C4 -> 0.95 | D24: =D4 -> 0.95 | E24: =E4 -> 0.95 | F24: =F4 -> 0.95 | G24: =G4 -> 0.95 | H24: =H4 -> 0.95 | I24: =I4 -> 0.95 | ... AE24: =AE4 -> 0.95
A25: hydrogen combined cycle | B25: =B4 -> 0.95 | C25: =C4 -> 0.95 | D25: =D4 -> 0.95 | E25: =E4 -> 0.95 | F25: =F4 -> 0.95 | G25: =G4 -> 0.95 | H25: =H4 -> 0.95 | I25: =I4 -> 0.95 | ... AE25: =AE4 -> 0.95
