Workbook
Name asdf: About!#REF!
Name cpi_2010to2012: About!#REF!
Name cpi_2013to2012: About!#REF!
Name cpi_2014to2012: About!#REF!
Name cpi_2016to2012: About!#REF!
Name cpi_2017to2012: About!#REF!
Name cpi_2018to2012: About!#REF!
Name cpi_2019to2012: About!#REF!
Name cpi_2020to2012: About!#REF!
Name cpi_2021to2012: About!#REF!
Name H2_kg_to_MMBtu: [1]Constants!$D$7
Name kWh_to_Btu: [1]Constants!$D$4
Name US_salestax: About!#REF!

Sheet About
A1: BNVP BAU New Vehicle Price
A4: Source: | B4: Exchange Rates
B5: 2019
B6: https://www.exchangerates.org.uk/USD-IDR-spot-exchange-rates-history-2019.html
B8: Indonesia - Investments
B9: Import tariff (CBU vehicles)
B10: 2016
B11: https://www.indonesia-investments.com/news/todays-headlines/indonesian-demand-for-imported-cbu-cars-still-strong/item6501?
B13: Global Fleet
B14: VAT (PPN)
B15: 2025
B16: https://www.globalfleet.com/en/taxation-and-legislation/asia-pacific/analysis/tax-turbulence-guiding-fleets-through-indonesias-vat-storm?a=YHE11&t%5B0%5D=Indonesia&t%5B1%5D=Taxation&curl=1
B18: Global Fleet
B19: Luxury goods tax (PPnBM)
B20: 2025
B21: https://www.globalfleet.com/en/taxation-and-legislation/asia-pacific/analysis/tax-turbulence-guiding-fleets-through-indonesias-vat-storm?a=YHE11&t%5B0%5D=Indonesia&t%5B1%5D=Taxation&curl=1
B23: Mordor Intellligence
B24: Dealer margin & logistics
B25: 2024
B26: https://www.mordorintelligence.com/industry-reports/indonesia-freight-logistics-market
B28: World Bank
B29: Final Consumption Expenditure
B30: 2010-2023
B31: https://databank.worldbank.org/reports.aspx?source=2&series=NE.CON.TOTL.CD&country=
A34: Currency Year
A35: The figures from the Center for Automotive Research come from a 2010 Automotive Yearbook
A36: and therefore are likely in 2010 dollars.
A37: The figures from TruckerToTrucker were collected in early 2015 and therefore use 2015 | B37: 2014 to 2012, for TruckerToTrucker
A38: dollars, but because we don't have a 2015 annual CPI-U figure available yet, we use 2014. | B38: 2013 to 2012, for American Public Transit Association
A39: 0.987 | B39: 2013 to 2012
A40: 0.953 | B40: 2016 to 2012
A41: 0.9366596 | B41: 2017 to 2012
A42: 0.914 | B42: 2018 to 2012
A43: 0.89805482 | B43: 2019 to 2012
A44: 0.88711067 | B44: 2020 to 2012
A45: 0.84730413 | B45: 2021 to 2012
A46: See "cpi.xlsx" in the InputData folder for source information.
A50: Note: | B50: To estimate the adjusted vehicle price for Indonesia based on a U.S. vehicle price, we compute an adjustment factor that combines two key elements: the FCE-based scaling and a correction factor accounting for country-specific cost components. First, we calculate the ratio of Final Consumption Expenditure (FCE) per capita between Indonesia and the U.S. to reflect differences in purchasing power and spending capacity. This gives a base scaling factor. Then, apply a correction factor to capture additional costs associated with importing vehicles into Indonesia. This correction factor is the sum of typical vehicle-related costs, such as import tariffs on completely built-up (CBU) vehicles, value-added tax (VAT or PPN), luxury goods tax (PPnBM), and dealer margins or logistics fees. For passenger cars, instead of using FCE, we directly estimate the scaling by comparing average Indonesian passenger car prices to U.S. passenger vehicle prices.

Sheet NVP-Indonesia
A1: Year | B1: 2011 | C1: 2012 | D1: 2013 | E1: 2014 | F1: 2015 | G1: 2016 | H1: 2017 | I1: 2018 | J1: 2019 | K1: 2020 | L1: 2021 | M1: 2022 | N1: 2023
A2: Average new car price (million Rupiah) | B2: 193 | C2: =ROUNDUP(($B$2+(($N$2-$B$2)/($N$1-$B$1))*(C1-$B$1)),0) -> 206 | D2: =ROUNDUP(($B$2+(($N$2-$B$2)/($N$1-$B$1))*(D1-$B$1)),0) -> 219 | E2: =ROUNDUP(($B$2+(($N$2-$B$2)/($N$1-$B$1))*(E1-$B$1)),0) -> 232 | F2: =ROUNDUP(($B$2+(($N$2-$B$2)/($N$1-$B$1))*(F1-$B$1)),0) -> 245 | G2: =ROUNDUP(($B$2+(($N$2-$B$2)/($N$1-$B$1))*(G1-$B$1)),0) -> 258 | H2: =ROUNDUP(($B$2+(($N$2-$B$2)/($N$1-$B$1))*(H1-$B$1)),0) -> 270 | I2: =ROUNDUP(($B$2+(($N$2-$B$2)/($N$1-$B$1))*(I1-$B$1)),0) -> 283 | J2: =ROUNDUP(($B$2+(($N$2-$B$2)/($N$1-$B$1))*(J1-$B$1)),0) -> 296 | ... M2: =ROUNDUP(($B$2+(($N$2-$B$2)/($N$1-$B$1))*(M1-$B$1)),0) -> 335 | N2: 347
A3: Million Rupiah to Rupiah | B3: 1000000
A4: 1 USD to Rupiah (2019) | B4: 14135.41
A5: 1 Rupiah to USD (2019) | B5: =1/B4 -> 7.0744322e-05
A6: Average new car price (USD) | B6: =ROUNDUP(B2*$B$3*$B$5,0) -> 13654 | C6: =ROUNDUP(C2*$B$3*$B$5,0) -> 14574 | D6: =ROUNDUP(D2*$B$3*$B$5,0) -> 15494 | E6: =ROUNDUP(E2*$B$3*$B$5,0) -> 16413 | F6: =ROUNDUP(F2*$B$3*$B$5,0) -> 17333 | G6: =ROUNDUP(G2*$B$3*$B$5,0) -> 18253 | H6: =ROUNDUP(H2*$B$3*$B$5,0) -> 19101 | I6: =ROUNDUP(I2*$B$3*$B$5,0) -> 20021 | ... N6: =ROUNDUP(N2*$B$3*$B$5,0) -> 24549
A8: Percentage increase overtime | B8: 0.05
A10: Year | B10: 2020 | C10: 2021 | D10: 2022 | E10: 2023 | F10: 2024 | G10: 2025 | H10: 2026 | I10: 2027 | J10: 2028 | K10: 2029 | L10: 2030 | M10: 2031 | N10: 2032 | O10: 2033 | P10: 2034 | Q10: 2035 | R10: 2036 | S10: 2037 | T10: 2038 | U10: 2039 | V10: 2040 | W10: 2041 | X10: 2042 | Y10: 2043 | Z10: 2044 | AA10: 2045 | AB10: 2046 | AC10: 2047 | AD10: 2048 | AE10: 2049 | AF10: 2050 | AG10: 2051 | AH10: 2052 | AI10: 2053 | AJ10: 2054 | AK10: 2055 | AL10: 2056 | AM10: 2057 | AN10: 2058 | AO10: 2059 | AP10: 2060 | AQ10: 2061 | AR10: 2062 | AS10: 2063 | AT10: 2064 | AU10: 2065 | AV10: 2066 | AW10: 2067 | AX10: 2068 | AY10: 2069 | AZ10: 2070
A11: Average new car price (2012 USD) - Percentage Increase | B11: =K6 -> 21860 | C11: =L6 -> 22780 | D11: =M6 -> 23700 | E11: =N6 -> 24549 | F11: =ROUNDUP(E11+E11*$B$8, 0) -> 25777 | G11: =ROUNDUP(F11+F11*$B$8, 0) -> 27066 | H11: =ROUNDUP(G11+G11*$B$8, 0) -> 28420 | I11: =ROUNDUP(H11+H11*$B$8, 0) -> 29841 | J11: =ROUNDUP(I11+I11*$B$8, 0) -> 31334 | K11: =ROUNDUP(J11+J11*$B$8, 0) -> 32901 | L11: =ROUNDUP(K11+K11*$B$8, 0) -> 34547 | M11: =ROUNDUP(L11+L11*$B$8, 0) -> 36275 | ... AZ11: =ROUNDUP(AY11+AY11*$B$8, 0) -> 243261
A12: Average new car price (2012 USD) - Linear Forecast | B12: =B11 -> 21860 | C12: =C11 -> 22780 | D12: =D11 -> 23700 | E12: =E11 -> 24549 | F12: =ROUNDUP(_xlfn.FORECAST.LINEAR(F10,$B$12:$E$12,$B$10:$E$10), 0) -> 25469 | G12: =ROUNDUP(_xlfn.FORECAST.LINEAR(G10,$B$12:$E$12,$B$10:$E$10), 0) -> 26368 | H12: =ROUNDUP(_xlfn.FORECAST.LINEAR(H10,$B$12:$E$12,$B$10:$E$10), 0) -> 27267 | I12: =ROUNDUP(_xlfn.FORECAST.LINEAR(I10,$B$12:$E$12,$B$10:$E$10), 0) -> 28166 | J12: =ROUNDUP(_xlfn.FORECAST.LINEAR(J10,$B$12:$E$12,$B$10:$E$10), 0) -> 29064 | K12: =ROUNDUP(_xlfn.FORECAST.LINEAR(K10,$B$12:$E$12,$B$10:$E$10), 0) -> 29963 | L12: =ROUNDUP(_xlfn.FORECAST.LINEAR(L10,$B$12:$E$12,$B$10:$E$10), 0) -> 30862 | M12: =ROUNDUP(_xlfn.FORECAST.LINEAR(M10,$B$12:$E$12,$B$10:$E$10), 0) -> 31760 | ... AZ12: =ROUNDUP(_xlfn.FORECAST.LINEAR(AZ10,$B$12:$E$12,$B$10:$E$10), 0) -> 66810
A14: US New Vehicle Price
A15: BNVP-LDVs-psgr
A16: Price ($/vehicle) | B16: 2020 | C16: 2021 | D16: 2022 | E16: 2023 | F16: 2024 | G16: 2025 | H16: 2026 | I16: 2027 | J16: 2028 | K16: 2029 | L16: 2030 | M16: 2031 | N16: 2032 | O16: 2033 | P16: 2034 | Q16: 2035 | R16: 2036 | S16: 2037 | T16: 2038 | U16: 2039 | V16: 2040 | W16: 2041 | X16: 2042 | Y16: 2043 | Z16: 2044 | AA16: 2045 | AB16: 2046 | AC16: 2047 | AD16: 2048 | AE16: 2049 | AF16: 2050 | AG16: 2051 | AH16: 2052 | AI16: 2053 | AJ16: 2054 | AK16: 2055 | AL16: 2056 | AM16: 2057 | AN16: 2058 | AO16: 2059 | AP16: 2060 | AQ16: 2061 | AR16: 2062 | AS16: 2063 | AT16: 2064 | AU16: 2065 | AV16: 2066 | AW16: 2067 | AX16: 2068 | AY16: 2069 | AZ16: 2070
A17: battery electric vehicle | B17: 49825.128 | C17: 44974.651 | D17: 44014.219 | E17: 42953.309 | F17: 42057.542 | G17: 41521.193 | H17: 40991.55 | I17: 40480.256 | J17: 40050.501 | K17: 39618.7 | L17: 39193.065 | M17: 38851.711 | N17: 38445.374 | O17: 38068.778 | P17: 37707.033 | Q17: 37365.394 | R17: 37011.736 | S17: 36641.185 | T17: 36270.533 | U17: 35909.696 | V17: 35548.372 | W17: 35209.229 | X17: 34885.052 | Y17: 34557.402 | Z17: 34243.998 | AA17: 33954.038 | AB17: 33631.495 | AC17: 33320.219 | AD17: 33037.653 | AE17: 32722.528 | AF17: 32420.62 | AG17: 31015.295 | AH17: 30583.827 | AI17: 30152.359 | AJ17: 29720.891 | AK17: 29289.424 | AL17: 28857.956 | AM17: 28426.488 | AN17: 27995.02 | AO17: 27563.552 | AP17: 27132.085 | AQ17: 26700.617 | AR17: 26269.149 | AS17: 25837.681 | AT17: 25406.213 | AU17: 24974.746 | AV17: 24543.278 | AW17: 24111.81 | AX17: 23680.342 | AY17: 23248.875 | AZ17: 22817.407
A18: natural gas vehicle | B18: 36759.75 | C18: 36495.301 | D18: 36652.899 | E18: 36898.855 | F18: 37088.42 | G18: 37274.214 | H18: 37445.623 | I18: 37600.873 | J18: 37766.33 | K18: 37923.877 | L18: 38069.817 | M18: 38227.33 | N18: 38348.863 | O18: 38510.498 | P18: 38604.697 | Q18: 38681.121 | R18: 38748.487 | S18: 38814.705 | T18: 38876.265 | U18: 38939.471 | V18: 38983.894 | W18: 39034.301 | X18: 39076.492 | Y18: 39111.674 | Z18: 39147.674 | AA18: 39181.697 | AB18: 39212.991 | AC18: 39245.837 | AD18: 39278.913 | AE18: 39308.052 | AF18: 39337.439 | AG18: 39864.611 | AH18: 39959.684 | AI18: 40054.758 | AJ18: 40149.832 | AK18: 40244.906 | AL18: 40339.979 | AM18: 40435.053 | AN18: 40530.127 | AO18: 40625.2 | AP18: 40720.274 | AQ18: 40815.348 | AR18: 40910.422 | AS18: 41005.495 | AT18: 41100.569 | AU18: 41195.643 | AV18: 41290.717 | AW18: 41385.79 | AX18: 41480.864 | AY18: 41575.938 | AZ18: 41671.011
A19: gasoline vehicle | B19: 32342.636 | C19: 31217.363 | D19: 31436.447 | E19: 31582.449 | F19: 31757.9 | G19: 31937.089 | H19: 32051.631 | I19: 32113.77 | J19: 32185.62 | K19: 32243.903 | L19: 32274.622 | M19: 32331.769 | N19: 32347.685 | O19: 32381.444 | P19: 32396.375 | Q19: 32409.373 | R19: 32401.629 | S19: 32380.855 | T19: 32354.526 | U19: 32332.246 | V19: 32299.489 | W19: 32277.911 | X19: 32262.981 | Y19: 32240.582 | Z19: 32222.923 | AA19: 32218.675 | AB19: 32189.558 | AC19: 32165.915 | AD19: 32160.914 | AE19: 32130.598 | AF19: 32106.973 | AG19: 32390.103 | AH19: 32404.896 | AI19: 32419.689 | AJ19: 32434.482 | AK19: 32449.275 | AL19: 32464.068 | AM19: 32478.861 | AN19: 32493.654 | AO19: 32508.447 | AP19: 32523.24 | AQ19: 32538.033 | AR19: 32552.826 | AS19: 32567.619 | AT19: 32582.412 | AU19: 32597.205 | AV19: 32611.998 | AW19: 32626.791 | AX19: 32641.584 | AY19: 32656.377 | AZ19: 32671.17
A20: diesel vehicle | B20: 35443.546 | C20: 34572.73 | D20: 34849.204 | E20: 34983.821 | F20: 35151.364 | G20: 35326.619 | H20: 35410.191 | I20: 35435.494 | J20: 35474.588 | K20: 35499.908 | L20: 35487.978 | M20: 35511.964 | N20: 35480.242 | O20: 35474.108 | P20: 35461.937 | Q20: 35455.995 | R20: 35422.177 | S20: 35366.464 | T20: 35302.941 | U20: 35244.577 | V20: 35170.962 | W20: 35114.649 | X20: 35067.006 | Y20: 35011.117 | Z20: 34962.564 | AA20: 34932.466 | AB20: 34867.704 | AC20: 34811.011 | AD20: 34778.001 | AE20: 34711.17 | AF20: 34656.058 | AG20: 34943.404 | AH20: 34928.902 | AI20: 34914.4 | AJ20: 34899.898 | AK20: 34885.396 | AL20: 34870.893 | AM20: 34856.391 | AN20: 34841.889 | AO20: 34827.387 | AP20: 34812.885 | AQ20: 34798.383 | AR20: 34783.881 | AS20: 34769.379 | AT20: 34754.877 | AU20: 34740.375 | AV20: 34725.873 | AW20: 34711.371 | AX20: 34696.868 | AY20: 34682.366 | AZ20: 34667.864
A21: plugin hybrid vehicle | B21: 36885.812 | C21: 37390.063 | D21: 37336.116 | E21: 37519.774 | F21: 37560.849 | G21: 37672.814 | H21: 37718.564 | I21: 37744.624 | J21: 37799.089 | K21: 37869.295 | L21: 37947.783 | M21: 38048.195 | N21: 38134.621 | O21: 38250.401 | P21: 38309.624 | Q21: 38356.758 | R21: 38399.036 | S21: 38433.322 | T21: 38455.444 | U21: 38471.88 | V21: 38470.609 | W21: 38476.534 | X21: 38473.613 | Y21: 38464.26 | Z21: 38454.964 | AA21: 38445.041 | AB21: 38433.395 | AC21: 38423.684 | AD21: 38414.275 | AE21: 38406.062 | AF21: 38395.608 | AG21: 38782.846 | AH21: 38825.399 | AI21: 38867.951 | AJ21: 38910.504 | AK21: 38953.056 | AL21: 38995.609 | AM21: 39038.162 | AN21: 39080.714 | AO21: 39123.267 | AP21: 39165.82 | AQ21: 39208.372 | AR21: 39250.925 | AS21: 39293.478 | AT21: 39336.03 | AU21: 39378.583 | AV21: 39421.136 | AW21: 39463.688 | AX21: 39506.241 | AY21: 39548.794 | AZ21: 39591.346
A22: LPG vehicle | B22: 35929.333 | C22: 36517.782 | D22: 36483.97 | E22: 36547.532 | F22: 36633.721 | G22: 36794.3 | H22: 36928.46 | I22: 36997.316 | J22: 37058.276 | K22: 37124.274 | L22: 37186.148 | M22: 37247.67 | N22: 37300.144 | O22: 37363.114 | P22: 37405.731 | Q22: 37444.211 | R22: 37483.983 | S22: 37524.069 | T22: 37561.633 | U22: 37601.442 | V22: 37635.684 | W22: 37670.003 | X22: 37704.042 | Y22: 37736.312 | Z22: 37769.703 | AA22: 37804.107 | AB22: 37838.223 | AC22: 37873.503 | AD22: 37908.731 | AE22: 37944.389 | AF22: 37966.872 | AG22: 38189.454 | AH22: 38243.665 | AI22: 38297.875 | AJ22: 38352.086 | AK22: 38406.296 | AL22: 38460.507 | AM22: 38514.717 | AN22: 38568.928 | AO22: 38623.138 | AP22: 38677.349 | AQ22: 38731.559 | AR22: 38785.77 | AS22: 38839.98 | AT22: 38894.191 | AU22: 38948.401 | AV22: 39002.612 | AW22: 39056.822 | AX22: 39111.032 | AY22: 39165.243 | AZ22: 39219.453
A23: hydrogen vehicle | B23: 65082.118 | C23: 65067.963 | D23: 63660.552 | E23: 62421.595 | F23: 61170.116 | G23: 59874.757 | H23: 58736.772 | I23: 57689.483 | J23: 56690.542 | K23: 55738.719 | L23: 54831.315 | M23: 53967.601 | N23: 53140.492 | O23: 52357.768 | P23: 51589.549 | Q23: 50852.967 | R23: 50151.391 | S23: 49482.28 | T23: 48844.264 | U23: 48236.533 | V23: 47655.606 | W23: 47102.665 | X23: 46575.275 | Y23: 46072.297 | Z23: 45593.078 | AA23: 45136.282 | AB23: 44700.604 | AC23: 44285.587 | AD23: 43889.741 | AE23: 43512.798 | AF23: 43136.219 | AG23: 40253.789 | AH23: 39509.072 | AI23: 38764.355 | AJ23: 38019.639 | AK23: 37274.922 | AL23: 36530.205 | AM23: 35785.489 | AN23: 35040.772 | AO23: 34296.055 | AP23: 33551.339 | AQ23: 32806.622 | AR23: 32061.905 | AS23: 31317.189 | AT23: 30572.472 | AU23: 29827.755 | AV23: 29083.039 | AW23: 28338.322 | AX23: 27593.605 | AY23: 26848.889 | AZ23: 26104.172
A25: BNVP-LDVs-frgt
A26: Price ($/vehicle) | B26: 2020 | C26: 2021 | D26: 2022 | E26: 2023 | F26: 2024 | G26: 2025 | H26: 2026 | I26: 2027 | J26: 2028 | K26: 2029 | L26: 2030 | M26: 2031 | N26: 2032 | O26: 2033 | P26: 2034 | Q26: 2035 | R26: 2036 | S26: 2037 | T26: 2038 | U26: 2039 | V26: 2040 | W26: 2041 | X26: 2042 | Y26: 2043 | Z26: 2044 | AA26: 2045 | AB26: 2046 | AC26: 2047 | AD26: 2048 | AE26: 2049 | AF26: 2050 | AG26: 2051 | AH26: 2052 | AI26: 2053 | AJ26: 2054 | AK26: 2055 | AL26: 2056 | AM26: 2057 | AN26: 2058 | AO26: 2059 | AP26: 2060 | AQ26: 2061 | AR26: 2062 | AS26: 2063 | AT26: 2064 | AU26: 2065 | AV26: 2066 | AW26: 2067 | AX26: 2068 | AY26: 2069 | AZ26: 2070
A27: battery electric vehicle | B27: 74481.202 | C27: 74481.202 | D27: 74481.202 | E27: 74481.202 | F27: 74481.202 | G27: 74481.202 | H27: 74481.202 | I27: 74481.202 | J27: 74481.202 | K27: 74481.202 | L27: 74481.202 | M27: 74481.202 | N27: 74481.202 | O27: 74481.202 | P27: 74481.202 | Q27: 74481.202 | R27: 74481.202 | S27: 74481.202 | T27: 74481.202 | U27: 74481.202 | V27: 74481.202 | W27: 74481.202 | X27: 74481.202 | Y27: 74481.202 | Z27: 74481.202 | AA27: 74481.202 | AB27: 74481.202 | AC27: 74481.202 | AD27: 74481.202 | AE27: 74481.202 | AF27: 74481.202 | AG27: 74481.202 | AH27: 74481.202 | AI27: 74481.202 | AJ27: 74481.202 | AK27: 74481.202 | AL27: 74481.202 | AM27: 74481.202 | AN27: 74481.202 | AO27: 74481.202 | AP27: 74481.202 | AQ27: 74481.202 | AR27: 74481.202 | AS27: 74481.202 | AT27: 74481.202 | AU27: 74481.202 | AV27: 74481.202 | AW27: 74481.202 | AX27: 74481.202 | AY27: 74481.202 | AZ27: 74481.202
A28: natural gas vehicle | B28: 51983.088 | C28: 51609.123 | D28: 51831.988 | E28: 52179.801 | F28: 52447.871 | G28: 52710.607 | H28: 52953.003 | I28: 53172.546 | J28: 53406.524 | K28: 53629.316 | L28: 53835.695 | M28: 54058.438 | N28: 54230.301 | O28: 54458.874 | P28: 54592.084 | Q28: 54700.157 | R28: 54795.422 | S28: 54889.063 | T28: 54976.117 | U28: 55065.499 | V28: 55128.319 | W28: 55199.6 | X28: 55259.265 | Y28: 55309.016 | Z28: 55359.925 | AA28: 55408.038 | AB28: 55452.292 | AC28: 55498.74 | AD28: 55545.514 | AE28: 55586.72 | AF28: 55628.278 | AG28: 56373.767 | AH28: 56508.214 | AI28: 56642.66 | AJ28: 56777.107 | AK28: 56911.554 | AL28: 57046 | AM28: 57180.447 | AN28: 57314.894 | AO28: 57449.34 | AP28: 57583.787 | AQ28: 57718.234 | AR28: 57852.68 | AS28: 57987.127 | AT28: 58121.574 | AU28: 58256.02 | AV28: 58390.467 | AW28: 58524.914 | AX28: 58659.36 | AY28: 58793.807 | AZ28: 58928.254
A29: gasoline vehicle | B29: 45736.713 | C29: 45736.713 | D29: 45736.713 | E29: 45736.713 | F29: 45736.713 | G29: 45736.713 | H29: 45736.713 | I29: 45736.713 | J29: 45736.713 | K29: 45736.713 | L29: 45736.713 | M29: 45736.713 | N29: 45736.713 | O29: 45736.713 | P29: 45736.713 | Q29: 45736.713 | R29: 45736.713 | S29: 45736.713 | T29: 45736.713 | U29: 45736.713 | V29: 45736.713 | W29: 45736.713 | X29: 45736.713 | Y29: 45736.713 | Z29: 45736.713 | AA29: 45736.713 | AB29: 45736.713 | AC29: 45736.713 | AD29: 45736.713 | AE29: 45736.713 | AF29: 45736.713 | AG29: 45736.713 | AH29: 45736.713 | AI29: 45736.713 | AJ29: 45736.713 | AK29: 45736.713 | AL29: 45736.713 | AM29: 45736.713 | AN29: 45736.713 | AO29: 45736.713 | AP29: 45736.713 | AQ29: 45736.713 | AR29: 45736.713 | AS29: 45736.713 | AT29: 45736.713 | AU29: 45736.713 | AV29: 45736.713 | AW29: 45736.713 | AX29: 45736.713 | AY29: 45736.713 | AZ29: 45736.713
A30: diesel vehicle | B30: 50818.57 | C30: 50818.57 | D30: 50818.57 | E30: 50818.57 | F30: 50818.57 | G30: 50818.57 | H30: 50818.57 | I30: 50818.57 | J30: 50818.57 | K30: 50818.57 | L30: 50818.57 | M30: 50818.57 | N30: 50818.57 | O30: 50818.57 | P30: 50818.57 | Q30: 50818.57 | R30: 50818.57 | S30: 50818.57 | T30: 50818.57 | U30: 50818.57 | V30: 50818.57 | W30: 50818.57 | X30: 50818.57 | Y30: 50818.57 | Z30: 50818.57 | AA30: 50818.57 | AB30: 50818.57 | AC30: 50818.57 | AD30: 50818.57 | AE30: 50818.57 | AF30: 50818.57 | AG30: 50818.57 | AH30: 50818.57 | AI30: 50818.57 | AJ30: 50818.57 | AK30: 50818.57 | AL30: 50818.57 | AM30: 50818.57 | AN30: 50818.57 | AO30: 50818.57 | AP30: 50818.57 | AQ30: 50818.57 | AR30: 50818.57 | AS30: 50818.57 | AT30: 50818.57 | AU30: 50818.57 | AV30: 50818.57 | AW30: 50818.57 | AX30: 50818.57 | AY30: 50818.57 | AZ30: 50818.57
A31: plugin hybrid vehicle | B31: 52161.357 | C31: 52874.433 | D31: 52798.145 | E31: 53057.862 | F31: 53115.947 | G31: 53274.28 | H31: 53338.977 | I31: 53375.829 | J31: 53452.85 | K31: 53552.129 | L31: 53663.122 | M31: 53805.119 | N31: 53927.335 | O31: 54091.064 | P31: 54174.813 | Q31: 54241.466 | R31: 54301.253 | S31: 54349.738 | T31: 54381.021 | U31: 54404.263 | V31: 54402.467 | W31: 54410.845 | X31: 54406.715 | Y31: 54393.489 | Z31: 54380.342 | AA31: 54366.31 | AB31: 54349.841 | AC31: 54336.108 | AD31: 54322.803 | AE31: 54311.189 | AF31: 54296.405 | AG31: 54844.01 | AH31: 54904.185 | AI31: 54964.36 | AJ31: 55024.535 | AK31: 55084.71 | AL31: 55144.885 | AM31: 55205.06 | AN31: 55265.235 | AO31: 55325.41 | AP31: 55385.585 | AQ31: 55445.76 | AR31: 55505.935 | AS31: 55566.11 | AT31: 55626.285 | AU31: 55686.46 | AV31: 55746.635 | AW31: 55806.81 | AX31: 55866.985 | AY31: 55927.16 | AZ31: 55987.335
A32: LPG vehicle | B32: 50808.77 | C32: 51640.914 | D32: 51593.1 | E32: 51682.984 | F32: 51804.867 | G32: 52031.947 | H32: 52221.667 | I32: 52319.038 | J32: 52405.243 | K32: 52498.573 | L32: 52586.071 | M32: 52673.071 | N32: 52747.277 | O32: 52836.324 | P32: 52896.59 | Q32: 52951.005 | R32: 53007.249 | S32: 53063.936 | T32: 53117.056 | U32: 53173.35 | V32: 53221.773 | W32: 53270.305 | X32: 53318.44 | Y32: 53364.075 | Z32: 53411.295 | AA32: 53459.946 | AB32: 53508.19 | AC32: 53558.081 | AD32: 53607.897 | AE32: 53658.322 | AF32: 53690.117 | AG32: 54004.877 | AH32: 54081.538 | AI32: 54158.198 | AJ32: 54234.859 | AK32: 54311.52 | AL32: 54388.181 | AM32: 54464.841 | AN32: 54541.502 | AO32: 54618.163 | AP32: 54694.823 | AQ32: 54771.484 | AR32: 54848.145 | AS32: 54924.806 | AT32: 55001.466 | AU32: 55078.127 | AV32: 55154.788 | AW32: 55231.448 | AX32: 55308.109 | AY32: 55384.77 | AZ32: 55461.43
A33: hydrogen vehicle | B33: 93314.03 | C33: 93293.735 | D33: 91275.805 | E33: 89499.402 | F33: 87705.045 | G33: 85847.774 | H33: 84216.142 | I33: 82714.551 | J33: 81282.281 | K33: 79917.567 | L33: 78616.541 | M33: 77378.157 | N33: 76192.258 | O33: 75069.996 | P33: 73968.533 | Q33: 72912.43 | R33: 71906.517 | S33: 70947.153 | T33: 70032.372 | U33: 69161.015 | V33: 68328.087 | W33: 67535.288 | X33: 66779.121 | Y33: 66057.957 | Z33: 65370.857 | AA33: 64715.909 | AB33: 64091.238 | AC33: 63496.192 | AD33: 62928.631 | AE33: 62388.175 | AF33: 61848.24 | AG33: 57715.443 | AH33: 56647.677 | AI33: 55579.91 | AJ33: 54512.143 | AK33: 53444.377 | AL33: 52376.61 | AM33: 51308.843 | AN33: 50241.077 | AO33: 49173.31 | AP33: 48105.543 | AQ33: 47037.777 | AR33: 45970.01 | AS33: 44902.243 | AT33: 43834.477 | AU33: 42766.71 | AV33: 41698.943 | AW33: 40631.177 | AX33: 39563.41 | AY33: 38495.643 | AZ33: 37427.877
A35: BNVP-HDVs-psgr
A36: Price ($/vehicle) | B36: 2020 | C36: 2021 | D36: 2022 | E36: 2023 | F36: 2024 | G36: 2025 | H36: 2026 | I36: 2027 | J36: 2028 | K36: 2029 | L36: 2030 | M36: 2031 | N36: 2032 | O36: 2033 | P36: 2034 | Q36: 2035 | R36: 2036 | S36: 2037 | T36: 2038 | U36: 2039 | V36: 2040 | W36: 2041 | X36: 2042 | Y36: 2043 | Z36: 2044 | AA36: 2045 | AB36: 2046 | AC36: 2047 | AD36: 2048 | AE36: 2049 | AF36: 2050 | AG36: 2051 | AH36: 2052 | AI36: 2053 | AJ36: 2054 | AK36: 2055 | AL36: 2056 | AM36: 2057 | AN36: 2058 | AO36: 2059 | AP36: 2060 | AQ36: 2061 | AR36: 2062 | AS36: 2063 | AT36: 2064 | AU36: 2065 | AV36: 2066 | AW36: 2067 | AX36: 2068 | AY36: 2069 | AZ36: 2070
A37: battery electric vehicle | B37: 787140.4 | C37: 787140.4 | D37: 787140.4 | E37: 787140.4 | F37: 787140.4 | G37: 787140.4 | H37: 787140.4 | I37: 787140.4 | J37: 787140.4 | K37: 787140.4 | L37: 787140.4 | M37: 787140.4 | N37: 787140.4 | O37: 787140.4 | P37: 787140.4 | Q37: 787140.4 | R37: 787140.4 | S37: 787140.4 | T37: 787140.4 | U37: 787140.4 | V37: 787140.4 | W37: 787140.4 | X37: 787140.4 | Y37: 787140.4 | Z37: 787140.4 | AA37: 787140.4 | AB37: 787140.4 | AC37: 787140.4 | AD37: 787140.4 | AE37: 787140.4 | AF37: 787140.4 | AG37: 787140.4 | AH37: 787140.4 | AI37: 787140.4 | AJ37: 787140.4 | AK37: 787140.4 | AL37: 787140.4 | AM37: 787140.4 | AN37: 787140.4 | AO37: 787140.4 | AP37: 787140.4 | AQ37: 787140.4 | AR37: 787140.4 | AS37: 787140.4 | AT37: 787140.4 | AU37: 787140.4 | AV37: 787140.4 | AW37: 787140.4 | AX37: 787140.4 | AY37: 787140.4 | AZ37: 787140.4
A38: natural gas vehicle | B38: 543571.43 | C38: 539660.99 | D38: 541991.42 | E38: 545628.4 | F38: 548431.52 | G38: 551178.88 | H38: 553713.53 | I38: 556009.23 | J38: 558455.87 | K38: 560785.54 | L38: 562943.58 | M38: 565272.73 | N38: 567069.86 | O38: 569459.98 | P38: 570852.91 | Q38: 571983 | R38: 572979.15 | S38: 573958.33 | T38: 574868.62 | U38: 575803.27 | V38: 576460.15 | W38: 577205.52 | X38: 577829.42 | Y38: 578349.65 | Z38: 578881.99 | AA38: 579385.1 | AB38: 579847.85 | AC38: 580333.54 | AD38: 580822.64 | AE38: 581253.52 | AF38: 581688.07 | AG38: 589483.43 | AH38: 590889.3 | AI38: 592295.17 | AJ38: 593701.03 | AK38: 595106.9 | AL38: 596512.77 | AM38: 597918.64 | AN38: 599324.51 | AO38: 600730.38 | AP38: 602136.24 | AQ38: 603542.11 | AR38: 604947.98 | AS38: 606353.85 | AT38: 607759.72 | AU38: 609165.58 | AV38: 610571.45 | AW38: 611977.32 | AX38: 613383.19 | AY38: 614789.06 | AZ38: 616194.93
A39: gasoline vehicle | B39: 425813.12 | C39: 425813.12 | D39: 425813.12 | E39: 425813.12 | F39: 425813.12 | G39: 425813.12 | H39: 425813.12 | I39: 425813.12 | J39: 425813.12 | K39: 425813.12 | L39: 425813.12 | M39: 425813.12 | N39: 425813.12 | O39: 425813.12 | P39: 425813.12 | Q39: 425813.12 | R39: 425813.12 | S39: 425813.12 | T39: 425813.12 | U39: 425813.12 | V39: 425813.12 | W39: 425813.12 | X39: 425813.12 | Y39: 425813.12 | Z39: 425813.12 | AA39: 425813.12 | AB39: 425813.12 | AC39: 425813.12 | AD39: 425813.12 | AE39: 425813.12 | AF39: 425813.12 | AG39: 425813.12 | AH39: 425813.12 | AI39: 425813.12 | AJ39: 425813.12 | AK39: 425813.12 | AL39: 425813.12 | AM39: 425813.12 | AN39: 425813.12 | AO39: 425813.12 | AP39: 425813.12 | AQ39: 425813.12 | AR39: 425813.12 | AS39: 425813.12 | AT39: 425813.12 | AU39: 425813.12 | AV39: 425813.12 | AW39: 425813.12 | AX39: 425813.12 | AY39: 425813.12 | AZ39: 425813.12
A40: diesel vehicle | B40: 425813.12 | C40: 425813.12 | D40: 425813.12 | E40: 425813.12 | F40: 425813.12 | G40: 425813.12 | H40: 425813.12 | I40: 425813.12 | J40: 425813.12 | K40: 425813.12 | L40: 425813.12 | M40: 425813.12 | N40: 425813.12 | O40: 425813.12 | P40: 425813.12 | Q40: 425813.12 | R40: 425813.12 | S40: 425813.12 | T40: 425813.12 | U40: 425813.12 | V40: 425813.12 | W40: 425813.12 | X40: 425813.12 | Y40: 425813.12 | Z40: 425813.12 | AA40: 425813.12 | AB40: 425813.12 | AC40: 425813.12 | AD40: 425813.12 | AE40: 425813.12 | AF40: 425813.12 | AG40: 425813.12 | AH40: 425813.12 | AI40: 425813.12 | AJ40: 425813.12 | AK40: 425813.12 | AL40: 425813.12 | AM40: 425813.12 | AN40: 425813.12 | AO40: 425813.12 | AP40: 425813.12 | AQ40: 425813.12 | AR40: 425813.12 | AS40: 425813.12 | AT40: 425813.12 | AU40: 425813.12 | AV40: 425813.12 | AW40: 425813.12 | AX40: 425813.12 | AY40: 425813.12 | AZ40: 425813.12
A41: plugin hybrid vehicle | B41: 616714.29 | C41: 625145.13 | D41: 624243.15 | E41: 627313.84 | F41: 628000.59 | G41: 629872.59 | H41: 630637.52 | I41: 631073.23 | J41: 631983.87 | K41: 633157.67 | L41: 634469.96 | M41: 636148.81 | N41: 637593.8 | O41: 639529.6 | P41: 640519.78 | Q41: 641307.83 | R41: 642014.7 | S41: 642587.95 | T41: 642957.82 | U41: 643232.62 | V41: 643211.38 | W41: 643310.43 | X41: 643261.6 | Y41: 643105.23 | Z41: 642949.79 | AA41: 642783.89 | AB41: 642589.17 | AC41: 642426.81 | AD41: 642269.5 | AE41: 642132.18 | AF41: 641957.39 | AG41: 648431.84 | AH41: 649143.3 | AI41: 649854.76 | AJ41: 650566.22 | AK41: 651277.68 | AL41: 651989.14 | AM41: 652700.6 | AN41: 653412.06 | AO41: 654123.53 | AP41: 654834.99 | AQ41: 655546.45 | AR41: 656257.91 | AS41: 656969.37 | AT41: 657680.83 | AU41: 658392.29 | AV41: 659103.75 | AW41: 659815.22 | AX41: 660526.68 | AY41: 661238.14 | AZ41: 661949.6
A42: LPG vehicle | B42: 556134.73 | C42: 565243.08 | D42: 564719.73 | E42: 565703.57 | F42: 567037.66 | G42: 569523.2 | H42: 571599.8 | I42: 572665.59 | J42: 573609.15 | K42: 574630.71 | L42: 575588.44 | M42: 576540.71 | N42: 577352.94 | O42: 578327.62 | P42: 578987.27 | Q42: 579582.88 | R42: 580198.5 | S42: 580818.97 | T42: 581400.42 | U42: 582016.59 | V42: 582546.61 | W42: 583077.82 | X42: 583604.69 | Y42: 584104.19 | Z42: 584621.04 | AA42: 585153.56 | AB42: 585681.63 | AC42: 586227.71 | AD42: 586772.99 | AE42: 587324.92 | AF42: 587672.93 | AG42: 591118.18 | AH42: 591957.28 | AI42: 592796.38 | AJ42: 593635.49 | AK42: 594474.59 | AL42: 595313.69 | AM42: 596152.79 | AN42: 596991.89 | AO42: 597830.99 | AP42: 598670.09 | AQ42: 599509.19 | AR42: 600348.29 | AS42: 601187.39 | AT42: 602026.49 | AU42: 602865.6 | AV42: 603704.7 | AW42: 604543.8 | AX42: 605382.9 | AY42: 606222 | AZ42: 607061.1
A43: hydrogen vehicle | B43: 856850.98 | C43: 856664.62 | D43: 838135.09 | E43: 821823.37 | F43: 805346.78 | G43: 788292.49 | H43: 773310.12 | I43: 759521.84 | J43: 746370.1 | K43: 733838.69 | L43: 721892.09 | M43: 710520.7 | N43: 699631.24 | O43: 689326.14 | P43: 679212.01 | Q43: 669514.4 | R43: 660277.66 | S43: 651468.36 | T43: 643068.43 | U43: 635067.24 | V43: 627418.93 | W43: 620139.09 | X43: 613195.62 | Y43: 606573.58 | Z43: 600264.33 | AA43: 594250.29 | AB43: 588514.29 | AC43: 583050.31 | AD43: 577838.72 | AE43: 572876.01 | AF43: 567918.08 | AG43: 529968.9 | AH43: 520164.19 | AI43: 510359.48 | AJ43: 500554.78 | AK43: 490750.07 | AL43: 480945.36 | AM43: 471140.65 | AN43: 461335.94 | AO43: 451531.23 | AP43: 441726.52 | AQ43: 431921.81 | AR43: 422117.1 | AS43: 412312.4 | AT43: 402507.69 | AU43: 392702.98 | AV43: 382898.27 | AW43: 373093.56 | AX43: 363288.85 | AY43: 353484.14 | AZ43: 343679.43
A45: BNVP-HDVs-frgt
A46: Price ($/vehicle) | B46: 2020 | C46: 2021 | D46: 2022 | E46: 2023 | F46: 2024 | G46: 2025 | H46: 2026 | I46: 2027 | J46: 2028 | K46: 2029 | L46: 2030 | M46: 2031 | N46: 2032 | O46: 2033 | P46: 2034 | Q46: 2035 | R46: 2036 | S46: 2037 | T46: 2038 | U46: 2039 | V46: 2040 | W46: 2041 | X46: 2042 | Y46: 2043 | Z46: 2044 | AA46: 2045 | AB46: 2046 | AC46: 2047 | AD46: 2048 | AE46: 2049 | AF46: 2050 | AG46: 2051 | AH46: 2052 | AI46: 2053 | AJ46: 2054 | AK46: 2055 | AL46: 2056 | AM46: 2057 | AN46: 2058 | AO46: 2059 | AP46: 2060 | AQ46: 2061 | AR46: 2062 | AS46: 2063 | AT46: 2064 | AU46: 2065 | AV46: 2066 | AW46: 2067 | AX46: 2068 | AY46: 2069 | AZ46: 2070
...

Sheet BNVP-LDVs-psgr
A1: Price ($/vehicle) | B1: 2020 | C1: 2021 | D1: 2022 | E1: 2023 | F1: 2024 | G1: 2025 | H1: 2026 | I1: 2027 | J1: 2028 | K1: 2029 | L1: 2030 | M1: 2031 | N1: 2032 | O1: 2033 | P1: 2034 | Q1: 2035 | R1: 2036 | S1: 2037 | T1: 2038 | U1: 2039 | V1: 2040 | W1: 2041 | X1: 2042 | Y1: 2043 | Z1: 2044 | AA1: 2045 | AB1: 2046 | AC1: 2047 | AD1: 2048 | AE1: 2049 | AF1: 2050 | AG1: 2051 | AH1: 2052 | AI1: 2053 | AJ1: 2054 | AK1: 2055 | AL1: 2056 | AM1: 2057 | AN1: 2058 | AO1: 2059 | AP1: 2060 | AQ1: 2061 | AR1: 2062 | AS1: 2063 | AT1: 2064 | AU1: 2065 | AV1: 2066 | AW1: 2067 | AX1: 2068 | AY1: 2069 | AZ1: 2070
A2: battery electric vehicle | B2: =('NVP-Indonesia'!$B$12+'NVP-Indonesia'!$B$12*'NVP-Indonesia'!$B140) -> 21521.202 | C2: =(B2+B2*'NVP-Indonesia'!$B140) -> 21187.654 | D2: =(C2+C2*'NVP-Indonesia'!$B140) -> 20859.276 | E2: =(D2+D2*'NVP-Indonesia'!$B140) -> 20535.987 | F2: =(E2+E2*'NVP-Indonesia'!$B140) -> 20217.709 | G2: =(F2+F2*'NVP-Indonesia'!$B140) -> 19904.364 | H2: =(G2+G2*'NVP-Indonesia'!$B140) -> 19595.875 | I2: =(H2+H2*'NVP-Indonesia'!$B140) -> 19292.167 | J2: =(I2+I2*'NVP-Indonesia'!$B140) -> 18993.166 | ... AZ2: =(AY2+AY2*'NVP-Indonesia'!$B140) -> 9855.6297
A3: natural gas vehicle | B3: =('NVP-Indonesia'!$B$12+'NVP-Indonesia'!$B$12*'NVP-Indonesia'!$B141) -> 21914.895 | C3: =(B3+B3*'NVP-Indonesia'!$B141) -> 21969.927 | D3: =(C3+C3*'NVP-Indonesia'!$B141) -> 22025.098 | E3: =(D3+D3*'NVP-Indonesia'!$B141) -> 22080.407 | F3: =(E3+E3*'NVP-Indonesia'!$B141) -> 22135.855 | G3: =(F3+F3*'NVP-Indonesia'!$B141) -> 22191.443 | H3: =(G3+G3*'NVP-Indonesia'!$B141) -> 22247.17 | I3: =(H3+H3*'NVP-Indonesia'!$B141) -> 22303.037 | J3: =(I3+I3*'NVP-Indonesia'!$B141) -> 22359.044 | ... AZ3: =(AY3+AY3*'NVP-Indonesia'!$B141) -> 24842.82
A4: gasoline vehicle | B4: =('NVP-Indonesia'!$B$12+'NVP-Indonesia'!$B$12*'NVP-Indonesia'!$B142) -> 21864.419 | C4: =(B4+B4*'NVP-Indonesia'!$B142) -> 21868.839 | D4: =(C4+C4*'NVP-Indonesia'!$B142) -> 21873.26 | E4: =(D4+D4*'NVP-Indonesia'!$B142) -> 21877.682 | F4: =(E4+E4*'NVP-Indonesia'!$B142) -> 21882.104 | G4: =(F4+F4*'NVP-Indonesia'!$B142) -> 21886.528 | H4: =(G4+G4*'NVP-Indonesia'!$B142) -> 21890.952 | I4: =(H4+H4*'NVP-Indonesia'!$B142) -> 21895.378 | J4: =(I4+I4*'NVP-Indonesia'!$B142) -> 21899.804 | ... AZ4: =(AY4+AY4*'NVP-Indonesia'!$B142) -> 22086.516
A5: diesel vehicle | B5: =('NVP-Indonesia'!$B$12+'NVP-Indonesia'!$B$12*'NVP-Indonesia'!$B143) -> 21850.328 | C5: =(B5+B5*'NVP-Indonesia'!$B143) -> 21840.66 | D5: =(C5+C5*'NVP-Indonesia'!$B143) -> 21830.996 | E5: =(D5+D5*'NVP-Indonesia'!$B143) -> 21821.337 | F5: =(E5+E5*'NVP-Indonesia'!$B143) -> 21811.682 | G5: =(F5+F5*'NVP-Indonesia'!$B143) -> 21802.031 | H5: =(G5+G5*'NVP-Indonesia'!$B143) -> 21792.384 | I5: =(H5+H5*'NVP-Indonesia'!$B143) -> 21782.742 | J5: =(I5+I5*'NVP-Indonesia'!$B143) -> 21773.104 | ... AZ5: =(AY5+AY5*'NVP-Indonesia'!$B143) -> 21372.133
A6: plugin hybrid vehicle | B6: =('NVP-Indonesia'!$B$12+'NVP-Indonesia'!$B$12*'NVP-Indonesia'!$B144) -> 21890.968 | C6: =(B6+B6*'NVP-Indonesia'!$B144) -> 21921.981 | D6: =(C6+C6*'NVP-Indonesia'!$B144) -> 21953.037 | E6: =(D6+D6*'NVP-Indonesia'!$B144) -> 21984.137 | F6: =(E6+E6*'NVP-Indonesia'!$B144) -> 22015.282 | G6: =(F6+F6*'NVP-Indonesia'!$B144) -> 22046.47 | H6: =(G6+G6*'NVP-Indonesia'!$B144) -> 22077.703 | I6: =(H6+H6*'NVP-Indonesia'!$B144) -> 22108.98 | J6: =(I6+I6*'NVP-Indonesia'!$B144) -> 22140.301 | ... AZ6: =(AY6+AY6*'NVP-Indonesia'!$B144) -> 23496.647
A7: LPG vehicle | B7: =('NVP-Indonesia'!$B$12+'NVP-Indonesia'!$B$12*'NVP-Indonesia'!$B145) -> 21898.341 | C7: =(B7+B7*'NVP-Indonesia'!$B145) -> 21936.748 | D7: =(C7+C7*'NVP-Indonesia'!$B145) -> 21975.224 | E7: =(D7+D7*'NVP-Indonesia'!$B145) -> 22013.766 | F7: =(E7+E7*'NVP-Indonesia'!$B145) -> 22052.376 | G7: =(F7+F7*'NVP-Indonesia'!$B145) -> 22091.054 | H7: =(G7+G7*'NVP-Indonesia'!$B145) -> 22129.8 | I7: =(H7+H7*'NVP-Indonesia'!$B145) -> 22168.614 | J7: =(I7+I7*'NVP-Indonesia'!$B145) -> 22207.496 | ... AZ7: =(AY7+AY7*'NVP-Indonesia'!$B145) -> 23903.615
A8: hydrogen vehicle | B8: =('NVP-Indonesia'!$B$12+'NVP-Indonesia'!$B$12*'NVP-Indonesia'!$B146) -> 21464.221 | C8: =(B8+B8*'NVP-Indonesia'!$B146) -> 21075.607 | D8: =(C8+C8*'NVP-Indonesia'!$B146) -> 20694.029 | E8: =(D8+D8*'NVP-Indonesia'!$B146) -> 20319.36 | F8: =(E8+E8*'NVP-Indonesia'!$B146) -> 19951.474 | G8: =(F8+F8*'NVP-Indonesia'!$B146) -> 19590.249 | H8: =(G8+G8*'NVP-Indonesia'!$B146) -> 19235.563 | I8: =(H8+H8*'NVP-Indonesia'!$B146) -> 18887.3 | J8: =(I8+I8*'NVP-Indonesia'!$B146) -> 18545.342 | ... AZ8: =(AY8+AY8*'NVP-Indonesia'!$B146) -> 8609.2113

Sheet BNVP-LDVs-frgt
A1: Price ($/vehicle) | B1: 2020 | C1: 2021 | D1: 2022 | E1: 2023 | F1: 2024 | G1: 2025 | H1: 2026 | I1: 2027 | J1: 2028 | K1: 2029 | L1: 2030 | M1: 2031 | N1: 2032 | O1: 2033 | P1: 2034 | Q1: 2035 | R1: 2036 | S1: 2037 | T1: 2038 | U1: 2039 | V1: 2040 | W1: 2041 | X1: 2042 | Y1: 2043 | Z1: 2044 | AA1: 2045 | AB1: 2046 | AC1: 2047 | AD1: 2048 | AE1: 2049 | AF1: 2050 | AG1: 2051 | AH1: 2052 | AI1: 2053 | AJ1: 2054 | AK1: 2055 | AL1: 2056 | AM1: 2057 | AN1: 2058 | AO1: 2059 | AP1: 2060 | AQ1: 2061 | AR1: 2062 | AS1: 2063 | AT1: 2064 | AU1: 2065 | AV1: 2066 | AW1: 2067 | AX1: 2068 | AY1: 2069 | AZ1: 2070
A2: battery electric vehicle | B2: ='NVP-Indonesia'!B27*'NVP-Indonesia'!$B$176 -> 58095.337 | C2: ='NVP-Indonesia'!C27*'NVP-Indonesia'!$B$176 -> 58095.337 | D2: ='NVP-Indonesia'!D27*'NVP-Indonesia'!$B$176 -> 58095.337 | E2: ='NVP-Indonesia'!E27*'NVP-Indonesia'!$B$176 -> 58095.337 | F2: ='NVP-Indonesia'!F27*'NVP-Indonesia'!$B$176 -> 58095.337 | G2: ='NVP-Indonesia'!G27*'NVP-Indonesia'!$B$176 -> 58095.337 | H2: ='NVP-Indonesia'!H27*'NVP-Indonesia'!$B$176 -> 58095.337 | I2: ='NVP-Indonesia'!I27*'NVP-Indonesia'!$B$176 -> 58095.337 | ... AZ2: ='NVP-Indonesia'!AZ27*'NVP-Indonesia'!$B$176 -> 58095.337
A3: natural gas vehicle | B3: ='NVP-Indonesia'!B28*'NVP-Indonesia'!$B$176 -> 40546.809 | C3: ='NVP-Indonesia'!C28*'NVP-Indonesia'!$B$176 -> 40255.116 | D3: ='NVP-Indonesia'!D28*'NVP-Indonesia'!$B$176 -> 40428.95 | E3: ='NVP-Indonesia'!E28*'NVP-Indonesia'!$B$176 -> 40700.245 | F3: ='NVP-Indonesia'!F28*'NVP-Indonesia'!$B$176 -> 40909.339 | G3: ='NVP-Indonesia'!G28*'NVP-Indonesia'!$B$176 -> 41114.274 | H3: ='NVP-Indonesia'!H28*'NVP-Indonesia'!$B$176 -> 41303.342 | I3: ='NVP-Indonesia'!I28*'NVP-Indonesia'!$B$176 -> 41474.586 | ... AZ3: ='NVP-Indonesia'!AZ28*'NVP-Indonesia'!$B$176 -> 45964.038
A4: gasoline vehicle | B4: ='NVP-Indonesia'!B29*'NVP-Indonesia'!$B$176 -> 35674.636 | C4: ='NVP-Indonesia'!C29*'NVP-Indonesia'!$B$176 -> 35674.636 | D4: ='NVP-Indonesia'!D29*'NVP-Indonesia'!$B$176 -> 35674.636 | E4: ='NVP-Indonesia'!E29*'NVP-Indonesia'!$B$176 -> 35674.636 | F4: ='NVP-Indonesia'!F29*'NVP-Indonesia'!$B$176 -> 35674.636 | G4: ='NVP-Indonesia'!G29*'NVP-Indonesia'!$B$176 -> 35674.636 | H4: ='NVP-Indonesia'!H29*'NVP-Indonesia'!$B$176 -> 35674.636 | I4: ='NVP-Indonesia'!I29*'NVP-Indonesia'!$B$176 -> 35674.636 | ... AZ4: ='NVP-Indonesia'!AZ29*'NVP-Indonesia'!$B$176 -> 35674.636
A5: diesel vehicle | B5: ='NVP-Indonesia'!B30*'NVP-Indonesia'!$B$176 -> 39638.484 | C5: ='NVP-Indonesia'!C30*'NVP-Indonesia'!$B$176 -> 39638.484 | D5: ='NVP-Indonesia'!D30*'NVP-Indonesia'!$B$176 -> 39638.484 | E5: ='NVP-Indonesia'!E30*'NVP-Indonesia'!$B$176 -> 39638.484 | F5: ='NVP-Indonesia'!F30*'NVP-Indonesia'!$B$176 -> 39638.484 | G5: ='NVP-Indonesia'!G30*'NVP-Indonesia'!$B$176 -> 39638.484 | H5: ='NVP-Indonesia'!H30*'NVP-Indonesia'!$B$176 -> 39638.484 | I5: ='NVP-Indonesia'!I30*'NVP-Indonesia'!$B$176 -> 39638.484 | ... AZ5: ='NVP-Indonesia'!AZ30*'NVP-Indonesia'!$B$176 -> 39638.484
A6: plugin hybrid vehicle | B6: ='NVP-Indonesia'!B31*'NVP-Indonesia'!$B$176 -> 40685.859 | C6: ='NVP-Indonesia'!C31*'NVP-Indonesia'!$B$176 -> 41242.058 | D6: ='NVP-Indonesia'!D31*'NVP-Indonesia'!$B$176 -> 41182.553 | E6: ='NVP-Indonesia'!E31*'NVP-Indonesia'!$B$176 -> 41385.132 | F6: ='NVP-Indonesia'!F31*'NVP-Indonesia'!$B$176 -> 41430.439 | G6: ='NVP-Indonesia'!G31*'NVP-Indonesia'!$B$176 -> 41553.938 | H6: ='NVP-Indonesia'!H31*'NVP-Indonesia'!$B$176 -> 41604.402 | I6: ='NVP-Indonesia'!I31*'NVP-Indonesia'!$B$176 -> 41633.147 | ... AZ6: ='NVP-Indonesia'!AZ31*'NVP-Indonesia'!$B$176 -> 43670.122
A7: LPG vehicle | B7: ='NVP-Indonesia'!B32*'NVP-Indonesia'!$B$176 -> 39630.84 | C7: ='NVP-Indonesia'!C32*'NVP-Indonesia'!$B$176 -> 40279.913 | D7: ='NVP-Indonesia'!D32*'NVP-Indonesia'!$B$176 -> 40242.618 | E7: ='NVP-Indonesia'!E32*'NVP-Indonesia'!$B$176 -> 40312.727 | F7: ='NVP-Indonesia'!F32*'NVP-Indonesia'!$B$176 -> 40407.796 | G7: ='NVP-Indonesia'!G32*'NVP-Indonesia'!$B$176 -> 40584.919 | H7: ='NVP-Indonesia'!H32*'NVP-Indonesia'!$B$176 -> 40732.9 | I7: ='NVP-Indonesia'!I32*'NVP-Indonesia'!$B$176 -> 40808.85 | ... AZ7: ='NVP-Indonesia'!AZ32*'NVP-Indonesia'!$B$176 -> 43259.916
A8: hydrogen vehicle | B8: ='NVP-Indonesia'!B33*'NVP-Indonesia'!$B$176 -> 72784.944 | C8: ='NVP-Indonesia'!C33*'NVP-Indonesia'!$B$176 -> 72769.113 | D8: ='NVP-Indonesia'!D33*'NVP-Indonesia'!$B$176 -> 71195.128 | E8: ='NVP-Indonesia'!E33*'NVP-Indonesia'!$B$176 -> 69809.534 | F8: ='NVP-Indonesia'!F33*'NVP-Indonesia'!$B$176 -> 68409.935 | G8: ='NVP-Indonesia'!G33*'NVP-Indonesia'!$B$176 -> 66961.263 | H8: ='NVP-Indonesia'!H33*'NVP-Indonesia'!$B$176 -> 65688.591 | I8: ='NVP-Indonesia'!I33*'NVP-Indonesia'!$B$176 -> 64517.35 | ... AZ8: ='NVP-Indonesia'!AZ33*'NVP-Indonesia'!$B$176 -> 29193.744

Sheet BNVP-HDVs-psgr
A1: Price ($/vehicle) | B1: 2020 | C1: 2021 | D1: 2022 | E1: 2023 | F1: 2024 | G1: 2025 | H1: 2026 | I1: 2027 | J1: 2028 | K1: 2029 | L1: 2030 | M1: 2031 | N1: 2032 | O1: 2033 | P1: 2034 | Q1: 2035 | R1: 2036 | S1: 2037 | T1: 2038 | U1: 2039 | V1: 2040 | W1: 2041 | X1: 2042 | Y1: 2043 | Z1: 2044 | AA1: 2045 | AB1: 2046 | AC1: 2047 | AD1: 2048 | AE1: 2049 | AF1: 2050 | AG1: 2051 | AH1: 2052 | AI1: 2053 | AJ1: 2054 | AK1: 2055 | AL1: 2056 | AM1: 2057 | AN1: 2058 | AO1: 2059 | AP1: 2060 | AQ1: 2061 | AR1: 2062 | AS1: 2063 | AT1: 2064 | AU1: 2065 | AV1: 2066 | AW1: 2067 | AX1: 2068 | AY1: 2069 | AZ1: 2070
A2: battery electric vehicle | B2: ='NVP-Indonesia'!$B$12+'NVP-Indonesia'!$B$12*'NVP-Indonesia'!B151 -> 21860 | C2: =B2+B2*'NVP-Indonesia'!B151 -> 21860 | D2: =C2+C2*'NVP-Indonesia'!C151 -> 21860 | E2: =D2+D2*'NVP-Indonesia'!D151 -> 21860 | F2: =E2+E2*'NVP-Indonesia'!E151 -> 21860 | G2: =F2+F2*'NVP-Indonesia'!F151 -> 21860 | H2: =G2+G2*'NVP-Indonesia'!G151 -> 21860 | I2: =H2+H2*'NVP-Indonesia'!H151 -> 21860 | J2: =I2+I2*'NVP-Indonesia'!I151 -> 21860 | ... AZ2: =AY2+AY2*'NVP-Indonesia'!AY151 -> 21860
A3: natural gas vehicle | B3: ='NVP-Indonesia'!$B$12+'NVP-Indonesia'!$B$12*'NVP-Indonesia'!B152 -> 21914.895 | C3: =B3+B3*'NVP-Indonesia'!B152 -> 21969.927 | D3: =C3+C3*'NVP-Indonesia'!C152 -> 21969.927 | E3: =D3+D3*'NVP-Indonesia'!D152 -> 21969.927 | F3: =E3+E3*'NVP-Indonesia'!E152 -> 21969.927 | G3: =F3+F3*'NVP-Indonesia'!F152 -> 21969.927 | H3: =G3+G3*'NVP-Indonesia'!G152 -> 21969.927 | I3: =H3+H3*'NVP-Indonesia'!H152 -> 21969.927 | J3: =I3+I3*'NVP-Indonesia'!I152 -> 21969.927 | ... AZ3: =AY3+AY3*'NVP-Indonesia'!AY152 -> 21969.927
A4: gasoline vehicle | B4: ='NVP-Indonesia'!$B$12+'NVP-Indonesia'!$B$12*'NVP-Indonesia'!B153 -> 21860 | C4: =B4+B4*'NVP-Indonesia'!B153 -> 21860 | D4: =C4+C4*'NVP-Indonesia'!C153 -> 21860 | E4: =D4+D4*'NVP-Indonesia'!D153 -> 21860 | F4: =E4+E4*'NVP-Indonesia'!E153 -> 21860 | G4: =F4+F4*'NVP-Indonesia'!F153 -> 21860 | H4: =G4+G4*'NVP-Indonesia'!G153 -> 21860 | I4: =H4+H4*'NVP-Indonesia'!H153 -> 21860 | J4: =I4+I4*'NVP-Indonesia'!I153 -> 21860 | ... AZ4: =AY4+AY4*'NVP-Indonesia'!AY153 -> 21860
A5: diesel vehicle | B5: ='NVP-Indonesia'!$B$12+'NVP-Indonesia'!$B$12*'NVP-Indonesia'!B154 -> 21860 | C5: =B5+B5*'NVP-Indonesia'!B154 -> 21860 | D5: =C5+C5*'NVP-Indonesia'!C154 -> 21860 | E5: =D5+D5*'NVP-Indonesia'!D154 -> 21860 | F5: =E5+E5*'NVP-Indonesia'!E154 -> 21860 | G5: =F5+F5*'NVP-Indonesia'!F154 -> 21860 | H5: =G5+G5*'NVP-Indonesia'!G154 -> 21860 | I5: =H5+H5*'NVP-Indonesia'!H154 -> 21860 | J5: =I5+I5*'NVP-Indonesia'!I154 -> 21860 | ... AZ5: =AY5+AY5*'NVP-Indonesia'!AY154 -> 21860
A6: plugin hybrid vehicle | B6: ='NVP-Indonesia'!$B$12+'NVP-Indonesia'!$B$12*'NVP-Indonesia'!B155 -> 21890.968 | C6: =B6+B6*'NVP-Indonesia'!B155 -> 21921.981 | D6: =C6+C6*'NVP-Indonesia'!C155 -> 21921.981 | E6: =D6+D6*'NVP-Indonesia'!D155 -> 21921.981 | F6: =E6+E6*'NVP-Indonesia'!E155 -> 21921.981 | G6: =F6+F6*'NVP-Indonesia'!F155 -> 21921.981 | H6: =G6+G6*'NVP-Indonesia'!G155 -> 21921.981 | I6: =H6+H6*'NVP-Indonesia'!H155 -> 21921.981 | J6: =I6+I6*'NVP-Indonesia'!I155 -> 21921.981 | ... AZ6: =AY6+AY6*'NVP-Indonesia'!AY155 -> 21921.981
A7: LPG vehicle | B7: ='NVP-Indonesia'!$B$12+'NVP-Indonesia'!$B$12*'NVP-Indonesia'!B156 -> 21898.341 | C7: =B7+B7*'NVP-Indonesia'!B156 -> 21936.748 | D7: =C7+C7*'NVP-Indonesia'!C156 -> 21936.748 | E7: =D7+D7*'NVP-Indonesia'!D156 -> 21936.748 | F7: =E7+E7*'NVP-Indonesia'!E156 -> 21936.748 | G7: =F7+F7*'NVP-Indonesia'!F156 -> 21936.748 | H7: =G7+G7*'NVP-Indonesia'!G156 -> 21936.748 | I7: =H7+H7*'NVP-Indonesia'!H156 -> 21936.748 | J7: =I7+I7*'NVP-Indonesia'!I156 -> 21936.748 | ... AZ7: =AY7+AY7*'NVP-Indonesia'!AY156 -> 21936.748
A8: hydrogen vehicle | B8: ='NVP-Indonesia'!$B$12+'NVP-Indonesia'!$B$12*'NVP-Indonesia'!B157 -> 21464.221 | C8: =B8+B8*'NVP-Indonesia'!B157 -> 21075.607 | D8: =C8+C8*'NVP-Indonesia'!C157 -> 21075.607 | E8: =D8+D8*'NVP-Indonesia'!D157 -> 21075.607 | F8: =E8+E8*'NVP-Indonesia'!E157 -> 21075.607 | G8: =F8+F8*'NVP-Indonesia'!F157 -> 21075.607 | H8: =G8+G8*'NVP-Indonesia'!G157 -> 21075.607 | I8: =H8+H8*'NVP-Indonesia'!H157 -> 21075.607 | J8: =I8+I8*'NVP-Indonesia'!I157 -> 21075.607 | ... AZ8: =AY8+AY8*'NVP-Indonesia'!AY157 -> 21075.607

Sheet BNVP-HDVs-frgt
A1: Price ($/vehicle) | B1: 2020 | C1: 2021 | D1: 2022 | E1: 2023 | F1: 2024 | G1: 2025 | H1: 2026 | I1: 2027 | J1: 2028 | K1: 2029 | L1: 2030 | M1: 2031 | N1: 2032 | O1: 2033 | P1: 2034 | Q1: 2035 | R1: 2036 | S1: 2037 | T1: 2038 | U1: 2039 | V1: 2040 | W1: 2041 | X1: 2042 | Y1: 2043 | Z1: 2044 | AA1: 2045 | AB1: 2046 | AC1: 2047 | AD1: 2048 | AE1: 2049 | AF1: 2050 | AG1: 2051 | AH1: 2052 | AI1: 2053 | AJ1: 2054 | AK1: 2055 | AL1: 2056 | AM1: 2057 | AN1: 2058 | AO1: 2059 | AP1: 2060 | AQ1: 2061 | AR1: 2062 | AS1: 2063 | AT1: 2064 | AU1: 2065 | AV1: 2066 | AW1: 2067 | AX1: 2068 | AY1: 2069 | AZ1: 2070
A2: battery electric vehicle | B2: ='NVP-Indonesia'!B47*'NVP-Indonesia'!$B$176 -> 165612.15 | C2: ='NVP-Indonesia'!C47*'NVP-Indonesia'!$B$176 -> 165612.15 | D2: ='NVP-Indonesia'!D47*'NVP-Indonesia'!$B$176 -> 165612.15 | E2: ='NVP-Indonesia'!E47*'NVP-Indonesia'!$B$176 -> 165612.15 | F2: ='NVP-Indonesia'!F47*'NVP-Indonesia'!$B$176 -> 165612.15 | G2: ='NVP-Indonesia'!G47*'NVP-Indonesia'!$B$176 -> 165612.15 | H2: ='NVP-Indonesia'!H47*'NVP-Indonesia'!$B$176 -> 165612.15 | I2: ='NVP-Indonesia'!I47*'NVP-Indonesia'!$B$176 -> 165612.15 | ... AZ2: ='NVP-Indonesia'!AZ47*'NVP-Indonesia'!$B$176 -> 165612.15
A3: natural gas vehicle | B3: ='NVP-Indonesia'!B48*'NVP-Indonesia'!$B$176 -> 131883.19 | C3: ='NVP-Indonesia'!C48*'NVP-Indonesia'!$B$176 -> 130934.43 | D3: ='NVP-Indonesia'!D48*'NVP-Indonesia'!$B$176 -> 131499.84 | E3: ='NVP-Indonesia'!E48*'NVP-Indonesia'!$B$176 -> 132382.26 | F3: ='NVP-Indonesia'!F48*'NVP-Indonesia'!$B$176 -> 133062.36 | G3: ='NVP-Indonesia'!G48*'NVP-Indonesia'!$B$176 -> 133728.94 | H3: ='NVP-Indonesia'!H48*'NVP-Indonesia'!$B$176 -> 134343.9 | I3: ='NVP-Indonesia'!I48*'NVP-Indonesia'!$B$176 -> 134900.89 | ... AZ3: ='NVP-Indonesia'!AZ48*'NVP-Indonesia'!$B$176 -> 149503.36
A4: gasoline vehicle | B4: ='NVP-Indonesia'!B49*'NVP-Indonesia'!$B$176 -> 90895.799 | C4: ='NVP-Indonesia'!C49*'NVP-Indonesia'!$B$176 -> 90895.799 | D4: ='NVP-Indonesia'!D49*'NVP-Indonesia'!$B$176 -> 90895.799 | E4: ='NVP-Indonesia'!E49*'NVP-Indonesia'!$B$176 -> 90895.799 | F4: ='NVP-Indonesia'!F49*'NVP-Indonesia'!$B$176 -> 90895.799 | G4: ='NVP-Indonesia'!G49*'NVP-Indonesia'!$B$176 -> 90895.799 | H4: ='NVP-Indonesia'!H49*'NVP-Indonesia'!$B$176 -> 90895.799 | I4: ='NVP-Indonesia'!I49*'NVP-Indonesia'!$B$176 -> 90895.799 | ... AZ4: ='NVP-Indonesia'!AZ49*'NVP-Indonesia'!$B$176 -> 90895.799
A5: diesel vehicle | B5: ='NVP-Indonesia'!B50*'NVP-Indonesia'!$B$176 -> 90895.799 | C5: ='NVP-Indonesia'!C50*'NVP-Indonesia'!$B$176 -> 90895.799 | D5: ='NVP-Indonesia'!D50*'NVP-Indonesia'!$B$176 -> 90895.799 | E5: ='NVP-Indonesia'!E50*'NVP-Indonesia'!$B$176 -> 90895.799 | F5: ='NVP-Indonesia'!F50*'NVP-Indonesia'!$B$176 -> 90895.799 | G5: ='NVP-Indonesia'!G50*'NVP-Indonesia'!$B$176 -> 90895.799 | H5: ='NVP-Indonesia'!H50*'NVP-Indonesia'!$B$176 -> 90895.799 | I5: ='NVP-Indonesia'!I50*'NVP-Indonesia'!$B$176 -> 90895.799 | ... AZ5: ='NVP-Indonesia'!AZ50*'NVP-Indonesia'!$B$176 -> 90895.799
A6: plugin hybrid vehicle | B6: ='NVP-Indonesia'!B51*'NVP-Indonesia'!$B$176 -> 228319.42 | C6: ='NVP-Indonesia'!C51*'NVP-Indonesia'!$B$176 -> 231440.68 | D6: ='NVP-Indonesia'!D51*'NVP-Indonesia'!$B$176 -> 231106.75 | E6: ='NVP-Indonesia'!E51*'NVP-Indonesia'!$B$176 -> 232243.57 | F6: ='NVP-Indonesia'!F51*'NVP-Indonesia'!$B$176 -> 232497.82 | G6: ='NVP-Indonesia'!G51*'NVP-Indonesia'!$B$176 -> 233190.87 | H6: ='NVP-Indonesia'!H51*'NVP-Indonesia'!$B$176 -> 233474.06 | I6: ='NVP-Indonesia'!I51*'NVP-Indonesia'!$B$176 -> 233635.37 | ... AZ6: ='NVP-Indonesia'!AZ51*'NVP-Indonesia'!$B$176 -> 245066.39
A7: LPG vehicle | B7: ='NVP-Indonesia'!B52*'NVP-Indonesia'!$B$176 -> 128903.9 | C7: ='NVP-Indonesia'!C52*'NVP-Indonesia'!$B$176 -> 131015.08 | D7: ='NVP-Indonesia'!D52*'NVP-Indonesia'!$B$176 -> 130893.78 | E7: ='NVP-Indonesia'!E52*'NVP-Indonesia'!$B$176 -> 131121.81 | F7: ='NVP-Indonesia'!F52*'NVP-Indonesia'!$B$176 -> 131431.04 | G7: ='NVP-Indonesia'!G52*'NVP-Indonesia'!$B$176 -> 132007.15 | H7: ='NVP-Indonesia'!H52*'NVP-Indonesia'!$B$176 -> 132488.47 | I7: ='NVP-Indonesia'!I52*'NVP-Indonesia'!$B$176 -> 132735.51 | ... AZ7: ='NVP-Indonesia'!AZ52*'NVP-Indonesia'!$B$176 -> 140707.89
A8: hydrogen vehicle | B8: ='NVP-Indonesia'!B53*'NVP-Indonesia'!$B$176 -> 277734.94 | C8: ='NVP-Indonesia'!C53*'NVP-Indonesia'!$B$176 -> 277674.53 | D8: ='NVP-Indonesia'!D53*'NVP-Indonesia'!$B$176 -> 271668.47 | E8: ='NVP-Indonesia'!E53*'NVP-Indonesia'!$B$176 -> 266381.28 | F8: ='NVP-Indonesia'!F53*'NVP-Indonesia'!$B$176 -> 261040.65 | G8: ='NVP-Indonesia'!G53*'NVP-Indonesia'!$B$176 -> 255512.77 | H8: ='NVP-Indonesia'!H53*'NVP-Indonesia'!$B$176 -> 250656.47 | I8: ='NVP-Indonesia'!I53*'NVP-Indonesia'!$B$176 -> 246187.21 | ... AZ8: ='NVP-Indonesia'!AZ53*'NVP-Indonesia'!$B$176 -> 111398.35

Sheet BNVP-aircraft-psgr
A1: Price ($/vehicle) | B1: 2020 | C1: 2021 | D1: 2022 | E1: 2023 | F1: 2024 | G1: 2025 | H1: 2026 | I1: 2027 | J1: 2028 | K1: 2029 | L1: 2030 | M1: 2031 | N1: 2032 | O1: 2033 | P1: 2034 | Q1: 2035 | R1: 2036 | S1: 2037 | T1: 2038 | U1: 2039 | V1: 2040 | W1: 2041 | X1: 2042 | Y1: 2043 | Z1: 2044 | AA1: 2045 | AB1: 2046 | AC1: 2047 | AD1: 2048 | AE1: 2049 | AF1: 2050 | AG1: 2051 | AH1: 2052 | AI1: 2053 | AJ1: 2054 | AK1: 2055 | AL1: 2056 | AM1: 2057 | AN1: 2058 | AO1: 2059 | AP1: 2060 | AQ1: 2061 | AR1: 2062 | AS1: 2063 | AT1: 2064 | AU1: 2065 | AV1: 2066 | AW1: 2067 | AX1: 2068 | AY1: 2069 | AZ1: 2070
A2: battery electric vehicle | B2: ='NVP-Indonesia'!B57*'NVP-Indonesia'!$B$176 -> 93481595 | C2: =B2 -> 93481595 | D2: =C2 -> 93481595 | E2: =D2 -> 93481595 | F2: =E2 -> 93481595 | G2: =F2 -> 93481595 | H2: =G2 -> 93481595 | I2: =H2 -> 93481595 | J2: =I2 -> 93481595 | ... AF2: =AE2 -> 93481595 | AG2: =_xlfn.FORECAST.LINEAR(AG$1,$B2:$AF2,$B$1:$AF$1) -> 93481595 | AH2: =_xlfn.FORECAST.LINEAR(AH$1,$B2:$AF2,$B$1:$AF$1) -> 93481595 | AI2: =_xlfn.FORECAST.LINEAR(AI$1,$B2:$AF2,$B$1:$AF$1) -> 93481595 | AJ2: =_xlfn.FORECAST.LINEAR(AJ$1,$B2:$AF2,$B$1:$AF$1) -> 93481595 | AK2: =_xlfn.FORECAST.LINEAR(AK$1,$B2:$AF2,$B$1:$AF$1) -> 93481595 | AL2: =_xlfn.FORECAST.LINEAR(AL$1,$B2:$AF2,$B$1:$AF$1) -> 93481595 | AM2: =_xlfn.FORECAST.LINEAR(AM$1,$B2:$AF2,$B$1:$AF$1) -> 93481595 | AN2: =_xlfn.FORECAST.LINEAR(AN$1,$B2:$AF2,$B$1:$AF$1) -> 93481595 | ... AZ2: =_xlfn.FORECAST.LINEAR(AZ$1,$B2:$AF2,$B$1:$AF$1) -> 93481595
A3: natural gas vehicle | B3: 999999999 | C3: 999999999 | D3: 999999999 | E3: 999999999 | F3: 999999999 | G3: 999999999 | H3: 999999999 | I3: 999999999 | J3: 999999999 | K3: 999999999 | L3: 999999999 | M3: 999999999 | N3: 999999999 | O3: 999999999 | P3: 999999999 | Q3: 999999999 | R3: 999999999 | S3: 999999999 | T3: 999999999 | U3: 999999999 | V3: 999999999 | W3: 999999999 | X3: 999999999 | Y3: 999999999 | Z3: 999999999 | AA3: 999999999 | AB3: 999999999 | AC3: 999999999 | AD3: 999999999 | AE3: 999999999 | AF3: 999999999 | AG3: 999999999 | AH3: 999999999 | AI3: 999999999 | AJ3: 999999999 | AK3: 999999999 | AL3: 999999999 | AM3: 999999999 | AN3: 999999999 | AO3: 999999999 | AP3: 999999999 | AQ3: 999999999 | AR3: 999999999 | AS3: 999999999 | AT3: 999999999 | AU3: 999999999 | AV3: 999999999 | AW3: 999999999 | AX3: 999999999 | AY3: 999999999 | AZ3: 999999999
A4: gasoline vehicle | B4: 999999999 | C4: 999999999 | D4: 999999999 | E4: 999999999 | F4: 999999999 | G4: 999999999 | H4: 999999999 | I4: 999999999 | J4: 999999999 | K4: 999999999 | L4: 999999999 | M4: 999999999 | N4: 999999999 | O4: 999999999 | P4: 999999999 | Q4: 999999999 | R4: 999999999 | S4: 999999999 | T4: 999999999 | U4: 999999999 | V4: 999999999 | W4: 999999999 | X4: 999999999 | Y4: 999999999 | Z4: 999999999 | AA4: 999999999 | AB4: 999999999 | AC4: 999999999 | AD4: 999999999 | AE4: 999999999 | AF4: 999999999 | AG4: 999999999 | AH4: 999999999 | AI4: 999999999 | AJ4: 999999999 | AK4: 999999999 | AL4: 999999999 | AM4: 999999999 | AN4: 999999999 | AO4: 999999999 | AP4: 999999999 | AQ4: 999999999 | AR4: 999999999 | AS4: 999999999 | AT4: 999999999 | AU4: 999999999 | AV4: 999999999 | AW4: 999999999 | AX4: 999999999 | AY4: 999999999 | AZ4: 999999999
A5: diesel vehicle | B5: ='NVP-Indonesia'!B60*'NVP-Indonesia'!$B$176 -> 50570000 | C5: =$B5 -> 50570000 | D5: =$B5 -> 50570000 | E5: =$B5 -> 50570000 | F5: =$B5 -> 50570000 | G5: =$B5 -> 50570000 | H5: =$B5 -> 50570000 | I5: =$B5 -> 50570000 | J5: =$B5 -> 50570000 | ... AF5: =$B5 -> 50570000 | AG5: =_xlfn.FORECAST.LINEAR(AG$1,$B5:$AF5,$B$1:$AF$1) -> 50570000 | AH5: =_xlfn.FORECAST.LINEAR(AH$1,$B5:$AF5,$B$1:$AF$1) -> 50570000 | AI5: =_xlfn.FORECAST.LINEAR(AI$1,$B5:$AF5,$B$1:$AF$1) -> 50570000 | AJ5: =_xlfn.FORECAST.LINEAR(AJ$1,$B5:$AF5,$B$1:$AF$1) -> 50570000 | AK5: =_xlfn.FORECAST.LINEAR(AK$1,$B5:$AF5,$B$1:$AF$1) -> 50570000 | AL5: =_xlfn.FORECAST.LINEAR(AL$1,$B5:$AF5,$B$1:$AF$1) -> 50570000 | AM5: =_xlfn.FORECAST.LINEAR(AM$1,$B5:$AF5,$B$1:$AF$1) -> 50570000 | AN5: =_xlfn.FORECAST.LINEAR(AN$1,$B5:$AF5,$B$1:$AF$1) -> 50570000 | ... AZ5: =_xlfn.FORECAST.LINEAR(AZ$1,$B5:$AF5,$B$1:$AF$1) -> 50570000
A6: plugin hybrid vehicle | B6: 999999999 | C6: 999999999 | D6: 999999999 | E6: 999999999 | F6: 999999999 | G6: 999999999 | H6: 999999999 | I6: 999999999 | J6: 999999999 | K6: 999999999 | L6: 999999999 | M6: 999999999 | N6: 999999999 | O6: 999999999 | P6: 999999999 | Q6: 999999999 | R6: 999999999 | S6: 999999999 | T6: 999999999 | U6: 999999999 | V6: 999999999 | W6: 999999999 | X6: 999999999 | Y6: 999999999 | Z6: 999999999 | AA6: 999999999 | AB6: 999999999 | AC6: 999999999 | AD6: 999999999 | AE6: 999999999 | AF6: 999999999 | AG6: 999999999 | AH6: 999999999 | AI6: 999999999 | AJ6: 999999999 | AK6: 999999999 | AL6: 999999999 | AM6: 999999999 | AN6: 999999999 | AO6: 999999999 | AP6: 999999999 | AQ6: 999999999 | AR6: 999999999 | AS6: 999999999 | AT6: 999999999 | AU6: 999999999 | AV6: 999999999 | AW6: 999999999 | AX6: 999999999 | AY6: 999999999 | AZ6: 999999999
A7: LPG vehicle | B7: 999999999 | C7: 999999999 | D7: 999999999 | E7: 999999999 | F7: 999999999 | G7: 999999999 | H7: 999999999 | I7: 999999999 | J7: 999999999 | K7: 999999999 | L7: 999999999 | M7: 999999999 | N7: 999999999 | O7: 999999999 | P7: 999999999 | Q7: 999999999 | R7: 999999999 | S7: 999999999 | T7: 999999999 | U7: 999999999 | V7: 999999999 | W7: 999999999 | X7: 999999999 | Y7: 999999999 | Z7: 999999999 | AA7: 999999999 | AB7: 999999999 | AC7: 999999999 | AD7: 999999999 | AE7: 999999999 | AF7: 999999999 | AG7: 999999999 | AH7: 999999999 | AI7: 999999999 | AJ7: 999999999 | AK7: 999999999 | AL7: 999999999 | AM7: 999999999 | AN7: 999999999 | AO7: 999999999 | AP7: 999999999 | AQ7: 999999999 | AR7: 999999999 | AS7: 999999999 | AT7: 999999999 | AU7: 999999999 | AV7: 999999999 | AW7: 999999999 | AX7: 999999999 | AY7: 999999999 | AZ7: 999999999
A8: hydrogen vehicle | B8: ='NVP-Indonesia'!B63*'NVP-Indonesia'!$B$176 -> 1.017605e+08 | C8: =C$5*('BNVP-HDVs-psgr'!C$8/'BNVP-HDVs-psgr'!C$5) -> 48755418 | D8: =D$5*('BNVP-HDVs-psgr'!D$8/'BNVP-HDVs-psgr'!D$5) -> 48755418 | E8: =E$5*('BNVP-HDVs-psgr'!E$8/'BNVP-HDVs-psgr'!E$5) -> 48755418 | F8: =F$5*('BNVP-HDVs-psgr'!F$8/'BNVP-HDVs-psgr'!F$5) -> 48755418 | G8: =G$5*('BNVP-HDVs-psgr'!G$8/'BNVP-HDVs-psgr'!G$5) -> 48755418 | H8: =H$5*('BNVP-HDVs-psgr'!H$8/'BNVP-HDVs-psgr'!H$5) -> 48755418 | I8: =I$5*('BNVP-HDVs-psgr'!I$8/'BNVP-HDVs-psgr'!I$5) -> 48755418 | J8: =J$5*('BNVP-HDVs-psgr'!J$8/'BNVP-HDVs-psgr'!J$5) -> 48755418 | ... AF8: =AF$5*('BNVP-HDVs-psgr'!AF$8/'BNVP-HDVs-psgr'!AF$5) -> 48755418 | AG8: =_xlfn.FORECAST.LINEAR(AG$1,$B8:$AF8,$B$1:$AF$1) -> 45335736 | AH8: =_xlfn.FORECAST.LINEAR(AH$1,$B8:$AF8,$B$1:$AF$1) -> 45015140 | AI8: =_xlfn.FORECAST.LINEAR(AI$1,$B8:$AF8,$B$1:$AF$1) -> 44694545 | AJ8: =_xlfn.FORECAST.LINEAR(AJ$1,$B8:$AF8,$B$1:$AF$1) -> 44373950 | AK8: =_xlfn.FORECAST.LINEAR(AK$1,$B8:$AF8,$B$1:$AF$1) -> 44053355 | AL8: =_xlfn.FORECAST.LINEAR(AL$1,$B8:$AF8,$B$1:$AF$1) -> 43732759 | AM8: =_xlfn.FORECAST.LINEAR(AM$1,$B8:$AF8,$B$1:$AF$1) -> 43412164 | AN8: =_xlfn.FORECAST.LINEAR(AN$1,$B8:$AF8,$B$1:$AF$1) -> 43091569 | ... AZ8: =_xlfn.FORECAST.LINEAR(AZ$1,$B8:$AF8,$B$1:$AF$1) -> 39244426

Sheet BNVP-rail-psgr
A1: Price ($/vehicle) | B1: 2020 | C1: 2021 | D1: 2022 | E1: 2023 | F1: 2024 | G1: 2025 | H1: 2026 | I1: 2027 | J1: 2028 | K1: 2029 | L1: 2030 | M1: 2031 | N1: 2032 | O1: 2033 | P1: 2034 | Q1: 2035 | R1: 2036 | S1: 2037 | T1: 2038 | U1: 2039 | V1: 2040 | W1: 2041 | X1: 2042 | Y1: 2043 | Z1: 2044 | AA1: 2045 | AB1: 2046 | AC1: 2047 | AD1: 2048 | AE1: 2049 | AF1: 2050 | AG1: 2051 | AH1: 2052 | AI1: 2053 | AJ1: 2054 | AK1: 2055 | AL1: 2056 | AM1: 2057 | AN1: 2058 | AO1: 2059 | AP1: 2060 | AQ1: 2061 | AR1: 2062 | AS1: 2063 | AT1: 2064 | AU1: 2065 | AV1: 2066 | AW1: 2067 | AX1: 2068 | AY1: 2069 | AZ1: 2070
A2: battery electric vehicle | B2: ='NVP-Indonesia'!B67*'NVP-Indonesia'!$B$176 -> 3250000 | C2: =B2 -> 3250000 | D2: =C2 -> 3250000 | E2: =D2 -> 3250000 | F2: =E2 -> 3250000 | G2: =F2 -> 3250000 | H2: =G2 -> 3250000 | I2: =H2 -> 3250000 | J2: =I2 -> 3250000 | ... AF2: =AE2 -> 3250000 | AG2: =_xlfn.FORECAST.LINEAR(AG$1,$B2:$AF2,$B$1:$AF$1) -> 3250000 | AH2: =_xlfn.FORECAST.LINEAR(AH$1,$B2:$AF2,$B$1:$AF$1) -> 3250000 | AI2: =_xlfn.FORECAST.LINEAR(AI$1,$B2:$AF2,$B$1:$AF$1) -> 3250000 | AJ2: =_xlfn.FORECAST.LINEAR(AJ$1,$B2:$AF2,$B$1:$AF$1) -> 3250000 | AK2: =_xlfn.FORECAST.LINEAR(AK$1,$B2:$AF2,$B$1:$AF$1) -> 3250000 | AL2: =_xlfn.FORECAST.LINEAR(AL$1,$B2:$AF2,$B$1:$AF$1) -> 3250000 | AM2: =_xlfn.FORECAST.LINEAR(AM$1,$B2:$AF2,$B$1:$AF$1) -> 3250000 | AN2: =_xlfn.FORECAST.LINEAR(AN$1,$B2:$AF2,$B$1:$AF$1) -> 3250000 | ... AZ2: =_xlfn.FORECAST.LINEAR(AZ$1,$B2:$AF2,$B$1:$AF$1) -> 3250000
A3: natural gas vehicle | B3: 999999999 | C3: 999999999 | D3: 999999999 | E3: 999999999 | F3: 999999999 | G3: 999999999 | H3: 999999999 | I3: 999999999 | J3: 999999999 | K3: 999999999 | L3: 999999999 | M3: 999999999 | N3: 999999999 | O3: 999999999 | P3: 999999999 | Q3: 999999999 | R3: 999999999 | S3: 999999999 | T3: 999999999 | U3: 999999999 | V3: 999999999 | W3: 999999999 | X3: 999999999 | Y3: 999999999 | Z3: 999999999 | AA3: 999999999 | AB3: 999999999 | AC3: 999999999 | AD3: 999999999 | AE3: 999999999 | AF3: 999999999 | AG3: 999999999 | AH3: 999999999 | AI3: 999999999 | AJ3: 999999999 | AK3: 999999999 | AL3: 999999999 | AM3: 999999999 | AN3: 999999999 | AO3: 999999999 | AP3: 999999999 | AQ3: 999999999 | AR3: 999999999 | AS3: 999999999 | AT3: 999999999 | AU3: 999999999 | AV3: 999999999 | AW3: 999999999 | AX3: 999999999 | AY3: 999999999 | AZ3: 999999999
A4: gasoline vehicle | B4: 999999999 | C4: 999999999 | D4: 999999999 | E4: 999999999 | F4: 999999999 | G4: 999999999 | H4: 999999999 | I4: 999999999 | J4: 999999999 | K4: 999999999 | L4: 999999999 | M4: 999999999 | N4: 999999999 | O4: 999999999 | P4: 999999999 | Q4: 999999999 | R4: 999999999 | S4: 999999999 | T4: 999999999 | U4: 999999999 | V4: 999999999 | W4: 999999999 | X4: 999999999 | Y4: 999999999 | Z4: 999999999 | AA4: 999999999 | AB4: 999999999 | AC4: 999999999 | AD4: 999999999 | AE4: 999999999 | AF4: 999999999 | AG4: 999999999 | AH4: 999999999 | AI4: 999999999 | AJ4: 999999999 | AK4: 999999999 | AL4: 999999999 | AM4: 999999999 | AN4: 999999999 | AO4: 999999999 | AP4: 999999999 | AQ4: 999999999 | AR4: 999999999 | AS4: 999999999 | AT4: 999999999 | AU4: 999999999 | AV4: 999999999 | AW4: 999999999 | AX4: 999999999 | AY4: 999999999 | AZ4: 999999999
A5: diesel vehicle | B5: ='NVP-Indonesia'!B70*'NVP-Indonesia'!$B$176 -> 1751206.9 | C5: =$B5 -> 1751206.9 | D5: =$B5 -> 1751206.9 | E5: =$B5 -> 1751206.9 | F5: =$B5 -> 1751206.9 | G5: =$B5 -> 1751206.9 | H5: =$B5 -> 1751206.9 | I5: =$B5 -> 1751206.9 | J5: =$B5 -> 1751206.9 | ... AF5: =$B5 -> 1751206.9 | AG5: =_xlfn.FORECAST.LINEAR(AG$1,$B5:$AF5,$B$1:$AF$1) -> 1751206.9 | AH5: =_xlfn.FORECAST.LINEAR(AH$1,$B5:$AF5,$B$1:$AF$1) -> 1751206.9 | AI5: =_xlfn.FORECAST.LINEAR(AI$1,$B5:$AF5,$B$1:$AF$1) -> 1751206.9 | AJ5: =_xlfn.FORECAST.LINEAR(AJ$1,$B5:$AF5,$B$1:$AF$1) -> 1751206.9 | AK5: =_xlfn.FORECAST.LINEAR(AK$1,$B5:$AF5,$B$1:$AF$1) -> 1751206.9 | AL5: =_xlfn.FORECAST.LINEAR(AL$1,$B5:$AF5,$B$1:$AF$1) -> 1751206.9 | AM5: =_xlfn.FORECAST.LINEAR(AM$1,$B5:$AF5,$B$1:$AF$1) -> 1751206.9 | AN5: =_xlfn.FORECAST.LINEAR(AN$1,$B5:$AF5,$B$1:$AF$1) -> 1751206.9 | ... AZ5: =_xlfn.FORECAST.LINEAR(AZ$1,$B5:$AF5,$B$1:$AF$1) -> 1751206.9
A6: plugin hybrid vehicle | B6: 999999999 | C6: 999999999 | D6: 999999999 | E6: 999999999 | F6: 999999999 | G6: 999999999 | H6: 999999999 | I6: 999999999 | J6: 999999999 | K6: 999999999 | L6: 999999999 | M6: 999999999 | N6: 999999999 | O6: 999999999 | P6: 999999999 | Q6: 999999999 | R6: 999999999 | S6: 999999999 | T6: 999999999 | U6: 999999999 | V6: 999999999 | W6: 999999999 | X6: 999999999 | Y6: 999999999 | Z6: 999999999 | AA6: 999999999 | AB6: 999999999 | AC6: 999999999 | AD6: 999999999 | AE6: 999999999 | AF6: 999999999 | AG6: 999999999 | AH6: 999999999 | AI6: 999999999 | AJ6: 999999999 | AK6: 999999999 | AL6: 999999999 | AM6: 999999999 | AN6: 999999999 | AO6: 999999999 | AP6: 999999999 | AQ6: 999999999 | AR6: 999999999 | AS6: 999999999 | AT6: 999999999 | AU6: 999999999 | AV6: 999999999 | AW6: 999999999 | AX6: 999999999 | AY6: 999999999 | AZ6: 999999999
