Workbook

Sheet About
A1: BPEaCP BAU Population Employment and Compensation Projections
A3: Sources: | B3: Population Projection
B4: World Bank
B5: Databank
B6: Population estimates and Projections
B7: http://databank.worldbank.org/data/reports.aspx?source=Health-Nutrition-and-Population-Statistics:-Population-estimates-and-projections#
B9: Employment-to-Population Ratio
B10: St. Louis Federal Reserve Bank
B11: 2020
B12: Employment-Population Ratio, Indonesia
B13: https://fred.stlouisfed.org/series/SLEMPTOTLSPZSIDN
B15: Total Employee Compensation (from IO tables, historical year)
B16: OECD
B17: 2018
B18: Input-Output Tables 2018 Edition (ISIC Rev. 4)
B19: https://stats.oecd.org/Index.aspx?DataSetCode=IOTS#
B20: Variable: VAL
B22: GNI
B23: The World Bank
B24: 2020
B25: GNI per capita (constant 2010 US$) - India
B26: https://data.worldbank.org/indicator/NY.GNP.PCAP.KD?locations=IN
B28: GDP
B29: The World Bank
B30: 2020
B31: GDP (constant 2010 US$) - India
B32: https://data.worldbank.org/indicator/NY.GDP.MKTP.KD?locations=IN
B34: GDP Forecast
B35: OECD
B36: 2018
B37: Quarterly National Accounts
B38: https://data.oecd.org/gdp/gdp-long-term-forecast.htm
B39: Real GDP long-term forecast
A41: Notes
A43: Number of Employees
A44: To project future numbers of employees, we sample the share of the population that is
A45: employed over a wide historical rage, and use that average going forward. The share of
A46: the population that is employed has remained relatively stable over time despite tremendous
A47: increases in productivity (output per employee), so we believe this is likely to continue to
A48: happen in the future, and we do not need to adjust for productivity increases. (That is,
...

Sheet Pop Projection
A1: YEAR | B1: TOTAL_POP
A2: 2014 | B2: ='Indonesia Population Data'!B19 -> 255129004
A3: 2015 | B3: ='Indonesia Population Data'!B20 -> 258383256
A4: 2016 | B4: ='Indonesia Population Data'!B21 -> 261554226
A5: 2017 | B5: ='Indonesia Population Data'!B22 -> 264645886
A6: 2018 | B6: ='Indonesia Population Data'!B23 -> 267663435
A7: 2019 | B7: ='Indonesia Population Data'!B24 -> 270625568
A8: 2020 | B8: ='Indonesia Population Data'!B25 -> 273524000
A9: 2021 | B9: ='Indonesia Population Data'!B26 -> 276362000
A10: 2022 | B10: ='Indonesia Population Data'!B27 -> 279135000
A11: 2023 | B11: ='Indonesia Population Data'!B28 -> 281844000
A12: 2024 | B12: ='Indonesia Population Data'!B29 -> 284495000
A13: 2025 | B13: ='Indonesia Population Data'!B30 -> 287090000
... A38: 2050 | B38: ='Indonesia Population Data'!B55 -> 330905000

Sheet Indonesia Population Data
A1: Country Name | B1: Indonesia
A2: Country Code | B2: IDN
A3: Series Name | B3: Population, total
A4: Series Code | B4: SP.POP.TOTL
A5: 2000 | B5: 211513823
A6: 2001 | B6: 214427417
A7: 2002 | B7: 217357793
A8: 2003 | B8: 220309469
A9: 2004 | B9: 223285676
A10: 2005 | B10: 226289470
A11: 2006 | B11: 229318262
A12: 2007 | B12: 232374245
A13: 2008 | B13: 235469762
A14: 2009 | B14: 238620563
A15: 2010 | B15: 241834215
A16: 2011 | B16: 245116206
... A55: 2050 | B55: 330905000

Sheet Emp Pop Ratio
A1: FRED Graph Observations
A2: Federal Reserve Economic Data
A3: Link: https://fred.stlouisfed.org
A4: Help: https://fred.stlouisfed.org/help-faq
A5: Economic Research Division
A6: Federal Reserve Bank of St. Louis
A8: SLEMPTOTLSPZSIDN | B8: Employment to Population Ratio for Indonesia, Percent, Annual, Not Seasonally Adjusted
A10: Frequency: Annual
A11: observation_date | B11: SLEMPTOTLSPZSIDN
A12: 33239 | B12: 63.799999
A13: 33604 | B13: 64.080002
A14: 33970 | B14: 63.299999
A15: 34335 | B15: 63.52
A16: 34700 | B16: 63.419998
A17: 35065 | B17: 63.299999
A18: 35431 | B18: 62.970001
A19: 35796 | B19: 62.860001
A20: 36161 | B20: 62.59
A21: 36526 | B21: 63.150002
A22: 36892 | B22: 62.330002
A23: 37257 | B23: 60.880001
... A41: 43831 | B41: 63.720001

Sheet Avg Emp-Pop Ratio
A1: Average Employment-to-Population Ratio
A2: from date | B2: 40179
A3: to date | B3: 43830
A5: is: | B5: =AVERAGEIFS('Emp Pop Ratio'!B:B,'Emp Pop Ratio'!A:A,">="&'Avg Emp-Pop Ratio'!B2,'Emp Pop Ratio'!A:A,"<="&'Avg Emp-Pop Ratio'!B3)/100 -> 0.64123

Sheet OECD VAL
A2: Dataset: Input-Output Tables 2018 edition
A3: Variable | C3: VAL: Value added
A4: Country | C4: IDN: Indonesia
A5: Time | C5: 2015
A6: Unit | C6: US Dollar, Millions
A7: To: (sector in column) | C7: D01T03: Agriculture, forestry and fishing | D7: D05T06: Mining and extraction of energy producing products | E7: D07T08: Mining and quarrying of non-energy producing products | F7: D09: Mining support service activities | G7: D10T12: Food products, beverages and tobacco | H7: D13T15: Textiles, wearing apparel, leather and related products | I7: D16: Wood and products of wood and cork | J7: D17T18: Paper products and printing | K7: D19: Coke and refined petroleum products | L7: D20T21: Chemicals and pharmaceutical products | M7: D22: Rubber and plastic products | N7: D23: Other non-metallic mineral products | O7: D24: Basic metals | P7: D25: Fabricated metal products | Q7: D26: Computer, electronic and optical products | R7: D27: Electrical equipment | S7: D28: Machinery and equipment, nec | T7: D29: Motor vehicles, trailers and semi-trailers | U7: D30: Other transport equipment | V7: D31T33: Other manufacturing; repair and installation of machinery and equipment | W7: D35T39: Electricity, gas, water supply, sewerage, waste and remediation services | X7: D41T43: Construction | Y7: D45T47: Wholesale and retail trade; repair of motor vehicles | Z7: D49T53: Transportation and storage | AA7: D55T56: Accomodation and food services | AB7: D58T60: Publishing, audiovisual and broadcasting activities | AC7: D61: Telecommunications | AD7: D62T63: IT and other information services | AE7: D64T66: Financial and insurance activities | AF7: D68: Real estate activities | AG7: D69T82: Other business sector services | AH7: D84: Public admin. and defence; compulsory social security | AI7: D85: Education | AJ7: D86T88: Human health and social work | AK7: D90T96: Arts, entertainment, recreation and other service activities | AL7: D97T98: Private households with employed persons
A8: From: (sector in row)
A9: LABR: Compensation of employees | C9: 29262.674 | D9: 4975.921 | E9: 2242.136 | F9: 2007.81 | G9: 14592.644 | H9: 3959.988 | I9: 1593.363 | J9: 1918.738 | K9: 6049.947 | L9: 5443.204 | M9: 2177.024 | N9: 1971.729 | O9: 1635.361 | P9: 1810.208 | Q9: 1727.854 | R9: 1053.039 | S9: 1174.977 | T9: 4857.665 | U9: 204.369 | V9: 898.873 | W9: 2769.524 | X9: 35126.419 | Y9: 33095.795 | Z9: 15284.426 | AA9: 8958.408 | AB9: 3090.285 | AC9: 6742.17 | AD9: 1462.417 | AE9: 10616.784 | AF9: 1332.691 | AG9: 4373.254 | AH9: 29908.789 | AI9: 23779.981 | AJ9: 4499.819 | AK9: 10633.826 | AL9: 1389.2
A10: OTXS: Other taxes less subsidies on production | C10: 967.635 | D10: 1917.439 | E10: 639.098 | F10: 249.272 | G10: 8878.738 | H10: 365.674 | I10: 174.383 | J10: 173.182 | K10: -9098.519 | L10: 60.228 | M10: 358.569 | N10: 409.186 | O10: 372.321 | P10: 186.873 | Q10: 374.298 | R10: 165.446 | S10: 167.331 | T10: 503.535 | U10: 17.329 | V10: 98.559 | W10: 85.218 | X10: 728.744 | Y10: 855.485 | Z10: 334.956 | AA10: 198.429 | AB10: 126.891 | AC10: 694.892 | AD10: 55.885 | AE10: 197.928 | AF10: 1060.796 | AG10: 114.321 | AH10: -324.755 | AI10: 89.658 | AJ10: 50.713 | AK10: 115.815 | AL10: 0
A11: GOPS: Gross operating surplus and mixed income | C11: 84985.291 | D11: 38614.54 | E11: 12666.565 | F11: 1983.818 | G11: 32496.018 | H11: 8326.038 | I11: 4008.254 | J11: 4407.48 | K11: 26771.572 | L11: 10033.068 | M11: 3829.807 | N11: 3793.386 | O11: 4669.318 | P11: 3097.219 | Q11: 6304.748 | R11: 2067.715 | S11: 1419.092 | T11: 10374.1 | U11: 373.602 | V11: 1876.168 | W11: 9349.358 | X11: 51317.436 | Y11: 79749.22 | Z11: 27264.617 | AA11: 16138.163 | AB11: 2551.723 | AC11: 14614.338 | AD11: 728.398 | AE11: 23623.788 | AF11: 21868.013 | AG11: 9604.825 | AH11: 3759.367 | AI11: 4867.961 | AJ11: 4553.269 | AK11: 7658.46 | AL11: 0
A12: Data extracted on 02 Mar 2021 20:27 UTC (GMT) from OECD.Stat

Sheet BGDP_calc
A4: World Bank | B4: USD 2012 $
A5: 1960 | B5: 6.3779253e+10
A6: 1961 | B6: 6.7440594e+10
A7: 1962 | B7: 6.8682835e+10
A8: 1963 | B8: 6.7146379e+10
A9: 1964 | B9: 6.9516443e+10
A10: 1965 | B10: 7.0268326e+10
A11: 1966 | B11: 7.2229759e+10
A12: 1967 | B12: 7.322682e+10
A13: 1968 | B13: 8.1219658e+10
A14: 1969 | B14: 8.6760706e+10
A15: 1970 | B15: 9.331516e+10
A16: 1971 | B16: 9.9869614e+10
... A95: 2050 | B95: 4.1026373e+12

Sheet EE Comp Projection
A1: We start with 2015 Total Employee Compensation and scale this value by forecasted real GDP growth/capita
A3: Employee Compensation | C3: 2000 | D3: 2001 | E3: 2002 | F3: 2003 | G3: 2004 | H3: 2005 | I3: 2006 | J3: 2007 | K3: 2008 | L3: 2009 | M3: 2010 | N3: 2011 | O3: 2012 | P3: 2013 | Q3: 2014 | R3: 2015 | S3: 2016 | T3: 2017 | U3: 2018 | V3: 2019 | W3: 2020 | X3: 2021 | Y3: 2022 | Z3: 2023 | AA3: 2024 | AB3: 2025 | AC3: 2026 | AD3: 2027 | AE3: 2028 | AF3: 2029 | AG3: 2030 | AH3: 2031 | AI3: 2032 | AJ3: 2033 | AK3: 2034 | AL3: 2035 | AM3: 2036 | AN3: 2037 | AO3: 2038 | AP3: 2039 | AQ3: 2040 | AR3: 2041 | AS3: 2042 | AT3: 2043 | AU3: 2044 | AV3: 2045 | AW3: 2046 | AX3: 2047 | AY3: 2048 | AZ3: 2049 | BA3: 2050
A4: GDP | B4: (USD 2012 $) | C4: {=TRANSPOSE(BGDP_calc!B45:B95)} -> 4.7735386e+11 | D4: 4.9474608e+11 | E4: 5.1700706e+11 | F4: 5.4172191e+11 | G4: 5.6897525e+11 | H4: 6.0136458e+11 | I4: 6.3444535e+11 | J4: 6.7470105e+11 | K4: 7.1527557e+11 | L4: 7.4838476e+11 | M4: 7.9496313e+11 | N4: 8.4401064e+11 | O4: 8.9490491e+11 | P4: 9.4463714e+11 | Q4: 9.9193199e+11 | R4: 1.0403018e+12 | S4: 1.0926609e+12 | T4: 1.1480565e+12 | U4: 1.2074076e+12 | V4: 1.2680764e+12 | W4: 1.3311979e+12 | X4: 1.3945631e+12 | Y4: 1.4588872e+12 | Z4: 1.5245391e+12 | AA4: 1.5919231e+12 | AB4: 1.6613294e+12 | AC4: 1.7328138e+12 | AD4: 1.8063577e+12 | AE4: 1.8820244e+12 | AF4: 1.9598518e+12 | AG4: 2.0397959e+12 | AH4: 2.1218415e+12 | AI4: 2.2061686e+12 | AJ4: 2.2928077e+12 | AK4: 2.3817979e+12 | AL4: 2.4731818e+12 | AM4: 2.5669441e+12 | AN4: 2.663029e+12 | AO4: 2.7615188e+12 | AP4: 2.8623647e+12 | AQ4: 2.9655049e+12 | AR4: 3.0709128e+12 | AS4: 3.1785513e+12 | AT4: 3.2883888e+12 | AU4: 3.4003245e+12 | AV4: 3.5140357e+12 | AW4: 3.6292e+12 | AX4: 3.7456842e+12 | AY4: 3.8634441e+12 | AZ4: 3.9824438e+12 | BA4: 4.1026373e+12
A5: Population | C5: {=TRANSPOSE('Indonesia Population Data'!B5:B55)} -> 211513823 | D5: 214427417 | E5: 217357793 | F5: 220309469 | G5: 223285676 | H5: 226289470 | I5: 229318262 | J5: 232374245 | K5: 235469762 | L5: 238620563 | M5: 241834215 | N5: 245116206 | O5: 248452413 | P5: 251806402 | Q5: 255129004 | R5: 258383256 | S5: 261554226 | T5: 264645886 | U5: 267663435 | V5: 270625568 | W5: 273524000 | X5: 276362000 | Y5: 279135000 | Z5: 281844000 | AA5: 284495000 | AB5: 287090000 | AC5: 289628000 | AD5: 292109000 | AE5: 294533000 | AF5: 296896000 | AG5: 299198000 | AH5: 301439000 | AI5: 303618000 | AJ5: 305733000 | AK5: 307783000 | AL5: 309765000 | AM5: 311679000 | AN5: 313525000 | AO5: 315300000 | AP5: 317005000 | AQ5: 318638000 | AR5: 320199000 | AS5: 321688000 | AT5: 323103000 | AU5: 324442000 | AV5: 325705000 | AW5: 326892000 | AX5: 328004000 | AY5: 329042000 | AZ5: 330008000 | BA5: 330905000
A6: GDP/capita | C6: =C4/C5 -> 2256.8447 | D6: =D4/D5 -> 2307.2893 | E6: =E4/E5 -> 2378.5992 | F6: =F4/F5 -> 2458.9134 | G6: =G4/G5 -> 2548.1942 | H6: =H4/H5 -> 2657.5014 | I6: =I4/I5 -> 2766.6586 | J6: =J4/J5 -> 2903.5105 | ... BA6: =BA4/BA5 -> 12398.233
A8: Annual change in GDP/capita | D8: =(D6-C6)/C6 -> 0.022351811 | E8: =(E6-D6)/D6 -> 0.030906335 | F8: =(F6-E6)/E6 -> 0.033765361 | G8: =(G6-F6)/F6 -> 0.036309023 | H8: =(H6-G6)/G6 -> 0.042895952 | I8: =(I6-H6)/H6 -> 0.041075153 | J8: =(J6-I6)/I6 -> 0.049464654 | K8: =(K6-J6)/J6 -> 0.046200333 | ... BA8: =(BA6-AZ6)/AZ6 -> 0.027388298
A10: OECD 2015 Total Employee Compensation
A11: =SUM('OECD VAL'!C9:AL9)*10^6 -> 2.8262131e+11 | B11: 2015 USD
A12: =A11*About!$A$58 -> 2.7377006e+11 | B12: 2012 USD
A14: Projected Future Employee Compensation (2012 USD)
B15: 2015 | C15: 2016 | D15: 2017 | E15: 2018 | F15: 2019 | G15: 2020 | H15: 2021 | I15: 2022 | J15: 2023 | K15: 2024 | L15: 2025 | M15: 2026 | N15: 2027 | O15: 2028 | P15: 2029 | Q15: 2030 | R15: 2031 | S15: 2032 | T15: 2033 | U15: 2034 | V15: 2035 | W15: 2036 | X15: 2037 | Y15: 2038 | Z15: 2039 | AA15: 2040 | AB15: 2041 | AC15: 2042 | AD15: 2043 | AE15: 2044 | AF15: 2045 | AG15: 2046 | AH15: 2047 | AI15: 2048 | AJ15: 2049 | AK15: 2050
A16: Perc Change in GDP as proxy for compensation | B16: =R8 -> 0.035554396 | C16: =S8 -> 0.037596938 | D16: =T8 -> 0.038423342 | E16: =U8 -> 0.039840571 | F16: =V8 -> 0.038751657 | G16: =W8 -> 0.038653243 | H16: =X8 -> 0.036842214 | I16: =Y8 -> 0.035732424 | ... AK16: =BA8 -> 0.027388298
A17: Projected Compensation (2012 $) | B17: =A12*(1+B16) -> 2.8350379e+11 | C17: =B17*(1+C16) -> 2.9416266e+11 | D17: =C17*(1+D16) -> 3.0546537e+11 | E17: =D17*(1+E16) -> 3.1763529e+11 | F17: =E17*(1+F16) -> 3.2994418e+11 | G17: =F17*(1+G16) -> 3.4269759e+11 | H17: =G17*(1+H16) -> 3.5532333e+11 | I17: =H17*(1+I16) -> 3.680199e+11 | J17: =I17*(1+J16) -> 3.8088482e+11 | ... AK17: =AJ17*(1+AK16) -> 8.7301898e+11

Sheet BPEaCP-population
A1: Unit: people | B1: {=TRANSPOSE('Pop Projection'!A7:B38)} -> 2019 | C1: 2020 | D1: 2021 | E1: 2022 | F1: 2023 | G1: 2024 | H1: 2025 | I1: 2026 | J1: 2027 | K1: 2028 | L1: 2029 | M1: 2030 | N1: 2031 | O1: 2032 | P1: 2033 | Q1: 2034 | R1: 2035 | S1: 2036 | T1: 2037 | U1: 2038 | V1: 2039 | W1: 2040 | X1: 2041 | Y1: 2042 | Z1: 2043 | AA1: 2044 | AB1: 2045 | AC1: 2046 | AD1: 2047 | AE1: 2048 | AF1: 2049 | AG1: 2050 | AH1: 2051 | AI1: 2052 | AJ1: 2053 | AK1: 2054 | AL1: 2055 | AM1: 2056 | AN1: 2057 | AO1: 2058 | AP1: 2059 | AQ1: 2060 | AR1: 2061 | AS1: 2062 | AT1: 2063 | AU1: 2064 | AV1: 2065 | AW1: 2066 | AX1: 2067 | AY1: 2068 | AZ1: 2069 | BA1: 2070
A2: Population | B2: 270625568 | C2: 273524000 | D2: 276362000 | E2: 279135000 | F2: 281844000 | G2: 284495000 | H2: 287090000 | I2: 289628000 | J2: 292109000 | K2: 294533000 | L2: 296896000 | M2: 299198000 | N2: 301439000 | O2: 303618000 | P2: 305733000 | Q2: 307783000 | R2: 309765000 | S2: 311679000 | T2: 313525000 | U2: 315300000 | V2: 317005000 | W2: 318638000 | X2: 320199000 | Y2: 321688000 | Z2: 323103000 | AA2: 324442000 | AB2: 325705000 | AC2: 326892000 | AD2: 328004000 | AE2: 329042000 | AF2: 330008000 | AG2: 330905000 | AH2: =_xlfn.FORECAST.LINEAR(AH1,$B$2:$AG$2,$B$1:$AG$1) -> 3.3821565e+08 | AI2: =_xlfn.FORECAST.LINEAR(AI1,$B$2:$AG$2,$B$1:$AG$1) -> 3.4017206e+08 | AJ2: =_xlfn.FORECAST.LINEAR(AJ1,$B$2:$AG$2,$B$1:$AG$1) -> 3.4212848e+08 | AK2: =_xlfn.FORECAST.LINEAR(AK1,$B$2:$AG$2,$B$1:$AG$1) -> 3.440849e+08 | AL2: =_xlfn.FORECAST.LINEAR(AL1,$B$2:$AG$2,$B$1:$AG$1) -> 3.4604131e+08 | AM2: =_xlfn.FORECAST.LINEAR(AM1,$B$2:$AG$2,$B$1:$AG$1) -> 3.4799773e+08 | AN2: =_xlfn.FORECAST.LINEAR(AN1,$B$2:$AG$2,$B$1:$AG$1) -> 3.4995415e+08 | AO2: =_xlfn.FORECAST.LINEAR(AO1,$B$2:$AG$2,$B$1:$AG$1) -> 3.5191056e+08 | ... BA2: =_xlfn.FORECAST.LINEAR(BA1,$B$2:$AG$2,$B$1:$AG$1) -> 3.7538757e+08

Sheet BPEaCP-employedpop
A1: Unit: people | B1: 2019 | C1: 2020 | D1: 2021 | E1: 2022 | F1: 2023 | G1: 2024 | H1: 2025 | I1: 2026 | J1: 2027 | K1: 2028 | L1: 2029 | M1: 2030 | N1: 2031 | O1: 2032 | P1: 2033 | Q1: 2034 | R1: 2035 | S1: 2036 | T1: 2037 | U1: 2038 | V1: 2039 | W1: 2040 | X1: 2041 | Y1: 2042 | Z1: 2043 | AA1: 2044 | AB1: 2045 | AC1: 2046 | AD1: 2047 | AE1: 2048 | AF1: 2049 | AG1: 2050 | AH1: 2051 | AI1: 2052 | AJ1: 2053 | AK1: 2054 | AL1: 2055 | AM1: 2056 | AN1: 2057 | AO1: 2058 | AP1: 2059 | AQ1: 2060 | AR1: 2061 | AS1: 2062 | AT1: 2063 | AU1: 2064 | AV1: 2065 | AW1: 2066 | AX1: 2067 | AY1: 2068 | AZ1: 2069 | BA1: 2070
A2: Employed Population | B2: ='BPEaCP-population'!B2*'Avg Emp-Pop Ratio'!$B$5 -> 1.7353323e+08 | C2: ='BPEaCP-population'!C2*'Avg Emp-Pop Ratio'!$B$5 -> 1.753918e+08 | D2: ='BPEaCP-population'!D2*'Avg Emp-Pop Ratio'!$B$5 -> 1.7721161e+08 | E2: ='BPEaCP-population'!E2*'Avg Emp-Pop Ratio'!$B$5 -> 1.7898974e+08 | F2: ='BPEaCP-population'!F2*'Avg Emp-Pop Ratio'!$B$5 -> 1.8072683e+08 | G2: ='BPEaCP-population'!G2*'Avg Emp-Pop Ratio'!$B$5 -> 1.8242673e+08 | H2: ='BPEaCP-population'!H2*'Avg Emp-Pop Ratio'!$B$5 -> 1.8409072e+08 | I2: ='BPEaCP-population'!I2*'Avg Emp-Pop Ratio'!$B$5 -> 1.8571816e+08 | ... AG2: ='BPEaCP-population'!AG2*'Avg Emp-Pop Ratio'!$B$5 -> 2.1218621e+08 | AH2: =_xlfn.FORECAST.LINEAR(AH1,$B$2:$AG$2,$B$1:$AG$1) -> 2.1687402e+08 | AI2: =_xlfn.FORECAST.LINEAR(AI1,$B$2:$AG$2,$B$1:$AG$1) -> 2.1812853e+08 | AJ2: =_xlfn.FORECAST.LINEAR(AJ1,$B$2:$AG$2,$B$1:$AG$1) -> 2.1938305e+08 | AK2: =_xlfn.FORECAST.LINEAR(AK1,$B$2:$AG$2,$B$1:$AG$1) -> 2.2063756e+08 | AL2: =_xlfn.FORECAST.LINEAR(AL1,$B$2:$AG$2,$B$1:$AG$1) -> 2.2189207e+08 | AM2: =_xlfn.FORECAST.LINEAR(AM1,$B$2:$AG$2,$B$1:$AG$1) -> 2.2314659e+08 | AN2: =_xlfn.FORECAST.LINEAR(AN1,$B$2:$AG$2,$B$1:$AG$1) -> 2.244011e+08 | AO2: =_xlfn.FORECAST.LINEAR(AO1,$B$2:$AG$2,$B$1:$AG$1) -> 2.2565561e+08 | ... BA2: =_xlfn.FORECAST.LINEAR(BA1,$B$2:$AG$2,$B$1:$AG$1) -> 2.4070977e+08

Sheet BPEaCP-employeecomp
A1: Unit: 2012 $ | B1: 2019 | C1: 2020 | D1: 2021 | E1: 2022 | F1: 2023 | G1: 2024 | H1: 2025 | I1: 2026 | J1: 2027 | K1: 2028 | L1: 2029 | M1: 2030 | N1: 2031 | O1: 2032 | P1: 2033 | Q1: 2034 | R1: 2035 | S1: 2036 | T1: 2037 | U1: 2038 | V1: 2039 | W1: 2040 | X1: 2041 | Y1: 2042 | Z1: 2043 | AA1: 2044 | AB1: 2045 | AC1: 2046 | AD1: 2047 | AE1: 2048 | AF1: 2049 | AG1: 2050 | AH1: 2051 | AI1: 2052 | AJ1: 2053 | AK1: 2054 | AL1: 2055 | AM1: 2056 | AN1: 2057 | AO1: 2058 | AP1: 2059 | AQ1: 2060 | AR1: 2061 | AS1: 2062 | AT1: 2063 | AU1: 2064 | AV1: 2065 | AW1: 2066 | AX1: 2067 | AY1: 2068 | AZ1: 2069 | BA1: 2070
A2: Total EE Compensation | B2: ='EE Comp Projection'!F17 -> 3.2994418e+11 | C2: ='EE Comp Projection'!G17 -> 3.4269759e+11 | D2: ='EE Comp Projection'!H17 -> 3.5532333e+11 | E2: ='EE Comp Projection'!I17 -> 3.680199e+11 | F2: ='EE Comp Projection'!J17 -> 3.8088482e+11 | G2: ='EE Comp Projection'!K17 -> 3.940137e+11 | H2: ='EE Comp Projection'!L17 -> 4.0747556e+11 | I2: ='EE Comp Projection'!M17 -> 4.2128426e+11 | ... AG2: ='EE Comp Projection'!AK17 -> 8.7301898e+11 | AH2: =_xlfn.FORECAST.LINEAR(AH1,$B$2:$AG$2,$B$1:$AG$1) -> 8.5899231e+11 | AI2: =_xlfn.FORECAST.LINEAR(AI1,$B$2:$AG$2,$B$1:$AG$1) -> 8.76433e+11 | AJ2: =_xlfn.FORECAST.LINEAR(AJ1,$B$2:$AG$2,$B$1:$AG$1) -> 8.9387368e+11 | AK2: =_xlfn.FORECAST.LINEAR(AK1,$B$2:$AG$2,$B$1:$AG$1) -> 9.1131437e+11 | AL2: =_xlfn.FORECAST.LINEAR(AL1,$B$2:$AG$2,$B$1:$AG$1) -> 9.2875505e+11 | AM2: =_xlfn.FORECAST.LINEAR(AM1,$B$2:$AG$2,$B$1:$AG$1) -> 9.4619574e+11 | AN2: =_xlfn.FORECAST.LINEAR(AN1,$B$2:$AG$2,$B$1:$AG$1) -> 9.6363642e+11 | AO2: =_xlfn.FORECAST.LINEAR(AO1,$B$2:$AG$2,$B$1:$AG$1) -> 9.8107711e+11 | ... BA2: =_xlfn.FORECAST.LINEAR(BA1,$B$2:$AG$2,$B$1:$AG$1) -> 1.1903653e+12
