Workbook
Name Eno_TM: '[1]1997 Table 1a Modified'!#REF!
Name Eno_Tons: '[1]1997 Table 1a Modified'!#REF!
Name Sum_T2: '[1]1997 Table 1a Modified'!#REF!
Name Sum_TTM: '[1]1997 Table 1a Modified'!#REF!
Name ti_tbl_50: #REF!
Name ti_tbl_69: #REF!

Sheet About
A1: BHNVFEAL BAU Historical New Vehicle Fuel Economy After Lifetime
A3: Sources: | B3: BAU New Vehicle Fuel Economy
B4: For sources and calculations, see the variable BNVFE.
B6: LDVs
B7: EIA
B8: 2008
B9: Annual Energy Outlook 2008
B10: https://www.eia.gov/outlooks/archive/aeo08/index.html
B11: Tables 35, 49, 55
B13: Perc Reduction in Fuel Use for Electricity
B14: For sources and calculations, see the variable PTFURfE.
B16: Perc of Electricity Use for Plug-In Hybrid Vehicles
B17: For source, see the variable BPoEFUbVT.
B19: Vehicle Lifetimes
B20: For sources and calculations, see the variable AVL.
B22: Efficiency modifiers for LPG and hydrogen vehicles
B23: See the variable BNVFE
A25: SYFAFE Start Year Fleet Avg Fuel Economy
A27: Source | B27: IESR (2024)
B28: https://iesr.or.id/en/
A34: Comments | B34: These data come from the LEAP (Long-range Energy Alternatives Planning) Indonesia model and represent BAU (Business As Usual) scenarios projected for the country. The BAU scenarios assume no significant changes to current energy policies or interventions, providing a baseline for analyzing future energy consumption, emissions, and sectoral growth under existing conditions. This model helps evaluate long-term trends in Indonesia's energy use and environmental impacts, serving as a foundation for comparing potential outcomes from alternative policy scenarios aimed at sustainable development and climate goals.
A45: Notes
A46: To estimate the BAU New Vehicle Fuel Economy in historical years (up to one
A47: vehicle lifetime before the first simulated year of the model run), we use
A48: a somewhat simplified approach. We linearly extrapolate backwards from
A49: the future year values in BNVFE, using the entire period (2016-2050) as the
A50: basis for extrapolation. We adjust the Y-intercept of the extrapolated
A51: line when needed to avoid any discontinuity.
A53: More than one vehicle lifetime into
A54: the model run, the model will have switched
A55: over to using data from retiring vehicles that were added during the
A56: model run itself and no longer needs to reference the historical input data
A57: in this variable. However, we include values in this variable out to
... A68: energy consumption that more closely matches EIA's AEO trajectory: freight LDVs, passenger HDVs, freight HDVs, passenger ships, passenger motorbikes.

Sheet BNVFE
A1: This tab contains BAU New Vehicle Fuel Economy (BNVFE) data for the primary
A2: vehicle technology for each vehicle/cargo combination. This is the technology
A3: from which the BAU new vehicle fuel economies of the other technologies
A4: are calculated.
A6: BAU New Vehicle Fuel Economy (from BNVFE variable)
A7: vehicle type | B7: cargo type | D7: 2020 | E7: 2021 | F7: 2022 | G7: 2023 | H7: 2024 | I7: 2025 | J7: 2026 | K7: 2027 | L7: 2028 | M7: 2029 | N7: 2030 | O7: 2031 | P7: 2032 | Q7: 2033 | R7: 2034 | S7: 2035 | T7: 2036 | U7: 2037 | V7: 2038 | W7: 2039 | X7: 2040 | Y7: 2041 | Z7: 2042 | AA7: 2043 | AB7: 2044 | AC7: 2045 | AD7: 2046 | AE7: 2047 | AF7: 2048 | AG7: 2049 | AH7: 2050
A8: LDVs | B8: psgr | C8: gasoline vehicle | D8: 0.00037068405 | E8: 0.00038286968 | F8: 0.0003899954 | G8: 0.00039439146 | H8: 0.00039758792 | I8: 0.0004167044 | J8: 0.00045449874 | K8: 0.0004557184 | L8: 0.00045632492 | M8: 0.00045682344 | N8: 0.00045864796 | O8: 0.00045942511 | P8: 0.00046038567 | Q8: 0.0004613799 | R8: 0.00046275845 | S8: 0.00046332164 | T8: 0.00046388593 | U8: 0.00046479081 | V8: 0.00046598088 | W8: 0.00046672535 | X8: 0.00046768413 | Y8: 0.00046835837 | Z8: 0.00046888408 | AA8: 0.00046949899 | AB8: 0.00047032072 | AC8: 0.00047135545 | AD8: 0.00047215509 | AE8: 0.000473012 | AF8: 0.00047379059 | AG8: 0.00047491928 | AH8: 0.00047615242
A9: LDVs | B9: frgt | C9: gasoline vehicle | D9: 0.00011578636 | E9: 0.00011589922 | F9: 0.00011538534 | G9: 0.00011535675 | H9: 0.00011555683 | I9: 0.00011619448 | J9: 0.00011675875 | K9: 0.00011708867 | L9: 0.00011617581 | M9: 0.0001159133 | N9: 0.00011553838 | O9: 0.00011496831 | P9: 0.00011417779 | Q9: 0.00011321127 | R9: 0.00011235905 | S9: 0.00011139733 | T9: 0.00011073582 | U9: 0.00010995313 | V9: 0.00010948774 | W9: 0.00010913517 | X9: 0.00010884248 | Y9: 0.00010859338 | Z9: 0.00010834433 | AA9: 0.00010815629 | AB9: 0.00010799885 | AC9: 0.00010784324 | AD9: 0.00010772425 | AE9: 0.00010749204 | AF9: 0.00010725769 | AG9: 0.00010704107 | AH9: 0.00010682755
A10: HDVs | B10: psgr | C10: diesel vehicle | D10: 0.00098533459 | E10: 0.00099880214 | F10: 0.0010144916 | G10: 0.0010338641 | H10: 0.0010578484 | I10: 0.0010855564 | J10: 0.0011154933 | K10: 0.0011464331 | L10: 0.0011621954 | M10: 0.0011852372 | N10: 0.0012047748 | O10: 0.0012221312 | P10: 0.0012324377 | Q10: 0.0012337189 | R10: 0.0012346974 | S10: 0.0012348004 | T10: 0.0012352949 | U10: 0.0012357035 | V10: 0.0012358092 | W10: 0.0012356634 | X10: 0.0012356553 | Y10: 0.0012356638 | Z10: 0.0012356742 | AA10: 0.0012356002 | AB10: 0.0012356763 | AC10: 0.0012358725 | AD10: 0.0012358611 | AE10: 0.0012361943 | AF10: 0.0012367164 | AG10: 0.0012373051 | AH10: 0.0012379719
A11: HDVs | B11: frgt | C11: diesel vehicle | D11: 0.00072928094 | E11: 0.00073924874 | F11: 0.00075086107 | G11: 0.00076519938 | H11: 0.00078295096 | I11: 0.00080345861 | J11: 0.00082561601 | K11: 0.0008485156 | L11: 0.00086018189 | M11: 0.00087723593 | N11: 0.00089169638 | O11: 0.0009045425 | P11: 0.00091217069 | Q11: 0.00091311894 | R11: 0.00091384318 | S11: 0.0009139194 | T11: 0.00091428537 | U11: 0.00091458782 | V11: 0.00091466602 | W11: 0.0009145581 | X11: 0.00091455215 | Y11: 0.00091455845 | Z11: 0.00091456614 | AA11: 0.00091451136 | AB11: 0.00091456765 | AC11: 0.00091471287 | AD11: 0.00091470448 | AE11: 0.0009149511 | AF11: 0.00091533746 | AG11: 0.00091577324 | AH11: 0.00091626672
A12: aircraft | B12: psgr | C12: diesel vehicle | D12: 0.00046616941 | E12: 0.00047399299 | F12: 0.00047625318 | G12: 0.00047962764 | H12: 0.00048472425 | I12: 0.00048856489 | J12: 0.00049188762 | K12: 0.00049507466 | L12: 0.00049827927 | M12: 0.00050141939 | N12: 0.00050473115 | O12: 0.000508169 | P12: 0.00051181801 | Q12: 0.00051566571 | R12: 0.0005196142 | S12: 0.00052372057 | T12: 0.00052782109 | U12: 0.0005319193 | V12: 0.00053596469 | W12: 0.00053988919 | X12: 0.00054375066 | Y12: 0.00054758253 | Z12: 0.00055141486 | AA12: 0.00055528894 | AB12: 0.00055903875 | AC12: 0.00056267984 | AD12: 0.00056625804 | AE12: 0.0005697667 | AF12: 0.00057342147 | AG12: 0.00057704088 | AH12: 0.00058064147
A13: aircraft | B13: frgt | C13: diesel vehicle | D13: 0.00012002513 | E13: 0.00012203947 | F13: 0.00012262141 | G13: 0.00012349023 | H13: 0.00012480246 | I13: 0.00012579132 | J13: 0.00012664682 | K13: 0.00012746739 | L13: 0.00012829249 | M13: 0.00012910098 | N13: 0.00012995366 | O13: 0.00013083881 | P13: 0.00013177832 | Q13: 0.00013276899 | R13: 0.00013378562 | S13: 0.00013484289 | T13: 0.00013589865 | U13: 0.00013695382 | V13: 0.00013799539 | W13: 0.00013900584 | X13: 0.00014000006 | Y13: 0.00014098665 | Z13: 0.00014197336 | AA13: 0.00014297083 | AB13: 0.0001439363 | AC13: 0.00014487377 | AD13: 0.00014579506 | AE13: 0.00014669843 | AF13: 0.00014763943 | AG13: 0.00014857132 | AH13: 0.00014949837
A14: rail | B14: psgr | C14: diesel vehicle | D14: 0.00038868922 | E14: 0.00038835965 | F14: 0.00038810531 | G14: 0.00038794345 | H14: 0.00038779756 | I14: 0.0003876866 | J14: 0.00038756372 | K14: 0.00038743413 | L14: 0.00038741625 | M14: 0.00038738694 | N14: 0.00038727323 | O14: 0.00038728018 | P14: 0.00038723286 | Q14: 0.00038719654 | R14: 0.00038712837 | S14: 0.00038710174 | T14: 0.0003870196 | U14: 0.00038693459 | V14: 0.00038684314 | W14: 0.00038675224 | X14: 0.0003866264 | Y14: 0.00038650754 | Z14: 0.00038637937 | AA14: 0.00038623677 | AB14: 0.00038608335 | AC14: 0.00038590701 | AD14: 0.00038573556 | AE14: 0.00038555651 | AF14: 0.00038536129 | AG14: 0.00038512787 | AH14: 0.0003848769
A15: rail | B15: psgr | C15: battery electric vehicle | D15: 0.001249043 | E15: 0.0012479839 | F15: 0.0012471666 | G15: 0.0012466465 | H15: 0.0012461776 | I15: 0.0012458211 | J15: 0.0012454262 | K15: 0.0012450098 | L15: 0.0012449523 | M15: 0.0012448581 | N15: 0.0012444927 | O15: 0.001244515 | P15: 0.001244363 | Q15: 0.0012442463 | R15: 0.0012440272 | S15: 0.0012439416 | T15: 0.0012436777 | U15: 0.0012434045 | V15: 0.0012431106 | W15: 0.0012428185 | X15: 0.0012424141 | Y15: 0.0012420322 | Z15: 0.0012416203 | AA15: 0.0012411621 | AB15: 0.001240669 | AC15: 0.0012401024 | AD15: 0.0012395515 | AE15: 0.0012389761 | AF15: 0.0012383487 | AG15: 0.0012375987 | AH15: 0.0012367922
A16: rail | B16: frgt | C16: diesel vehicle | D16: 0.003489371 | E16: 0.003512003 | F16: 0.003534782 | G16: 0.00355771 | H16: 0.003580785 | I16: 0.00360401 | J16: 0.003627386 | K16: 0.003650914 | L16: 0.003674594 | M16: 0.003698428 | N16: 0.003722416 | O16: 0.00374656 | P16: 0.00377086 | Q16: 0.003795318 | R16: 0.003819935 | S16: 0.003844712 | T16: 0.003869649 | U16: 0.003894748 | V16: 0.003920009 | W16: 0.003945435 | X16: 0.003971025 | Y16: 0.003996782 | Z16: 0.004022705 | AA16: 0.004048797 | AB16: 0.004075058 | AC16: 0.004101489 | AD16: 0.004128091 | AE16: 0.004154866 | AF16: 0.004181815 | AG16: 0.004208939 | AH16: 0.004236238
A17: ships | B17: psgr | C17: diesel vehicle | D17: 1.0049397e-05 | E17: 1.0049397e-05 | F17: 1.0049397e-05 | G17: 1.0049397e-05 | H17: 1.0049397e-05 | I17: 1.0049397e-05 | J17: 1.0049397e-05 | K17: 1.0049397e-05 | L17: 1.0049397e-05 | M17: 1.0049397e-05 | N17: 1.0049397e-05 | O17: 1.0049397e-05 | P17: 1.0049397e-05 | Q17: 1.0049397e-05 | R17: 1.0049397e-05 | S17: 1.0049397e-05 | T17: 1.0049397e-05 | U17: 1.0049397e-05 | V17: 1.0049397e-05 | W17: 1.0049397e-05 | X17: 1.0049397e-05 | Y17: 1.0049397e-05 | Z17: 1.0049397e-05 | AA17: 1.0049397e-05 | AB17: 1.0049397e-05 | AC17: 1.0049397e-05 | AD17: 1.0049397e-05 | AE17: 1.0049397e-05 | AF17: 1.0049397e-05 | AG17: 1.0049397e-05 | AH17: 1.0049397e-05
A18: ships | B18: frgt | C18: diesel vehicle | D18: 0.0049715257 | E18: 0.0049715257 | F18: 0.0049715257 | G18: 0.0049715257 | H18: 0.0049715257 | I18: 0.0049715257 | J18: 0.0049715257 | K18: 0.0049715257 | L18: 0.0049715257 | M18: 0.0049715257 | N18: 0.0049715257 | O18: 0.0049715257 | P18: 0.0049715257 | Q18: 0.0049715257 | R18: 0.0049715257 | S18: 0.0049715257 | T18: 0.0049715257 | U18: 0.0049715257 | V18: 0.0049715257 | W18: 0.0049715257 | X18: 0.0049715257 | Y18: 0.0049715257 | Z18: 0.0049715257 | AA18: 0.0049715257 | AB18: 0.0049715257 | AC18: 0.0049715257 | AD18: 0.0049715257 | AE18: 0.0049715257 | AF18: 0.0049715257 | AG18: 0.0049715257 | AH18: 0.0049715257
A19: motorbikes | B19: psgr | C19: gasoline vehicle | D19: 0.0011107106 | E19: 0.0011107106 | F19: 0.0011107106 | G19: 0.0011107106 | H19: 0.0011107106 | I19: 0.0011107106 | J19: 0.0011107106 | K19: 0.0011107106 | L19: 0.0011107106 | M19: 0.0011107106 | N19: 0.0011107106 | O19: 0.0011107106 | P19: 0.0011107106 | Q19: 0.0011107106 | R19: 0.0011107106 | S19: 0.0011107106 | T19: 0.0011107106 | U19: 0.0011107106 | V19: 0.0011107106 | W19: 0.0011107106 | X19: 0.0011107106 | Y19: 0.0011107106 | Z19: 0.0011107106 | AA19: 0.0011107106 | AB19: 0.0011107106 | AC19: 0.0011107106 | AD19: 0.0011107106 | AE19: 0.0011107106 | AF19: 0.0011107106 | AG19: 0.0011107106 | AH19: 0.0011107106
A20: motorbikes | B20: frgt | C20: gasoline vehicle | D20: 0 | E20: 0 | F20: 0 | G20: 0 | H20: 0 | I20: 0 | J20: 0 | K20: 0 | L20: 0 | M20: 0 | N20: 0 | O20: 0 | P20: 0 | Q20: 0 | R20: 0 | S20: 0 | T20: 0 | U20: 0 | V20: 0 | W20: 0 | X20: 0 | Y20: 0 | Z20: 0 | AA20: 0 | AB20: 0 | AC20: 0 | AD20: 0 | AE20: 0 | AF20: 0 | AG20: 0 | AH20: 0
A22: All passenger LDVs
A23: Fuel Economy (thing*miles/BTU) | B23: 2020 | C23: 2021 | D23: 2022 | E23: 2023 | F23: 2024 | G23: 2025 | H23: 2026 | I23: 2027 | J23: 2028 | K23: 2029 | L23: 2030 | M23: 2031 | N23: 2032 | O23: 2033 | P23: 2034 | Q23: 2035 | R23: 2036 | S23: 2037 | T23: 2038 | U23: 2039 | V23: 2040 | W23: 2041 | X23: 2042 | Y23: 2043 | Z23: 2044 | AA23: 2045 | AB23: 2046 | AC23: 2047 | AD23: 2048 | AE23: 2049 | AF23: 2050
A24: battery electric vehicle | B24: 0.0013016015 | C24: 0.0012926577 | D24: 0.0012869319 | E24: 0.0012796984 | F24: 0.0012723109 | G24: 0.0012688723 | H24: 0.0012656141 | I24: 0.0012602292 | J24: 0.0012562225 | K24: 0.0012526643 | L24: 0.0012501278 | M24: 0.0012487083 | N24: 0.0012467654 | O24: 0.001245938 | P24: 0.0012454911 | Q24: 0.0012451425 | R24: 0.0012441678 | S24: 0.0012437111 | T24: 0.0012434472 | U24: 0.0012431449 | V24: 0.0012427495 | W24: 0.0012426415 | X24: 0.001242527 | Y24: 0.0012423666 | Z24: 0.0012423662 | AA24: 0.0012424553 | AB24: 0.0012425304 | AC24: 0.0012424094 | AD24: 0.0012423079 | AE24: 0.0012421595 | AF24: 0.0012421847
A25: natural gas vehicle | B25: 0.0003802953 | C25: 0.00039476635 | D25: 0.0004031771 | E25: 0.00040861195 | F25: 0.00041215479 | G25: 0.00041613805 | H25: 0.00041864714 | I25: 0.00041871977 | J25: 0.00041845993 | K25: 0.00041824574 | L25: 0.0004189224 | M25: 0.0004187405 | N25: 0.00041850499 | O25: 0.00041826481 | P25: 0.00041829176 | Q25: 0.00041761857 | R25: 0.00041687945 | S25: 0.00041641133 | T25: 0.0004161345 | U25: 0.00041551323 | V25: 0.00041503634 | W25: 0.00041461933 | X25: 0.00041413078 | Y25: 0.00041366186 | Z25: 0.00041331259 | AA25: 0.0004130648 | AB25: 0.00041264229 | AC25: 0.00041222665 | AD25: 0.00041170489 | AE25: 0.00041134545 | AF25: 0.0004110109
A26: gasoline vehicle | B26: 0.00040104357 | C26: 0.00041543936 | D26: 0.00042324569 | E26: 0.0004284225 | F26: 0.00043223887 | G26: 0.0004366193 | H26: 0.00044073838 | I26: 0.00044130434 | J26: 0.00044139331 | K26: 0.00044143859 | L26: 0.00044252279 | M26: 0.00044258102 | N26: 0.00044262644 | O26: 0.00044263526 | P26: 0.00044289079 | Q26: 0.00044235185 | R26: 0.00044180682 | S26: 0.00044151692 | T26: 0.00044141526 | U26: 0.00044094859 | V26: 0.00044065284 | W26: 0.00044046477 | X26: 0.00044016736 | Y26: 0.00043991921 | Z26: 0.00043980677 | AA26: 0.00043981133 | AB26: 0.0004396046 | AC26: 0.00043945698 | AD26: 0.00043919625 | AE26: 0.00043913823 | AF26: 0.00043909652
A27: diesel vehicle | B27: 0.00042164837 | C27: 0.00043038372 | D27: 0.00043420466 | E27: 0.00043755647 | F27: 0.00043967944 | G27: 0.00044460624 | H27: 0.00044496012 | I27: 0.00044386794 | J27: 0.0004433754 | K27: 0.00044271109 | L27: 0.00044204868 | M27: 0.000441347 | N27: 0.0004407415 | O27: 0.0004400499 | P27: 0.00043959874 | Q27: 0.00043896792 | R27: 0.00043853822 | S27: 0.00043806793 | T27: 0.00043761382 | U27: 0.00043728429 | V27: 0.00043676208 | W27: 0.00043641079 | X27: 0.00043601813 | Y27: 0.00043568341 | Z27: 0.00043535955 | AA27: 0.0004350988 | AB27: 0.00043470212 | AC27: 0.00043438066 | AD27: 0.00043404467 | AE27: 0.00043370048 | AF27: 0.00043334687
A28: plugin hybrid vehicle | B28: 0.00065738319 | C28: 0.00067868209 | D28: 0.00068605104 | E28: 0.000689952 | F28: 0.0007025507 | G28: 0.00073075494 | H28: 0.00076511495 | I28: 0.00076729531 | J28: 0.00076615764 | K28: 0.00076497535 | L28: 0.00076434508 | M28: 0.00076297469 | N28: 0.00076220702 | O28: 0.00076135115 | P28: 0.00076059039 | Q28: 0.00075941522 | R28: 0.00075865921 | S28: 0.00075779554 | T28: 0.00075675471 | U28: 0.00075542246 | V28: 0.00075410271 | W28: 0.00075263394 | X28: 0.00075087689 | Y28: 0.00074906249 | Z28: 0.0007470072 | AA28: 0.00074466972 | AB28: 0.00074187743 | AC28: 0.00073887113 | AD28: 0.00073528956 | AE28: 0.00073158064 | AF28: 0.00072734242
A29: LPG vehicle | B29: 0.00036368321 | C29: 0.00037519786 | D29: 0.00038292342 | E29: 0.00038737442 | F29: 0.00039018163 | G29: 0.00039393487 | H29: 0.00039580813 | I29: 0.00039580687 | J29: 0.0003956887 | K29: 0.00039552372 | L29: 0.0003959371 | M29: 0.00039597128 | N29: 0.00039568311 | O29: 0.00039545024 | P29: 0.00039533736 | Q29: 0.0003948785 | R29: 0.00039428117 | S29: 0.00039378232 | T29: 0.0003934965 | U29: 0.00039297415 | V29: 0.00039250689 | W29: 0.00039211185 | X29: 0.00039168761 | Y29: 0.00039122732 | Z29: 0.00039085143 | AA29: 0.00039051217 | AB29: 0.00039011493 | AC29: 0.00038968024 | AD29: 0.00038920742 | AE29: 0.00038876188 | AF29: 0.00038837157
A30: hydrogen vehicle | B30: 0.00058794415 | C30: 0.00058596971 | D30: 0.00058487716 | E30: 0.00058450716 | F30: 0.00058509865 | G30: 0.00058547839 | H30: 0.0005867737 | I30: 0.0005855519 | J30: 0.0005848625 | K30: 0.0005839237 | L30: 0.00058323582 | M30: 0.00058232847 | N30: 0.00058140476 | O30: 0.00058053415 | P30: 0.00057985999 | Q30: 0.0005790672 | R30: 0.00057830388 | S30: 0.00057772941 | T30: 0.0005772879 | U30: 0.00057687866 | V30: 0.00057657581 | W30: 0.00057638685 | X30: 0.00057622519 | Y30: 0.00057612077 | Z30: 0.00057610601 | AA30: 0.00057616719 | AB30: 0.00057619221 | AC30: 0.00057620062 | AD30: 0.00057622282 | AE30: 0.00057625953 | AF30: 0.00057635527

Sheet SYFAFE
A1: Fuel Economy (passenger*miles/BTU) | B1: battery electric vehicle | C1: natural gas vehicle | D1: gasoline vehicle | E1: diesel vehicle | F1: plugin hybrid vehicle | G1: LPG vehicle | H1: hydrogen vehicle
A2: LDVs | B2: 0.0038548169 | C2: 0.0012015196 | D2: 0.00053392525 | E2: 0.00061041558 | F2: 0.00064059395 | G2: 0 | H2: 0
A3: HDVs | B3: 0.0058893036 | C3: 0.0012411171 | D3: 0 | E3: 0.0010956177 | F3: 0.001149784 | G3: 0 | H3: 0
A4: aircraft | B4: 0 | C4: 0 | D4: 0.0019867491 | E4: 0 | F4: 0 | G4: 0 | H4: 0
A5: rail | B5: 0.0032433054 | C5: 0 | D5: 0 | E5: 0.00096414358 | F5: 0.010095949 | G5: 0 | H5: 0
A6: ships | B6: 0 | C6: 0 | D6: 0.00022779144 | E6: 8.5088223e-08 | F6: 0 | G6: 0 | H6: 0
A7: motorbikes | B7: 0.0098648568 | C7: 0.0012056566 | D7: 0.0011311305 | E7: 0 | F7: 0 | G7: 0 | H7: 0
A9: Fuel Economy (freight ton*miles/BTU) | B9: battery electric vehicle | C9: natural gas vehicle | D9: gasoline vehicle | E9: diesel vehicle | F9: plugin hybrid vehicle | G9: LPG vehicle | H9: hydrogen vehicle
A10: LDVs | B10: 0.0004869412 | C10: 0 | D10: 0 | E10: 0.00051101512 | F10: 0 | G10: 0 | H10: 0
A11: HDVs | B11: 0.0033390254 | C11: 0 | D11: 0 | E11: 0.0035041037 | F11: 0 | G11: 0 | H11: 0
A12: aircraft | B12: 0 | C12: 0 | D12: 0.0001192731 | E12: 0 | F12: 0 | G12: 0 | H12: 0
A13: rail | B13: 0 | C13: 0 | D13: 6.0774298e-05 | E13: 5.7911221e-05 | F13: 0 | G13: 0 | H13: 0
A14: ships | B14: 0 | C14: 0 | D14: 3.7546381e-05 | E14: 3.6868405e-05 | F14: 0 | G14: 0 | H14: 0
A15: motorbikes | B15: 0 | C15: 0 | D15: 0 | E15: 0 | F15: 0 | G15: 0 | H15: 0

Sheet Other Values
A1: Perc Reduction in Fuel Use for Electricity
A2: LDVs and motorbikes | B2: 0.68595041
A3: HDVs | B3: 0.68881037
A5: Perc of Electricity Use for Plug-In Hybrid Vehicles
A6: electricity share | B6: 0.55
A8: Vehicle Lifetimes (years)
A9: LDVs | B9: 13.378782
A10: HDVs | B10: 28
A11: aircraft | B11: 24
A12: rail | B12: 34
A13: ships | B13: 33
A14: motorbikes | B14: 17.223321

Sheet Calculations
A1: Vehicle Loadings (in people or freight tons / vehicle) | D1: Source:
A2: passenger LDVs | B2: 1.67 | D2: For sources and calculations, see the variable AVLo.
A3: freight LDVs | B3: 1
A4: passenger HDVs | B4: 21.2
A5: freight HDVs | B5: 16
A6: passenger rail | B6: 48.656732
A8: BTU per Gallon Liquid Fuels | AK8: Source:
A9: gasoline | B9: 120476 | AK9: EIA | AL9: Energy Explained: Units and Calculators
A10: diesel | B10: 137452 | AK10: 2017 | AL10: https://www.eia.gov/energyexplained/index.cfm/index.cfm?page=about_energy_units
A12: Historical AEO fuel economy - passenger LDVs
B13: 2007 | C13: 2007 | D13: 2020
A14: Source | C14: AEO 2010 Table 7
A15: MPG | C15: 22.670399
A16: thing-miles/BTU | B16: =TREND(C16:D16,C13:D13,B13) -> 0.00031424986 | C16: =C15*$B$2/$B$9 -> 0.00031424986 | D16: =BNVFE!D8 -> 0.00037068405
A18: Historical fuel economy - freight HDV
A19: 2002 diesel heavy-duty vehicles | B19: 5.76
A20: Ratio of 2019 AEO overall freight efficiency to "heavy" freight efficiency, AEO 2019 | B20: =7.1/6.1 -> 1.1639344
A21: 2002 Average Freight HDV efficiency (MPG) | B21: =B19*$B$20 -> 6.7042623
A22: 2002 Average Freight HDV efficiency (thing-miles/BTU) | B22: =B21*$B$5/$B$10 -> 0.00078040477
A24: Hydrogen vs. Gasoline Efficiency | D24: Source:
A25: gasoline car efficiency | B25: 0.2 | D25: See the variable BNVFE
A26: hydrogen FCV efficiency | B26: 0.6
A27: distance multiplier for hydrogen vehicles | B27: =B26/B25 -> 3
A29: Propane (LPG) vs. Gasoline Efficiency | D29: Source:
A30: reduction in efficiency for propane | B30: 0.225 | D30: See the variable BNVFE
A31: distance multiplier for propane vehicles | B31: =1-B30 -> 0.775

Sheet Extrapolations
C1: 1983 | D1: 1984 | E1: 1985 | F1: 1986 | G1: 1987 | H1: 1988 | I1: 1989 | J1: 1990 | K1: 1991 | L1: 1992 | M1: 1993 | N1: 1994 | O1: 1995 | P1: 1996 | Q1: 1997 | R1: 1998 | S1: 1999 | T1: 2000 | U1: 2001 | V1: 2002 | W1: 2003 | X1: 2004 | Y1: 2005 | Z1: 2006 | AA1: 2007 | AB1: 2008 | AC1: 2009 | AD1: 2010 | AE1: 2011 | AF1: 2012 | AG1: 2013 | AH1: 2014 | AI1: 2015 | AJ1: 2016 | AK1: 2017 | AL1: 2018 | AM1: 2019 | AN1: 2020 | AO1: 2021 | AP1: 2022 | AQ1: 2023 | AR1: 2024 | AS1: 2025 | AT1: 2026 | AU1: 2027 | AV1: 2028 | AW1: 2029 | AX1: 2030 | AY1: 2031 | AZ1: 2032 | BA1: 2033 | BB1: 2034 | BC1: 2035 | BD1: 2036 | BE1: 2037 | BF1: 2038 | BG1: 2039 | BH1: 2040 | BI1: 2041 | BJ1: 2042 | BK1: 2043 | BL1: 2044 | BM1: 2045 | BN1: 2046 | BO1: 2047 | BP1: 2048 | BQ1: 2049 | BR1: 2050
A2: LDVs | B2: psgr | AA2: =Calculations!C16 -> 0.00031424986 | AB2: =($AN$2-$AA$2)/COUNT($AB$1:$AN$1)+AA2 -> 0.00031859095 | AC2: =($AN$2-$AA$2)/COUNT($AB$1:$AN$1)+AB2 -> 0.00032293204 | AD2: =($AN$2-$AA$2)/COUNT($AB$1:$AN$1)+AC2 -> 0.00032727313 | AE2: =($AN$2-$AA$2)/COUNT($AB$1:$AN$1)+AD2 -> 0.00033161423 | AF2: =($AN$2-$AA$2)/COUNT($AB$1:$AN$1)+AE2 -> 0.00033595532 | AG2: =($AN$2-$AA$2)/COUNT($AB$1:$AN$1)+AF2 -> 0.00034029641 | AH2: =($AN$2-$AA$2)/COUNT($AB$1:$AN$1)+AG2 -> 0.0003446375 | AI2: =($AN$2-$AA$2)/COUNT($AB$1:$AN$1)+AH2 -> 0.00034897859 | ... AM2: =($AN$2-$AA$2)/COUNT($AB$1:$AN$1)+AL2 -> 0.00036634295 | AN2: =BNVFE!D8 -> 0.00037068405 | AO2: =BNVFE!E8 -> 0.00038286968 | AP2: =BNVFE!F8 -> 0.0003899954 | AQ2: =BNVFE!G8 -> 0.00039439146 | AR2: =BNVFE!H8 -> 0.00039758792 | AS2: =BNVFE!I8 -> 0.0004167044 | AT2: =BNVFE!J8 -> 0.00045449874 | AU2: =BNVFE!K8 -> 0.0004557184 | ... BR2: =BNVFE!AH8 -> 0.00047615242
A3: LDVs | B3: frgt | AA3: {=TREND($AN$3:$AR$3,$AN$1:$AR$1,AA1)} -> 0.00011709921 | AB3: {=TREND($AN$3:$AR$3,$AN$1:$AR$1,AB1)} -> 0.00011699905 | AC3: {=TREND($AN$3:$AR$3,$AN$1:$AR$1,AC1)} -> 0.0001168989 | AD3: {=TREND($AN$3:$AR$3,$AN$1:$AR$1,AD1)} -> 0.00011679874 | AE3: {=TREND($AN$3:$AR$3,$AN$1:$AR$1,AE1)} -> 0.00011669859 | AF3: {=TREND($AN$3:$AR$3,$AN$1:$AR$1,AF1)} -> 0.00011659844 | AG3: {=TREND($AN$3:$AR$3,$AN$1:$AR$1,AG1)} -> 0.00011649828 | AH3: {=TREND($AN$3:$AR$3,$AN$1:$AR$1,AH1)} -> 0.00011639813 | ... AM3: {=TREND($AN$3:$AR$3,$AN$1:$AR$1,AM1)} -> 0.00011589736 | AN3: =BNVFE!D9 -> 0.00011578636 | AO3: =BNVFE!E9 -> 0.00011589922 | AP3: =BNVFE!F9 -> 0.00011538534 | AQ3: =BNVFE!G9 -> 0.00011535675 | AR3: =BNVFE!H9 -> 0.00011555683 | AS3: =BNVFE!I9 -> 0.00011619448 | AT3: =BNVFE!J9 -> 0.00011675875 | AU3: =BNVFE!K9 -> 0.00011708867 | ... BR3: =BNVFE!AH9 -> 0.00010682755
A4: HDVs | B4: psgr | L4: =L5/M5*M4 -> 0.0010544082 | M4: =M5/N5*N4 -> 0.0010544082 | N4: =N5/O5*O4 -> 0.0010544082 | O4: =O5/P5*P4 -> 0.0010544082 | P4: =P5/Q5*Q4 -> 0.0010544082 | Q4: =Q5/R5*R4 -> 0.0010544082 | R4: =R5/S5*S4 -> 0.0010544082 | S4: =S5/T5*T4 -> 0.0010544082 | ... AM4: =AM5/AN5*AN4 -> 0.0009926055 | AN4: =BNVFE!D10 -> 0.00098533459 | AO4: =BNVFE!E10 -> 0.00099880214 | AP4: =BNVFE!F10 -> 0.0010144916 | AQ4: =BNVFE!G10 -> 0.0010338641 | AR4: =BNVFE!H10 -> 0.0010578484 | AS4: =BNVFE!I10 -> 0.0010855564 | AT4: =BNVFE!J10 -> 0.0011154933 | AU4: =BNVFE!K10 -> 0.0011464331 | ... BR4: =BNVFE!AH10 -> 0.0012379719
A5: HDVs | B5: frgt | L5: =M5 -> 0.00078040477 | M5: =N5 -> 0.00078040477 | N5: =O5 -> 0.00078040477 | O5: =P5 -> 0.00078040477 | P5: =Q5 -> 0.00078040477 | Q5: =R5 -> 0.00078040477 | R5: =S5 -> 0.00078040477 | S5: =T5 -> 0.00078040477 | ... U5: =V5 -> 0.00078040477 | V5: =Calculations!B22 -> 0.00078040477 | W5: =($AN$5-$V$5)/COUNT($V$1:$AN$1)+V5 -> 0.00077771404 | X5: =($AN$5-$V$5)/COUNT($V$1:$AN$1)+W5 -> 0.00077502332 | Y5: =($AN$5-$V$5)/COUNT($V$1:$AN$1)+X5 -> 0.00077233259 | Z5: =($AN$5-$V$5)/COUNT($V$1:$AN$1)+Y5 -> 0.00076964186 | AA5: =($AN$5-$V$5)/COUNT($V$1:$AN$1)+Z5 -> 0.00076695113 | AB5: =($AN$5-$V$5)/COUNT($V$1:$AN$1)+AA5 -> 0.0007642604 | AC5: =($AN$5-$V$5)/COUNT($V$1:$AN$1)+AB5 -> 0.00076156967 | AD5: =($AN$5-$V$5)/COUNT($V$1:$AN$1)+AC5 -> 0.00075887895 | ... AM5: =($AN$5-$V$5)/COUNT($V$1:$AN$1)+AL5 -> 0.00073466239 | AN5: =BNVFE!D11 -> 0.00072928094 | AO5: =BNVFE!E11 -> 0.00073924874 | AP5: =BNVFE!F11 -> 0.00075086107 | AQ5: =BNVFE!G11 -> 0.00076519938 | AR5: =BNVFE!H11 -> 0.00078295096 | AS5: =BNVFE!I11 -> 0.00080345861 | AT5: =BNVFE!J11 -> 0.00082561601 | AU5: =BNVFE!K11 -> 0.0008485156 | ... BR5: =BNVFE!AH11 -> 0.00091626672
A6: aircraft | B6: psgr | P6: =TREND($AN6:$BR6,$AN$1:$BR$1,P$1) -> 0.00037813606 | Q6: =TREND($AN6:$BR6,$AN$1:$BR$1,Q$1) -> 0.00038189121 | R6: =TREND($AN6:$BR6,$AN$1:$BR$1,R$1) -> 0.00038564636 | S6: =TREND($AN6:$BR6,$AN$1:$BR$1,S$1) -> 0.0003894015 | T6: =TREND($AN6:$BR6,$AN$1:$BR$1,T$1) -> 0.00039315665 | U6: =TREND($AN6:$BR6,$AN$1:$BR$1,U$1) -> 0.0003969118 | V6: =TREND($AN6:$BR6,$AN$1:$BR$1,V$1) -> 0.00040066694 | W6: =TREND($AN6:$BR6,$AN$1:$BR$1,W$1) -> 0.00040442209 | ... AM6: =TREND($AN6:$BR6,$AN$1:$BR$1,AM$1) -> 0.00046450444 | AN6: =BNVFE!D12 -> 0.00046616941 | AO6: =BNVFE!E12 -> 0.00047399299 | AP6: =BNVFE!F12 -> 0.00047625318 | AQ6: =BNVFE!G12 -> 0.00047962764 | AR6: =BNVFE!H12 -> 0.00048472425 | AS6: =BNVFE!I12 -> 0.00048856489 | AT6: =BNVFE!J12 -> 0.00049188762 | AU6: =BNVFE!K12 -> 0.00049507466 | ... BR6: =BNVFE!AH12 -> 0.00058064147
A7: aircraft | B7: frgt | P7: =TREND($AN7:$BR7,$AN$1:$BR$1,P$1)-($AR7-$AN7) -> 9.2581756e-05 | Q7: =TREND($AN7:$BR7,$AN$1:$BR$1,Q$1)-($AR7-$AN7) -> 9.3548598e-05 | R7: =TREND($AN7:$BR7,$AN$1:$BR$1,R$1)-($AR7-$AN7) -> 9.4515439e-05 | S7: =TREND($AN7:$BR7,$AN$1:$BR$1,S$1)-($AR7-$AN7) -> 9.5482281e-05 | T7: =TREND($AN7:$BR7,$AN$1:$BR$1,T$1)-($AR7-$AN7) -> 9.6449123e-05 | U7: =TREND($AN7:$BR7,$AN$1:$BR$1,U$1)-($AR7-$AN7) -> 9.7415964e-05 | V7: =TREND($AN7:$BR7,$AN$1:$BR$1,V$1)-($AR7-$AN7) -> 9.8382806e-05 | W7: =TREND($AN7:$BR7,$AN$1:$BR$1,W$1)-($AR7-$AN7) -> 9.9349647e-05 | ... AM7: =TREND($AN7:$BR7,$AN$1:$BR$1,AM$1)-($AR7-$AN7) -> 0.00011481911 | AN7: =BNVFE!D13 -> 0.00012002513 | AO7: =BNVFE!E13 -> 0.00012203947 | AP7: =BNVFE!F13 -> 0.00012262141 | AQ7: =BNVFE!G13 -> 0.00012349023 | AR7: =BNVFE!H13 -> 0.00012480246 | AS7: =BNVFE!I13 -> 0.00012579132 | AT7: =BNVFE!J13 -> 0.00012664682 | AU7: =BNVFE!K13 -> 0.00012746739 | ... BR7: =BNVFE!AH13 -> 0.00014949837
A8: rail | B8: psgr - diesel | F8: =TREND($AN8:$AS8,$AN$1:$AS$1,F$1) -> 0.00039525226 | G8: =TREND($AN8:$AS8,$AN$1:$AS$1,G$1) -> 0.00039505622 | H8: =TREND($AN8:$AS8,$AN$1:$AS$1,H$1) -> 0.00039486018 | I8: =TREND($AN8:$AS8,$AN$1:$AS$1,I$1) -> 0.00039466415 | J8: =TREND($AN8:$AS8,$AN$1:$AS$1,J$1) -> 0.00039446811 | K8: =TREND($AN8:$AS8,$AN$1:$AS$1,K$1) -> 0.00039427208 | L8: =TREND($AN8:$AS8,$AN$1:$AS$1,L$1) -> 0.00039407604 | M8: =TREND($AN8:$AS8,$AN$1:$AS$1,M$1) -> 0.00039388001 | ... AM8: =TREND($AN8:$AS8,$AN$1:$AS$1,AM$1) -> 0.00038878309 | AN8: =BNVFE!D14 -> 0.00038868922 | AO8: =BNVFE!E14 -> 0.00038835965 | AP8: =BNVFE!F14 -> 0.00038810531 | AQ8: =BNVFE!G14 -> 0.00038794345 | AR8: =BNVFE!H14 -> 0.00038779756 | AS8: =BNVFE!I14 -> 0.0003876866 | AT8: =BNVFE!J14 -> 0.00038756372 | AU8: =BNVFE!K14 -> 0.00038743413 | ... BR8: =BNVFE!AH14 -> 0.0003848769
A9: rail | B9: psgr - electric | F9: =TREND($AN9:$AS9,$AN$1:$AS$1,F$1) -> 0.0012701331 | G9: =TREND($AN9:$AS9,$AN$1:$AS$1,G$1) -> 0.0012695031 | H9: =TREND($AN9:$AS9,$AN$1:$AS$1,H$1) -> 0.0012688732 | I9: =TREND($AN9:$AS9,$AN$1:$AS$1,I$1) -> 0.0012682432 | J9: =TREND($AN9:$AS9,$AN$1:$AS$1,J$1) -> 0.0012676133 | K9: =TREND($AN9:$AS9,$AN$1:$AS$1,K$1) -> 0.0012669833 | L9: =TREND($AN9:$AS9,$AN$1:$AS$1,L$1) -> 0.0012663534 | M9: =TREND($AN9:$AS9,$AN$1:$AS$1,M$1) -> 0.0012657234 | ... AM9: =TREND($AN9:$AS9,$AN$1:$AS$1,AM$1) -> 0.0012493446 | AN9: =BNVFE!D15 -> 0.001249043 | AO9: =BNVFE!E15 -> 0.0012479839 | AP9: =BNVFE!F15 -> 0.0012471666 | AQ9: =BNVFE!G15 -> 0.0012466465 | AR9: =BNVFE!H15 -> 0.0012461776 | AS9: =BNVFE!I15 -> 0.0012458211 | AT9: =BNVFE!J15 -> 0.0012454262 | AU9: =BNVFE!K15 -> 0.0012450098 | ... BR9: =BNVFE!AH15 -> 0.0012367922
A10: rail | B10: frgt | F10: =TREND($AN10:$BR10,$AN$1:$BR$1,F$1) -> 0.0026319489 | G10: =TREND($AN10:$BR10,$AN$1:$BR$1,G$1) -> 0.0026568304 | H10: =TREND($AN10:$BR10,$AN$1:$BR$1,H$1) -> 0.0026817119 | I10: =TREND($AN10:$BR10,$AN$1:$BR$1,I$1) -> 0.0027065934 | J10: =TREND($AN10:$BR10,$AN$1:$BR$1,J$1) -> 0.0027314749 | K10: =TREND($AN10:$BR10,$AN$1:$BR$1,K$1) -> 0.0027563565 | L10: =TREND($AN10:$BR10,$AN$1:$BR$1,L$1) -> 0.002781238 | M10: =TREND($AN10:$BR10,$AN$1:$BR$1,M$1) -> 0.0028061195 | ... AM10: =TREND($AN10:$BR10,$AN$1:$BR$1,AM$1) -> 0.0034530387 | AN10: =BNVFE!D16 -> 0.003489371 | AO10: =BNVFE!E16 -> 0.003512003 | AP10: =BNVFE!F16 -> 0.003534782 | AQ10: =BNVFE!G16 -> 0.00355771 | AR10: =BNVFE!H16 -> 0.003580785 | AS10: =BNVFE!I16 -> 0.00360401 | AT10: =BNVFE!J16 -> 0.003627386 | AU10: =BNVFE!K16 -> 0.003650914 | ... BR10: =BNVFE!AH16 -> 0.004236238
A11: ships | B11: psgr | G11: =TREND($AN11:$BR11,$AN$1:$BR$1,G$1) -> 1.0049397e-05 | H11: =TREND($AN11:$BR11,$AN$1:$BR$1,H$1) -> 1.0049397e-05 | I11: =TREND($AN11:$BR11,$AN$1:$BR$1,I$1) -> 1.0049397e-05 | J11: =TREND($AN11:$BR11,$AN$1:$BR$1,J$1) -> 1.0049397e-05 | K11: =TREND($AN11:$BR11,$AN$1:$BR$1,K$1) -> 1.0049397e-05 | L11: =TREND($AN11:$BR11,$AN$1:$BR$1,L$1) -> 1.0049397e-05 | M11: =TREND($AN11:$BR11,$AN$1:$BR$1,M$1) -> 1.0049397e-05 | N11: =TREND($AN11:$BR11,$AN$1:$BR$1,N$1) -> 1.0049397e-05 | ... AM11: =TREND($AN11:$BR11,$AN$1:$BR$1,AM$1) -> 1.0049397e-05 | AN11: =BNVFE!D17 -> 1.0049397e-05 | AO11: =BNVFE!E17 -> 1.0049397e-05 | AP11: =BNVFE!F17 -> 1.0049397e-05 | AQ11: =BNVFE!G17 -> 1.0049397e-05 | AR11: =BNVFE!H17 -> 1.0049397e-05 | AS11: =BNVFE!I17 -> 1.0049397e-05 | AT11: =BNVFE!J17 -> 1.0049397e-05 | AU11: =BNVFE!K17 -> 1.0049397e-05 | ... BR11: =BNVFE!AH17 -> 1.0049397e-05
A12: ships | B12: frgt | G12: =TREND($AN12:$BR12,$AN$1:$BR$1,G$1) -> 0.0049715257 | H12: =TREND($AN12:$BR12,$AN$1:$BR$1,H$1) -> 0.0049715257 | I12: =TREND($AN12:$BR12,$AN$1:$BR$1,I$1) -> 0.0049715257 | J12: =TREND($AN12:$BR12,$AN$1:$BR$1,J$1) -> 0.0049715257 | K12: =TREND($AN12:$BR12,$AN$1:$BR$1,K$1) -> 0.0049715257 | L12: =TREND($AN12:$BR12,$AN$1:$BR$1,L$1) -> 0.0049715257 | M12: =TREND($AN12:$BR12,$AN$1:$BR$1,M$1) -> 0.0049715257 | N12: =TREND($AN12:$BR12,$AN$1:$BR$1,N$1) -> 0.0049715257 | ... AM12: =TREND($AN12:$BR12,$AN$1:$BR$1,AM$1) -> 0.0049715257 | AN12: =BNVFE!D18 -> 0.0049715257 | AO12: =BNVFE!E18 -> 0.0049715257 | AP12: =BNVFE!F18 -> 0.0049715257 | AQ12: =BNVFE!G18 -> 0.0049715257 | AR12: =BNVFE!H18 -> 0.0049715257 | AS12: =BNVFE!I18 -> 0.0049715257 | AT12: =BNVFE!J18 -> 0.0049715257 | AU12: =BNVFE!K18 -> 0.0049715257 | ... BR12: =BNVFE!AH18 -> 0.0049715257
A13: motorbikes | B13: psgr | W13: =TREND($AN13:$BR13,$AN$1:$BR$1,W$1) -> 0.0011107106 | X13: =TREND($AN13:$BR13,$AN$1:$BR$1,X$1) -> 0.0011107106 | Y13: =TREND($AN13:$BR13,$AN$1:$BR$1,Y$1) -> 0.0011107106 | Z13: =TREND($AN13:$BR13,$AN$1:$BR$1,Z$1) -> 0.0011107106 | AA13: =TREND($AN13:$BR13,$AN$1:$BR$1,AA$1) -> 0.0011107106 | AB13: =TREND($AN13:$BR13,$AN$1:$BR$1,AB$1) -> 0.0011107106 | AC13: =TREND($AN13:$BR13,$AN$1:$BR$1,AC$1) -> 0.0011107106 | AD13: =TREND($AN13:$BR13,$AN$1:$BR$1,AD$1) -> 0.0011107106 | ... AM13: =TREND($AN13:$BR13,$AN$1:$BR$1,AM$1) -> 0.0011107106 | AN13: =BNVFE!D19 -> 0.0011107106 | AO13: =BNVFE!E19 -> 0.0011107106 | AP13: =BNVFE!F19 -> 0.0011107106 | AQ13: =BNVFE!G19 -> 0.0011107106 | AR13: =BNVFE!H19 -> 0.0011107106 | AS13: =BNVFE!I19 -> 0.0011107106 | AT13: =BNVFE!J19 -> 0.0011107106 | AU13: =BNVFE!K19 -> 0.0011107106 | ... BR13: =BNVFE!AH19 -> 0.0011107106
A14: motorbikes | B14: frgt | W14: =$AM14 -> 0 | X14: =$AM14 -> 0 | Y14: =$AM14 -> 0 | Z14: =$AM14 -> 0 | AA14: =$AM14 -> 0 | AB14: =$AM14 -> 0 | AC14: =$AM14 -> 0 | AD14: =$AM14 -> 0 | ... AL14: =$AM14 -> 0 | AM14: =BNVFE!D20 -> 0 | AN14: =BNVFE!D20 -> 0 | AO14: =BNVFE!E20 -> 0 | AP14: =BNVFE!F20 -> 0 | AQ14: =BNVFE!G20 -> 0 | AR14: =BNVFE!H20 -> 0 | AS14: =BNVFE!I20 -> 0 | AT14: =BNVFE!J20 -> 0 | AU14: =BNVFE!K20 -> 0 | ... BR14: =BNVFE!AH20 -> 0

Sheet BHNVFEAL-LDVs-psgr
A1: Fuel Economy ((thing*miles)/BTU) | B1: 2020 | C1: 2021 | D1: 2022 | E1: 2023 | F1: 2024 | G1: 2025 | H1: 2026 | I1: 2027 | J1: 2028 | K1: 2029 | L1: 2030 | M1: 2031 | N1: 2032 | O1: 2033 | P1: 2034 | Q1: 2035 | R1: 2036 | S1: 2037 | T1: 2038 | U1: 2039 | V1: 2040 | W1: 2041 | X1: 2042 | Y1: 2043 | Z1: 2044 | AA1: 2045 | AB1: 2046 | AC1: 2047 | AD1: 2048 | AE1: 2049 | AF1: 2050
A2: battery electric vehicle | B2: =SYFAFE!$B$2 -> 0.0038548169 | C2: =SYFAFE!$B$2 -> 0.0038548169 | D2: =SYFAFE!$B$2 -> 0.0038548169 | E2: =SYFAFE!$B$2 -> 0.0038548169 | F2: =SYFAFE!$B$2 -> 0.0038548169 | G2: =SYFAFE!$B$2 -> 0.0038548169 | H2: =SYFAFE!$B$2 -> 0.0038548169 | I2: =SYFAFE!$B$2 -> 0.0038548169 | ... AF2: =SYFAFE!$B$2 -> 0.0038548169
A3: natural gas vehicle | B3: =BNVFE!B25*('BHNVFEAL-LDVs-psgr'!B$4/BNVFE!B$26) -> 0.00029799193 | C3: =BNVFE!C25*('BHNVFEAL-LDVs-psgr'!C$4/BNVFE!C$26) -> 0.00030273729 | D3: =BNVFE!D25*('BHNVFEAL-LDVs-psgr'!D$4/BNVFE!D$26) -> 0.00030761992 | E3: =BNVFE!E25*('BHNVFEAL-LDVs-psgr'!E$4/BNVFE!E$26) -> 0.0003121398 | F3: =BNVFE!F25*('BHNVFEAL-LDVs-psgr'!F$4/BNVFE!F$26) -> 0.00031620569 | G3: =BNVFE!G25*('BHNVFEAL-LDVs-psgr'!G$4/BNVFE!G$26) -> 0.00032019608 | H3: =BNVFE!H25*('BHNVFEAL-LDVs-psgr'!H$4/BNVFE!H$26) -> 0.00032323965 | I3: =BNVFE!I25*('BHNVFEAL-LDVs-psgr'!I$4/BNVFE!I$26) -> 0.00032700004 | ... AF3: =BNVFE!AF25*('BHNVFEAL-LDVs-psgr'!AF$4/BNVFE!AF$26) -> 0.00043506173
A4: gasoline vehicle | B4: =Extrapolations!AA2 -> 0.00031424986 | C4: =Extrapolations!AB2 -> 0.00031859095 | D4: =Extrapolations!AC2 -> 0.00032293204 | E4: =Extrapolations!AD2 -> 0.00032727313 | F4: =Extrapolations!AE2 -> 0.00033161423 | G4: =Extrapolations!AF2 -> 0.00033595532 | H4: =Extrapolations!AG2 -> 0.00034029641 | I4: =Extrapolations!AH2 -> 0.0003446375 | ... AF4: =Extrapolations!BE2 -> 0.00046479081
A5: diesel vehicle | B5: =BNVFE!B27*('BHNVFEAL-LDVs-psgr'!B$4/BNVFE!B$26) -> 0.00033039538 | C5: =BNVFE!C27*('BHNVFEAL-LDVs-psgr'!C$4/BNVFE!C$26) -> 0.00033005144 | D5: =BNVFE!D27*('BHNVFEAL-LDVs-psgr'!D$4/BNVFE!D$26) -> 0.00033129362 | E5: =BNVFE!E27*('BHNVFEAL-LDVs-psgr'!E$4/BNVFE!E$26) -> 0.0003342506 | F5: =BNVFE!F27*('BHNVFEAL-LDVs-psgr'!F$4/BNVFE!F$26) -> 0.00033732264 | G5: =BNVFE!G27*('BHNVFEAL-LDVs-psgr'!G$4/BNVFE!G$26) -> 0.00034210084 | H5: =BNVFE!H27*('BHNVFEAL-LDVs-psgr'!H$4/BNVFE!H$26) -> 0.00034355604 | I5: =BNVFE!I27*('BHNVFEAL-LDVs-psgr'!I$4/BNVFE!I$26) -> 0.00034663955 | ... AF5: =BNVFE!AF27*('BHNVFEAL-LDVs-psgr'!AF$4/BNVFE!AF$26) -> 0.00045870472
A6: plugin hybrid vehicle | B6: =BNVFE!B28*('BHNVFEAL-LDVs-psgr'!B$4/BNVFE!B$26) -> 0.00051511255 | C6: =BNVFE!C28*('BHNVFEAL-LDVs-psgr'!C$4/BNVFE!C$26) -> 0.00052046579 | D6: =BNVFE!D28*('BHNVFEAL-LDVs-psgr'!D$4/BNVFE!D$26) -> 0.00052344978 | E6: =BNVFE!E28*('BHNVFEAL-LDVs-psgr'!E$4/BNVFE!E$26) -> 0.00052705625 | F6: =BNVFE!F28*('BHNVFEAL-LDVs-psgr'!F$4/BNVFE!F$26) -> 0.00053899781 | G6: =BNVFE!G28*('BHNVFEAL-LDVs-psgr'!G$4/BNVFE!G$26) -> 0.00056227704 | H6: =BNVFE!H28*('BHNVFEAL-LDVs-psgr'!H$4/BNVFE!H$26) -> 0.00059074926 | I6: =BNVFE!I28*('BHNVFEAL-LDVs-psgr'!I$4/BNVFE!I$26) -> 0.00059922079 | ... AF6: =BNVFE!AF28*('BHNVFEAL-LDVs-psgr'!AF$4/BNVFE!AF$26) -> 0.00076990379
A7: LPG vehicle | B7: =BNVFE!B29*('BHNVFEAL-LDVs-psgr'!B$4/BNVFE!B$26) -> 0.00028497502 | C7: =BNVFE!C29*('BHNVFEAL-LDVs-psgr'!C$4/BNVFE!C$26) -> 0.00028773067 | D7: =BNVFE!D29*('BHNVFEAL-LDVs-psgr'!D$4/BNVFE!D$26) -> 0.00029216657 | E7: =BNVFE!E29*('BHNVFEAL-LDVs-psgr'!E$4/BNVFE!E$26) -> 0.0002959164 | F7: =BNVFE!F29*('BHNVFEAL-LDVs-psgr'!F$4/BNVFE!F$26) -> 0.00029934785 | G7: =BNVFE!G29*('BHNVFEAL-LDVs-psgr'!G$4/BNVFE!G$26) -> 0.00030311191 | H7: =BNVFE!H29*('BHNVFEAL-LDVs-psgr'!H$4/BNVFE!H$26) -> 0.00030560553 | I7: =BNVFE!I29*('BHNVFEAL-LDVs-psgr'!I$4/BNVFE!I$26) -> 0.00030910616 | ... AF7: =BNVFE!AF29*('BHNVFEAL-LDVs-psgr'!AF$4/BNVFE!AF$26) -> 0.00041109763
A8: hydrogen vehicle | B8: =SYFAFE!$H$2 -> 0 | C8: =B8 -> 0 | D8: =C8 -> 0 | E8: =D8 -> 0 | F8: =E8 -> 0 | G8: =F8 -> 0 | H8: =G8 -> 0 | I8: =H8 -> 0 | J8: =I8 -> 0 | ... AF8: =AE8 -> 0

Sheet BHNVFEAL-LDVs-frgt
A1: Fuel Economy ((thing*miles)/BTU) | B1: 2020 | C1: 2021 | D1: 2022 | E1: 2023 | F1: 2024 | G1: 2025 | H1: 2026 | I1: 2027 | J1: 2028 | K1: 2029 | L1: 2030 | M1: 2031 | N1: 2032 | O1: 2033 | P1: 2034 | Q1: 2035 | R1: 2036 | S1: 2037 | T1: 2038 | U1: 2039 | V1: 2040 | W1: 2041 | X1: 2042 | Y1: 2043 | Z1: 2044 | AA1: 2045 | AB1: 2046 | AC1: 2047 | AD1: 2048 | AE1: 2049 | AF1: 2050
A2: battery electric vehicle | B2: {=TRANSPOSE(SYFAFE!B10:H10)} -> 0.0004869412 | C2: =B2 -> 0.0004869412 | D2: =C2 -> 0.0004869412 | E2: =D2 -> 0.0004869412 | F2: =E2 -> 0.0004869412 | G2: =F2 -> 0.0004869412 | H2: =G2 -> 0.0004869412 | I2: =H2 -> 0.0004869412 | J2: =I2 -> 0.0004869412 | ... AF2: =AE2 -> 0.0004869412
A3: natural gas vehicle | B3: 0 | C3: =B3 -> 0 | D3: =C3 -> 0 | E3: =D3 -> 0 | F3: =E3 -> 0 | G3: =F3 -> 0 | H3: =G3 -> 0 | I3: =H3 -> 0 | J3: =I3 -> 0 | ... AF3: =AE3 -> 0
A4: gasoline vehicle | B4: 0 | C4: =B4 -> 0 | D4: =C4 -> 0 | E4: =D4 -> 0 | F4: =E4 -> 0 | G4: =F4 -> 0 | H4: =G4 -> 0 | I4: =H4 -> 0 | J4: =I4 -> 0 | ... AF4: =AE4 -> 0
A5: diesel vehicle | B5: 0.00051101512 | C5: =B5 -> 0.00051101512 | D5: =C5 -> 0.00051101512 | E5: =D5 -> 0.00051101512 | F5: =E5 -> 0.00051101512 | G5: =F5 -> 0.00051101512 | H5: =G5 -> 0.00051101512 | I5: =H5 -> 0.00051101512 | J5: =I5 -> 0.00051101512 | ... AF5: =AE5 -> 0.00051101512
A6: plugin hybrid vehicle | B6: 0 | C6: =B6 -> 0 | D6: =C6 -> 0 | E6: =D6 -> 0 | F6: =E6 -> 0 | G6: =F6 -> 0 | H6: =G6 -> 0 | I6: =H6 -> 0 | J6: =I6 -> 0 | ... AF6: =AE6 -> 0
A7: LPG vehicle | B7: 0 | C7: =B7 -> 0 | D7: =C7 -> 0 | E7: =D7 -> 0 | F7: =E7 -> 0 | G7: =F7 -> 0 | H7: =G7 -> 0 | I7: =H7 -> 0 | J7: =I7 -> 0 | ... AF7: =AE7 -> 0
A8: hydrogen vehicle | B8: 0 | C8: =B8 -> 0 | D8: =C8 -> 0 | E8: =D8 -> 0 | F8: =E8 -> 0 | G8: =F8 -> 0 | H8: =G8 -> 0 | I8: =H8 -> 0 | J8: =I8 -> 0 | ... AF8: =AE8 -> 0

Sheet BHNVFEAL-HDVs-psgr
A1: Fuel Economy ((thing*miles)/BTU) | B1: 2020 | C1: 2021 | D1: 2022 | E1: 2023 | F1: 2024 | G1: 2025 | H1: 2026 | I1: 2027 | J1: 2028 | K1: 2029 | L1: 2030 | M1: 2031 | N1: 2032 | O1: 2033 | P1: 2034 | Q1: 2035 | R1: 2036 | S1: 2037 | T1: 2038 | U1: 2039 | V1: 2040 | W1: 2041 | X1: 2042 | Y1: 2043 | Z1: 2044 | AA1: 2045 | AB1: 2046 | AC1: 2047 | AD1: 2048 | AE1: 2049 | AF1: 2050
A2: battery electric vehicle | B2: {=TRANSPOSE(SYFAFE!B3:H3)} -> 0.0058893036 | C2: =B2 -> 0.0058893036 | D2: =C2 -> 0.0058893036 | E2: =D2 -> 0.0058893036 | F2: =E2 -> 0.0058893036 | G2: =F2 -> 0.0058893036 | H2: =G2 -> 0.0058893036 | I2: =H2 -> 0.0058893036 | J2: =I2 -> 0.0058893036 | ... AF2: =AE2 -> 0.0058893036
A3: natural gas vehicle | B3: 0.0012411171 | C3: =B3 -> 0.0012411171 | D3: =C3 -> 0.0012411171 | E3: =D3 -> 0.0012411171 | F3: =E3 -> 0.0012411171 | G3: =F3 -> 0.0012411171 | H3: =G3 -> 0.0012411171 | I3: =H3 -> 0.0012411171 | J3: =I3 -> 0.0012411171 | ... AF3: =AE3 -> 0.0012411171
A4: gasoline vehicle | B4: 0 | C4: =B4 -> 0 | D4: =C4 -> 0 | E4: =D4 -> 0 | F4: =E4 -> 0 | G4: =F4 -> 0 | H4: =G4 -> 0 | I4: =H4 -> 0 | J4: =I4 -> 0 | ... AF4: =AE4 -> 0
A5: diesel vehicle | B5: 0.0010956177 | C5: =B5 -> 0.0010956177 | D5: =C5 -> 0.0010956177 | E5: =D5 -> 0.0010956177 | F5: =E5 -> 0.0010956177 | G5: =F5 -> 0.0010956177 | H5: =G5 -> 0.0010956177 | I5: =H5 -> 0.0010956177 | J5: =I5 -> 0.0010956177 | ... AF5: =AE5 -> 0.0010956177
A6: plugin hybrid vehicle | B6: 0.001149784 | C6: =B6 -> 0.001149784 | D6: =C6 -> 0.001149784 | E6: =D6 -> 0.001149784 | F6: =E6 -> 0.001149784 | G6: =F6 -> 0.001149784 | H6: =G6 -> 0.001149784 | I6: =H6 -> 0.001149784 | J6: =I6 -> 0.001149784 | ... AF6: =AE6 -> 0.001149784
A7: LPG vehicle | B7: 0 | C7: =B7 -> 0 | D7: =C7 -> 0 | E7: =D7 -> 0 | F7: =E7 -> 0 | G7: =F7 -> 0 | H7: =G7 -> 0 | I7: =H7 -> 0 | J7: =I7 -> 0 | ... AF7: =AE7 -> 0
A8: hydrogen vehicle | B8: 0 | C8: =B8 -> 0 | D8: =C8 -> 0 | E8: =D8 -> 0 | F8: =E8 -> 0 | G8: =F8 -> 0 | H8: =G8 -> 0 | I8: =H8 -> 0 | J8: =I8 -> 0 | ... AF8: =AE8 -> 0

Sheet BHNVFEAL-HDVs-frgt
A1: Fuel Economy ((thing*miles)/BTU) | B1: 2020 | C1: 2021 | D1: 2022 | E1: 2023 | F1: 2024 | G1: 2025 | H1: 2026 | I1: 2027 | J1: 2028 | K1: 2029 | L1: 2030 | M1: 2031 | N1: 2032 | O1: 2033 | P1: 2034 | Q1: 2035 | R1: 2036 | S1: 2037 | T1: 2038 | U1: 2039 | V1: 2040 | W1: 2041 | X1: 2042 | Y1: 2043 | Z1: 2044 | AA1: 2045 | AB1: 2046 | AC1: 2047 | AD1: 2048 | AE1: 2049 | AF1: 2050
A2: battery electric vehicle | B2: {=TRANSPOSE(SYFAFE!B11:H11)} -> 0.0033390254 | C2: =B2 -> 0.0033390254 | D2: =C2 -> 0.0033390254 | E2: =D2 -> 0.0033390254 | F2: =E2 -> 0.0033390254 | G2: =F2 -> 0.0033390254 | H2: =G2 -> 0.0033390254 | I2: =H2 -> 0.0033390254 | J2: =I2 -> 0.0033390254 | ... AF2: =AE2 -> 0.0033390254
A3: natural gas vehicle | B3: 0 | C3: =B3 -> 0 | D3: =C3 -> 0 | E3: =D3 -> 0 | F3: =E3 -> 0 | G3: =F3 -> 0 | H3: =G3 -> 0 | I3: =H3 -> 0 | J3: =I3 -> 0 | ... AF3: =AE3 -> 0
A4: gasoline vehicle | B4: 0 | C4: =B4 -> 0 | D4: =C4 -> 0 | E4: =D4 -> 0 | F4: =E4 -> 0 | G4: =F4 -> 0 | H4: =G4 -> 0 | I4: =H4 -> 0 | J4: =I4 -> 0 | ... AF4: =AE4 -> 0
A5: diesel vehicle | B5: 0.0035041037 | C5: =B5 -> 0.0035041037 | D5: =C5 -> 0.0035041037 | E5: =D5 -> 0.0035041037 | F5: =E5 -> 0.0035041037 | G5: =F5 -> 0.0035041037 | H5: =G5 -> 0.0035041037 | I5: =H5 -> 0.0035041037 | J5: =I5 -> 0.0035041037 | ... AF5: =AE5 -> 0.0035041037
A6: plugin hybrid vehicle | B6: 0 | C6: =B6 -> 0 | D6: =C6 -> 0 | E6: =D6 -> 0 | F6: =E6 -> 0 | G6: =F6 -> 0 | H6: =G6 -> 0 | I6: =H6 -> 0 | J6: =I6 -> 0 | ... AF6: =AE6 -> 0
A7: LPG vehicle | B7: 0 | C7: =B7 -> 0 | D7: =C7 -> 0 | E7: =D7 -> 0 | F7: =E7 -> 0 | G7: =F7 -> 0 | H7: =G7 -> 0 | I7: =H7 -> 0 | J7: =I7 -> 0 | ... AF7: =AE7 -> 0
A8: hydrogen vehicle | B8: 0 | C8: =B8 -> 0 | D8: =C8 -> 0 | E8: =D8 -> 0 | F8: =E8 -> 0 | G8: =F8 -> 0 | H8: =G8 -> 0 | I8: =H8 -> 0 | J8: =I8 -> 0 | ... AF8: =AE8 -> 0

Sheet BHNVFEAL-aircraft-psgr
A1: Fuel Economy ((thing*miles)/BTU) | B1: 2020 | C1: 2021 | D1: 2022 | E1: 2023 | F1: 2024 | G1: 2025 | H1: 2026 | I1: 2027 | J1: 2028 | K1: 2029 | L1: 2030 | M1: 2031 | N1: 2032 | O1: 2033 | P1: 2034 | Q1: 2035 | R1: 2036 | S1: 2037 | T1: 2038 | U1: 2039 | V1: 2040 | W1: 2041 | X1: 2042 | Y1: 2043 | Z1: 2044 | AA1: 2045 | AB1: 2046 | AC1: 2047 | AD1: 2048 | AE1: 2049 | AF1: 2050
A2: battery electric vehicle | B2: =B$5/(1-'Other Values'!$B$3) -> 0.0012151307 | C2: =C$5/(1-'Other Values'!$B$3) -> 0.0012271977 | D2: =D$5/(1-'Other Values'!$B$3) -> 0.0012392648 | E2: =E$5/(1-'Other Values'!$B$3) -> 0.0012513319 | F2: =F$5/(1-'Other Values'!$B$3) -> 0.0012633989 | G2: =G$5/(1-'Other Values'!$B$3) -> 0.001275466 | H2: =H$5/(1-'Other Values'!$B$3) -> 0.0012875331 | I2: =I$5/(1-'Other Values'!$B$3) -> 0.0012996001 | ... AF2: =AF$5/(1-'Other Values'!$B$3) -> 0.0015806684
A3: natural gas vehicle | B3: 0 | C3: 0 | D3: 0 | E3: 0 | F3: 0 | G3: 0 | H3: 0 | I3: 0 | J3: 0 | K3: 0 | L3: 0 | M3: 0 | N3: 0 | O3: 0 | P3: 0 | Q3: 0 | R3: 0 | S3: 0 | T3: 0 | U3: 0 | V3: 0 | W3: 0 | X3: 0 | Y3: 0 | Z3: 0 | AA3: 0 | AB3: 0 | AC3: 0 | AD3: 0 | AE3: 0 | AF3: 0
A4: gasoline vehicle | B4: 0 | C4: 0 | D4: 0 | E4: 0 | F4: 0 | G4: 0 | H4: 0 | I4: 0 | J4: 0 | K4: 0 | L4: 0 | M4: 0 | N4: 0 | O4: 0 | P4: 0 | Q4: 0 | R4: 0 | S4: 0 | T4: 0 | U4: 0 | V4: 0 | W4: 0 | X4: 0 | Y4: 0 | Z4: 0 | AA4: 0 | AB4: 0 | AC4: 0 | AD4: 0 | AE4: 0 | AF4: 0
A5: diesel vehicle | B5: =Extrapolations!P6 -> 0.00037813606 | C5: =Extrapolations!Q6 -> 0.00038189121 | D5: =Extrapolations!R6 -> 0.00038564636 | E5: =Extrapolations!S6 -> 0.0003894015 | F5: =Extrapolations!T6 -> 0.00039315665 | G5: =Extrapolations!U6 -> 0.0003969118 | H5: =Extrapolations!V6 -> 0.00040066694 | I5: =Extrapolations!W6 -> 0.00040442209 | ... AF5: =Extrapolations!AT6 -> 0.00049188762
A6: plugin hybrid vehicle | B6: 0 | C6: 0 | D6: 0 | E6: 0 | F6: 0 | G6: 0 | H6: 0 | I6: 0 | J6: 0 | K6: 0 | L6: 0 | M6: 0 | N6: 0 | O6: 0 | P6: 0 | Q6: 0 | R6: 0 | S6: 0 | T6: 0 | U6: 0 | V6: 0 | W6: 0 | X6: 0 | Y6: 0 | Z6: 0 | AA6: 0 | AB6: 0 | AC6: 0 | AD6: 0 | AE6: 0 | AF6: 0
A7: LPG vehicle | B7: 0 | C7: 0 | D7: 0 | E7: 0 | F7: 0 | G7: 0 | H7: 0 | I7: 0 | J7: 0 | K7: 0 | L7: 0 | M7: 0 | N7: 0 | O7: 0 | P7: 0 | Q7: 0 | R7: 0 | S7: 0 | T7: 0 | U7: 0 | V7: 0 | W7: 0 | X7: 0 | Y7: 0 | Z7: 0 | AA7: 0 | AB7: 0 | AC7: 0 | AD7: 0 | AE7: 0 | AF7: 0
A8: hydrogen vehicle | B8: =B$5*Calculations!$B$27 -> 0.0011344082 | C8: =C$5*Calculations!$B$27 -> 0.0011456736 | D8: =D$5*Calculations!$B$27 -> 0.0011569391 | E8: =E$5*Calculations!$B$27 -> 0.0011682045 | F8: =F$5*Calculations!$B$27 -> 0.00117947 | G8: =G$5*Calculations!$B$27 -> 0.0011907354 | H8: =H$5*Calculations!$B$27 -> 0.0012020008 | I8: =I$5*Calculations!$B$27 -> 0.0012132663 | ... AF8: =AF$5*Calculations!$B$27 -> 0.0014756629

Sheet BHNVFEAL-aircraft-frgt
A1: Fuel Economy ((thing*miles)/BTU) | B1: 2020 | C1: 2021 | D1: 2022 | E1: 2023 | F1: 2024 | G1: 2025 | H1: 2026 | I1: 2027 | J1: 2028 | K1: 2029 | L1: 2030 | M1: 2031 | N1: 2032 | O1: 2033 | P1: 2034 | Q1: 2035 | R1: 2036 | S1: 2037 | T1: 2038 | U1: 2039 | V1: 2040 | W1: 2041 | X1: 2042 | Y1: 2043 | Z1: 2044 | AA1: 2045 | AB1: 2046 | AC1: 2047 | AD1: 2048 | AE1: 2049 | AF1: 2050
A2: battery electric vehicle | B2: =B$5/(1-'Other Values'!$B$3) -> 0.00029750913 | C2: =C$5/(1-'Other Values'!$B$3) -> 0.00030061605 | D2: =D$5/(1-'Other Values'!$B$3) -> 0.00030372297 | E2: =E$5/(1-'Other Values'!$B$3) -> 0.00030682989 | F2: =F$5/(1-'Other Values'!$B$3) -> 0.00030993681 | G2: =G$5/(1-'Other Values'!$B$3) -> 0.00031304373 | H2: =H$5/(1-'Other Values'!$B$3) -> 0.00031615065 | I2: =I$5/(1-'Other Values'!$B$3) -> 0.00031925757 | ... AF2: =AF$5/(1-'Other Values'!$B$3) -> 0.00040697636
A3: natural gas vehicle | B3: 0 | C3: 0 | D3: 0 | E3: 0 | F3: 0 | G3: 0 | H3: 0 | I3: 0 | J3: 0 | K3: 0 | L3: 0 | M3: 0 | N3: 0 | O3: 0 | P3: 0 | Q3: 0 | R3: 0 | S3: 0 | T3: 0 | U3: 0 | V3: 0 | W3: 0 | X3: 0 | Y3: 0 | Z3: 0 | AA3: 0 | AB3: 0 | AC3: 0 | AD3: 0 | AE3: 0 | AF3: 0
A4: gasoline vehicle | B4: 0 | C4: 0 | D4: 0 | E4: 0 | F4: 0 | G4: 0 | H4: 0 | I4: 0 | J4: 0 | K4: 0 | L4: 0 | M4: 0 | N4: 0 | O4: 0 | P4: 0 | Q4: 0 | R4: 0 | S4: 0 | T4: 0 | U4: 0 | V4: 0 | W4: 0 | X4: 0 | Y4: 0 | Z4: 0 | AA4: 0 | AB4: 0 | AC4: 0 | AD4: 0 | AE4: 0 | AF4: 0
A5: diesel vehicle | B5: =Extrapolations!P7 -> 9.2581756e-05 | C5: =Extrapolations!Q7 -> 9.3548598e-05 | D5: =Extrapolations!R7 -> 9.4515439e-05 | E5: =Extrapolations!S7 -> 9.5482281e-05 | F5: =Extrapolations!T7 -> 9.6449123e-05 | G5: =Extrapolations!U7 -> 9.7415964e-05 | H5: =Extrapolations!V7 -> 9.8382806e-05 | I5: =Extrapolations!W7 -> 9.9349647e-05 | ... AF5: =Extrapolations!AT7 -> 0.00012664682
A6: plugin hybrid vehicle | B6: 0 | C6: 0 | D6: 0 | E6: 0 | F6: 0 | G6: 0 | H6: 0 | I6: 0 | J6: 0 | K6: 0 | L6: 0 | M6: 0 | N6: 0 | O6: 0 | P6: 0 | Q6: 0 | R6: 0 | S6: 0 | T6: 0 | U6: 0 | V6: 0 | W6: 0 | X6: 0 | Y6: 0 | Z6: 0 | AA6: 0 | AB6: 0 | AC6: 0 | AD6: 0 | AE6: 0 | AF6: 0
A7: LPG vehicle | B7: 0 | C7: 0 | D7: 0 | E7: 0 | F7: 0 | G7: 0 | H7: 0 | I7: 0 | J7: 0 | K7: 0 | L7: 0 | M7: 0 | N7: 0 | O7: 0 | P7: 0 | Q7: 0 | R7: 0 | S7: 0 | T7: 0 | U7: 0 | V7: 0 | W7: 0 | X7: 0 | Y7: 0 | Z7: 0 | AA7: 0 | AB7: 0 | AC7: 0 | AD7: 0 | AE7: 0 | AF7: 0
A8: hydrogen vehicle | B8: =B$5*Calculations!$B$27 -> 0.00027774527 | C8: =C$5*Calculations!$B$27 -> 0.00028064579 | D8: =D$5*Calculations!$B$27 -> 0.00028354632 | E8: =E$5*Calculations!$B$27 -> 0.00028644684 | F8: =F$5*Calculations!$B$27 -> 0.00028934737 | G8: =G$5*Calculations!$B$27 -> 0.00029224789 | H8: =H$5*Calculations!$B$27 -> 0.00029514842 | I8: =I$5*Calculations!$B$27 -> 0.00029804894 | ... AF8: =AF$5*Calculations!$B$27 -> 0.00037994047

Sheet BHNVFEAL-rail-psgr
A1: Fuel Economy ((thing*miles)/BTU) | B1: 2020 | C1: 2021 | D1: 2022 | E1: 2023 | F1: 2024 | G1: 2025 | H1: 2026 | I1: 2027 | J1: 2028 | K1: 2029 | L1: 2030 | M1: 2031 | N1: 2032 | O1: 2033 | P1: 2034 | Q1: 2035 | R1: 2036 | S1: 2037 | T1: 2038 | U1: 2039 | V1: 2040 | W1: 2041 | X1: 2042 | Y1: 2043 | Z1: 2044 | AA1: 2045 | AB1: 2046 | AC1: 2047 | AD1: 2048 | AE1: 2049 | AF1: 2050
A2: battery electric vehicle | B2: =Extrapolations!F9 -> 0.0012701331 | C2: =Extrapolations!G9 -> 0.0012695031 | D2: =Extrapolations!H9 -> 0.0012688732 | E2: =Extrapolations!I9 -> 0.0012682432 | F2: =Extrapolations!J9 -> 0.0012676133 | G2: =Extrapolations!K9 -> 0.0012669833 | H2: =Extrapolations!L9 -> 0.0012663534 | I2: =Extrapolations!M9 -> 0.0012657234 | ... AF2: =Extrapolations!AJ9 -> 0.0012512345
A3: natural gas vehicle | B3: 0 | C3: 0 | D3: 0 | E3: 0 | F3: 0 | G3: 0 | H3: 0 | I3: 0 | J3: 0 | K3: 0 | L3: 0 | M3: 0 | N3: 0 | O3: 0 | P3: 0 | Q3: 0 | R3: 0 | S3: 0 | T3: 0 | U3: 0 | V3: 0 | W3: 0 | X3: 0 | Y3: 0 | Z3: 0 | AA3: 0 | AB3: 0 | AC3: 0 | AD3: 0 | AE3: 0 | AF3: 0
A4: gasoline vehicle | B4: 0 | C4: 0 | D4: 0 | E4: 0 | F4: 0 | G4: 0 | H4: 0 | I4: 0 | J4: 0 | K4: 0 | L4: 0 | M4: 0 | N4: 0 | O4: 0 | P4: 0 | Q4: 0 | R4: 0 | S4: 0 | T4: 0 | U4: 0 | V4: 0 | W4: 0 | X4: 0 | Y4: 0 | Z4: 0 | AA4: 0 | AB4: 0 | AC4: 0 | AD4: 0 | AE4: 0 | AF4: 0
A5: diesel vehicle | B5: =Extrapolations!P6 -> 0.00037813606 | C5: =Extrapolations!Q6 -> 0.00038189121 | D5: =Extrapolations!R6 -> 0.00038564636 | E5: =Extrapolations!S6 -> 0.0003894015 | F5: =Extrapolations!T6 -> 0.00039315665 | G5: =Extrapolations!U6 -> 0.0003969118 | H5: =Extrapolations!V6 -> 0.00040066694 | I5: =Extrapolations!W6 -> 0.00040442209 | ... AF5: =Extrapolations!AT6 -> 0.00049188762
A6: plugin hybrid vehicle | B6: 0 | C6: 0 | D6: 0 | E6: 0 | F6: 0 | G6: 0 | H6: 0 | I6: 0 | J6: 0 | K6: 0 | L6: 0 | M6: 0 | N6: 0 | O6: 0 | P6: 0 | Q6: 0 | R6: 0 | S6: 0 | T6: 0 | U6: 0 | V6: 0 | W6: 0 | X6: 0 | Y6: 0 | Z6: 0 | AA6: 0 | AB6: 0 | AC6: 0 | AD6: 0 | AE6: 0 | AF6: 0
A7: LPG vehicle | B7: 0 | C7: 0 | D7: 0 | E7: 0 | F7: 0 | G7: 0 | H7: 0 | I7: 0 | J7: 0 | K7: 0 | L7: 0 | M7: 0 | N7: 0 | O7: 0 | P7: 0 | Q7: 0 | R7: 0 | S7: 0 | T7: 0 | U7: 0 | V7: 0 | W7: 0 | X7: 0 | Y7: 0 | Z7: 0 | AA7: 0 | AB7: 0 | AC7: 0 | AD7: 0 | AE7: 0 | AF7: 0
A8: hydrogen vehicle | B8: =B$5*Calculations!$B$27 -> 0.0011344082 | C8: =C$5*Calculations!$B$27 -> 0.0011456736 | D8: =D$5*Calculations!$B$27 -> 0.0011569391 | E8: =E$5*Calculations!$B$27 -> 0.0011682045 | F8: =F$5*Calculations!$B$27 -> 0.00117947 | G8: =G$5*Calculations!$B$27 -> 0.0011907354 | H8: =H$5*Calculations!$B$27 -> 0.0012020008 | I8: =I$5*Calculations!$B$27 -> 0.0012132663 | ... AF8: =AF$5*Calculations!$B$27 -> 0.0014756629

Sheet BHNVFEAL-rail-frgt
A1: Fuel Economy ((thing*miles)/BTU) | B1: 2020 | C1: 2021 | D1: 2022 | E1: 2023 | F1: 2024 | G1: 2025 | H1: 2026 | I1: 2027 | J1: 2028 | K1: 2029 | L1: 2030 | M1: 2031 | N1: 2032 | O1: 2033 | P1: 2034 | Q1: 2035 | R1: 2036 | S1: 2037 | T1: 2038 | U1: 2039 | V1: 2040 | W1: 2041 | X1: 2042 | Y1: 2043 | Z1: 2044 | AA1: 2045 | AB1: 2046 | AC1: 2047 | AD1: 2048 | AE1: 2049 | AF1: 2050
A2: battery electric vehicle | B2: =B$5/(1-'Other Values'!$B$3) -> 0.0084577011 | C2: =C$5/(1-'Other Values'!$B$3) -> 0.0085376572 | D2: =D$5/(1-'Other Values'!$B$3) -> 0.0086176133 | E2: =E$5/(1-'Other Values'!$B$3) -> 0.0086975694 | F2: =F$5/(1-'Other Values'!$B$3) -> 0.0087775255 | G2: =G$5/(1-'Other Values'!$B$3) -> 0.0088574816 | H2: =H$5/(1-'Other Values'!$B$3) -> 0.0089374377 | I2: =I$5/(1-'Other Values'!$B$3) -> 0.0090173938 | ... AF2: =AF$5/(1-'Other Values'!$B$3) -> 0.010856384
A3: natural gas vehicle | B3: 0 | C3: 0 | D3: 0 | E3: 0 | F3: 0 | G3: 0 | H3: 0 | I3: 0 | J3: 0 | K3: 0 | L3: 0 | M3: 0 | N3: 0 | O3: 0 | P3: 0 | Q3: 0 | R3: 0 | S3: 0 | T3: 0 | U3: 0 | V3: 0 | W3: 0 | X3: 0 | Y3: 0 | Z3: 0 | AA3: 0 | AB3: 0 | AC3: 0 | AD3: 0 | AE3: 0 | AF3: 0
A4: gasoline vehicle | B4: 0 | C4: 0 | D4: 0 | E4: 0 | F4: 0 | G4: 0 | H4: 0 | I4: 0 | J4: 0 | K4: 0 | L4: 0 | M4: 0 | N4: 0 | O4: 0 | P4: 0 | Q4: 0 | R4: 0 | S4: 0 | T4: 0 | U4: 0 | V4: 0 | W4: 0 | X4: 0 | Y4: 0 | Z4: 0 | AA4: 0 | AB4: 0 | AC4: 0 | AD4: 0 | AE4: 0 | AF4: 0
A5: diesel vehicle | B5: =Extrapolations!F10 -> 0.0026319489 | C5: =Extrapolations!G10 -> 0.0026568304 | D5: =Extrapolations!H10 -> 0.0026817119 | E5: =Extrapolations!I10 -> 0.0027065934 | F5: =Extrapolations!J10 -> 0.0027314749 | G5: =Extrapolations!K10 -> 0.0027563565 | H5: =Extrapolations!L10 -> 0.002781238 | I5: =Extrapolations!M10 -> 0.0028061195 | ... AF5: =Extrapolations!AJ10 -> 0.0033783942
A6: plugin hybrid vehicle | B6: 0 | C6: 0 | D6: 0 | E6: 0 | F6: 0 | G6: 0 | H6: 0 | I6: 0 | J6: 0 | K6: 0 | L6: 0 | M6: 0 | N6: 0 | O6: 0 | P6: 0 | Q6: 0 | R6: 0 | S6: 0 | T6: 0 | U6: 0 | V6: 0 | W6: 0 | X6: 0 | Y6: 0 | Z6: 0 | AA6: 0 | AB6: 0 | AC6: 0 | AD6: 0 | AE6: 0 | AF6: 0
A7: LPG vehicle | B7: 0 | C7: 0 | D7: 0 | E7: 0 | F7: 0 | G7: 0 | H7: 0 | I7: 0 | J7: 0 | K7: 0 | L7: 0 | M7: 0 | N7: 0 | O7: 0 | P7: 0 | Q7: 0 | R7: 0 | S7: 0 | T7: 0 | U7: 0 | V7: 0 | W7: 0 | X7: 0 | Y7: 0 | Z7: 0 | AA7: 0 | AB7: 0 | AC7: 0 | AD7: 0 | AE7: 0 | AF7: 0
A8: hydrogen vehicle | B8: =B$5*Calculations!$B$27 -> 0.0078958467 | C8: =C$5*Calculations!$B$27 -> 0.0079704913 | D8: =D$5*Calculations!$B$27 -> 0.0080451358 | E8: =E$5*Calculations!$B$27 -> 0.0081197803 | F8: =F$5*Calculations!$B$27 -> 0.0081944248 | G8: =G$5*Calculations!$B$27 -> 0.0082690694 | H8: =H$5*Calculations!$B$27 -> 0.0083437139 | I8: =I$5*Calculations!$B$27 -> 0.0084183584 | ... AF8: =AF$5*Calculations!$B$27 -> 0.010135183

Sheet BHNVFEAL-ships-psgr
A1: Fuel Economy ((thing*miles)/BTU) | B1: 2020 | C1: 2021 | D1: 2022 | E1: 2023 | F1: 2024 | G1: 2025 | H1: 2026 | I1: 2027 | J1: 2028 | K1: 2029 | L1: 2030 | M1: 2031 | N1: 2032 | O1: 2033 | P1: 2034 | Q1: 2035 | R1: 2036 | S1: 2037 | T1: 2038 | U1: 2039 | V1: 2040 | W1: 2041 | X1: 2042 | Y1: 2043 | Z1: 2044 | AA1: 2045 | AB1: 2046 | AC1: 2047 | AD1: 2048 | AE1: 2049 | AF1: 2050
A2: battery electric vehicle | B2: {=TRANSPOSE(SYFAFE!B6:H6)} -> 0 | C2: =B2 -> 0 | D2: =C2 -> 0 | E2: =D2 -> 0 | F2: =E2 -> 0 | G2: =F2 -> 0 | H2: =G2 -> 0 | I2: =H2 -> 0 | J2: =I2 -> 0 | ... AF2: =AE2 -> 0
A3: natural gas vehicle | B3: 0 | C3: =B3 -> 0 | D3: =C3 -> 0 | E3: =D3 -> 0 | F3: =E3 -> 0 | G3: =F3 -> 0 | H3: =G3 -> 0 | I3: =H3 -> 0 | J3: =I3 -> 0 | ... AF3: =AE3 -> 0
A4: gasoline vehicle | B4: 0.00022779144 | C4: =B4 -> 0.00022779144 | D4: =C4 -> 0.00022779144 | E4: =D4 -> 0.00022779144 | F4: =E4 -> 0.00022779144 | G4: =F4 -> 0.00022779144 | H4: =G4 -> 0.00022779144 | I4: =H4 -> 0.00022779144 | J4: =I4 -> 0.00022779144 | ... AF4: =AE4 -> 0.00022779144
A5: diesel vehicle | B5: 8.5088223e-08 | C5: =B5 -> 8.5088223e-08 | D5: =C5 -> 8.5088223e-08 | E5: =D5 -> 8.5088223e-08 | F5: =E5 -> 8.5088223e-08 | G5: =F5 -> 8.5088223e-08 | H5: =G5 -> 8.5088223e-08 | I5: =H5 -> 8.5088223e-08 | J5: =I5 -> 8.5088223e-08 | ... AF5: =AE5 -> 8.5088223e-08
A6: plugin hybrid vehicle | B6: 0 | C6: =B6 -> 0 | D6: =C6 -> 0 | E6: =D6 -> 0 | F6: =E6 -> 0 | G6: =F6 -> 0 | H6: =G6 -> 0 | I6: =H6 -> 0 | J6: =I6 -> 0 | ... AF6: =AE6 -> 0
A7: LPG vehicle | B7: 0 | C7: =B7 -> 0 | D7: =C7 -> 0 | E7: =D7 -> 0 | F7: =E7 -> 0 | G7: =F7 -> 0 | H7: =G7 -> 0 | I7: =H7 -> 0 | J7: =I7 -> 0 | ... AF7: =AE7 -> 0
A8: hydrogen vehicle | B8: 0 | C8: =B8 -> 0 | D8: =C8 -> 0 | E8: =D8 -> 0 | F8: =E8 -> 0 | G8: =F8 -> 0 | H8: =G8 -> 0 | I8: =H8 -> 0 | J8: =I8 -> 0 | ... AF8: =AE8 -> 0

Sheet BHNVFEAL-ships-frgt
A1: Fuel Economy ((thing*miles)/BTU) | B1: 2020 | C1: 2021 | D1: 2022 | E1: 2023 | F1: 2024 | G1: 2025 | H1: 2026 | I1: 2027 | J1: 2028 | K1: 2029 | L1: 2030 | M1: 2031 | N1: 2032 | O1: 2033 | P1: 2034 | Q1: 2035 | R1: 2036 | S1: 2037 | T1: 2038 | U1: 2039 | V1: 2040 | W1: 2041 | X1: 2042 | Y1: 2043 | Z1: 2044 | AA1: 2045 | AB1: 2046 | AC1: 2047 | AD1: 2048 | AE1: 2049 | AF1: 2050
A2: battery electric vehicle | B2: =B$5/(1-'Other Values'!$B$3) -> 0.015975872 | C2: =C$5/(1-'Other Values'!$B$3) -> 0.015975872 | D2: =D$5/(1-'Other Values'!$B$3) -> 0.015975872 | E2: =E$5/(1-'Other Values'!$B$3) -> 0.015975872 | F2: =F$5/(1-'Other Values'!$B$3) -> 0.015975872 | G2: =G$5/(1-'Other Values'!$B$3) -> 0.015975872 | H2: =H$5/(1-'Other Values'!$B$3) -> 0.015975872 | I2: =I$5/(1-'Other Values'!$B$3) -> 0.015975872 | ... AF2: =AF$5/(1-'Other Values'!$B$3) -> 0.015975872
A3: natural gas vehicle | B3: 0 | C3: 0 | D3: 0 | E3: 0 | F3: 0 | G3: 0 | H3: 0 | I3: 0 | J3: 0 | K3: 0 | L3: 0 | M3: 0 | N3: 0 | O3: 0 | P3: 0 | Q3: 0 | R3: 0 | S3: 0 | T3: 0 | U3: 0 | V3: 0 | W3: 0 | X3: 0 | Y3: 0 | Z3: 0 | AA3: 0 | AB3: 0 | AC3: 0 | AD3: 0 | AE3: 0 | AF3: 0
A4: gasoline vehicle | B4: 0 | C4: 0 | D4: 0 | E4: 0 | F4: 0 | G4: 0 | H4: 0 | I4: 0 | J4: 0 | K4: 0 | L4: 0 | M4: 0 | N4: 0 | O4: 0 | P4: 0 | Q4: 0 | R4: 0 | S4: 0 | T4: 0 | U4: 0 | V4: 0 | W4: 0 | X4: 0 | Y4: 0 | Z4: 0 | AA4: 0 | AB4: 0 | AC4: 0 | AD4: 0 | AE4: 0 | AF4: 0
A5: diesel vehicle | B5: =Extrapolations!G12 -> 0.0049715257 | C5: =Extrapolations!H12 -> 0.0049715257 | D5: =Extrapolations!I12 -> 0.0049715257 | E5: =Extrapolations!J12 -> 0.0049715257 | F5: =Extrapolations!K12 -> 0.0049715257 | G5: =Extrapolations!L12 -> 0.0049715257 | H5: =Extrapolations!M12 -> 0.0049715257 | I5: =Extrapolations!N12 -> 0.0049715257 | ... AF5: =Extrapolations!AK12 -> 0.0049715257
A6: plugin hybrid vehicle | B6: 0 | C6: 0 | D6: 0 | E6: 0 | F6: 0 | G6: 0 | H6: 0 | I6: 0 | J6: 0 | K6: 0 | L6: 0 | M6: 0 | N6: 0 | O6: 0 | P6: 0 | Q6: 0 | R6: 0 | S6: 0 | T6: 0 | U6: 0 | V6: 0 | W6: 0 | X6: 0 | Y6: 0 | Z6: 0 | AA6: 0 | AB6: 0 | AC6: 0 | AD6: 0 | AE6: 0 | AF6: 0
A7: LPG vehicle | B7: 0 | C7: 0 | D7: 0 | E7: 0 | F7: 0 | G7: 0 | H7: 0 | I7: 0 | J7: 0 | K7: 0 | L7: 0 | M7: 0 | N7: 0 | O7: 0 | P7: 0 | Q7: 0 | R7: 0 | S7: 0 | T7: 0 | U7: 0 | V7: 0 | W7: 0 | X7: 0 | Y7: 0 | Z7: 0 | AA7: 0 | AB7: 0 | AC7: 0 | AD7: 0 | AE7: 0 | AF7: 0
A8: hydrogen vehicle | B8: =B$5*Calculations!$B$27 -> 0.014914577 | C8: =C$5*Calculations!$B$27 -> 0.014914577 | D8: =D$5*Calculations!$B$27 -> 0.014914577 | E8: =E$5*Calculations!$B$27 -> 0.014914577 | F8: =F$5*Calculations!$B$27 -> 0.014914577 | G8: =G$5*Calculations!$B$27 -> 0.014914577 | H8: =H$5*Calculations!$B$27 -> 0.014914577 | I8: =I$5*Calculations!$B$27 -> 0.014914577 | ... AF8: =AF$5*Calculations!$B$27 -> 0.014914577

Sheet BHNVFEAL-motorbikes-psgr
A1: Fuel Economy ((thing*miles)/BTU) | B1: 2020 | C1: 2021 | D1: 2022 | E1: 2023 | F1: 2024 | G1: 2025 | H1: 2026 | I1: 2027 | J1: 2028 | K1: 2029 | L1: 2030 | M1: 2031 | N1: 2032 | O1: 2033 | P1: 2034 | Q1: 2035 | R1: 2036 | S1: 2037 | T1: 2038 | U1: 2039 | V1: 2040 | W1: 2041 | X1: 2042 | Y1: 2043 | Z1: 2044 | AA1: 2045 | AB1: 2046 | AC1: 2047 | AD1: 2048 | AE1: 2049 | AF1: 2050
A2: battery electric vehicle | B2: {=TRANSPOSE(SYFAFE!B7:H7)} -> 0.0098648568 | C2: =B2 -> 0.0098648568 | D2: =C2 -> 0.0098648568 | E2: =D2 -> 0.0098648568 | F2: =E2 -> 0.0098648568 | G2: =F2 -> 0.0098648568 | H2: =G2 -> 0.0098648568 | I2: =H2 -> 0.0098648568 | J2: =I2 -> 0.0098648568 | ... AF2: =AE2 -> 0.0098648568
A3: natural gas vehicle | B3: 0.0012056566 | C3: =B3 -> 0.0012056566 | D3: =C3 -> 0.0012056566 | E3: =D3 -> 0.0012056566 | F3: =E3 -> 0.0012056566 | G3: =F3 -> 0.0012056566 | H3: =G3 -> 0.0012056566 | I3: =H3 -> 0.0012056566 | J3: =I3 -> 0.0012056566 | ... AF3: =AE3 -> 0.0012056566
A4: gasoline vehicle | B4: 0.0011311305 | C4: =B4 -> 0.0011311305 | D4: =C4 -> 0.0011311305 | E4: =D4 -> 0.0011311305 | F4: =E4 -> 0.0011311305 | G4: =F4 -> 0.0011311305 | H4: =G4 -> 0.0011311305 | I4: =H4 -> 0.0011311305 | J4: =I4 -> 0.0011311305 | ... AF4: =AE4 -> 0.0011311305
A5: diesel vehicle | B5: 0 | C5: =B5 -> 0 | D5: =C5 -> 0 | E5: =D5 -> 0 | F5: =E5 -> 0 | G5: =F5 -> 0 | H5: =G5 -> 0 | I5: =H5 -> 0 | J5: =I5 -> 0 | ... AF5: =AE5 -> 0
