Workbook

Sheet About
A1: BEbIC BAU Employment by BPS Code
A3: Source: | B3: OECD data
B4: https://stats.oecd.org/Index.aspx?DataSetCode=TIM_2021#
A7: Note:
A8: Data that used in this calculation as on 2019
A11: BPCiObIC BAU Percent Change in Output by ISIC Code
A13: Source: | B13: Most Industries
B14: OECD
B15: 2021
B16: Input-Output Tables 2021 Edition (ISIC Rev. 4)
B17: https://stats.oecd.org/Index.aspx?DataSetCode=IOTS_2021
B18: Variable: TTL
A21: Notes: | B21: We examine each industry to determin the appropriate trend, then carry that forward.
B22: From there, we estimate the annual percentage growth.
B24: Note that this is not linked to BIFUbC nor fuel production.

Sheet OECD EMPN
A1: =DotStatQuery(B1) -> #NAME? | B1: Sorry, the query is too large to fit into the Excel cell. You will not be able to update your table with the .Stat Populator.
A2: Dataset: Trade in employment (TiM) 2021 ed.
A3: Partner | G3: WLD: World
A4: Indicator | G4: EMPN: Employment
A5: Country | G5: IDN: Indonesia
A6: Unit | G6: Persons, Thousands
A7: Time | H7: 1995 | I7: 1996 | J7: 1997 | K7: 1998 | L7: 1999 | M7: 2000 | N7: 2001 | O7: 2002 | P7: 2003 | Q7: 2004 | R7: 2005 | S7: 2006 | T7: 2007 | U7: 2008 | V7: 2009 | W7: 2010 | X7: 2011 | Y7: 2012 | Z7: 2013 | AA7: 2014 | AB7: 2015 | AC7: 2016 | AD7: 2017 | AE7: 2018 | AF7: 2019 | AG7: 2020 | AH7: 2021 | AI7: 2022 | AJ7: 2023 | AK7: 2024 | AL7: 2025
A8: Industry
A9: DTOTAL: TOTAL | H9: 79687.2 | I9: 81839.8 | J9: 83992.4 | K9: 85494.9 | L9: 87752.3 | M9: 89284.6 | N9: 90310.9 | O9: 91285.7 | P9: 92129.9 | Q9: 93299.6 | R9: 94215.7 | S9: 94453.3 | T9: 95317 | U9: 98756.7 | V9: 102301.3 | W9: 104678.1 | X9: 107806.7 | Y9: 109731.1 | Z9: 113283.4 | AA9: 114345.3 | AB9: 116399 | AC9: 117833 | AD9: 119529.8 | AE9: 122780.6 | AF9: =ROUNDUP(_xlfn.FORECAST.LINEAR($AF$7,H9:AE9,$H$7:$AE$7), 0) -> 122110 | AG9: =ROUNDUP(_xlfn.FORECAST.LINEAR($AG$7,H9:AE9,$H$7:$AE$7), 0) -> 123923 | AH9: =ROUNDUP(_xlfn.FORECAST.LINEAR($AH$7,H9:AE9,$H$7:$AE$7), 0) -> 125737 | AI9: =ROUNDUP(_xlfn.FORECAST.LINEAR($AI$7,H9:AE9,$H$7:$AE$7), 0) -> 127551 | AJ9: =ROUNDUP(_xlfn.FORECAST.LINEAR($AJ$7,H9:AE9,$H$7:$AE$7), 0) -> 129364 | AK9: =ROUNDUP(_xlfn.FORECAST.LINEAR($AK$7,H9:AE9,$H$7:$AE$7), 0) -> 131178 | AL9: =ROUNDUP(_xlfn.FORECAST.LINEAR($AL$7,H9:AE9,$H$7:$AE$7), 0) -> 132992
A10: DTOTAL: TOTAL | B10: D01T03: Agriculture, hunting, forestry and fishing | H10: 35935.8 | I10: 36800.8 | J10: 37630.2 | K10: 37975.4 | L10: 39093.2 | M10: 39671.4 | N10: 39940.6 | O10: 40260.4 | P10: 40647.7 | Q10: 41067.6 | R10: 41357 | S10: 40767 | T10: 40357.8 | U10: 40492 | V10: 41309.4 | W10: 40932.7 | X10: 40058.1 | Y10: 39354.8 | Z10: 39621.1 | AA10: 39200.3 | AB10: 38462.7 | AC10: 37495 | AD10: 36803.3 | AE10: 36651.6 | AF10: =ROUNDUP(_xlfn.FORECAST.LINEAR($AF$7,H10:AE10,$H$7:$AE$7), 0) -> 39328 | AG10: =ROUNDUP(_xlfn.FORECAST.LINEAR($AG$7,H10:AE10,$H$7:$AE$7), 0) -> 39334 | AH10: =ROUNDUP(_xlfn.FORECAST.LINEAR($AH$7,H10:AE10,$H$7:$AE$7), 0) -> 39341 | AI10: =ROUNDUP(_xlfn.FORECAST.LINEAR($AI$7,H10:AE10,$H$7:$AE$7), 0) -> 39348 | AJ10: =ROUNDUP(_xlfn.FORECAST.LINEAR($AJ$7,H10:AE10,$H$7:$AE$7), 0) -> 39354 | AK10: =ROUNDUP(_xlfn.FORECAST.LINEAR($AK$7,H10:AE10,$H$7:$AE$7), 0) -> 39361 | AL10: =ROUNDUP(_xlfn.FORECAST.LINEAR($AL$7,H10:AE10,$H$7:$AE$7), 0) -> 39367
B11: D01T03: Agriculture, hunting, forestry and fishing | C11: D01T02: Agriculture, hunting, forestry | H11: 31803 | I11: 32547.3 | J11: 33247.9 | K11: 33511.6 | L11: 34492.1 | M11: 34988.1 | N11: 35187.4 | O11: 35450 | P11: 35772.5 | Q11: 36140.5 | R11: 36359.6 | S11: 35872.7 | T11: 35545.9 | U11: 35618.5 | V11: 36438.4 | W11: 36141.1 | X11: 35178.7 | Y11: 34431.7 | Z11: 34478.1 | AA11: 33715.3 | AB11: 32364.4 | AC11: 31368.8 | AD11: 30835.5 | AE11: 30569 | AF11: =ROUNDUP(_xlfn.FORECAST.LINEAR($AF$7,H11:AE11,$H$7:$AE$7), 0) -> 33454 | AG11: =ROUNDUP(_xlfn.FORECAST.LINEAR($AG$7,H11:AE11,$H$7:$AE$7), 0) -> 33390 | AH11: =ROUNDUP(_xlfn.FORECAST.LINEAR($AH$7,H11:AE11,$H$7:$AE$7), 0) -> 33326 | AI11: =ROUNDUP(_xlfn.FORECAST.LINEAR($AI$7,H11:AE11,$H$7:$AE$7), 0) -> 33262 | AJ11: =ROUNDUP(_xlfn.FORECAST.LINEAR($AJ$7,H11:AE11,$H$7:$AE$7), 0) -> 33198 | AK11: =ROUNDUP(_xlfn.FORECAST.LINEAR($AK$7,H11:AE11,$H$7:$AE$7), 0) -> 33134 | AL11: =ROUNDUP(_xlfn.FORECAST.LINEAR($AL$7,H11:AE11,$H$7:$AE$7), 0) -> 33070
C12: D03: Fishing and aquaculture | H12: 4132.8 | I12: 4253.5 | J12: 4382.3 | K12: 4463.8 | L12: 4601.1 | M12: 4683.3 | N12: 4753.2 | O12: 4810.4 | P12: 4875.2 | Q12: 4927.1 | R12: 4997.4 | S12: 4894.3 | T12: 4811.9 | U12: 4873.5 | V12: 4870.9 | W12: 4791.5 | X12: 4879.3 | Y12: 4923.1 | Z12: 5143 | AA12: 5485 | AB12: 6098.3 | AC12: 6126.2 | AD12: 5967.8 | AE12: 6082.7 | AF12: =ROUNDUP(_xlfn.FORECAST.LINEAR($AF$7,H12:AE12,$H$7:$AE$7), 0) -> 5875 | AG12: =ROUNDUP(_xlfn.FORECAST.LINEAR($AG$7,H12:AE12,$H$7:$AE$7), 0) -> 5945 | AH12: =ROUNDUP(_xlfn.FORECAST.LINEAR($AH$7,H12:AE12,$H$7:$AE$7), 0) -> 6016 | AI12: =ROUNDUP(_xlfn.FORECAST.LINEAR($AI$7,H12:AE12,$H$7:$AE$7), 0) -> 6086 | AJ12: =ROUNDUP(_xlfn.FORECAST.LINEAR($AJ$7,H12:AE12,$H$7:$AE$7), 0) -> 6157 | AK12: =ROUNDUP(_xlfn.FORECAST.LINEAR($AK$7,H12:AE12,$H$7:$AE$7), 0) -> 6227 | AL12: =ROUNDUP(_xlfn.FORECAST.LINEAR($AL$7,H12:AE12,$H$7:$AE$7), 0) -> 6298
B13: D05T09: Mining and quarrying | H13: 713.8 | I13: 733.1 | J13: 754.5 | K13: 761.2 | L13: 786.1 | M13: 805.3 | N13: 803.2 | O13: 795.9 | P13: 806.6 | Q13: 816.2 | R13: 851.3 | S13: 923.1 | T13: 969.2 | U13: 1026.9 | V13: 1118.8 | W13: 1185 | X13: 1372 | Y13: 1557.7 | Z13: 1476.1 | AA13: 1502.1 | AB13: 1348.5 | AC13: 1368 | AD13: 1336 | AE13: 1373.2 | AF13: =ROUNDUP(_xlfn.FORECAST.LINEAR($AF$7,H13:AE13,$H$7:$AE$7), 0) -> 1523 | AG13: =ROUNDUP(_xlfn.FORECAST.LINEAR($AG$7,H13:AE13,$H$7:$AE$7), 0) -> 1561 | AH13: =ROUNDUP(_xlfn.FORECAST.LINEAR($AH$7,H13:AE13,$H$7:$AE$7), 0) -> 1599 | AI13: =ROUNDUP(_xlfn.FORECAST.LINEAR($AI$7,H13:AE13,$H$7:$AE$7), 0) -> 1637 | AJ13: =ROUNDUP(_xlfn.FORECAST.LINEAR($AJ$7,H13:AE13,$H$7:$AE$7), 0) -> 1675 | AK13: =ROUNDUP(_xlfn.FORECAST.LINEAR($AK$7,H13:AE13,$H$7:$AE$7), 0) -> 1713 | AL13: =ROUNDUP(_xlfn.FORECAST.LINEAR($AL$7,H13:AE13,$H$7:$AE$7), 0) -> 1751
B14: D05T09: Mining and quarrying | C14: D05T06: Mining and quarrying, energy producing products | H14: 338.7 | I14: 349 | J14: 359.7 | K14: 365.3 | L14: 378.5 | M14: 383 | N14: 391.7 | O14: 402.4 | P14: 407.8 | Q14: 412.5 | R14: 411.9 | S14: 448.4 | T14: 472.3 | U14: 502.5 | V14: 552.9 | W14: 570.1 | X14: 686.8 | Y14: 773.3 | Z14: 743.9 | AA14: 760.2 | AB14: 716.3 | AC14: 725.5 | AD14: 702.2 | AE14: 724.9 | AF14: =ROUNDUP(_xlfn.FORECAST.LINEAR($AF$7,H14:AE14,$H$7:$AE$7), 0) -> 788 | AG14: =ROUNDUP(_xlfn.FORECAST.LINEAR($AG$7,H14:AE14,$H$7:$AE$7), 0) -> 809 | AH14: =ROUNDUP(_xlfn.FORECAST.LINEAR($AH$7,H14:AE14,$H$7:$AE$7), 0) -> 831 | AI14: =ROUNDUP(_xlfn.FORECAST.LINEAR($AI$7,H14:AE14,$H$7:$AE$7), 0) -> 852 | AJ14: =ROUNDUP(_xlfn.FORECAST.LINEAR($AJ$7,H14:AE14,$H$7:$AE$7), 0) -> 873 | AK14: =ROUNDUP(_xlfn.FORECAST.LINEAR($AK$7,H14:AE14,$H$7:$AE$7), 0) -> 894 | AL14: =ROUNDUP(_xlfn.FORECAST.LINEAR($AL$7,H14:AE14,$H$7:$AE$7), 0) -> 915
C15: D07T08: Mining and quarrying, non-energy producing products | H15: 345.6 | I15: 353.9 | J15: 363.6 | K15: 364.2 | L15: 374.8 | M15: 389.3 | N15: 377.2 | O15: 358.2 | P15: 362.8 | Q15: 367.4 | R15: 403.3 | S15: 435.9 | T15: 456.1 | U15: 481.2 | V15: 517.6 | W15: 566.4 | X15: 623.2 | Y15: 708.9 | Z15: 658.8 | AA15: 663.6 | AB15: 554.4 | AC15: 563.8 | AD15: 559 | AE15: 570.1 | AF15: =ROUNDUP(_xlfn.FORECAST.LINEAR($AF$7,H15:AE15,$H$7:$AE$7), 0) -> 655 | AG15: =ROUNDUP(_xlfn.FORECAST.LINEAR($AG$7,H15:AE15,$H$7:$AE$7), 0) -> 669 | AH15: =ROUNDUP(_xlfn.FORECAST.LINEAR($AH$7,H15:AE15,$H$7:$AE$7), 0) -> 683 | AI15: =ROUNDUP(_xlfn.FORECAST.LINEAR($AI$7,H15:AE15,$H$7:$AE$7), 0) -> 697 | AJ15: =ROUNDUP(_xlfn.FORECAST.LINEAR($AJ$7,H15:AE15,$H$7:$AE$7), 0) -> 712 | AK15: =ROUNDUP(_xlfn.FORECAST.LINEAR($AK$7,H15:AE15,$H$7:$AE$7), 0) -> 726 | AL15: =ROUNDUP(_xlfn.FORECAST.LINEAR($AL$7,H15:AE15,$H$7:$AE$7), 0) -> 740
C16: D09: Mining support service activities | H16: 29.5 | I16: 30.2 | J16: 31.1 | K16: 31.7 | L16: 32.8 | M16: 33 | N16: 34.4 | O16: 35.4 | P16: 36 | Q16: 36.3 | R16: 36.2 | S16: 38.8 | T16: 40.7 | U16: 43.3 | V16: 48.3 | W16: 48.6 | X16: 61.9 | Y16: 75.4 | Z16: 73.4 | AA16: 78.3 | AB16: 77.7 | AC16: 78.7 | AD16: 74.9 | AE16: 78.1 | AF16: =ROUNDUP(_xlfn.FORECAST.LINEAR($AF$7,H16:AE16,$H$7:$AE$7), 0) -> 81 | AG16: =ROUNDUP(_xlfn.FORECAST.LINEAR($AG$7,H16:AE16,$H$7:$AE$7), 0) -> 84 | AH16: =ROUNDUP(_xlfn.FORECAST.LINEAR($AH$7,H16:AE16,$H$7:$AE$7), 0) -> 87 | AI16: =ROUNDUP(_xlfn.FORECAST.LINEAR($AI$7,H16:AE16,$H$7:$AE$7), 0) -> 89 | AJ16: =ROUNDUP(_xlfn.FORECAST.LINEAR($AJ$7,H16:AE16,$H$7:$AE$7), 0) -> 92 | AK16: =ROUNDUP(_xlfn.FORECAST.LINEAR($AK$7,H16:AE16,$H$7:$AE$7), 0) -> 94 | AL16: =ROUNDUP(_xlfn.FORECAST.LINEAR($AL$7,H16:AE16,$H$7:$AE$7), 0) -> 97
B17: D10T33: Total Manufacturing | H17: 9939.7 | I17: 10226.2 | J17: 10530.8 | K17: 11023.8 | L17: 11102.5 | M17: 11405.5 | N17: 11595.5 | O17: 11573.6 | P17: 11653.7 | Q17: 11805.2 | R17: 11998.3 | S17: 11844.7 | T17: 12031.6 | U17: 12306.2 | V17: 12693.5 | W17: 13333.5 | X17: 14264 | Y17: 14932.8 | Z17: 15298.8 | AA17: 15406.3 | AB17: 15954.8 | AC17: 15941.5 | AD17: 16862.9 | AE17: 17626.5 | AF17: =ROUNDUP(_xlfn.FORECAST.LINEAR($AF$7,H17:AE17,$H$7:$AE$7), 0) -> 16757 | AG17: =ROUNDUP(_xlfn.FORECAST.LINEAR($AG$7,H17:AE17,$H$7:$AE$7), 0) -> 17060 | AH17: =ROUNDUP(_xlfn.FORECAST.LINEAR($AH$7,H17:AE17,$H$7:$AE$7), 0) -> 17363 | AI17: =ROUNDUP(_xlfn.FORECAST.LINEAR($AI$7,H17:AE17,$H$7:$AE$7), 0) -> 17665 | AJ17: =ROUNDUP(_xlfn.FORECAST.LINEAR($AJ$7,H17:AE17,$H$7:$AE$7), 0) -> 17968 | AK17: =ROUNDUP(_xlfn.FORECAST.LINEAR($AK$7,H17:AE17,$H$7:$AE$7), 0) -> 18271 | AL17: =ROUNDUP(_xlfn.FORECAST.LINEAR($AL$7,H17:AE17,$H$7:$AE$7), 0) -> 18573
B18: D10T33: Total Manufacturing | C18: D10T12: Food products, beverages and tobacco | H18: 2209.9 | I18: 2172.7 | J18: 2239.7 | K18: 2194.5 | L18: 2340.2 | M18: 2342.9 | N18: 2326.9 | O18: 2403.7 | P18: 2450.4 | Q18: 2481 | R18: 2520.7 | S18: 2613.8 | T18: 2703.7 | U18: 2760.6 | V18: 2827.3 | W18: 3094.3 | X18: 3200.6 | Y18: 3278.8 | Z18: 3265.6 | AA18: 3182.2 | AB18: 3042.7 | AC18: 2988.6 | AD18: 3236.3 | AE18: 3331.1 | AF18: =ROUNDUP(_xlfn.FORECAST.LINEAR($AF$7,H18:AE18,$H$7:$AE$7), 0) -> 3403 | AG18: =ROUNDUP(_xlfn.FORECAST.LINEAR($AG$7,H18:AE18,$H$7:$AE$7), 0) -> 3458 | AH18: =ROUNDUP(_xlfn.FORECAST.LINEAR($AH$7,H18:AE18,$H$7:$AE$7), 0) -> 3512 | AI18: =ROUNDUP(_xlfn.FORECAST.LINEAR($AI$7,H18:AE18,$H$7:$AE$7), 0) -> 3567 | AJ18: =ROUNDUP(_xlfn.FORECAST.LINEAR($AJ$7,H18:AE18,$H$7:$AE$7), 0) -> 3622 | AK18: =ROUNDUP(_xlfn.FORECAST.LINEAR($AK$7,H18:AE18,$H$7:$AE$7), 0) -> 3677 | AL18: =ROUNDUP(_xlfn.FORECAST.LINEAR($AL$7,H18:AE18,$H$7:$AE$7), 0) -> 3732
C19: D13T15: Textiles, textile products, leather and footwear | H19: 2826.1 | I19: 3074.7 | J19: 3164.4 | K19: 3583.2 | L19: 3346.6 | M19: 3548 | N19: 3700.5 | O19: 3531 | P19: 3499.5 | Q19: 3543 | R19: 3591.8 | S19: 3428.5 | T19: 3401.4 | U19: 3449.9 | V19: 3603.3 | W19: 3690.1 | X19: 3980.4 | Y19: 4237.3 | Z19: 4430.3 | AA19: 4551 | AB19: 4878.4 | AC19: 4830.7 | AD19: 5051.4 | AE19: 5319 | AF19: =ROUNDUP(_xlfn.FORECAST.LINEAR($AF$7,H19:AE19,$H$7:$AE$7), 0) -> 4895 | AG19: =ROUNDUP(_xlfn.FORECAST.LINEAR($AG$7,H19:AE19,$H$7:$AE$7), 0) -> 4979 | AH19: =ROUNDUP(_xlfn.FORECAST.LINEAR($AH$7,H19:AE19,$H$7:$AE$7), 0) -> 5063 | AI19: =ROUNDUP(_xlfn.FORECAST.LINEAR($AI$7,H19:AE19,$H$7:$AE$7), 0) -> 5147 | AJ19: =ROUNDUP(_xlfn.FORECAST.LINEAR($AJ$7,H19:AE19,$H$7:$AE$7), 0) -> 5231 | AK19: =ROUNDUP(_xlfn.FORECAST.LINEAR($AK$7,H19:AE19,$H$7:$AE$7), 0) -> 5315 | AL19: =ROUNDUP(_xlfn.FORECAST.LINEAR($AL$7,H19:AE19,$H$7:$AE$7), 0) -> 5399
C20: D16T18: Wood and paper products and printing | H20: 866 | I20: 851.3 | J20: 877.6 | K20: 859.7 | L20: 916.8 | M20: 918.2 | N20: 913.1 | O20: 943.1 | P20: 962.5 | Q20: 972.7 | R20: 988.5 | S20: 1021.4 | T20: 1045 | U20: 1073.7 | V20: 1121.9 | W20: 1156.2 | X20: 1265.5 | Y20: 1351.3 | Z20: 1402.9 | AA20: 1424.9 | AB20: 1505.9 | AC20: 1454.5 | AD20: 1517.6 | AE20: 1601.5 | AF20: =ROUNDUP(_xlfn.FORECAST.LINEAR($AF$7,H20:AE20,$H$7:$AE$7), 0) -> 1544 | AG20: =ROUNDUP(_xlfn.FORECAST.LINEAR($AG$7,H20:AE20,$H$7:$AE$7), 0) -> 1577 | AH20: =ROUNDUP(_xlfn.FORECAST.LINEAR($AH$7,H20:AE20,$H$7:$AE$7), 0) -> 1611 | AI20: =ROUNDUP(_xlfn.FORECAST.LINEAR($AI$7,H20:AE20,$H$7:$AE$7), 0) -> 1644 | AJ20: =ROUNDUP(_xlfn.FORECAST.LINEAR($AJ$7,H20:AE20,$H$7:$AE$7), 0) -> 1678 | AK20: =ROUNDUP(_xlfn.FORECAST.LINEAR($AK$7,H20:AE20,$H$7:$AE$7), 0) -> 1711 | AL20: =ROUNDUP(_xlfn.FORECAST.LINEAR($AL$7,H20:AE20,$H$7:$AE$7), 0) -> 1744
C21: D16T18: Wood and paper products and printing | D21: D16: Wood and products of wood and cork | H21: 491.9 | I21: 483.7 | J21: 498.6 | K21: 488.5 | L21: 520.9 | M21: 521.7 | N21: 518.6 | O21: 535.6 | P21: 546.7 | Q21: 552.5 | R21: 561.4 | S21: 580.5 | T21: 593.6 | U21: 610.1 | V21: 638.3 | W21: 655.3 | X21: 697.7 | Y21: 730.1 | Z21: 742.5 | AA21: 738.3 | AB21: 766.7 | AC21: 721.4 | AD21: 750.7 | AE21: 793.6 | AF21: =ROUNDUP(_xlfn.FORECAST.LINEAR($AF$7,H21:AE21,$H$7:$AE$7), 0) -> 793 | AG21: =ROUNDUP(_xlfn.FORECAST.LINEAR($AG$7,H21:AE21,$H$7:$AE$7), 0) -> 807 | AH21: =ROUNDUP(_xlfn.FORECAST.LINEAR($AH$7,H21:AE21,$H$7:$AE$7), 0) -> 821 | AI21: =ROUNDUP(_xlfn.FORECAST.LINEAR($AI$7,H21:AE21,$H$7:$AE$7), 0) -> 835 | AJ21: =ROUNDUP(_xlfn.FORECAST.LINEAR($AJ$7,H21:AE21,$H$7:$AE$7), 0) -> 850 | AK21: =ROUNDUP(_xlfn.FORECAST.LINEAR($AK$7,H21:AE21,$H$7:$AE$7), 0) -> 864 | AL21: =ROUNDUP(_xlfn.FORECAST.LINEAR($AL$7,H21:AE21,$H$7:$AE$7), 0) -> 878
D22: D17T18: Paper products and printing | H22: 374.1 | I22: 367.6 | J22: 379 | K22: 371.3 | L22: 395.9 | M22: 396.5 | N22: 394.5 | O22: 407.4 | P22: 415.8 | Q22: 420.3 | R22: 427.1 | S22: 440.8 | T22: 451.4 | U22: 463.6 | V22: 483.6 | W22: 500.9 | X22: 567.8 | Y22: 621.2 | Z22: 660.4 | AA22: 686.6 | AB22: 739.2 | AC22: 733.1 | AD22: 766.8 | AE22: 807.9 | AF22: =ROUNDUP(_xlfn.FORECAST.LINEAR($AF$7,H22:AE22,$H$7:$AE$7), 0) -> 752 | AG22: =ROUNDUP(_xlfn.FORECAST.LINEAR($AG$7,H22:AE22,$H$7:$AE$7), 0) -> 771 | AH22: =ROUNDUP(_xlfn.FORECAST.LINEAR($AH$7,H22:AE22,$H$7:$AE$7), 0) -> 790 | AI22: =ROUNDUP(_xlfn.FORECAST.LINEAR($AI$7,H22:AE22,$H$7:$AE$7), 0) -> 809 | AJ22: =ROUNDUP(_xlfn.FORECAST.LINEAR($AJ$7,H22:AE22,$H$7:$AE$7), 0) -> 828 | AK22: =ROUNDUP(_xlfn.FORECAST.LINEAR($AK$7,H22:AE22,$H$7:$AE$7), 0) -> 847 | AL22: =ROUNDUP(_xlfn.FORECAST.LINEAR($AL$7,H22:AE22,$H$7:$AE$7), 0) -> 867
C23: D19T23: Chemicals and non-metallic mineral products | H23: 1596.4 | I23: 1552.5 | J23: 1593.8 | K23: 1561.4 | L23: 1665.2 | M23: 1699.9 | N23: 1720.3 | O23: 1762.1 | P23: 1769.2 | Q23: 1806.1 | R23: 1847.9 | S23: 1920.3 | T23: 1981.9 | U23: 2039.9 | V23: 2002.4 | W23: 2216.1 | X23: 2476.4 | Y23: 2610.3 | Z23: 2671.1 | AA23: 2666.6 | AB23: 2616.2 | AC23: 2857.5 | AD23: 3126.7 | AE23: 3195.1 | AF23: =ROUNDUP(_xlfn.FORECAST.LINEAR($AF$7,H23:AE23,$H$7:$AE$7), 0) -> 2995 | AG23: =ROUNDUP(_xlfn.FORECAST.LINEAR($AG$7,H23:AE23,$H$7:$AE$7), 0) -> 3065 | AH23: =ROUNDUP(_xlfn.FORECAST.LINEAR($AH$7,H23:AE23,$H$7:$AE$7), 0) -> 3135 | AI23: =ROUNDUP(_xlfn.FORECAST.LINEAR($AI$7,H23:AE23,$H$7:$AE$7), 0) -> 3204 | AJ23: =ROUNDUP(_xlfn.FORECAST.LINEAR($AJ$7,H23:AE23,$H$7:$AE$7), 0) -> 3274 | AK23: =ROUNDUP(_xlfn.FORECAST.LINEAR($AK$7,H23:AE23,$H$7:$AE$7), 0) -> 3344 | AL23: =ROUNDUP(_xlfn.FORECAST.LINEAR($AL$7,H23:AE23,$H$7:$AE$7), 0) -> 3414
C24: D19T23: Chemicals and non-metallic mineral products | D24: D19: Coke and refined petroleum products | H24: 12.8 | I24: 12.2 | J24: 12.4 | K24: 12.2 | L24: 13 | M24: 13.8 | N24: 14.8 | O24: 14.9 | P24: 14.5 | Q24: 15.1 | R24: 15.7 | S24: 16.1 | T24: 16.7 | U24: 17.4 | V24: 15.3 | W24: 18.4 | X24: 28.5 | Y24: 36.8 | Z24: 45.9 | AA24: 55.4 | AB24: 62.2 | AC24: 101.5 | AD24: 117.7 | AE24: 115.6 | AF24: =ROUNDUP(_xlfn.FORECAST.LINEAR($AF$7,H24:AE24,$H$7:$AE$7), 0) -> 80 | AG24: =ROUNDUP(_xlfn.FORECAST.LINEAR($AG$7,H24:AE24,$H$7:$AE$7), 0) -> 84 | AH24: =ROUNDUP(_xlfn.FORECAST.LINEAR($AH$7,H24:AE24,$H$7:$AE$7), 0) -> 88 | AI24: =ROUNDUP(_xlfn.FORECAST.LINEAR($AI$7,H24:AE24,$H$7:$AE$7), 0) -> 92 | AJ24: =ROUNDUP(_xlfn.FORECAST.LINEAR($AJ$7,H24:AE24,$H$7:$AE$7), 0) -> 95 | AK24: =ROUNDUP(_xlfn.FORECAST.LINEAR($AK$7,H24:AE24,$H$7:$AE$7), 0) -> 99 | AL24: =ROUNDUP(_xlfn.FORECAST.LINEAR($AL$7,H24:AE24,$H$7:$AE$7), 0) -> 103
D25: D20T21: Chemicals and pharmaceutical products | H25: 442.8 | I25: 428.6 | J25: 440.1 | K25: 431.2 | L25: 459.8 | M25: 468.9 | N25: 464.5 | O25: 476 | P25: 477.5 | Q25: 488.3 | R25: 499.4 | S25: 529 | T25: 552.2 | U25: 564.4 | V25: 543.1 | W25: 639.2 | X25: 686.4 | Y25: 712.7 | Z25: 716.6 | AA25: 701.3 | AB25: 634.8 | AC25: 712.7 | AD25: 808.5 | AE25: 806.6 | AF25: =ROUNDUP(_xlfn.FORECAST.LINEAR($AF$7,H25:AE25,$H$7:$AE$7), 0) -> 778 | AG25: =ROUNDUP(_xlfn.FORECAST.LINEAR($AG$7,H25:AE25,$H$7:$AE$7), 0) -> 794 | AH25: =ROUNDUP(_xlfn.FORECAST.LINEAR($AH$7,H25:AE25,$H$7:$AE$7), 0) -> 811 | AI25: =ROUNDUP(_xlfn.FORECAST.LINEAR($AI$7,H25:AE25,$H$7:$AE$7), 0) -> 827 | AJ25: =ROUNDUP(_xlfn.FORECAST.LINEAR($AJ$7,H25:AE25,$H$7:$AE$7), 0) -> 844 | AK25: =ROUNDUP(_xlfn.FORECAST.LINEAR($AK$7,H25:AE25,$H$7:$AE$7), 0) -> 860 | AL25: =ROUNDUP(_xlfn.FORECAST.LINEAR($AL$7,H25:AE25,$H$7:$AE$7), 0) -> 877
D26: D20T21: Chemicals and pharmaceutical products | E26: D20: Chemical and chemical products | H26: 300.8 | I26: 295.8 | J26: 303.6 | K26: 297.4 | L26: 317.3 | M26: 324 | N26: 344.4 | O26: 352.9 | P26: 353.5 | Q26: 362.2 | R26: 370.4 | S26: 360.2 | T26: 379.6 | U26: 386 | V26: 365.1 | W26: 451.3 | X26: 516.4 | Y26: 526.2 | Z26: 518.6 | AA26: 497 | AB26: 418.2 | AC26: 483 | AD26: 565.8 | AE26: 552.7 | AF26: =ROUNDUP(_xlfn.FORECAST.LINEAR($AF$7,H26:AE26,$H$7:$AE$7), 0) -> 546 | AG26: =ROUNDUP(_xlfn.FORECAST.LINEAR($AG$7,H26:AE26,$H$7:$AE$7), 0) -> 557 | AH26: =ROUNDUP(_xlfn.FORECAST.LINEAR($AH$7,H26:AE26,$H$7:$AE$7), 0) -> 569 | AI26: =ROUNDUP(_xlfn.FORECAST.LINEAR($AI$7,H26:AE26,$H$7:$AE$7), 0) -> 580 | AJ26: =ROUNDUP(_xlfn.FORECAST.LINEAR($AJ$7,H26:AE26,$H$7:$AE$7), 0) -> 592 | AK26: =ROUNDUP(_xlfn.FORECAST.LINEAR($AK$7,H26:AE26,$H$7:$AE$7), 0) -> 603 | AL26: =ROUNDUP(_xlfn.FORECAST.LINEAR($AL$7,H26:AE26,$H$7:$AE$7), 0) -> 615
E27: D21: Pharmaceuticals, medicinal chemical and botanical products | H27: 142 | I27: 132.8 | J27: 136.4 | K27: 133.8 | L27: 142.6 | M27: 145 | N27: 120.1 | O27: 123.1 | P27: 123.9 | Q27: 126.1 | R27: 129 | S27: 168.8 | T27: 172.7 | U27: 178.4 | V27: 177.9 | W27: 187.9 | X27: 170 | Y27: 186.5 | Z27: 198 | AA27: 204.3 | AB27: 216.6 | AC27: 229.7 | AD27: 242.7 | AE27: 253.9 | AF27: =ROUNDUP(_xlfn.FORECAST.LINEAR($AF$7,H27:AE27,$H$7:$AE$7), 0) -> 232 | AG27: =ROUNDUP(_xlfn.FORECAST.LINEAR($AG$7,H27:AE27,$H$7:$AE$7), 0) -> 238 | AH27: =ROUNDUP(_xlfn.FORECAST.LINEAR($AH$7,H27:AE27,$H$7:$AE$7), 0) -> 243 | AI27: =ROUNDUP(_xlfn.FORECAST.LINEAR($AI$7,H27:AE27,$H$7:$AE$7), 0) -> 248 | AJ27: =ROUNDUP(_xlfn.FORECAST.LINEAR($AJ$7,H27:AE27,$H$7:$AE$7), 0) -> 253 | AK27: =ROUNDUP(_xlfn.FORECAST.LINEAR($AK$7,H27:AE27,$H$7:$AE$7), 0) -> 258 | AL27: =ROUNDUP(_xlfn.FORECAST.LINEAR($AL$7,H27:AE27,$H$7:$AE$7), 0) -> 263
D28: D22: Rubber and plastics products | H28: 765.6 | I28: 746 | J28: 765.9 | K28: 750.3 | L28: 800.2 | M28: 816.8 | N28: 832.8 | O28: 853.2 | P28: 856.9 | Q28: 874.5 | R28: 894.7 | S28: 921.7 | T28: 950 | U28: 978.6 | V28: 963.4 | W28: 1058.3 | X28: 1238.8 | Y28: 1351.7 | Z28: 1428.3 | AA28: 1469 | AB28: 1496.8 | AC28: 1649 | AD28: 1786.7 | AE28: 1837.8 | AF28: =ROUNDUP(_xlfn.FORECAST.LINEAR($AF$7,H28:AE28,$H$7:$AE$7), 0) -> 1660 | AG28: =ROUNDUP(_xlfn.FORECAST.LINEAR($AG$7,H28:AE28,$H$7:$AE$7), 0) -> 1705 | AH28: =ROUNDUP(_xlfn.FORECAST.LINEAR($AH$7,H28:AE28,$H$7:$AE$7), 0) -> 1751 | AI28: =ROUNDUP(_xlfn.FORECAST.LINEAR($AI$7,H28:AE28,$H$7:$AE$7), 0) -> 1797 | AJ28: =ROUNDUP(_xlfn.FORECAST.LINEAR($AJ$7,H28:AE28,$H$7:$AE$7), 0) -> 1843 | AK28: =ROUNDUP(_xlfn.FORECAST.LINEAR($AK$7,H28:AE28,$H$7:$AE$7), 0) -> 1888 | AL28: =ROUNDUP(_xlfn.FORECAST.LINEAR($AL$7,H28:AE28,$H$7:$AE$7), 0) -> 1934
D29: D23: Other non-metallic mineral products | H29: 375.2 | I29: 365.6 | J29: 375.4 | K29: 367.7 | L29: 392.2 | M29: 400.4 | N29: 408.1 | O29: 418 | P29: 420.3 | Q29: 428.2 | R29: 438.2 | S29: 453.5 | T29: 462.9 | U29: 479.5 | V29: 480.5 | W29: 500.2 | X29: 522.7 | Y29: 509.1 | Z29: 480.2 | AA29: 440.9 | AB29: 422.3 | AC29: 394.4 | AD29: 413.9 | AE29: 435 | AF29: =ROUNDUP(_xlfn.FORECAST.LINEAR($AF$7,H29:AE29,$H$7:$AE$7), 0) -> 479 | AG29: =ROUNDUP(_xlfn.FORECAST.LINEAR($AG$7,H29:AE29,$H$7:$AE$7), 0) -> 483 | AH29: =ROUNDUP(_xlfn.FORECAST.LINEAR($AH$7,H29:AE29,$H$7:$AE$7), 0) -> 486 | AI29: =ROUNDUP(_xlfn.FORECAST.LINEAR($AI$7,H29:AE29,$H$7:$AE$7), 0) -> 490 | AJ29: =ROUNDUP(_xlfn.FORECAST.LINEAR($AJ$7,H29:AE29,$H$7:$AE$7), 0) -> 494 | AK29: =ROUNDUP(_xlfn.FORECAST.LINEAR($AK$7,H29:AE29,$H$7:$AE$7), 0) -> 498 | AL29: =ROUNDUP(_xlfn.FORECAST.LINEAR($AL$7,H29:AE29,$H$7:$AE$7), 0) -> 501
C30: D24T25: Basic metals and fabricated metal products | H30: 504.6 | I30: 496.3 | J30: 511.6 | K30: 501.2 | L30: 534.5 | M30: 535.3 | N30: 532.1 | O30: 560.1 | P30: 561.1 | Q30: 568.5 | R30: 575.8 | S30: 596.5 | T30: 607.9 | U30: 626 | V30: 659.1 | W30: 663.8 | X30: 820.9 | Y30: 1001.6 | Z30: 1188 | AA30: 1378.7 | AB30: 1701.5 | AC30: 1837.4 | AD30: 1892.3 | AE30: 2014.6 | AF30: =ROUNDUP(_xlfn.FORECAST.LINEAR($AF$7,H30:AE30,$H$7:$AE$7), 0) -> 1629 | AG30: =ROUNDUP(_xlfn.FORECAST.LINEAR($AG$7,H30:AE30,$H$7:$AE$7), 0) -> 1690 | AH30: =ROUNDUP(_xlfn.FORECAST.LINEAR($AH$7,H30:AE30,$H$7:$AE$7), 0) -> 1750 | AI30: =ROUNDUP(_xlfn.FORECAST.LINEAR($AI$7,H30:AE30,$H$7:$AE$7), 0) -> 1811 | AJ30: =ROUNDUP(_xlfn.FORECAST.LINEAR($AJ$7,H30:AE30,$H$7:$AE$7), 0) -> 1872 | AK30: =ROUNDUP(_xlfn.FORECAST.LINEAR($AK$7,H30:AE30,$H$7:$AE$7), 0) -> 1932 | AL30: =ROUNDUP(_xlfn.FORECAST.LINEAR($AL$7,H30:AE30,$H$7:$AE$7), 0) -> 1993
C31: D24T25: Basic metals and fabricated metal products | D31: D24: Basic metals | H31: 154.9 | I31: 152.4 | J31: 157.1 | K31: 153.9 | L31: 164.1 | M31: 164.4 | N31: 163.4 | O31: 178.9 | P31: 172.3 | Q31: 175.8 | R31: 176.8 | S31: 183.2 | T31: 186.6 | U31: 192.2 | V31: 202.6 | W31: 203.3 | X31: 240.2 | Y31: 279.7 | Z31: 316.5 | AA31: 350 | AB31: 412.9 | AC31: 422.6 | AD31: 434.2 | AE31: 463 | AF31: =ROUNDUP(_xlfn.FORECAST.LINEAR($AF$7,H31:AE31,$H$7:$AE$7), 0) -> 398 | AG31: =ROUNDUP(_xlfn.FORECAST.LINEAR($AG$7,H31:AE31,$H$7:$AE$7), 0) -> 411 | AH31: =ROUNDUP(_xlfn.FORECAST.LINEAR($AH$7,H31:AE31,$H$7:$AE$7), 0) -> 424 | AI31: =ROUNDUP(_xlfn.FORECAST.LINEAR($AI$7,H31:AE31,$H$7:$AE$7), 0) -> 437 | AJ31: =ROUNDUP(_xlfn.FORECAST.LINEAR($AJ$7,H31:AE31,$H$7:$AE$7), 0) -> 449 | AK31: =ROUNDUP(_xlfn.FORECAST.LINEAR($AK$7,H31:AE31,$H$7:$AE$7), 0) -> 462 | AL31: =ROUNDUP(_xlfn.FORECAST.LINEAR($AL$7,H31:AE31,$H$7:$AE$7), 0) -> 475
D32: D25: Fabricated metal products | H32: 349.7 | I32: 343.9 | J32: 354.5 | K32: 347.3 | L32: 370.4 | M32: 371 | N32: 368.7 | O32: 381.2 | P32: 388.8 | Q32: 392.8 | R32: 399 | S32: 413.3 | T32: 421.3 | U32: 433.8 | V32: 456.5 | W32: 460.5 | X32: 580.8 | Y32: 721.8 | Z32: 871.6 | AA32: 1028.7 | AB32: 1288.6 | AC32: 1414.8 | AD32: 1458.1 | AE32: 1551.6 | AF32: =ROUNDUP(_xlfn.FORECAST.LINEAR($AF$7,H32:AE32,$H$7:$AE$7), 0) -> 1231 | AG32: =ROUNDUP(_xlfn.FORECAST.LINEAR($AG$7,H32:AE32,$H$7:$AE$7), 0) -> 1279 | AH32: =ROUNDUP(_xlfn.FORECAST.LINEAR($AH$7,H32:AE32,$H$7:$AE$7), 0) -> 1327 | AI32: =ROUNDUP(_xlfn.FORECAST.LINEAR($AI$7,H32:AE32,$H$7:$AE$7), 0) -> 1375 | AJ32: =ROUNDUP(_xlfn.FORECAST.LINEAR($AJ$7,H32:AE32,$H$7:$AE$7), 0) -> 1423 | AK32: =ROUNDUP(_xlfn.FORECAST.LINEAR($AK$7,H32:AE32,$H$7:$AE$7), 0) -> 1471 | AL32: =ROUNDUP(_xlfn.FORECAST.LINEAR($AL$7,H32:AE32,$H$7:$AE$7), 0) -> 1519
C33: D26T27: Computer, electronic and electrical equipment | H33: 608.8 | I33: 762.6 | J33: 786.7 | K33: 994.4 | L33: 881.6 | M33: 941.8 | N33: 986 | O33: 910.4 | P33: 917.1 | Q33: 924.7 | R33: 940 | S33: 727.8 | T33: 721.9 | U33: 742.3 | V33: 788.9 | W33: 782.8 | X33: 800.6 | Y33: 779.2 | Z33: 737.6 | AA33: 683.3 | AB33: 682.9 | AC33: 574.8 | AD33: 586.2 | AE33: 628.2 | AF33: =ROUNDUP(_xlfn.FORECAST.LINEAR($AF$7,H33:AE33,$H$7:$AE$7), 0) -> 659 | AG33: =ROUNDUP(_xlfn.FORECAST.LINEAR($AG$7,H33:AE33,$H$7:$AE$7), 0) -> 649 | AH33: =ROUNDUP(_xlfn.FORECAST.LINEAR($AH$7,H33:AE33,$H$7:$AE$7), 0) -> 638 | AI33: =ROUNDUP(_xlfn.FORECAST.LINEAR($AI$7,H33:AE33,$H$7:$AE$7), 0) -> 628 | AJ33: =ROUNDUP(_xlfn.FORECAST.LINEAR($AJ$7,H33:AE33,$H$7:$AE$7), 0) -> 618 | AK33: =ROUNDUP(_xlfn.FORECAST.LINEAR($AK$7,H33:AE33,$H$7:$AE$7), 0) -> 607 | AL33: =ROUNDUP(_xlfn.FORECAST.LINEAR($AL$7,H33:AE33,$H$7:$AE$7), 0) -> 597
C34: D26T27: Computer, electronic and electrical equipment | D34: D26: Computer, electronic and optical equipment | H34: 372.9 | I34: 488.5 | J34: 503.8 | K34: 718.7 | L34: 586.7 | M34: 648.3 | N34: 650.7 | O34: 562.9 | P34: 561.5 | Q34: 566.4 | R34: 575.8 | S34: 453.4 | T34: 444.3 | U34: 455.8 | V34: 483.1 | W34: 486.6 | X34: 466.8 | Y34: 448.9 | Z34: 419.7 | AA34: 383.8 | AB34: 373.1 | AC34: 316.7 | AD34: 325.7 | AE34: 346.8 | AF34: =ROUNDUP(_xlfn.FORECAST.LINEAR($AF$7,H34:AE34,$H$7:$AE$7), 0) -> 356 | AG34: =ROUNDUP(_xlfn.FORECAST.LINEAR($AG$7,H34:AE34,$H$7:$AE$7), 0) -> 345 | AH34: =ROUNDUP(_xlfn.FORECAST.LINEAR($AH$7,H34:AE34,$H$7:$AE$7), 0) -> 335 | AI34: =ROUNDUP(_xlfn.FORECAST.LINEAR($AI$7,H34:AE34,$H$7:$AE$7), 0) -> 325 | AJ34: =ROUNDUP(_xlfn.FORECAST.LINEAR($AJ$7,H34:AE34,$H$7:$AE$7), 0) -> 314 | AK34: =ROUNDUP(_xlfn.FORECAST.LINEAR($AK$7,H34:AE34,$H$7:$AE$7), 0) -> 304 | AL34: =ROUNDUP(_xlfn.FORECAST.LINEAR($AL$7,H34:AE34,$H$7:$AE$7), 0) -> 294
D35: D27: Electrical equipment | H35: 236 | I35: 274.1 | J35: 282.8 | K35: 275.6 | L35: 295 | M35: 293.5 | N35: 335.2 | O35: 347.5 | P35: 355.6 | Q35: 358.3 | R35: 364.2 | S35: 274.3 | T35: 277.6 | U35: 286.5 | V35: 305.8 | W35: 296.2 | X35: 333.8 | Y35: 330.3 | Z35: 317.8 | AA35: 299.5 | AB35: 309.9 | AC35: 258.2 | AD35: 260.6 | AE35: 281.4 | AF35: =ROUNDUP(_xlfn.FORECAST.LINEAR($AF$7,H35:AE35,$H$7:$AE$7), 0) -> 304 | AG35: =ROUNDUP(_xlfn.FORECAST.LINEAR($AG$7,H35:AE35,$H$7:$AE$7), 0) -> 304 | AH35: =ROUNDUP(_xlfn.FORECAST.LINEAR($AH$7,H35:AE35,$H$7:$AE$7), 0) -> 304 | AI35: =ROUNDUP(_xlfn.FORECAST.LINEAR($AI$7,H35:AE35,$H$7:$AE$7), 0) -> 304 | AJ35: =ROUNDUP(_xlfn.FORECAST.LINEAR($AJ$7,H35:AE35,$H$7:$AE$7), 0) -> 304 | AK35: =ROUNDUP(_xlfn.FORECAST.LINEAR($AK$7,H35:AE35,$H$7:$AE$7), 0) -> 304 | AL35: =ROUNDUP(_xlfn.FORECAST.LINEAR($AL$7,H35:AE35,$H$7:$AE$7), 0) -> 304
C36: D28: Machinery and equipment, nec | H36: 87.5 | I36: 86.1 | J36: 88.7 | K36: 86.9 | L36: 92.7 | M36: 92.8 | N36: 92.3 | O36: 95.3 | P36: 97.3 | Q36: 98.3 | R36: 99.9 | S36: 103.3 | T36: 105.7 | U36: 108.6 | V36: 113.5 | W36: 116.9 | X36: 118.3 | Y36: 118.1 | Z36: 114.6 | AA36: 108.8 | AB36: 107.6 | AC36: 97.1 | AD36: 101.3 | AE36: 106.9 | AF36: =ROUNDUP(_xlfn.FORECAST.LINEAR($AF$7,H36:AE36,$H$7:$AE$7), 0) -> 116 | AG36: =ROUNDUP(_xlfn.FORECAST.LINEAR($AG$7,H36:AE36,$H$7:$AE$7), 0) -> 117 | AH36: =ROUNDUP(_xlfn.FORECAST.LINEAR($AH$7,H36:AE36,$H$7:$AE$7), 0) -> 118 | AI36: =ROUNDUP(_xlfn.FORECAST.LINEAR($AI$7,H36:AE36,$H$7:$AE$7), 0) -> 119 | AJ36: =ROUNDUP(_xlfn.FORECAST.LINEAR($AJ$7,H36:AE36,$H$7:$AE$7), 0) -> 120 | AK36: =ROUNDUP(_xlfn.FORECAST.LINEAR($AK$7,H36:AE36,$H$7:$AE$7), 0) -> 121 | AL36: =ROUNDUP(_xlfn.FORECAST.LINEAR($AL$7,H36:AE36,$H$7:$AE$7), 0) -> 122
C37: D29T30: Transport equipment | H37: 414 | I37: 418.3 | J37: 431.3 | K37: 422.5 | L37: 450.5 | M37: 450.9 | N37: 453 | O37: 467.9 | P37: 477.8 | Q37: 482.6 | R37: 490.4 | S37: 458.7 | T37: 468.6 | U37: 481.6 | V37: 504.7 | W37: 516.3 | X37: 585.8 | Y37: 652.6 | Z37: 707 | AA37: 749.2 | AB37: 832.4 | AC37: 832 | AD37: 863.8 | AE37: 914.5 | AF37: =ROUNDUP(_xlfn.FORECAST.LINEAR($AF$7,H37:AE37,$H$7:$AE$7), 0) -> 819 | AG37: =ROUNDUP(_xlfn.FORECAST.LINEAR($AG$7,H37:AE37,$H$7:$AE$7), 0) -> 839 | AH37: =ROUNDUP(_xlfn.FORECAST.LINEAR($AH$7,H37:AE37,$H$7:$AE$7), 0) -> 860 | AI37: =ROUNDUP(_xlfn.FORECAST.LINEAR($AI$7,H37:AE37,$H$7:$AE$7), 0) -> 880 | AJ37: =ROUNDUP(_xlfn.FORECAST.LINEAR($AJ$7,H37:AE37,$H$7:$AE$7), 0) -> 900 | AK37: =ROUNDUP(_xlfn.FORECAST.LINEAR($AK$7,H37:AE37,$H$7:$AE$7), 0) -> 921 | AL37: =ROUNDUP(_xlfn.FORECAST.LINEAR($AL$7,H37:AE37,$H$7:$AE$7), 0) -> 941
C38: D29T30: Transport equipment | D38: D29: Motor vehicles, trailers and semi-trailers | H38: 207 | I38: 201.1 | J38: 207.3 | K38: 203.1 | L38: 216.6 | M38: 217 | N38: 214.7 | O38: 221.7 | P38: 226.3 | Q38: 228.7 | R38: 232.4 | S38: 251.9 | T38: 257.3 | U38: 264.7 | V38: 277.4 | W38: 283.3 | X38: 328.7 | Y38: 376.8 | Z38: 419.5 | AA38: 456.5 | AB38: 520.6 | AC38: 533.2 | AD38: 553.7 | AE38: 586.2 | AF38: =ROUNDUP(_xlfn.FORECAST.LINEAR($AF$7,H38:AE38,$H$7:$AE$7), 0) -> 516 | AG38: =ROUNDUP(_xlfn.FORECAST.LINEAR($AG$7,H38:AE38,$H$7:$AE$7), 0) -> 532 | AH38: =ROUNDUP(_xlfn.FORECAST.LINEAR($AH$7,H38:AE38,$H$7:$AE$7), 0) -> 548 | AI38: =ROUNDUP(_xlfn.FORECAST.LINEAR($AI$7,H38:AE38,$H$7:$AE$7), 0) -> 565 | AJ38: =ROUNDUP(_xlfn.FORECAST.LINEAR($AJ$7,H38:AE38,$H$7:$AE$7), 0) -> 581 | AK38: =ROUNDUP(_xlfn.FORECAST.LINEAR($AK$7,H38:AE38,$H$7:$AE$7), 0) -> 597 | AL38: =ROUNDUP(_xlfn.FORECAST.LINEAR($AL$7,H38:AE38,$H$7:$AE$7), 0) -> 614
D39: D30: Other transport equipment | H39: 207 | I39: 217.2 | J39: 224 | K39: 219.4 | L39: 234 | M39: 233.9 | N39: 238.3 | O39: 246.2 | P39: 251.5 | Q39: 253.9 | R39: 258 | S39: 206.9 | T39: 211.3 | U39: 216.9 | V39: 227.3 | W39: 233 | X39: 257.1 | Y39: 275.8 | Z39: 287.4 | AA39: 292.7 | AB39: 311.9 | AC39: 298.8 | AD39: 310.1 | AE39: 328.2 | AF39: =ROUNDUP(_xlfn.FORECAST.LINEAR($AF$7,H39:AE39,$H$7:$AE$7), 0) -> 303 | AG39: =ROUNDUP(_xlfn.FORECAST.LINEAR($AG$7,H39:AE39,$H$7:$AE$7), 0) -> 308 | AH39: =ROUNDUP(_xlfn.FORECAST.LINEAR($AH$7,H39:AE39,$H$7:$AE$7), 0) -> 312 | AI39: =ROUNDUP(_xlfn.FORECAST.LINEAR($AI$7,H39:AE39,$H$7:$AE$7), 0) -> 316 | AJ39: =ROUNDUP(_xlfn.FORECAST.LINEAR($AJ$7,H39:AE39,$H$7:$AE$7), 0) -> 320 | AK39: =ROUNDUP(_xlfn.FORECAST.LINEAR($AK$7,H39:AE39,$H$7:$AE$7), 0) -> 324 | AL39: =ROUNDUP(_xlfn.FORECAST.LINEAR($AL$7,H39:AE39,$H$7:$AE$7), 0) -> 328
C40: D31T33: Manufacturing nec; repair and installation of machinery and equipment | H40: 826.4 | I40: 811.9 | J40: 837 | K40: 820 | L40: 874.4 | M40: 875.7 | N40: 871.4 | O40: 900 | P40: 918.7 | Q40: 928.2 | R40: 943.2 | S40: 974.4 | T40: 995.6 | U40: 1023.7 | V40: 1072.4 | W40: 1096.9 | X40: 1015.4 | Y40: 903.6 | Z40: 781.8 | AA40: 661.7 | AB40: 587.1 | AC40: 469 | AD40: 487.2 | AE40: 515.7 | AF40: =ROUNDUP(_xlfn.FORECAST.LINEAR($AF$7,H40:AE40,$H$7:$AE$7), 0) -> 702 | AG40: =ROUNDUP(_xlfn.FORECAST.LINEAR($AG$7,H40:AE40,$H$7:$AE$7), 0) -> 691 | AH40: =ROUNDUP(_xlfn.FORECAST.LINEAR($AH$7,H40:AE40,$H$7:$AE$7), 0) -> 680 | AI40: =ROUNDUP(_xlfn.FORECAST.LINEAR($AI$7,H40:AE40,$H$7:$AE$7), 0) -> 669 | AJ40: =ROUNDUP(_xlfn.FORECAST.LINEAR($AJ$7,H40:AE40,$H$7:$AE$7), 0) -> 657 | AK40: =ROUNDUP(_xlfn.FORECAST.LINEAR($AK$7,H40:AE40,$H$7:$AE$7), 0) -> 646 | AL40: =ROUNDUP(_xlfn.FORECAST.LINEAR($AL$7,H40:AE40,$H$7:$AE$7), 0) -> 635
...

Sheet Output by industry
A1: Industrial Sector (EPS) | B1: 2019 | C1: 2020 | D1: 2021 | E1: 2022 | F1: 2023 | G1: 2024 | H1: 2025 | I1: 2026 | J1: 2027 | K1: 2028 | L1: 2029 | M1: 2030 | N1: 2031 | O1: 2032 | P1: 2033 | Q1: 2034 | R1: 2035 | S1: 2036 | T1: 2037 | U1: 2038 | V1: 2039 | W1: 2040 | X1: 2041 | Y1: 2042 | Z1: 2043 | AA1: 2044 | AB1: 2045 | AC1: 2046 | AD1: 2047 | AE1: 2048 | AF1: 2049 | AG1: 2050
A2: agriculture and forestry 01T03 | B2: 0 | C2: 0 | D2: 0.044329089 | E2: 0.042447433 | F2: 0.040719015 | G2: 0.039125849 | H2: 0.037652657 | I2: 0.036286378 | J2: 0.035015782 | K2: 0.033831158 | L2: 0.032724065 | M2: 0.031687133 | N2: 0.030713898 | O2: 0.029798665 | P2: 0.028936399 | Q2: 0.028122631 | R2: 0.027353382 | S2: 0.026625095 | T2: 0.025934585 | U2: 0.025278985 | V2: 0.024655713 | W2: 0.024062437 | X2: 0.023497041 | Y2: 0.022957605 | Z2: 0.022442382 | AA2: 0.021949776 | AB2: 0.021478332 | AC2: 0.021026713 | AD2: 0.020593695 | AE2: 0.020178153 | AF2: 0.019779048 | AG2: 0.019395425
A3: coal mining 05 | B3: 0 | C3: 0 | D3: 0.044469221 | E3: 0.042575904 | F3: 0.040837222 | G3: 0.039234975 | H3: 0.037753709 | I3: 0.036380221 | J3: 0.03510316 | K3: 0.033912717 | L3: 0.032800367 | M3: 0.031758671 | N3: 0.030781104 | O3: 0.029861921 | P3: 0.028996044 | Q3: 0.028178965 | R3: 0.027406673 | S3: 0.026675584 | T3: 0.025982486 | U3: 0.025324493 | V3: 0.024699003 | W3: 0.024103667 | X3: 0.023536354 | Y3: 0.022995133 | Z3: 0.022478243 | AA3: 0.021984079 | AB3: 0.021511176 | AC3: 0.021058189 | AD3: 0.020623888 | AE3: 0.020207138 | AF3: 0.019806897 | AG3: 0.019422204
A4: oil and gas extraction 06 | B4: 0 | C4: 0 | D4: 0 | E4: 0 | F4: 0 | G4: 0 | H4: 0 | I4: 0 | J4: 0 | K4: 0 | L4: 0 | M4: 0 | N4: 0 | O4: 0 | P4: 0 | Q4: 0 | R4: 0 | S4: 0 | T4: 0 | U4: 0 | V4: 0 | W4: 0 | X4: 0 | Y4: 0 | Z4: 0 | AA4: 0 | AB4: 0 | AC4: 0 | AD4: 0 | AE4: 0 | AF4: 0 | AG4: 0
A5: other mining and quarrying 07T08 | B5: 0 | C5: 0 | D5: 0.046815031 | E5: 0.044721397 | F5: 0.042807008 | G5: 0.041049789 | H5: 0.039431149 | I5: 0.037935316 | J5: 0.036548825 | K5: 0.035260109 | L5: 0.034059179 | M5: 0.032937359 | N5: 0.031887083 | O5: 0.030901717 | P5: 0.029975425 | Q5: 0.029103049 | R5: 0.028280014 | S5: 0.02750225 | T5: 0.026766122 | U5: 0.026068373 | V5: 0.025406077 | W5: 0.024776601 | X5: 0.024177563 | Y5: 0.023606808 | Z5: 0.023062379 | AA5: 0.022542496 | AB5: 0.022045534 | AC5: 0.021570012 | AD5: 0.02111457 | AE5: 0.020677964 | AF5: 0.020259048 | AG5: 0.019856769
A6: food beverage and tobacco 10T12 | B6: 0 | C6: 0 | D6: 0.044871599 | E6: 0.042944605 | F6: 0.041176305 | G6: 0.03954787 | H6: 0.038043337 | I6: 0.036649084 | J6: 0.035353413 | K6: 0.034146228 | L6: 0.033018762 | M6: 0.031963371 | N6: 0.030973358 | O6: 0.03004283 | P6: 0.029166584 | Q6: 0.028340003 | R6: 0.027558981 | S6: 0.026819853 | T6: 0.026119336 | U6: 0.025454482 | V6: 0.024822635 | W6: 0.024221396 | X6: 0.023648594 | Y6: 0.023102258 | Z6: 0.022580595 | AA6: 0.022081971 | AB6: 0.021604893 | AC6: 0.021147993 | AD6: 0.020710017 | AE6: 0.020289815 | AF6: 0.019886325 | AG6: 0.01949857
A7: textiles apparel and leather 13T15 | B7: 0 | C7: 0 | D7: 0.043822254 | E7: 0.041982487 | F7: 0.040290972 | G7: 0.038730483 | H7: 0.037286364 | I7: 0.035946066 | J7: 0.034698781 | K7: 0.033535153 | L7: 0.032447036 | M7: 0.031427313 | N7: 0.030469731 | O7: 0.029568779 | P7: 0.028719576 | Q7: 0.027917789 | R7: 0.027159554 | S7: 0.026441417 | T7: 0.025760279 | U7: 0.025113352 | V7: 0.024498122 | W7: 0.023912315 | X7: 0.02335387 | Y7: 0.022820913 | Z7: 0.022311739 | AA7: 0.02182479 | AB7: 0.021358642 | AC7: 0.02091199 | AD7: 0.020483637 | AE7: 0.020072479 | AF7: 0.019677503 | AG7: 0.019297771
A8: wood products 16 | B8: 0 | C8: 0 | D8: 0.044912277 | E8: 0.042981864 | F8: 0.041210557 | G8: 0.039579465 | H8: 0.038072573 | I8: 0.036676215 | J8: 0.03537866 | K8: 0.034169779 | L8: 0.033040783 | M8: 0.031984006 | N8: 0.030992734 | O8: 0.03006106 | P8: 0.029183765 | Q8: 0.028356224 | R8: 0.02757432 | S8: 0.02683438 | T8: 0.026133114 | U8: 0.025467567 | V8: 0.024835078 | W8: 0.024233244 | X8: 0.023659888 | Y8: 0.023113036 | Z8: 0.022590892 | AA8: 0.022091818 | AB8: 0.021614319 | AC8: 0.021157024 | AD8: 0.020718678 | AE8: 0.020298128 | AF8: 0.019894311 | AG8: 0.019506247
A9: pulp paper and printing 17T18 | B9: 0 | C9: 0 | D9: 0.045412947 | E9: 0.0434402 | F9: 0.04163171 | G9: 0.039967783 | H9: 0.038431751 | I9: 0.037009414 | J9: 0.0356886 | K9: 0.034458813 | L9: 0.033310957 | M9: 0.032237108 | N9: 0.031230333 | O9: 0.030284537 | P9: 0.029394343 | Q9: 0.028554987 | R9: 0.027762237 | S9: 0.027012315 | T9: 0.026301841 | U9: 0.025627783 | V9: 0.024987411 | W9: 0.024378262 | X9: 0.023798105 | Y9: 0.02324492 | Z9: 0.022716868 | AA9: 0.022212275 | AB9: 0.021729611 | AC9: 0.021267477 | AD9: 0.02082459 | AE9: 0.020399774 | AF9: 0.019991942 | AG9: 0.019600098
A10: refined petroleum and coke 19 | B10: 0 | C10: 0 | D10: 0.045048756 | E10: 0.043106846 | F10: 0.041325437 | G10: 0.03968542 | H10: 0.038170603 | I10: 0.036767178 | J10: 0.035463293 | K10: 0.03424872 | L10: 0.033114588 | M10: 0.032053161 | N10: 0.031057664 | O10: 0.030122141 | P10: 0.02924133 | Q10: 0.028410567 | R10: 0.027625705 | S10: 0.026883042 | T10: 0.026179264 | U10: 0.025511394 | V10: 0.024876754 | W10: 0.024272922 | X10: 0.023697709 | Y10: 0.023149128 | Z10: 0.02262537 | AA10: 0.022124789 | AB10: 0.021645878 | AC10: 0.021187262 | AD10: 0.020747675 | AE10: 0.020325959 | AF10: 0.019921044 | AG10: 0.019531948
A11: chemicals 20 | B11: 0 | C11: 0 | D11: 0.044912276 | E11: 0.042981862 | F11: 0.041210556 | G11: 0.039579464 | H11: 0.038072572 | I11: 0.036676214 | J11: 0.035378659 | K11: 0.034169778 | L11: 0.033040782 | M11: 0.031984005 | N11: 0.030992734 | O11: 0.030061059 | P11: 0.029183764 | Q11: 0.028356223 | R11: 0.027574319 | S11: 0.02683438 | T11: 0.026133114 | U11: 0.025467567 | V11: 0.024835078 | W11: 0.024233243 | X11: 0.023659888 | Y11: 0.023113036 | Z11: 0.022590892 | AA11: 0.022091818 | AB11: 0.021614318 | AC11: 0.021157024 | AD11: 0.020718678 | AE11: 0.020298128 | AF11: 0.01989431 | AG11: 0.019506247
A12: rubber and plastic products 22 | B12: 0 | C12: 0 | D12: 0 | E12: 0 | F12: 0 | G12: 0 | H12: 0 | I12: 0 | J12: 0 | K12: 0 | L12: 0 | M12: 0 | N12: 0 | O12: 0 | P12: 0 | Q12: 0 | R12: 0 | S12: 0 | T12: 0 | U12: 0 | V12: 0 | W12: 0 | X12: 0 | Y12: 0 | Z12: 0 | AA12: 0 | AB12: 0 | AC12: 0 | AD12: 0 | AE12: 0 | AF12: 0 | AG12: 0
... A26: construction 41T43 | B26: 0 | C26: 0 | D26: 0.0446731 | E26: 0.042762755 | F26: 0.041009093 | G26: 0.039393598 | H26: 0.037900558 | I26: 0.03651656 | J26: 0.035230079 | K26: 0.034031159 | L26: 0.032911154 | M26: 0.031862522 | N26: 0.03087865 | O26: 0.029953719 | P26: 0.029082588 | Q26: 0.028260694 | R26: 0.027483977 | S26: 0.026748814 | T26: 0.026051955 | U26: 0.025390483 | V26: 0.02476177 | W26: 0.02416344 | X26: 0.023593344 | Y26: 0.023049528 | Z26: 0.022530218 | AA26: 0.022033791 | AB26: 0.02155877 | AC26: 0.021103798 | AD26: 0.020667632 | AE26: 0.020249131 | AF26: 0.019847241 | AG26: 0.019460994
A30: We'll use linear interpolation to backcast the values for 2019 and 2020 based on the available data for 2021 and 2022 for each industry sector.
A32: Here's how you can calculate it in Excel:
A34: Calculate the slope (m) and y-intercept (b):
A35: For each industry sector, use the values for 2021 and 2022 to find the slope and y-intercept.
A36: Calculate the backcast values for 2019 and 2020:
A37: Use the slope and y-intercept to interpolate the values for 2019 and 2020 for each sector.
A39: Industrial Sector (EPS) | B39: Backcast 2019 | C39: Backcast 2020
A40: agriculture and forestry 01T03 | B40: 0.044 | C40: 0.042
A41: coal mining 05 | B41: 0.044 | C41: 0.042
A42: oil and gas extraction 06 | B42: 0.044 | C42: 0.042
A43: other mining and quarrying 07T08 | B43: 0.046 | C43: 0.044
A44: food beverage and tobacco 10T12 | B44: 0.045 | C44: 0.043
A45: textiles apparel and leather 13T15 | B45: 0.044 | C45: 0.042
A46: wood products 16 | B46: 0.045 | C46: 0.043
A47: pulp paper and printing 17T18 | B47: 0.045 | C47: 0.043
A48: refined petroleum and coke 19 | B48: 0.045 | C48: 0.043
A49: chemicals 20 | B49: 0.045 | C49: 0.043
A50: rubber and plastic products 22 | B50: 0.044 | C50: 0.042
A51: glass and glass products 231 | B51: 0.044 | C51: 0.042
... A64: construction 41T43 | B64: 0.045 | C64: 0.043

Sheet Conversion
A1: Unit: Thousands of jobs | B1: ISIC 01T03 | C1: ISIC 05 | D1: ISIC 06 | E1: ISIC 07T08 | F1: ISIC 09 | G1: ISIC 10T12 | H1: ISIC 13T15 | I1: ISIC 16 | J1: ISIC 17T18 | K1: ISIC 19 | L1: ISIC 20 | M1: ISIC 21 | N1: ISIC 22 | O1: ISIC 231 | P1: ISIC 239 | Q1: ISIC 241 | R1: ISIC 242 | S1: ISIC 25 | T1: ISIC 26 | U1: ISIC 27 | V1: ISIC 28 | W1: ISIC 29 | X1: ISIC 30 | Y1: ISIC 31T33 | Z1: ISIC 351 | AA1: ISIC 352T353 | AB1: ISIC 36T39 | AC1: ISIC 41T43 | AD1: ISIC 45T47 | AE1: ISIC 49T53 | AF1: ISIC 55T56 | AG1: ISIC 58T60 | AH1: ISIC 61 | AI1: ISIC 62T63 | AJ1: ISIC 64T66 | AK1: ISIC 68 | AL1: ISIC 69T82 | AM1: ISIC 84 | AN1: ISIC 85 | AO1: ISIC 86T88 | AP1: ISIC 90T96 | AQ1: ISIC 97T98
A2: IND: Indonesia | B2: ='OECD EMPN'!AF10 -> 39328 | C2: ='OECD EMPN'!AF13 -> 1523 | D2: ='OECD EMPN'!AF14 -> 788 | E2: ='OECD EMPN'!AF15 -> 655 | F2: ='OECD EMPN'!AF16 -> 81 | G2: ='OECD EMPN'!AF18 -> 3403 | H2: ='OECD EMPN'!AF19 -> 4895 | I2: ='OECD EMPN'!AF21 -> 793 | J2: ='OECD EMPN'!AF22 -> 752 | K2: ='OECD EMPN'!AF24 -> 80 | L2: ='OECD EMPN'!AF26 -> 546 | M2: ='OECD EMPN'!AF27 -> 232 | N2: ='OECD EMPN'!AF28 -> 1660 | O2: =ROUNDUP('OECD EMPN'!AF29*'Output by industry'!B51, 0) -> 22 | P2: ='OECD EMPN'!AF29-Conversion!O2 -> 457 | Q2: ='OECD EMPN'!AF30 -> 1629 | R2: ='OECD EMPN'!AF31 -> 398 | S2: ='OECD EMPN'!AF32 -> 1231 | T2: ='OECD EMPN'!AF34 -> 356 | U2: ='OECD EMPN'!AF35 -> 304 | V2: ='OECD EMPN'!AF36 -> 116 | W2: ='OECD EMPN'!AF38 -> 516 | X2: ='OECD EMPN'!AF39 -> 303 | Y2: ='OECD EMPN'!AF40 -> 702 | Z2: =ROUNDUP('OECD EMPN'!AF42*'Output by industry'!B42, 0) -> 19 | AA2: ='OECD EMPN'!AF42-Conversion!Z2 -> 396 | AB2: ='OECD EMPN'!AF43 -> 144 | AC2: ='OECD EMPN'!AF44 -> 7554 | AD2: ='OECD EMPN'!AF47 -> 24551 | AE2: ='OECD EMPN'!AF48 -> 4300 | AF2: ='OECD EMPN'!AF54 -> 5648 | AG2: ='OECD EMPN'!AF56 -> 189 | AH2: ='OECD EMPN'!AF57 -> 511 | AI2: ='OECD EMPN'!AF58 -> 124 | AJ2: ='OECD EMPN'!AF59 -> 1655 | AK2: ='OECD EMPN'!AF60 -> 201 | AL2: ='OECD EMPN'!AF61 -> 779 | AM2: ='OECD EMPN'!AF66 -> 6005 | AN2: ='OECD EMPN'!AF67 -> 6422 | AO2: ='OECD EMPN'!AF68 -> 1753 | AP2: ='OECD EMPN'!AF70 -> 2836 | AQ2: ='OECD EMPN'!AF73 -> 1424
A5: Thousands of Jobs | B5: 1000

Sheet BEbIC
A1: Unit: jobs | B1: ISIC 01T03 | C1: ISIC 05 | D1: ISIC 06 | E1: ISIC 07T08 | F1: ISIC 09 | G1: ISIC 10T12 | H1: ISIC 13T15 | I1: ISIC 16 | J1: ISIC 17T18 | K1: ISIC 19 | L1: ISIC 20 | M1: ISIC 21 | N1: ISIC 22 | O1: ISIC 231 | P1: ISIC 239 | Q1: ISIC 241 | R1: ISIC 242 | S1: ISIC 25 | T1: ISIC 26 | U1: ISIC 27 | V1: ISIC 28 | W1: ISIC 29 | X1: ISIC 30 | Y1: ISIC 31T33 | Z1: ISIC 351 | AA1: ISIC 352T353 | AB1: ISIC 36T39 | AC1: ISIC 41T43 | AD1: ISIC 45T47 | AE1: ISIC 49T53 | AF1: ISIC 55T56 | AG1: ISIC 58T60 | AH1: ISIC 61 | AI1: ISIC 62T63 | AJ1: ISIC 64T66 | AK1: ISIC 68 | AL1: ISIC 69T82 | AM1: ISIC 84 | AN1: ISIC 85 | AO1: ISIC 86T88 | AP1: ISIC 90T96 | AQ1: ISIC 97T98
A2: IND: Indonesia | B2: =Conversion!B2*Conversion!$B$5 -> 39328000 | C2: =Conversion!C2*Conversion!$B$5 -> 1523000 | D2: =Conversion!D2*Conversion!$B$5 -> 788000 | E2: =Conversion!E2*Conversion!$B$5 -> 655000 | F2: =Conversion!F2*Conversion!$B$5 -> 81000 | G2: =Conversion!G2*Conversion!$B$5 -> 3403000 | H2: =Conversion!H2*Conversion!$B$5 -> 4895000 | I2: =Conversion!I2*Conversion!$B$5 -> 793000 | ... AQ2: =Conversion!AQ2*Conversion!$B$5 -> 1424000
