Workbook

Sheet About
A1: BGDPbES BAU Guaranteed Dispatch Percentage by Electricity Source
A3: Source: | B3: EIA
B4: 2022
B5: Short Term Energy Outlook
B6: https://www.eia.gov/outlooks/steo/
B7: Table 7d
B9: BPS
B10: https://esdm.go.id/assets/media/content/content-handbook-of-energy-and-economic-statistics-of-indonesia-2023.pdf
A12: Notes:
A13: This variable is used to specify the percentage of potential electricity output from each
A14: source that is guaranteed (e.g. dispatched before any least-cost dispatching
A15: begins) in the BAU case.
A17: Some dispatch from peaking plants (natural gas peakers and petroleum-fired plants)
A18: is guaranteed in the model, to provide for grid stability and regulation needs.
A19: The model will disatch these plants in the guaranteed dispatch section by the larger
A20: of the default amount or the amount specified here by the user.
A22: For the US, we use EIA's STEO to align historical 2020 generation.

Sheet STEO 7d
A1: 7d. U.S. Regional Electricity Generation, Electric Power Sector
A2: https://www.eia.gov/outlooks/steo/data/browser/#/?v=22&f=A&s=0&maptype=0&ctype=linechart
A3: Wed Jun 01 2022 10:35:45 GMT-0700 (Pacific Daylight Time)
A4: Source: U.S. Energy Information Administration
A5: remove | C5: map | D5: linechart | E5: units | F5: source key | G5: 2017 | H5: 2018 | I5: 2019 | J5: 2020 | K5: 2021 | L5: 2022 | M5: 2023 | N5: 2024 | O5: 2025 | P5: 2026 | Q5: 2027 | R5: 2028 | S5: 2029 | T5: 2030 | U5: 2031 | V5: 2032 | W5: 2033 | X5: 2034 | Y5: 2035 | Z5: 2036 | AA5: 2037 | AB5: 2038 | AC5: 2039 | AD5: 2040 | AE5: 2041 | AF5: 2042 | AG5: 2043 | AH5: 2044 | AI5: 2045 | AJ5: 2046 | AK5: 2047 | AL5: 2048 | AM5: 2049 | AN5: 2050
A6: 7d. U.S. Regional Electricity Generation, Electric Power Sector | B6: 7d. U.S. Regional Electricity Generation, Electric Power Sector | C6: 0 | D6: 0
A7: United States | B7: United States | C7: 0 | D7: 0
A8: Natural gas | B8: Electric power sector generation by natural gas: U.S. total | C8: 1 | D8: 1 | E8: billion kilowatthours | F8: NGEPGEN_US | G8: 1196.75 | H8: 1365.82 | I8: 1477.14 | J8: 1519.68 | K8: 1473.64 | L8: 1487.04 | M8: 1460.88
A9: Coal | B9: Electric power sector generation by coal: Indonesia | C9: 1 | D9: 1 | E9: billion kilowatthours | F9: CLEPGEN_US | G9: 147.964 | H9: 160.013 | I9: 174.493 | J9: 180.869 | K9: 189.684 | L9: 205.308 | M9: 216.777 | N9: =_xlfn.FORECAST.LINEAR(N5,$G$9:$M$9,$G$5:$M$5) -> 226.76114 | O9: =_xlfn.FORECAST.LINEAR(O5,$G$9:$M$9,$G$5:$M$5) -> 237.91186 | P9: =_xlfn.FORECAST.LINEAR(P5,$G$9:$M$9,$G$5:$M$5) -> 249.06257 | Q9: =_xlfn.FORECAST.LINEAR(Q5,$G$9:$M$9,$G$5:$M$5) -> 260.21329 | R9: =_xlfn.FORECAST.LINEAR(R5,$G$9:$M$9,$G$5:$M$5) -> 271.364 | S9: =_xlfn.FORECAST.LINEAR(S5,$G$9:$M$9,$G$5:$M$5) -> 282.51471 | T9: =_xlfn.FORECAST.LINEAR(T5,$G$9:$M$9,$G$5:$M$5) -> 293.66543 | U9: =_xlfn.FORECAST.LINEAR(U5,$G$9:$M$9,$G$5:$M$5) -> 304.81614 | ... AN9: =_xlfn.FORECAST.LINEAR(AN5,$G$9:$M$9,$G$5:$M$5) -> 516.67971
A10: Nuclear | B10: Electric power sector generation by nuclear: U.S. total | C10: 1 | D10: 1 | E10: billion kilowatthours | F10: NUEPGEN_US | G10: 804.95 | H10: 807.08 | I10: 809.41 | J10: 789.88 | K10: 778.15 | L10: 778.23 | M10: 788.98
A11: Renewable energy sources | B11: Electric power sector generation by renewables: U.S. total | C11: 1 | D11: 1 | E11: billion kilowatthours | F11: RTEPGEN_US | G11: 653.16 | H11: 673.74 | I11: 696.66 | J11: 752 | K11: 795.16 | L11: 890.44 | M11: 949.38
A12: Conventional hydropower | B12: Electric power sector generation by conventional hydropower: U.S. total | C12: 1 | D12: 1 | E12: billion kilowatthours | F12: HVEPGEN_US | G12: 298.71 | H12: 291.15 | I12: 286.65 | J12: 284.06 | K12: 259.02 | L12: 270.75 | M12: 273.46
A13: Wind | B13: Electric power sector generation by wind: U.S. total | C13: 1 | D13: 1 | E13: billion kilowatthours | F13: WNEPGEN_US | G13: 254.07 | H13: 272.4 | I13: 295.6 | J13: 337.15 | K13: 378.63 | L13: 431.47 | M13: 450.02
A14: Solar | B14: Electric power sector generation by solar: U.S. total | C14: 1 | D14: 1 | E14: billion kilowatthours | F14: SOEPGEN_US | G14: 52.72 | H14: 63.25 | I14: 71.26 | J14: 88.51 | K14: 113.87 | L14: 146.02 | M14: 184.09
A15: Biomass | B15: Electric power sector generation by biomass: U.S. total | C15: 1 | D15: 1 | E15: billion kilowatthours | F15: BMEPGEN_US | G15: 31.73 | H15: 31.01 | I15: 28.11 | J15: 26.84 | K15: 27.91 | L15: 26.25 | M15: 26.13
A16: Geothermal | B16: Electric power sector generation by geothermal: U.S. total | C16: 1 | D16: 1 | E16: billion kilowatthours | F16: GEEPGEN_US | G16: 15.93 | H16: 15.93 | I16: 15.03 | J16: 15.44 | K16: 15.74 | L16: 15.94 | M16: 15.69
A17: Pumped storage hydropower | B17: Electric power sector generation by pumped storage hydropower: U.S. total | C17: 1 | D17: 1 | E17: billion kilowatthours | F17: HPEPGEN_US | G17: -6.49 | H17: -5.9 | I17: -5.26 | J17: -5.32 | K17: -5.11 | L17: -4.97 | M17: -4.85
A18: Petroleum | B18: Electric power sector generation by petroleum: U.S. total | C18: 1 | D18: 1 | E18: billion kilowatthours | F18: PAEPGEN_US | G18: 20.04 | H18: 23.93 | I18: 17.22 | J18: 16.33 | K18: 17.8 | L18: 18.18 | M18: 16.89
A19: Other gases | B19: Electric power sector generation by other gases: U.S. total | C19: 1 | D19: 1 | E19: billion kilowatthours | F19: OGEPGEN_US | G19: 4.13 | H19: 4.09 | I19: 4.04 | J19: 3.17 | K19: 3.17 | L19: 3.31 | M19: 3.22
A20: Other nonrenewable fuels | B20: Electric power sector generation by other nonrenewable fuels: U.S. total | C20: 1 | D20: 1 | E20: billion kilowatthours | F20: OBEPGEN_US | G20: 6.99 | H20: 7.24 | I20: 7.69 | J20: 7.59 | K20: 7.18 | L20: 6.95 | M20: 6.73
A21: Total net generation | B21: Total Electric Power Sector Net Generation: U.S. Total | C21: 1 | D21: 1 | E21: billion kilowatthours | F21: TOEPGEN_US | G21: 3877.37 | H21: 4018.17 | I21: 3965.63 | J21: 3851.03 | K21: 3962.79 | L21: 4041.84 | M21: 4044.16
A22: New England (ISO-NE) | B22: New England (ISO-NE) | C22: 0 | D22: 0
A23: Natural gas | B23: Electric power sector generation by natural gas: New England (ISO-NE) | C23: 1 | D23: 1 | E23: billion kilowatthours | F23: NGEPGEN_NE | G23: 48.8 | H23: 49.02 | I23: 46.65 | J23: 49.1 | K23: 51.48 | L23: 55.33 | M23: 55.27
A24: Coal | B24: Electric power sector generation by coal: New England (ISO-NE) | C24: 1 | D24: 1 | E24: billion kilowatthours | F24: CLEPGEN_NE | G24: 1.68 | H24: 1.05 | I24: 0.46 | J24: 0.16 | K24: 0.58 | L24: 0.84 | M24: 0.84
A25: Nuclear | B25: Electric power sector generation by nuclear: New England (ISO-NE) | C25: 1 | D25: 1 | E25: billion kilowatthours | F25: NUEPGEN_NE | G25: 31.54 | H25: 31.38 | I25: 29.82 | J25: 25.58 | K25: 27.07 | L25: 27.85 | M25: 26.24
A26: Conventional hydropower | B26: Electric power sector generation by conventional hydropower: New England (ISO-NE) | C26: 1 | D26: 1 | E26: billion kilowatthours | F26: HVEPGEN_NE | G26: 7.09 | H26: 7.47 | I26: 7.6 | J26: 6.61 | K26: 6.28 | L26: 6.87 | M26: 7.18
A27: Nonhydro renewables | B27: Electric power sector generation by non-hydropower renewables | C27: 1 | D27: 1 | E27: billion kilowatthours | F27: RNEPGEN_NE | G27: 10.13 | H27: 10.12 | I27: 9.77 | J27: 10.15 | K27: 11.25 | L27: 11.86 | M27: 12.12
A28: Other energy sources | B28: Electric power sector generation by other energy sources: New England (ISO-NE) | C28: 1 | D28: 1 | E28: billion kilowatthours | F28: XXEPGEN_NE | G28: 1.85 | H28: 2.26 | I28: 1.41 | J28: 1.43 | K28: 1.5 | L28: 2.54 | M28: 1.75
A29: Total generation | B29: Total electric power sector net generation: New England (ISO-NE) | C29: 1 | D29: 1 | E29: billion kilowatthours | F29: TOEPGEN_NE | G29: 101.09 | H29: 101.29 | I29: 95.71 | J29: 93.02 | K29: 98.16 | L29: 105.3 | M29: 103.4
A30: Net energy for load | B30: Net energy for load: New England (ISO-NE) | C30: 1 | D30: 1 | E30: billion kilowatthours | F30: ELLOAD_NE | G30: 117.19 | H30: 119.52 | I30: 115.3 | J30: 113.08 | K30: 116.36 | L30: 118.31 | M30: 119.9
A31: New York (NYISO) | B31: New York (NYISO) | C31: 0 | D31: 0
A32: Natural gas | B32: Electric power sector generation by natural gas: New York (NYISO) | C32: 1 | D32: 1 | E32: billion kilowatthours | F32: NGEPGEN_NY | G32: 51.74 | H32: 55.55 | I32: 52.36 | J32: 57.13 | K32: 61.87 | L32: 58.19 | M32: 58.31
A33: Coal | B33: Electric power sector generation by coal: New York (NYISO) | C33: 1 | D33: 1 | E33: billion kilowatthours | F33: CLEPGEN_NY | G33: 0.56 | H33: 0.68 | I33: 0.42 | J33: 0.14 | K33: 0 | L33: 0 | M33: 0
A34: Nuclear | B34: Electric power sector generation by nuclear: New York (NYISO) | C34: 1 | D34: 1 | E34: billion kilowatthours | F34: NUEPGEN_NY | G34: 42.17 | H34: 42.92 | I34: 44.87 | J34: 38.43 | K34: 31.14 | L34: 26.68 | M34: 27.1
A35: Conventional hydropower | B35: Electric power sector generation by conventional hydropower: New York (NYISO) | C35: 1 | D35: 1 | E35: billion kilowatthours | F35: HVEPGEN_NY | G35: 30.06 | H35: 29.56 | I35: 30.55 | J35: 29.48 | K35: 27.9 | L35: 28.3 | M35: 29.67
A36: Nonhydro renewables | B36: Electric power sector generation by non-hydropower renewables | C36: 1 | D36: 1 | E36: billion kilowatthours | F36: RNEPGEN_NY | G36: 6.15 | H36: 6.03 | I36: 6.52 | J36: 6.93 | K36: 7.13 | L36: 8.07 | M36: 10.27
A37: Other energy sources | B37: Electric power sector generation by other energy sources: New York (NYISO) | C37: 1 | D37: 1 | E37: billion kilowatthours | F37: XXEPGEN_NY | G37: 0.84 | H37: 1.87 | I37: 0.9 | J37: 0.75 | K37: 1.27 | L37: 1.84 | M37: 1.19
A38: Total generation | B38: Total electric power sector net generation: New York (NYISO) | C38: 1 | D38: 1 | E38: billion kilowatthours | F38: TOEPGEN_NY | G38: 131.53 | H38: 136.61 | I38: 135.62 | J38: 132.87 | K38: 129.31 | L38: 123.08 | M38: 126.54
A39: Net energy for load | B39: Net energy for load: New York (NYISO) | C39: 1 | D39: 1 | E39: billion kilowatthours | F39: ELLOAD_NY | G39: 151.22 | H39: 156 | I39: 150.68 | J39: 145.31 | K39: 149.03 | L39: 149.69 | M39: 149.18
A40: Mid-Atlantic (PJM) | B40: Mid-Atlantic (PJM) | C40: 0 | D40: 0
...

Sheet Capacity
A1: Time (Year) | B1: 2020 | C1: 2021 | D1: 2022 | E1: 2023 | F1: 2024 | G1: 2025 | H1: 2026 | I1: 2027 | J1: 2028 | K1: 2029 | L1: 2030 | M1: 2031 | N1: 2032 | O1: 2033 | P1: 2034 | Q1: 2035 | R1: 2036 | S1: 2037 | T1: 2038 | U1: 2039 | V1: 2040 | W1: 2041 | X1: 2042 | Y1: 2043 | Z1: 2044 | AA1: 2045 | AB1: 2046 | AC1: 2047 | AD1: 2048 | AE1: 2049 | AF1: 2050
A2: Output Electricity Generation Capacity[hard coal es] : BAU-Dispatch | B2: 92.826 | C2: 119.915 | D2: 146.741 | E2: 173.83 | F2: 201.182 | G2: 225.904 | H2: 250.889 | I2: 275.874 | J2: 300.333 | K2: 324.529 | L2: 348.462 | M2: 348.462 | N2: 348.462 | O2: 348.462 | P2: 348.462 | Q2: 348.462 | R2: 348.462 | S2: 348.462 | T2: 348.462 | U2: 348.462 | V2: 348.462 | W2: 348.462 | X2: 348.462 | Y2: 348.462 | Z2: 348.462 | AA2: 348.462 | AB2: 348.462 | AC2: 348.462 | AD2: 348.462 | AE2: 348.462 | AF2: 348.462
A3: Output Electricity Generation Capacity[natural gas nonpeaker es] : BAU-Dispatch | B3: 17.04 | C3: 23.748 | D3: 30.924 | E3: 38.256 | F3: 45.276 | G3: 51.516 | H3: 57.444 | I3: 63.372 | J3: 69.612 | K3: 75.852 | L3: 82.092 | M3: 82.092 | N3: 82.092 | O3: 82.092 | P3: 82.092 | Q3: 82.092 | R3: 82.092 | S3: 82.092 | T3: 82.092 | U3: 82.092 | V3: 82.092 | W3: 82.092 | X3: 82.092 | Y3: 82.092 | Z3: 82.092 | AA3: 82.092 | AB3: 82.092 | AC3: 82.092 | AD3: 82.092 | AE3: 82.092 | AF3: 82.092
A4: Output Electricity Generation Capacity[nuclear es] : BAU-Dispatch | B4: 0 | C4: 0 | D4: 0 | E4: 0 | F4: 0 | G4: 0 | H4: 0 | I4: 0 | J4: 0 | K4: 0 | L4: 0 | M4: 0 | N4: 0 | O4: 0 | P4: 0 | Q4: 0 | R4: 0 | S4: 0 | T4: 0 | U4: 0 | V4: 0 | W4: 0 | X4: 0 | Y4: 0 | Z4: 0 | AA4: 0 | AB4: 0 | AC4: 0 | AD4: 0 | AE4: 0 | AF4: 0
A5: Output Electricity Generation Capacity[hydro es] : BAU-Dispatch | B5: 5.575 | C5: 6.119 | D5: 6.326 | E5: 6.735 | F5: 7.111 | G5: 9.778 | H5: 10.148 | I5: 10.647 | J5: 12.26 | K5: 14.051 | L5: 16.007 | M5: 16.007 | N5: 16.007 | O5: 16.007 | P5: 16.007 | Q5: 16.007 | R5: 16.007 | S5: 16.007 | T5: 16.007 | U5: 16.007 | V5: 16.007 | W5: 16.007 | X5: 16.007 | Y5: 16.007 | Z5: 16.007 | AA5: 16.007 | AB5: 16.007 | AC5: 16.007 | AD5: 16.007 | AE5: 16.007 | AF5: 16.007
A6: Output Electricity Generation Capacity[onshore wind es] : BAU-Dispatch | B6: 0.154 | C6: 0.154 | D6: 0.154 | E6: 0.184 | F6: 0.519 | G6: 0.674 | H6: 0.744 | I6: 0.814 | J6: 0.884 | K6: 0.954 | L6: 1.024 | M6: 1.024 | N6: 1.024 | O6: 1.024 | P6: 1.024 | Q6: 1.024 | R6: 1.024 | S6: 1.024 | T6: 1.024 | U6: 1.024 | V6: 1.024 | W6: 1.024 | X6: 1.024 | Y6: 1.024 | Z6: 1.024 | AA6: 1.024 | AB6: 1.024 | AC6: 1.024 | AD6: 1.024 | AE6: 1.024 | AF6: 1.024
A7: Output Electricity Generation Capacity[solar PV es] : BAU-Dispatch | B7: 0.165 | C7: 0.225 | D7: 0.511 | E7: 1.819 | F7: 2.443 | G7: 4.073 | H7: 4.199 | I7: 4.347 | J7: 4.511 | K7: 4.683 | L7: 4.839 | M7: 4.839 | N7: 4.839 | O7: 4.839 | P7: 4.839 | Q7: 4.839 | R7: 4.839 | S7: 4.839 | T7: 4.839 | U7: 4.839 | V7: 4.839 | W7: 4.839 | X7: 4.839 | Y7: 4.839 | Z7: 4.839 | AA7: 4.839 | AB7: 4.839 | AC7: 4.839 | AD7: 4.839 | AE7: 4.839 | AF7: 4.839
A8: Output Electricity Generation Capacity[solar thermal es] : BAU-Dispatch | B8: 0 | C8: 0 | D8: 0 | E8: 0 | F8: 0 | G8: 0 | H8: 0 | I8: 0 | J8: 0 | K8: 0 | L8: 0 | M8: 0 | N8: 0 | O8: 0 | P8: 0 | Q8: 0 | R8: 0 | S8: 0 | T8: 0 | U8: 0 | V8: 0 | W8: 0 | X8: 0 | Y8: 0 | Z8: 0 | AA8: 0 | AB8: 0 | AC8: 0 | AD8: 0 | AE8: 0 | AF8: 0
A9: Output Electricity Generation Capacity[biomass es] : BAU-Dispatch | B9: 0.147 | C9: 0.147 | D9: 0.183 | E9: 0.255 | F9: 0.435 | G9: 0.651 | H9: 0.669 | I9: 0.687 | J9: 0.705 | K9: 0.723 | L9: 0.741 | M9: 0.741 | N9: 0.741 | O9: 0.741 | P9: 0.741 | Q9: 0.741 | R9: 0.741 | S9: 0.741 | T9: 0.741 | U9: 0.741 | V9: 0.741 | W9: 0.741 | X9: 0.741 | Y9: 0.741 | Z9: 0.741 | AA9: 0.741 | AB9: 0.741 | AC9: 0.741 | AD9: 0.741 | AE9: 0.741 | AF9: 0.741
A10: Output Electricity Generation Capacity[geothermal es] : BAU-Dispatch | B10: 2.261 | C10: 2.391 | D10: 2.495 | E10: 2.677 | F10: 2.807 | G10: 3.665 | H10: 3.951 | I10: 4.068 | J10: 4.51 | K10: 4.744 | L10: 5.55 | M10: 5.55 | N10: 5.55 | O10: 5.55 | P10: 5.55 | Q10: 5.55 | R10: 5.55 | S10: 5.55 | T10: 5.55 | U10: 5.55 | V10: 5.55 | W10: 5.55 | X10: 5.55 | Y10: 5.55 | Z10: 5.55 | AA10: 5.55 | AB10: 5.55 | AC10: 5.55 | AD10: 5.55 | AE10: 5.55 | AF10: 5.55
A11: Output Electricity Generation Capacity[petroleum es] : BAU-Dispatch | B11: 4.78 | C11: 4.78 | D11: 4.78 | E11: 4.78 | F11: 4.78 | G11: 4.78 | H11: 4.78 | I11: 4.78 | J11: 4.78 | K11: 4.78 | L11: 4.78 | M11: 4.78 | N11: 4.78 | O11: 4.78 | P11: 4.78 | Q11: 4.78 | R11: 4.78 | S11: 4.78 | T11: 4.78 | U11: 4.78 | V11: 4.78 | W11: 4.78 | X11: 4.78 | Y11: 4.78 | Z11: 4.78 | AA11: 4.78 | AB11: 4.78 | AC11: 4.78 | AD11: 4.78 | AE11: 4.78 | AF11: 4.78
A12: Output Electricity Generation Capacity[natural gas peaker es] : BAU-Dispatch | B12: 2.842 | C12: 2.842 | D12: 2.842 | E12: 2.842 | F12: 2.842 | G12: 2.842 | H12: 2.842 | I12: 2.842 | J12: 2.842 | K12: 2.842 | L12: 2.842 | M12: 2.842 | N12: 2.842 | O12: 2.842 | P12: 2.842 | Q12: 2.842 | R12: 2.842 | S12: 2.842 | T12: 2.842 | U12: 2.842 | V12: 2.842 | W12: 2.842 | X12: 2.842 | Y12: 2.842 | Z12: 2.842 | AA12: 2.842 | AB12: 2.842 | AC12: 2.842 | AD12: 2.842 | AE12: 2.842 | AF12: 2.842
... A17: Output Electricity Generation Capacity[municipal solid waste es] : BAU-Dispatch | B17: 0 | C17: 0 | D17: 0 | E17: 0 | F17: 0 | G17: 0 | H17: 0 | I17: 0 | J17: 0 | K17: 0 | L17: 0 | M17: 0 | N17: 0 | O17: 0 | P17: 0 | Q17: 0 | R17: 0 | S17: 0 | T17: 0 | U17: 0 | V17: 0 | W17: 0 | X17: 0 | Y17: 0 | Z17: 0 | AA17: 0 | AB17: 0 | AC17: 0 | AD17: 0 | AE17: 0 | AF17: 0

Sheet Capacity Factors
A1: Time (Time) | B1: 2020 | C1: 2021 | D1: 2022 | E1: 2023 | F1: 2024 | G1: 2025 | H1: 2026 | I1: 2027 | J1: 2028 | K1: 2029 | L1: 2030 | M1: 2031 | N1: 2032 | O1: 2033 | P1: 2034 | Q1: 2035 | R1: 2036 | S1: 2037 | T1: 2038 | U1: 2039 | V1: 2040 | W1: 2041 | X1: 2042 | Y1: 2043 | Z1: 2044 | AA1: 2045 | AB1: 2046 | AC1: 2047 | AD1: 2048 | AE1: 2049 | AF1: 2050
A2: Bid Capacity Factor x Hours per Year[hard coal es,preexisting retiring] : MostRecentRun | B2: 3854.4 | C2: 4084.67 | D2: 3854.4 | E2: 3854.4 | F2: 3854.4 | G2: 3854.4 | H2: 3854.4 | I2: 3854.4 | J2: 3854.4 | K2: 3854.4 | L2: 3854.4 | M2: 3854.4 | N2: 3854.4 | O2: 3854.4 | P2: 3854.4 | Q2: 3854.4 | R2: 3854.4 | S2: 3854.4 | T2: 3854.4 | U2: 3854.4 | V2: 3854.4 | W2: 3854.4 | X2: 3854.4 | Y2: 3854.4 | Z2: 3854.4 | AA2: 3854.4 | AB2: 3854.4 | AC2: 3854.4 | AD2: 3854.4 | AE2: 3854.4 | AF2: 3854.4
A3: Bid Capacity Factor x Hours per Year[hard coal es,preexisting nonretiring] : MostRecentRun | B3: 0 | C3: 0 | D3: 0 | E3: 0 | F3: 0 | G3: 0 | H3: 0 | I3: 0 | J3: 0 | K3: 0 | L3: 0 | M3: 0 | N3: 0 | O3: 0 | P3: 0 | Q3: 0 | R3: 0 | S3: 0 | T3: 0 | U3: 0 | V3: 0 | W3: 0 | X3: 0 | Y3: 0 | Z3: 0 | AA3: 0 | AB3: 0 | AC3: 0 | AD3: 0 | AE3: 0 | AF3: 0
A4: Bid Capacity Factor x Hours per Year[hard coal es,newly built] : MostRecentRun | B4: 4239.84 | C4: 4493.14 | D4: 4239.84 | E4: 4239.84 | F4: 4239.84 | G4: 4239.84 | H4: 4239.84 | I4: 4239.84 | J4: 4239.84 | K4: 4239.84 | L4: 4239.84 | M4: 4239.84 | N4: 4239.84 | O4: 4239.84 | P4: 4239.84 | Q4: 4239.84 | R4: 4239.84 | S4: 4239.84 | T4: 4239.84 | U4: 4239.84 | V4: 4239.84 | W4: 4239.84 | X4: 4239.84 | Y4: 4239.84 | Z4: 4239.84 | AA4: 4239.84 | AB4: 4239.84 | AC4: 4239.84 | AD4: 4239.84 | AE4: 4239.84 | AF4: 4239.84
A5: Bid Capacity Factor x Hours per Year[natural gas nonpeaker es,preexisting retiring] : MostRecentRun | B5: 7884 | C5: 7884 | D5: 7884 | E5: 7884 | F5: 7884 | G5: 7884 | H5: 7884 | I5: 7884 | J5: 7884 | K5: 7884 | L5: 7884 | M5: 7884 | N5: 7884 | O5: 7884 | P5: 7884 | Q5: 7884 | R5: 7884 | S5: 7884 | T5: 7884 | U5: 7884 | V5: 7884 | W5: 7884 | X5: 7884 | Y5: 7884 | Z5: 7884 | AA5: 7884 | AB5: 7884 | AC5: 7884 | AD5: 7884 | AE5: 7884 | AF5: 7884
A6: Bid Capacity Factor x Hours per Year[natural gas nonpeaker es,preexisting nonretiring] : MostRecentRun | B6: 7884 | C6: 7884 | D6: 7884 | E6: 7884 | F6: 7884 | G6: 7884 | H6: 7884 | I6: 7884 | J6: 7884 | K6: 7884 | L6: 7884 | M6: 7884 | N6: 7884 | O6: 7884 | P6: 7884 | Q6: 7884 | R6: 7884 | S6: 7884 | T6: 7884 | U6: 7884 | V6: 7884 | W6: 7884 | X6: 7884 | Y6: 7884 | Z6: 7884 | AA6: 7884 | AB6: 7884 | AC6: 7884 | AD6: 7884 | AE6: 7884 | AF6: 7884
A7: Bid Capacity Factor x Hours per Year[natural gas nonpeaker es,newly built] : MostRecentRun | B7: 7884 | C7: 7884 | D7: 7884 | E7: 7884 | F7: 7884 | G7: 7884 | H7: 7884 | I7: 7884 | J7: 7884 | K7: 7884 | L7: 7884 | M7: 7884 | N7: 7884 | O7: 7884 | P7: 7884 | Q7: 7884 | R7: 7884 | S7: 7884 | T7: 7884 | U7: 7884 | V7: 7884 | W7: 7884 | X7: 7884 | Y7: 7884 | Z7: 7884 | AA7: 7884 | AB7: 7884 | AC7: 7884 | AD7: 7884 | AE7: 7884 | AF7: 7884
A8: Bid Capacity Factor x Hours per Year[nuclear es,preexisting retiring] : MostRecentRun | B8: 8094.24 | C8: 8094.24 | D8: 8094.24 | E8: 8094.24 | F8: 8094.24 | G8: 8094.24 | H8: 8094.24 | I8: 8094.24 | J8: 8094.24 | K8: 8094.24 | L8: 8094.24 | M8: 8094.24 | N8: 8094.24 | O8: 8094.24 | P8: 8094.24 | Q8: 8094.24 | R8: 8094.24 | S8: 8094.24 | T8: 8094.24 | U8: 8094.24 | V8: 8094.24 | W8: 8094.24 | X8: 8094.24 | Y8: 8094.24 | Z8: 8094.24 | AA8: 8094.24 | AB8: 8094.24 | AC8: 8094.24 | AD8: 8094.24 | AE8: 8094.24 | AF8: 8094.24
A9: Bid Capacity Factor x Hours per Year[nuclear es,preexisting nonretiring] : MostRecentRun | B9: 0 | C9: 0 | D9: 0 | E9: 0 | F9: 0 | G9: 0 | H9: 0 | I9: 0 | J9: 0 | K9: 0 | L9: 0 | M9: 0 | N9: 0 | O9: 0 | P9: 0 | Q9: 0 | R9: 0 | S9: 0 | T9: 0 | U9: 0 | V9: 0 | W9: 0 | X9: 0 | Y9: 0 | Z9: 0 | AA9: 0 | AB9: 0 | AC9: 0 | AD9: 0 | AE9: 0 | AF9: 0
A10: Bid Capacity Factor x Hours per Year[nuclear es,newly built] : MostRecentRun | B10: 8094.24 | C10: 8094.24 | D10: 8094.24 | E10: 8094.24 | F10: 8094.24 | G10: 8094.24 | H10: 8094.24 | I10: 8094.24 | J10: 8094.24 | K10: 8094.24 | L10: 8094.24 | M10: 8094.24 | N10: 8094.24 | O10: 8094.24 | P10: 8094.24 | Q10: 8094.24 | R10: 8094.24 | S10: 8094.24 | T10: 8094.24 | U10: 8094.24 | V10: 8094.24 | W10: 8094.24 | X10: 8094.24 | Y10: 8094.24 | Z10: 8094.24 | AA10: 8094.24 | AB10: 8094.24 | AC10: 8094.24 | AD10: 8094.24 | AE10: 8094.24 | AF10: 8094.24
A11: Bid Capacity Factor x Hours per Year[hydro es,preexisting retiring] : MostRecentRun | B11: 3565.32 | C11: 3565.32 | D11: 3565.32 | E11: 3565.32 | F11: 3565.32 | G11: 3565.32 | H11: 3565.32 | I11: 3565.32 | J11: 3565.32 | K11: 3565.32 | L11: 3565.32 | M11: 3565.32 | N11: 3565.32 | O11: 3565.32 | P11: 3565.32 | Q11: 3565.32 | R11: 3565.32 | S11: 3565.32 | T11: 3565.32 | U11: 3565.32 | V11: 3565.32 | W11: 3565.32 | X11: 3565.32 | Y11: 3565.32 | Z11: 3565.32 | AA11: 3565.32 | AB11: 3565.32 | AC11: 3565.32 | AD11: 3565.32 | AE11: 3565.32 | AF11: 3565.32
A12: Bid Capacity Factor x Hours per Year[hydro es,preexisting nonretiring] : MostRecentRun | B12: 0 | C12: 0 | D12: 0 | E12: 0 | F12: 0 | G12: 0 | H12: 0 | I12: 0 | J12: 0 | K12: 0 | L12: 0 | M12: 0 | N12: 0 | O12: 0 | P12: 0 | Q12: 0 | R12: 0 | S12: 0 | T12: 0 | U12: 0 | V12: 0 | W12: 0 | X12: 0 | Y12: 0 | Z12: 0 | AA12: 0 | AB12: 0 | AC12: 0 | AD12: 0 | AE12: 0 | AF12: 0
... A49: Bid Capacity Factor x Hours per Year[municipal solid waste es,newly built] : MostRecentRun | B49: 7884 | C49: 7884 | D49: 7884 | E49: 7884 | F49: 7884 | G49: 7884 | H49: 7884 | I49: 7884 | J49: 7884 | K49: 7884 | L49: 7884 | M49: 7884 | N49: 7884 | O49: 7884 | P49: 7884 | Q49: 7884 | R49: 7884 | S49: 7884 | T49: 7884 | U49: 7884 | V49: 7884 | W49: 7884 | X49: 7884 | Y49: 7884 | Z49: 7884 | AA49: 7884 | AB49: 7884 | AC49: 7884 | AD49: 7884 | AE49: 7884 | AF49: 7884

Sheet 2020 Calculations
B1: 2020 | C1: 2021 | D1: 2022 | E1: 2023 | F1: 2024 | G1: 2025 | H1: 2026 | I1: 2027 | J1: 2028 | K1: 2029 | L1: 2030 | M1: 2031 | N1: 2032 | O1: 2033 | P1: 2034 | Q1: 2035 | R1: 2036 | S1: 2037 | T1: 2038 | U1: 2039 | V1: 2040 | W1: 2041 | X1: 2042 | Y1: 2043 | Z1: 2044 | AA1: 2045 | AB1: 2046 | AC1: 2047 | AD1: 2048 | AE1: 2049 | AF1: 2050
A2: coal | B2: ='STEO 7d'!J9/(SUM(Capacity!B2*'Capacity Factors'!B2,Capacity!B35*'Capacity Factors'!B35))*1000*B5 -> 0.46760533 | C2: ='STEO 7d'!K9/(SUM(Capacity!C2*'Capacity Factors'!C2,Capacity!C35*'Capacity Factors'!C35))*1000 -> 0.38725783 | D2: ='STEO 7d'!L9/(SUM(Capacity!D2*'Capacity Factors'!D2,Capacity!D35*'Capacity Factors'!D35))*1000 -> 0.36299247 | E2: ='STEO 7d'!M9/(SUM(Capacity!E2*'Capacity Factors'!E2,Capacity!E35*'Capacity Factors'!E35))*1000 -> 0.32354276 | F2: ='STEO 7d'!N9/(SUM(Capacity!F2*'Capacity Factors'!F2,Capacity!F13*'Capacity Factors'!F35))*1000 -> 0.29232541 | G2: ='STEO 7d'!O9/(SUM(Capacity!G2*'Capacity Factors'!G2,Capacity!G13*'Capacity Factors'!G35))*1000 -> 0.27314692 | H2: ='STEO 7d'!P9/(SUM(Capacity!H2*'Capacity Factors'!H2,Capacity!H13*'Capacity Factors'!H35))*1000 -> 0.25748079 | I2: ='STEO 7d'!Q9/(SUM(Capacity!I2*'Capacity Factors'!I2,Capacity!I13*'Capacity Factors'!I35))*1000 -> 0.24465158 | J2: ='STEO 7d'!R9/(SUM(Capacity!J2*'Capacity Factors'!J2,Capacity!J13*'Capacity Factors'!J35))*1000 -> 0.23436232 | K2: ='STEO 7d'!S9/(SUM(Capacity!K2*'Capacity Factors'!K2,Capacity!K13*'Capacity Factors'!K35))*1000 -> 0.22580521 | L2: ='STEO 7d'!T9/(SUM(Capacity!L2*'Capacity Factors'!L2,Capacity!L13*'Capacity Factors'!L35))*1000 -> 0.21860015 | M2: ='STEO 7d'!U9/(SUM(Capacity!M2*'Capacity Factors'!M2,Capacity!M13*'Capacity Factors'!M35))*1000 -> 0.22690057 | ... AF2: ='STEO 7d'!AN9/(SUM(Capacity!AF2*'Capacity Factors'!AF2,Capacity!AF13*'Capacity Factors'!AF35))*1000 -> 0.38460864
A3: lignite | B3: ='STEO 7d'!J9/(SUM(Capacity!B2*'Capacity Factors'!B2,Capacity!B35*'Capacity Factors'!B35))*1000*B6 -> 0.40441542 | C3: =C2 -> 0.38725783 | D3: =D2 -> 0.36299247 | E3: =E2 -> 0.32354276 | F3: =F2 -> 0.29232541 | G3: =G2 -> 0.27314692 | H3: =H2 -> 0.25748079 | I3: =I2 -> 0.24465158 | J3: =J2 -> 0.23436232 | ... AF3: =AF2 -> 0.38460864
A5: Calibration multiplier (used to ensure 2020 output in the model aligns with STEO) | B5: 0.925
A6: Calibration multiplier (used to ensure 2020 output in the model aligns with STEO) | B6: 0.8

Sheet BGDPbES
A1: BAU Guaranteed Dispatch (dimensionless) | B1: 2015 | C1: 2016 | D1: 2017 | E1: 2018 | F1: 2019 | G1: 2020 | H1: 2021 | I1: 2022 | J1: 2023 | K1: 2024 | L1: 2025 | M1: 2026 | N1: 2027 | O1: 2028 | P1: 2029 | Q1: 2030 | R1: 2031 | S1: 2032 | T1: 2033 | U1: 2034 | V1: 2035 | W1: 2036 | X1: 2037 | Y1: 2038 | Z1: 2039 | AA1: 2040 | AB1: 2041 | AC1: 2042 | AD1: 2043 | AE1: 2044 | AF1: 2045 | AG1: 2046 | AH1: 2047 | AI1: 2048 | AJ1: 2049 | AK1: 2050 | AL1: 2051 | AM1: 2052 | AN1: 2053 | AO1: 2054 | AP1: 2055 | AQ1: 2056 | AR1: 2057 | AS1: 2058 | AT1: 2059 | AU1: 2060 | AV1: 2061 | AW1: 2062 | AX1: 2063 | AY1: 2064 | AZ1: 2065 | BA1: 2066 | BB1: 2067 | BC1: 2068 | BD1: 2069 | BE1: 2070
A2: hard coal | B2: 0 | C2: 0 | D2: 0 | E2: 0 | F2: 0 | G2: 0 | H2: 0 | I2: 0 | J2: 0 | K2: 0 | L2: 0 | M2: 0 | N2: 0 | O2: 0 | P2: 0 | Q2: 0 | R2: 0 | S2: 0 | T2: 0 | U2: 0 | V2: 0 | W2: 0 | X2: 0 | Y2: 0 | Z2: 0 | AA2: 0 | AB2: 0 | AC2: 0 | AD2: 0 | AE2: 0 | AF2: 0 | AG2: 0 | AH2: 0 | AI2: 0 | AJ2: 0 | AK2: 0 | AL2: 0 | AM2: 0 | AN2: 0 | AO2: 0 | AP2: 0 | AQ2: 0 | AR2: 0 | AS2: 0 | AT2: 0 | AU2: 0 | AV2: 0 | AW2: 0 | AX2: 0 | AY2: 0 | AZ2: 0 | BA2: 0 | BB2: 0 | BC2: 0 | BD2: 0 | BE2: 0
A3: natural gas steam turbine | B3: 0 | C3: 0 | D3: 0 | E3: 0 | F3: 0 | G3: 0 | H3: 0 | I3: 0 | J3: 0 | K3: 0 | L3: 0 | M3: 0 | N3: 0 | O3: 0 | P3: 0 | Q3: 0 | R3: 0 | S3: 0 | T3: 0 | U3: 0 | V3: 0 | W3: 0 | X3: 0 | Y3: 0 | Z3: 0 | AA3: 0 | AB3: 0 | AC3: 0 | AD3: 0 | AE3: 0 | AF3: 0 | AG3: 0 | AH3: 0 | AI3: 0 | AJ3: 0 | AK3: 0 | AL3: 0 | AM3: 0 | AN3: 0 | AO3: 0 | AP3: 0 | AQ3: 0 | AR3: 0 | AS3: 0 | AT3: 0 | AU3: 0 | AV3: 0 | AW3: 0 | AX3: 0 | AY3: 0 | AZ3: 0 | BA3: 0 | BB3: 0 | BC3: 0 | BD3: 0 | BE3: 0
A4: natural gas combined cycle | B4: 0 | C4: 0 | D4: 0 | E4: 0 | F4: 0 | G4: 0 | H4: 0 | I4: 0 | J4: 0 | K4: 0 | L4: 0 | M4: 0 | N4: 0 | O4: 0 | P4: 0 | Q4: 0 | R4: 0 | S4: 0 | T4: 0 | U4: 0 | V4: 0 | W4: 0 | X4: 0 | Y4: 0 | Z4: 0 | AA4: 0 | AB4: 0 | AC4: 0 | AD4: 0 | AE4: 0 | AF4: 0 | AG4: 0 | AH4: 0 | AI4: 0 | AJ4: 0 | AK4: 0 | AL4: 0 | AM4: 0 | AN4: 0 | AO4: 0 | AP4: 0 | AQ4: 0 | AR4: 0 | AS4: 0 | AT4: 0 | AU4: 0 | AV4: 0 | AW4: 0 | AX4: 0 | AY4: 0 | AZ4: 0 | BA4: 0 | BB4: 0 | BC4: 0 | BD4: 0 | BE4: 0
A5: nuclear | B5: 0 | C5: 0 | D5: 0 | E5: 0 | F5: 0 | G5: 0 | H5: 0 | I5: 0 | J5: 0 | K5: 0 | L5: 0 | M5: 0 | N5: 0 | O5: 0 | P5: 0 | Q5: 0 | R5: 0 | S5: 0 | T5: 0 | U5: 0 | V5: 0 | W5: 0 | X5: 0 | Y5: 0 | Z5: 0 | AA5: 0 | AB5: 0 | AC5: 0 | AD5: 0 | AE5: 0 | AF5: 0 | AG5: 0 | AH5: 0 | AI5: 0 | AJ5: 0 | AK5: 0 | AL5: 0 | AM5: 0 | AN5: 0 | AO5: 0 | AP5: 0 | AQ5: 0 | AR5: 0 | AS5: 0 | AT5: 0 | AU5: 0 | AV5: 0 | AW5: 0 | AX5: 0 | AY5: 0 | AZ5: 0 | BA5: 0 | BB5: 0 | BC5: 0 | BD5: 0 | BE5: 0
A6: hydro | B6: 0 | C6: 0 | D6: 0 | E6: 0 | F6: 0 | G6: 0 | H6: 0 | I6: 0 | J6: 0 | K6: 0 | L6: 0 | M6: 0 | N6: 0 | O6: 0 | P6: 0 | Q6: 0 | R6: 0 | S6: 0 | T6: 0 | U6: 0 | V6: 0 | W6: 0 | X6: 0 | Y6: 0 | Z6: 0 | AA6: 0 | AB6: 0 | AC6: 0 | AD6: 0 | AE6: 0 | AF6: 0 | AG6: 0 | AH6: 0 | AI6: 0 | AJ6: 0 | AK6: 0 | AL6: 0 | AM6: 0 | AN6: 0 | AO6: 0 | AP6: 0 | AQ6: 0 | AR6: 0 | AS6: 0 | AT6: 0 | AU6: 0 | AV6: 0 | AW6: 0 | AX6: 0 | AY6: 0 | AZ6: 0 | BA6: 0 | BB6: 0 | BC6: 0 | BD6: 0 | BE6: 0
A7: onshore wind | B7: 0 | C7: 0 | D7: 0 | E7: 0 | F7: 0 | G7: 0 | H7: 0 | I7: 0 | J7: 0 | K7: 0 | L7: 0 | M7: 0 | N7: 0 | O7: 0 | P7: 0 | Q7: 0 | R7: 0 | S7: 0 | T7: 0 | U7: 0 | V7: 0 | W7: 0 | X7: 0 | Y7: 0 | Z7: 0 | AA7: 0 | AB7: 0 | AC7: 0 | AD7: 0 | AE7: 0 | AF7: 0 | AG7: 0 | AH7: 0 | AI7: 0 | AJ7: 0 | AK7: 0 | AL7: 0 | AM7: 0 | AN7: 0 | AO7: 0 | AP7: 0 | AQ7: 0 | AR7: 0 | AS7: 0 | AT7: 0 | AU7: 0 | AV7: 0 | AW7: 0 | AX7: 0 | AY7: 0 | AZ7: 0 | BA7: 0 | BB7: 0 | BC7: 0 | BD7: 0 | BE7: 0
A8: solar PV | B8: 0 | C8: 0 | D8: 0 | E8: 0 | F8: 0 | G8: 0 | H8: 0 | I8: 0 | J8: 0 | K8: 0 | L8: 0 | M8: 0 | N8: 0 | O8: 0 | P8: 0 | Q8: 0 | R8: 0 | S8: 0 | T8: 0 | U8: 0 | V8: 0 | W8: 0 | X8: 0 | Y8: 0 | Z8: 0 | AA8: 0 | AB8: 0 | AC8: 0 | AD8: 0 | AE8: 0 | AF8: 0 | AG8: 0 | AH8: 0 | AI8: 0 | AJ8: 0 | AK8: 0 | AL8: 0 | AM8: 0 | AN8: 0 | AO8: 0 | AP8: 0 | AQ8: 0 | AR8: 0 | AS8: 0 | AT8: 0 | AU8: 0 | AV8: 0 | AW8: 0 | AX8: 0 | AY8: 0 | AZ8: 0 | BA8: 0 | BB8: 0 | BC8: 0 | BD8: 0 | BE8: 0
A9: solar thermal | B9: 0 | C9: 0 | D9: 0 | E9: 0 | F9: 0 | G9: 0 | H9: 0 | I9: 0 | J9: 0 | K9: 0 | L9: 0 | M9: 0 | N9: 0 | O9: 0 | P9: 0 | Q9: 0 | R9: 0 | S9: 0 | T9: 0 | U9: 0 | V9: 0 | W9: 0 | X9: 0 | Y9: 0 | Z9: 0 | AA9: 0 | AB9: 0 | AC9: 0 | AD9: 0 | AE9: 0 | AF9: 0 | AG9: 0 | AH9: 0 | AI9: 0 | AJ9: 0 | AK9: 0 | AL9: 0 | AM9: 0 | AN9: 0 | AO9: 0 | AP9: 0 | AQ9: 0 | AR9: 0 | AS9: 0 | AT9: 0 | AU9: 0 | AV9: 0 | AW9: 0 | AX9: 0 | AY9: 0 | AZ9: 0 | BA9: 0 | BB9: 0 | BC9: 0 | BD9: 0 | BE9: 0
A10: biomass | B10: 0 | C10: 0 | D10: 0 | E10: 0 | F10: 0 | G10: 0 | H10: 0 | I10: 0 | J10: 0 | K10: 0 | L10: 0 | M10: 0 | N10: 0 | O10: 0 | P10: 0 | Q10: 0 | R10: 0 | S10: 0 | T10: 0 | U10: 0 | V10: 0 | W10: 0 | X10: 0 | Y10: 0 | Z10: 0 | AA10: 0 | AB10: 0 | AC10: 0 | AD10: 0 | AE10: 0 | AF10: 0 | AG10: 0 | AH10: 0 | AI10: 0 | AJ10: 0 | AK10: 0 | AL10: 0 | AM10: 0 | AN10: 0 | AO10: 0 | AP10: 0 | AQ10: 0 | AR10: 0 | AS10: 0 | AT10: 0 | AU10: 0 | AV10: 0 | AW10: 0 | AX10: 0 | AY10: 0 | AZ10: 0 | BA10: 0 | BB10: 0 | BC10: 0 | BD10: 0 | BE10: 0
A11: geothermal | B11: 0 | C11: 0 | D11: 0 | E11: 0 | F11: 0 | G11: 0 | H11: 0 | I11: 0 | J11: 0 | K11: 0 | L11: 0 | M11: 0 | N11: 0 | O11: 0 | P11: 0 | Q11: 0 | R11: 0 | S11: 0 | T11: 0 | U11: 0 | V11: 0 | W11: 0 | X11: 0 | Y11: 0 | Z11: 0 | AA11: 0 | AB11: 0 | AC11: 0 | AD11: 0 | AE11: 0 | AF11: 0 | AG11: 0 | AH11: 0 | AI11: 0 | AJ11: 0 | AK11: 0 | AL11: 0 | AM11: 0 | AN11: 0 | AO11: 0 | AP11: 0 | AQ11: 0 | AR11: 0 | AS11: 0 | AT11: 0 | AU11: 0 | AV11: 0 | AW11: 0 | AX11: 0 | AY11: 0 | AZ11: 0 | BA11: 0 | BB11: 0 | BC11: 0 | BD11: 0 | BE11: 0
A12: petroleum | B12: 0 | C12: 0 | D12: 0 | E12: 0 | F12: 0 | G12: 0 | H12: 0 | I12: 0 | J12: 0 | K12: 0 | L12: 0 | M12: 0 | N12: 0 | O12: 0 | P12: 0 | Q12: 0 | R12: 0 | S12: 0 | T12: 0 | U12: 0 | V12: 0 | W12: 0 | X12: 0 | Y12: 0 | Z12: 0 | AA12: 0 | AB12: 0 | AC12: 0 | AD12: 0 | AE12: 0 | AF12: 0 | AG12: 0 | AH12: 0 | AI12: 0 | AJ12: 0 | AK12: 0 | AL12: 0 | AM12: 0 | AN12: 0 | AO12: 0 | AP12: 0 | AQ12: 0 | AR12: 0 | AS12: 0 | AT12: 0 | AU12: 0 | AV12: 0 | AW12: 0 | AX12: 0 | AY12: 0 | AZ12: 0 | BA12: 0 | BB12: 0 | BC12: 0 | BD12: 0 | BE12: 0
... A25: hydrogen combined cycle | B25: 0 | C25: 0 | D25: 0 | E25: 0 | F25: 0 | G25: 0 | H25: 0 | I25: 0 | J25: 0 | K25: 0 | L25: 0 | M25: 0 | N25: 0 | O25: 0 | P25: 0 | Q25: 0 | R25: 0 | S25: 0 | T25: 0 | U25: 0 | V25: 0 | W25: 0 | X25: 0 | Y25: 0 | Z25: 0 | AA25: 0 | AB25: 0 | AC25: 0 | AD25: 0 | AE25: 0 | AF25: 0 | AG25: 0 | AH25: 0 | AI25: 0 | AJ25: 0 | AK25: 0 | AL25: 0 | AM25: 0 | AN25: 0 | AO25: 0 | AP25: 0 | AQ25: 0 | AR25: 0 | AS25: 0 | AT25: 0 | AU25: 0 | AV25: 0 | AW25: 0 | AX25: 0 | AY25: 0 | AZ25: 0 | BA25: 0 | BB25: 0 | BC25: 0 | BD25: 0 | BE25: 0
