Workbook

Sheet About 
A1: BCEU BAU Components Energy Use
A3: Source | B3: IESR (2024)
B4: https://iesr.or.id/en/
A10: Comments | B10: These data come from the LEAP (Long-range Energy Alternatives Planning) Indonesia model and represent BAU (Business As Usual) scenarios projected for the country. The BAU scenarios assume no significant changes to current energy policies or interventions, providing a baseline for analyzing future energy consumption, emissions, and sectoral growth under existing conditions. This model helps evaluate long-term trends in Indonesia's energy use and environmental impacts, serving as a foundation for comparing potential outcomes from alternative policy scenarios aimed at sustainable development and climate goals.

Sheet Commercial
A1: Variable: Non Electricity Consumption: Total Final Energy Consumption (Thousand Gigajoule)
A2: Scenario: Business as Usual
A3: Branch: Demand\Commercial\Office\Conventional Office\Non Electricity Consumption\Gasoil Generator
A4: Region: Indonesia
A5: Thousand Gigajoule to Gigajoule | B5: 1000
A6: Branch | B6: 2022 | C6: 2023 | D6: 2024 | E6: 2025 | F6: 2026 | G6: 2027 | H6: 2028 | I6: 2029 | J6: 2030 | K6: 2031 | L6: 2032 | M6: 2033 | N6: 2034 | O6: 2035 | P6: 2036 | Q6: 2037 | R6: 2038 | S6: 2039 | T6: 2040 | U6: 2041 | V6: 2042 | W6: 2043 | X6: 2044 | Y6: 2045 | Z6: 2046 | AA6: 2047 | AB6: 2048 | AC6: 2049 | AD6: 2050 | AE6: 2051 | AF6: 2052 | AG6: 2053 | AH6: 2054 | AI6: 2055 | AJ6: 2056 | AK6: 2057 | AL6: 2058 | AM6: 2059 | AN6: 2060
A7: Gasoil Generator | B7: 328.18775 | C7: 344.62501 | D7: 347.9738 | E7: 351.33736 | F7: 356.71991 | G7: 362.14197 | H7: 367.60354 | I7: 373.10462 | J7: 378.64521 | K7: 383.69711 | L7: 388.7822 | M7: 393.90048 | N7: 399.05194 | O7: 404.23658 | P7: 408.90412 | Q7: 413.59844 | R7: 418.31956 | S7: 423.06746 | T7: 427.84214 | U7: 432.08976 | V7: 436.35792 | W7: 440.6466 | X7: 444.95581 | Y7: 449.28555 | Z7: 453.08941 | AA7: 456.9078 | AB7: 460.74072 | AC7: 464.58816 | AD7: 468.45012 | AE7: 470.96822 | AF7: 473.48631 | AG7: 476.0044 | AH7: 478.52249 | AI7: 481.04059 | AJ7: 483.55868 | AK7: 486.07677 | AL7: 488.59486 | AM7: 491.11296 | AN7: 493.63105
A8: Biogasoil Generator | B8: 3364.4751 | C8: 3532.9846 | D8: 3567.3153 | E8: 3601.7974 | F8: 3656.9776 | G8: 3712.5629 | H8: 3768.5531 | I8: 3824.9484 | J8: 3881.7487 | K8: 3933.5392 | L8: 3985.6699 | M8: 4038.1408 | N8: 4090.9519 | O8: 4144.1032 | P8: 4191.9533 | Q8: 4240.078 | R8: 4288.4773 | S8: 4337.1513 | T8: 4386.0998 | U8: 4429.6451 | V8: 4473.4008 | W8: 4517.367 | X8: 4561.5436 | Y8: 4605.9307 | Z8: 4644.9267 | AA8: 4684.0716 | AB8: 4723.3654 | AC8: 4762.8081 | AD8: 4802.3997 | AE8: 4828.2144 | AF8: 4854.0291 | AG8: 4879.8438 | AH8: 4905.6584 | AI8: 4931.4731 | AJ8: 4957.2878 | AK8: 4983.1025 | AL8: 5008.9171 | AM8: 5034.7318 | AN8: 5060.5465
A9: MDF Generator | B9: 2.9221903 | C9: 3.068548 | D9: 3.0983657 | E9: 3.1283148 | F9: 3.1762412 | G9: 3.2245193 | H9: 3.2731493 | I9: 3.322131 | J9: 3.3714644 | K9: 3.4164467 | L9: 3.4617245 | M9: 3.5072977 | N9: 3.5531664 | O9: 3.5993305 | P9: 3.6408904 | Q9: 3.6826888 | R9: 3.7247257 | S9: 3.767001 | T9: 3.8095149 | U9: 3.8473359 | V9: 3.8853396 | W9: 3.9235261 | X9: 3.9618954 | Y9: 4.0004475 | Z9: 4.0343171 | AA9: 4.0683162 | AB9: 4.1024445 | AC9: 4.1367022 | AD9: 4.1710892 | AE9: 4.1935104 | AF9: 4.2159315 | AG9: 4.2383527 | AH9: 4.2607738 | AI9: 4.283195 | AJ9: 4.3056161 | AK9: 4.3280372 | AL9: 4.3504584 | AM9: 4.3728795 | AN9: 4.3953007
A11: Variable: Non Electricity Consumption: Total Final Energy Consumption (Thousand Gigajoule)
A12: Scenario: Business as Usual
A13: Branch: Demand\Commercial\Hotel\Five Star\Non Electricity Consumption\Biomass Heat
A14: Region: Indonesia
A16: Branch | B16: 2022 | C16: 2023 | D16: 2024 | E16: 2025 | F16: 2026 | G16: 2027 | H16: 2028 | I16: 2029 | J16: 2030 | K16: 2031 | L16: 2032 | M16: 2033 | N16: 2034 | O16: 2035 | P16: 2036 | Q16: 2037 | R16: 2038 | S16: 2039 | T16: 2040 | U16: 2041 | V16: 2042 | W16: 2043 | X16: 2044 | Y16: 2045 | Z16: 2046 | AA16: 2047 | AB16: 2048 | AC16: 2049 | AD16: 2050 | AE16: 2051 | AF16: 2052 | AG16: 2053 | AH16: 2054 | AI16: 2055 | AJ16: 2056 | AK16: 2057 | AL16: 2058 | AM16: 2059 | AN16: 2060
A17: Biomass Heat | B17: 660.23083 | C17: 703.32055 | D17: 749.2225 | E17: 798.12023 | F17: 850.20925 | G17: 905.69784 | H17: 964.80787 | I17: 1027.7757 | J17: 1094.8531 | K17: 1166.3083 | L17: 1242.4269 | M17: 1323.5135 | N17: 1409.8921 | O17: 1501.9082 | P17: 1599.9297 | Q17: 1704.3485 | R17: 1815.5821 | S17: 1934.0754 | T17: 2060.3021 | U17: 2194.767 | V17: 2338.0076 | W17: 2490.5968 | X17: 2653.1447 | Y17: 2826.3012 | Z17: 3010.7587 | AA17: 3207.2547 | AB17: 3416.575 | AC17: 3639.5565 | AD17: 3877.0908 | AE17: 4130.1277 | AF17: 4399.6789 | AG17: 4686.8223 | AH17: 4992.7061 | AI17: 5318.5532 | AJ17: 5665.6665 | AK17: 6035.4342 | AL17: 6429.3345 | AM17: 6848.9426 | AN17: 7295.9363
A18: Solar Heat | B18: 403.3108 | C18: 429.63273 | D18: 457.67255 | E18: 487.54238 | F18: 519.36165 | G18: 553.2576 | H18: 589.36575 | I18: 627.83049 | J18: 668.80561 | K18: 712.45496 | L18: 758.95306 | M18: 808.48585 | N18: 861.25138 | O18: 917.46063 | P18: 977.33836 | Q18: 1041.124 | R18: 1109.0725 | S18: 1181.4558 | T18: 1258.563 | U18: 1340.7027 | V18: 1428.2031 | W18: 1521.4143 | X18: 1620.7088 | Y18: 1726.4838 | Z18: 1839.1621 | AA18: 1959.1943 | AB18: 2087.0604 | AC18: 2223.2716 | AD18: 2368.3726 | AE18: 2522.9436 | AF18: 2687.6025 | AG18: 2863.0079 | AH18: 3049.8611 | AI18: 3248.9091 | AJ18: 3460.9479 | AK18: 3686.8254 | AL18: 3927.4447 | AM18: 4183.7679 | AN18: 4456.82
A19: Gas Heat | B19: 313.17283 | C19: 333.61193 | D19: 355.38499 | E19: 378.57906 | F19: 403.28688 | G19: 429.60725 | H19: 457.64541 | I19: 487.51346 | J19: 519.33085 | K19: 553.22478 | L19: 589.33079 | M19: 627.79325 | N19: 668.76594 | O19: 712.4127 | P19: 758.90805 | Q19: 808.4379 | R19: 861.2003 | S19: 917.40621 | T19: 977.28039 | U19: 1041.0622 | V19: 1109.0068 | W19: 1181.3857 | X19: 1258.4884 | Y19: 1340.6231 | Z19: 1428.1184 | AA19: 1521.324 | AB19: 1620.6127 | AC19: 1726.3814 | AD19: 1839.053 | AE19: 1959.0781 | AF19: 2086.9366 | AG19: 2223.1397 | AH19: 2368.2321 | AI19: 2522.7939 | AJ19: 2687.4431 | AK19: 2862.8381 | AL19: 3049.6802 | AM19: 3248.7164 | AN19: 3460.7427
A20: Kerosene Heat | B20: 21.96271 | C20: 23.396098 | D20: 24.923036 | E20: 26.549628 | F20: 28.28238 | G20: 30.128219 | H20: 32.094526 | I20: 34.189163 | J20: 36.420506 | K20: 38.797477 | L20: 41.329579 | M20: 44.026939 | N20: 46.900341 | O20: 49.961274 | P20: 53.221978 | Q20: 56.69549 | R20: 60.395701 | S20: 64.337403 | T20: 68.53636 | U20: 73.00936 | V20: 77.774289 | W20: 82.850199 | X20: 88.257386 | Y20: 94.017471 | Z20: 100.15349 | AA20: 106.68997 | AB20: 113.65305 | AC20: 121.07057 | AD20: 128.9722 | AE20: 137.38952 | AF20: 146.35619 | AG20: 155.90808 | AH20: 166.08336 | AI20: 176.92273 | AJ20: 188.46952 | AK20: 200.76992 | AL20: 213.87309 | AM20: 227.83144 | AN20: 242.70077
A21: Gasoil Generator | B21: 16.796903 | C21: 17.893147 | D21: 19.060936 | E21: 20.304941 | F21: 21.630136 | G21: 23.041818 | H21: 24.545634 | I21: 26.147596 | J21: 27.854109 | K21: 29.671997 | L21: 31.608529 | M21: 33.671448 | N21: 35.869002 | O21: 38.209979 | P21: 40.703739 | Q21: 43.360253 | R21: 46.190144 | S21: 49.204727 | T21: 52.416055 | U21: 55.836969 | V21: 59.481148 | W21: 63.363163 | X21: 67.498536 | Y21: 71.903803 | Z21: 76.596578 | AA21: 81.595625 | AB21: 86.920933 | AC21: 92.593795 | AD21: 98.636895 | AE21: 105.0744 | AF21: 111.93204 | AG21: 119.23724 | AH21: 127.01921 | AI21: 135.30907 | AJ21: 144.13997 | AK21: 153.54721 | AL21: 163.56841 | AM21: 174.24364 | AN21: 185.61559
A22: Biogasoil Generator | B22: 172.19644 | C22: 183.43478 | D22: 195.40658 | E22: 208.15972 | F22: 221.74518 | G22: 236.2173 | H22: 251.63393 | I22: 268.05673 | J22: 285.55135 | K22: 304.18775 | L22: 324.04045 | M22: 345.18883 | N22: 367.71745 | O22: 391.7164 | P22: 417.28162 | Q22: 444.51535 | R22: 473.52648 | S22: 504.43101 | T22: 537.35251 | U22: 572.42262 | V22: 609.78157 | W22: 649.57874 | X22: 691.97325 | Y22: 737.13462 | Z22: 785.24344 | AA22: 836.49206 | AB22: 891.0854 | AC22: 949.24176 | AD22: 1011.1937 | AE22: 1077.1888 | AF22: 1147.4912 | AG22: 1222.3818 | AH22: 1302.16 | AI22: 1387.145 | AJ22: 1477.6765 | AK22: 1574.1166 | AL22: 1676.8507 | AM22: 1786.2897 | AN22: 1902.8712
A23: MDF Generator | B23: 0.14955996 | C23: 0.15932094 | D23: 0.16971896 | E23: 0.1807956 | F23: 0.19259516 | G23: 0.20516481 | H23: 0.21855481 | I23: 0.23281871 | J23: 0.24801354 | K23: 0.26420005 | L23: 0.28144297 | M23: 0.29981124 | N23: 0.31937831 | O23: 0.34022241 | P23: 0.3624269 | Q23: 0.38608056 | R23: 0.41127796 | S23: 0.43811987 | T23: 0.4667136 | U23: 0.49717348 | V23: 0.52962133 | W23: 0.56418687 | X23: 0.60100831 | Y23: 0.64023289 | Z23: 0.68201745 | AA23: 0.72652907 | AB23: 0.77394572 | AC23: 0.824457 | AD23: 0.87826488 | AE23: 0.9355845 | AF23: 0.99664508 | AG23: 1.0616907 | AH23: 1.1309816 | AI23: 1.2047947 | AJ23: 1.2834252 | AK23: 1.3671874 | AL23: 1.4564164 | AM23: 1.5514689 | AN23: 1.6527249
A24: LPG Heat | B24: 273.08574 | C24: 290.90858 | D24: 309.89462 | E24: 330.11978 | F24: 351.66492 | G24: 374.6162 | H24: 399.06539 | I24: 425.11024 | J24: 452.8549 | K24: 482.41031 | L24: 513.89464 | M24: 547.43378 | N24: 583.16184 | O24: 621.22168 | P24: 661.76549 | Q24: 704.95536 | R24: 750.96401 | S24: 799.9754 | T24: 852.18549 | U24: 907.80306 | V24: 967.05049 | W24: 1030.1647 | X24: 1097.398 | Y24: 1169.0193 | Z24: 1245.3149 | AA24: 1326.5899 | AB24: 1413.1693 | AC24: 1505.3992 | AD24: 1603.6486 | AE24: 1708.3101 | AF24: 1819.8023 | AG24: 1938.571 | AH24: 2065.0911 | AI24: 2199.8685 | AJ24: 2343.4421 | AK24: 2496.386 | AL24: 2659.3117 | AM24: 2832.8707 | AN24: 3017.757
A26: Variable: Non Electricity Consumption: Total Final Energy Consumption (Million Gigajoule)
A27: Scenario: Business as Usual
A28: Branch: Demand\Commercial\Hotel\Four Star\Non Electricity Consumption\Biomass Heat
A29: Region: Indonesia
A30: Million Gigajoule to Gigajoule | B30: 1000000
A31: Branch | B31: 2022 | C31: 2023 | D31: 2024 | E31: 2025 | F31: 2026 | G31: 2027 | H31: 2028 | I31: 2029 | J31: 2030 | K31: 2031 | L31: 2032 | M31: 2033 | N31: 2034 | O31: 2035 | P31: 2036 | Q31: 2037 | R31: 2038 | S31: 2039 | T31: 2040 | U31: 2041 | V31: 2042 | W31: 2043 | X31: 2044 | Y31: 2045 | Z31: 2046 | AA31: 2047 | AB31: 2048 | AC31: 2049 | AD31: 2050 | AE31: 2051 | AF31: 2052 | AG31: 2053 | AH31: 2054 | AI31: 2055 | AJ31: 2056 | AK31: 2057 | AL31: 2058 | AM31: 2059 | AN31: 2060
A32: Biomass Heat | B32: 1.4471193 | C32: 1.5415649 | D32: 1.6421746 | E32: 1.7493505 | F32: 1.8635212 | G32: 1.9851433 | H32: 2.1147029 | I32: 2.2527182 | J32: 2.399741 | K32: 2.5563592 | L32: 2.723199 | M32: 2.9009276 | N32: 3.0902555 | O32: 3.2919399 | P32: 3.5067872 | Q32: 3.7356563 | R32: 3.9794625 | S32: 4.2391807 | T32: 4.5158492 | U32: 4.8105744 | V32: 5.1245348 | W32: 5.4589856 | X32: 5.8152643 | Y32: 6.1947953 | Z32: 6.5990963 | AA32: 7.0297839 | AB32: 7.4885801 | AC32: 7.9773195 | AD32: 8.4979563 | AE32: 9.0525722 | AF32: 9.643385 | AG32: 10.272757 | AH32: 10.943205 | AI32: 11.657409 | AJ32: 12.418225 | AK32: 13.228696 | AL32: 14.092062 | AM32: 15.011775 | AN32: 15.991513
A33: Solar Heat | B33: 0.88399209 | C33: 0.9416855 | D33: 1.0031443 | E33: 1.0686141 | F33: 1.1383568 | G33: 1.2126512 | H33: 1.2917944 | I33: 1.3761029 | J33: 1.4659138 | K33: 1.5615861 | L33: 1.6635024 | M33: 1.7720703 | N33: 1.8877238 | O33: 2.0109254 | P33: 2.1421677 | Q33: 2.2819755 | R33: 2.4309077 | S33: 2.58956 | T33: 2.7585667 | U33: 2.9386035 | V33: 3.1303904 | W33: 3.3346941 | X33: 3.5523317 | Y33: 3.7841733 | Z33: 4.031146 | AA33: 4.2942372 | AB33: 4.574499 | AC33: 4.873052 | AD33: 5.1910899 | AE33: 5.5298844 | AF33: 5.8907903 | AG33: 6.2752505 | AH33: 6.6848024 | AI33: 7.1210835 | AJ33: 7.5858384 | AK33: 8.0809253 | AL33: 8.6083239 | AM33: 9.1701429 | AN33: 9.7686289
A34: Gas Heat | B34: 0.68642421 | C34: 0.73122343 | D34: 0.77894645 | E34: 0.8297841 | F34: 0.88393965 | G34: 0.94162964 | H34: 1.0030848 | I34: 1.0685507 | J34: 1.1382893 | K34: 1.2125793 | L34: 1.2917178 | M34: 1.3760213 | N34: 1.4658268 | O34: 1.5614935 | P34: 1.6634038 | Q34: 1.7719652 | R34: 1.8876118 | S34: 2.0108061 | T34: 2.1420406 | U34: 2.2818401 | V34: 2.4307635 | W34: 2.5894064 | X34: 2.7584031 | Y34: 2.9384292 | Z34: 3.1302047 | AA34: 3.3344963 | AB34: 3.552121 | AC34: 3.7839489 | AD34: 4.0309069 | AE34: 4.2939825 | AF34: 4.5742277 | AG34: 4.8727629 | AH34: 5.190782 | AI34: 5.5295564 | AJ34: 5.8904409 | AK34: 6.2748783 | AL34: 6.6844059 | AM34: 7.1206611 | AN34: 7.5853884
A35: Kerosene Heat | B35: 0.04813871 | C35: 0.051280464 | D35: 0.054627265 | E35: 0.058192493 | F35: 0.061990404 | G35: 0.066036185 | H35: 0.070346012 | I35: 0.074937118 | J35: 0.079827861 | K35: 0.085037797 | L35: 0.090587757 | M35: 0.096499933 | N35: 0.10279797 | O35: 0.10950704 | P35: 0.11665397 | Q35: 0.12426735 | R35: 0.13237761 | S35: 0.14101719 | T35: 0.15022062 | U35: 0.16002471 | V35: 0.17046867 | W35: 0.18159424 | X35: 0.19344592 | Y35: 0.2060711 | Z35: 0.21952025 | AA35: 0.23384716 | AB35: 0.24910911 | AC35: 0.26536712 | AD35: 0.28268621 | AE35: 0.30113562 | AF35: 0.32078912 | AG35: 0.3417253 | AH35: 0.36402788 | AI35: 0.38778602 | AJ35: 0.41309473 | AK35: 0.4400552 | AL35: 0.46877524 | AM35: 0.49936968 | AN35: 0.53196086
A36: Gasoil Generator | B36: 0.036816096 | C36: 0.039218885 | D36: 0.041778491 | E36: 0.044505149 | F36: 0.047409761 | G36: 0.050503941 | H36: 0.053800062 | I36: 0.057311303 | J36: 0.061051704 | K36: 0.06503622 | L36: 0.069280785 | M36: 0.07380237 | N36: 0.078619054 | O36: 0.083750097 | P36: 0.089216016 | Q36: 0.095038666 | R36: 0.10124133 | S36: 0.10784881 | T36: 0.11488752 | U36: 0.12238561 | V36: 0.13037306 | W36: 0.13888181 | X36: 0.14794588 | Y36: 0.15760151 | Z36: 0.16788732 | AA36: 0.17884442 | AB36: 0.19051663 | AC36: 0.20295063 | AD36: 0.21619613 | AE36: 0.23030609 | AF36: 0.24533693 | AG36: 0.26134875 | AH36: 0.27840558 | AI36: 0.29657562 | AJ36: 0.31593151 | AK36: 0.33655067 | AL36: 0.35851552 | AM36: 0.3819139 | AN36: 0.40683937
A37: Biogasoil Generator | B37: 0.37742676 | C37: 0.40205938 | D37: 0.42829963 | E37: 0.45625245 | F37: 0.48602959 | G37: 0.51775013 | H37: 0.5515409 | I37: 0.58753702 | J37: 0.6258824 | K37: 0.66673038 | L37: 0.71024429 | M37: 0.75659812 | N37: 0.80597721 | O37: 0.85857902 | P37: 0.91461385 | Q37: 0.97430579 | R37: 1.0378935 | S37: 1.1056312 | T37: 1.1777898 | U37: 1.2546578 | V37: 1.3365426 | W37: 1.4237716 | X37: 1.5166935 | Y37: 1.6156799 | Z37: 1.7211267 | AA37: 1.8334554 | AB37: 1.9531152 | AC37: 2.0805845 | AD37: 2.2163731 | AE37: 2.3610238 | AF37: 2.5151152 | AG37: 2.6792632 | AH37: 2.8541243 | AI37: 3.0403977 | AJ37: 3.2388281 | AK37: 3.450209 | AL37: 3.6753856 | AM37: 3.9152583 | AN37: 4.1707862
A38: MDF Generator | B38: 0.00032781126 | C38: 0.00034920574 | D38: 0.00037199652 | E38: 0.00039627473 | F38: 0.00042213745 | G38: 0.0004496881 | H38: 0.00047903682 | I38: 0.00051030098 | J38: 0.00054360559 | K38: 0.0005790838 | L38: 0.00061687749 | M38: 0.00065713777 | N38: 0.00070002562 | O38: 0.00074571253 | P38: 0.00079438118 | Q38: 0.00084622617 | R38: 0.00090145481 | S38: 0.00096028792 | T38: 0.0010229608 | U38: 0.0010897239 | V38: 0.0011608443 | W38: 0.0012366064 | X38: 0.0013173131 | Y38: 0.001403287 | Z38: 0.001494872 | AA38: 0.0015924343 | AB38: 0.0016963639 | AC38: 0.0018070765 | AD38: 0.0019250146 | AE38: 0.00205065 | AF38: 0.0021844849 | AG38: 0.0023270545 | AH38: 0.0024789288 | AI38: 0.0026407152 | AJ38: 0.0028130605 | AK38: 0.0029966538 | AL38: 0.0031922293 | AM38: 0.003400569 | AN38: 0.0036225058
A39: LPG Heat | B39: 0.5985598 | C39: 0.63762458 | D39: 0.67923891 | E39: 0.72356919 | F39: 0.77079266 | G39: 0.82109816 | H39: 0.87468682 | I39: 0.93177293 | J39: 0.99258474 | K39: 1.0573654 | L39: 1.126374 | M39: 1.1998864 | N39: 1.2781965 | O39: 1.3616175 | P39: 1.450483 | Q39: 1.5451482 | R39: 1.6459917 | S39: 1.7534167 | T39: 1.8678528 | U39: 1.9897576 | V39: 2.1196183 | W39: 2.2579544 | X39: 2.405319 | Y39: 2.5623012 | Z39: 2.7295289 | AA39: 2.9076706 | AB39: 3.0974386 | AC39: 3.2995918 | AD39: 3.5149384 | AE39: 3.7443395 | AF39: 3.9887125 | AG39: 4.2490343 | AH39: 4.5263459 | AI39: 4.8217562 | AJ39: 5.1364463 | AK39: 5.4716746 | AL39: 5.8287814 | AM39: 6.2091946 | AN39: 6.6144354
A41: Variable: Non Electricity Consumption: Total Final Energy Consumption (Million Gigajoule)
A42: Scenario: Business as Usual
A43: Branch: Demand\Commercial\Hotel\Three Star\Non Electricity Consumption\Biomass Heat
A44: Region: Indonesia
...

Sheet Commercial-Conversion
A1: Variable: Non Electricity Consumption: Total Final Energy Consumption (Gigajoule)
A2: Scenario: Business as Usual
A3: Branch: Demand\Commercial\Office\Conventional Office\Non Electricity Consumption\Gasoil Generator
A4: Region: Indonesia
A6: Branch | B6: 2022 | C6: 2023 | D6: 2024 | E6: 2025 | F6: 2026 | G6: 2027 | H6: 2028 | I6: 2029 | J6: 2030 | K6: 2031 | L6: 2032 | M6: 2033 | N6: 2034 | O6: 2035 | P6: 2036 | Q6: 2037 | R6: 2038 | S6: 2039 | T6: 2040 | U6: 2041 | V6: 2042 | W6: 2043 | X6: 2044 | Y6: 2045 | Z6: 2046 | AA6: 2047 | AB6: 2048 | AC6: 2049 | AD6: 2050 | AE6: 2051 | AF6: 2052 | AG6: 2053 | AH6: 2054 | AI6: 2055 | AJ6: 2056 | AK6: 2057 | AL6: 2058 | AM6: 2059 | AN6: 2060
A7: Gasoil Generator | B7: =Commercial!B7*Commercial!$B$5 -> 328187.75 | C7: =Commercial!C7*Commercial!$B$5 -> 344625.01 | D7: =Commercial!D7*Commercial!$B$5 -> 347973.8 | E7: =Commercial!E7*Commercial!$B$5 -> 351337.36 | F7: =Commercial!F7*Commercial!$B$5 -> 356719.91 | G7: =Commercial!G7*Commercial!$B$5 -> 362141.97 | H7: =Commercial!H7*Commercial!$B$5 -> 367603.54 | I7: =Commercial!I7*Commercial!$B$5 -> 373104.62 | ... AN7: =Commercial!AN7*Commercial!$B$5 -> 493631.05
A8: Biogasoil Generator | B8: =Commercial!B8*Commercial!$B$5 -> 3364475.1 | C8: =Commercial!C8*Commercial!$B$5 -> 3532984.6 | D8: =Commercial!D8*Commercial!$B$5 -> 3567315.3 | E8: =Commercial!E8*Commercial!$B$5 -> 3601797.4 | F8: =Commercial!F8*Commercial!$B$5 -> 3656977.6 | G8: =Commercial!G8*Commercial!$B$5 -> 3712562.9 | H8: =Commercial!H8*Commercial!$B$5 -> 3768553.1 | I8: =Commercial!I8*Commercial!$B$5 -> 3824948.4 | ... AN8: =Commercial!AN8*Commercial!$B$5 -> 5060546.5
A9: MDF Generator | B9: =Commercial!B9*Commercial!$B$5 -> 2922.1903 | C9: =Commercial!C9*Commercial!$B$5 -> 3068.548 | D9: =Commercial!D9*Commercial!$B$5 -> 3098.3657 | E9: =Commercial!E9*Commercial!$B$5 -> 3128.3148 | F9: =Commercial!F9*Commercial!$B$5 -> 3176.2412 | G9: =Commercial!G9*Commercial!$B$5 -> 3224.5193 | H9: =Commercial!H9*Commercial!$B$5 -> 3273.1493 | I9: =Commercial!I9*Commercial!$B$5 -> 3322.131 | ... AN9: =Commercial!AN9*Commercial!$B$5 -> 4395.3007
A11: Variable: Non Electricity Consumption: Total Final Energy Consumption (Gigajoule)
A12: Scenario: Business as Usual
A13: Branch: Demand\Commercial\Hotel\Five Star\Non Electricity Consumption\Biomass Heat
A14: Region: Indonesia
A16: Branch | B16: 2022 | C16: 2023 | D16: 2024 | E16: 2025 | F16: 2026 | G16: 2027 | H16: 2028 | I16: 2029 | J16: 2030 | K16: 2031 | L16: 2032 | M16: 2033 | N16: 2034 | O16: 2035 | P16: 2036 | Q16: 2037 | R16: 2038 | S16: 2039 | T16: 2040 | U16: 2041 | V16: 2042 | W16: 2043 | X16: 2044 | Y16: 2045 | Z16: 2046 | AA16: 2047 | AB16: 2048 | AC16: 2049 | AD16: 2050 | AE16: 2051 | AF16: 2052 | AG16: 2053 | AH16: 2054 | AI16: 2055 | AJ16: 2056 | AK16: 2057 | AL16: 2058 | AM16: 2059 | AN16: 2060
A17: Biomass Heat | B17: =Commercial!B17*Commercial!$B$5 -> 660230.83 | C17: =Commercial!C17*Commercial!$B$5 -> 703320.55 | D17: =Commercial!D17*Commercial!$B$5 -> 749222.5 | E17: =Commercial!E17*Commercial!$B$5 -> 798120.23 | F17: =Commercial!F17*Commercial!$B$5 -> 850209.25 | G17: =Commercial!G17*Commercial!$B$5 -> 905697.84 | H17: =Commercial!H17*Commercial!$B$5 -> 964807.87 | I17: =Commercial!I17*Commercial!$B$5 -> 1027775.7 | ... AN17: =Commercial!AN17*Commercial!$B$5 -> 7295936.3
A18: Solar Heat | B18: =Commercial!B18*Commercial!$B$5 -> 403310.8 | C18: =Commercial!C18*Commercial!$B$5 -> 429632.73 | D18: =Commercial!D18*Commercial!$B$5 -> 457672.55 | E18: =Commercial!E18*Commercial!$B$5 -> 487542.38 | F18: =Commercial!F18*Commercial!$B$5 -> 519361.65 | G18: =Commercial!G18*Commercial!$B$5 -> 553257.6 | H18: =Commercial!H18*Commercial!$B$5 -> 589365.75 | I18: =Commercial!I18*Commercial!$B$5 -> 627830.49 | ... AN18: =Commercial!AN18*Commercial!$B$5 -> 4456820
A19: Gas Heat | B19: =Commercial!B19*Commercial!$B$5 -> 313172.83 | C19: =Commercial!C19*Commercial!$B$5 -> 333611.93 | D19: =Commercial!D19*Commercial!$B$5 -> 355384.99 | E19: =Commercial!E19*Commercial!$B$5 -> 378579.06 | F19: =Commercial!F19*Commercial!$B$5 -> 403286.88 | G19: =Commercial!G19*Commercial!$B$5 -> 429607.25 | H19: =Commercial!H19*Commercial!$B$5 -> 457645.41 | I19: =Commercial!I19*Commercial!$B$5 -> 487513.46 | ... AN19: =Commercial!AN19*Commercial!$B$5 -> 3460742.7
A20: Kerosene Heat | B20: =Commercial!B20*Commercial!$B$5 -> 21962.71 | C20: =Commercial!C20*Commercial!$B$5 -> 23396.098 | D20: =Commercial!D20*Commercial!$B$5 -> 24923.036 | E20: =Commercial!E20*Commercial!$B$5 -> 26549.628 | F20: =Commercial!F20*Commercial!$B$5 -> 28282.38 | G20: =Commercial!G20*Commercial!$B$5 -> 30128.219 | H20: =Commercial!H20*Commercial!$B$5 -> 32094.526 | I20: =Commercial!I20*Commercial!$B$5 -> 34189.163 | ... AN20: =Commercial!AN20*Commercial!$B$5 -> 242700.77
A21: Gasoil Generator | B21: =Commercial!B21*Commercial!$B$5 -> 16796.903 | C21: =Commercial!C21*Commercial!$B$5 -> 17893.147 | D21: =Commercial!D21*Commercial!$B$5 -> 19060.936 | E21: =Commercial!E21*Commercial!$B$5 -> 20304.941 | F21: =Commercial!F21*Commercial!$B$5 -> 21630.136 | G21: =Commercial!G21*Commercial!$B$5 -> 23041.818 | H21: =Commercial!H21*Commercial!$B$5 -> 24545.634 | I21: =Commercial!I21*Commercial!$B$5 -> 26147.596 | ... AN21: =Commercial!AN21*Commercial!$B$5 -> 185615.59
A22: Biogasoil Generator | B22: =Commercial!B22*Commercial!$B$5 -> 172196.44 | C22: =Commercial!C22*Commercial!$B$5 -> 183434.78 | D22: =Commercial!D22*Commercial!$B$5 -> 195406.58 | E22: =Commercial!E22*Commercial!$B$5 -> 208159.72 | F22: =Commercial!F22*Commercial!$B$5 -> 221745.18 | G22: =Commercial!G22*Commercial!$B$5 -> 236217.3 | H22: =Commercial!H22*Commercial!$B$5 -> 251633.93 | I22: =Commercial!I22*Commercial!$B$5 -> 268056.73 | ... AN22: =Commercial!AN22*Commercial!$B$5 -> 1902871.2
A23: MDF Generator | B23: =Commercial!B23*Commercial!$B$5 -> 149.55996 | C23: =Commercial!C23*Commercial!$B$5 -> 159.32094 | D23: =Commercial!D23*Commercial!$B$5 -> 169.71896 | E23: =Commercial!E23*Commercial!$B$5 -> 180.7956 | F23: =Commercial!F23*Commercial!$B$5 -> 192.59516 | G23: =Commercial!G23*Commercial!$B$5 -> 205.16481 | H23: =Commercial!H23*Commercial!$B$5 -> 218.55481 | I23: =Commercial!I23*Commercial!$B$5 -> 232.81871 | ... AN23: =Commercial!AN23*Commercial!$B$5 -> 1652.7249
A24: LPG Heat | B24: =Commercial!B24*Commercial!$B$5 -> 273085.74 | C24: =Commercial!C24*Commercial!$B$5 -> 290908.58 | D24: =Commercial!D24*Commercial!$B$5 -> 309894.62 | E24: =Commercial!E24*Commercial!$B$5 -> 330119.78 | F24: =Commercial!F24*Commercial!$B$5 -> 351664.92 | G24: =Commercial!G24*Commercial!$B$5 -> 374616.2 | H24: =Commercial!H24*Commercial!$B$5 -> 399065.39 | I24: =Commercial!I24*Commercial!$B$5 -> 425110.24 | ... AN24: =Commercial!AN24*Commercial!$B$5 -> 3017757
A26: Variable: Non Electricity Consumption: Total Final Energy Consumption (Gigajoule)
A27: Scenario: Business as Usual
A28: Branch: Demand\Commercial\Hotel\Four Star\Non Electricity Consumption\Biomass Heat
A29: Region: Indonesia
A31: Branch | B31: 2022 | C31: 2023 | D31: 2024 | E31: 2025 | F31: 2026 | G31: 2027 | H31: 2028 | I31: 2029 | J31: 2030 | K31: 2031 | L31: 2032 | M31: 2033 | N31: 2034 | O31: 2035 | P31: 2036 | Q31: 2037 | R31: 2038 | S31: 2039 | T31: 2040 | U31: 2041 | V31: 2042 | W31: 2043 | X31: 2044 | Y31: 2045 | Z31: 2046 | AA31: 2047 | AB31: 2048 | AC31: 2049 | AD31: 2050 | AE31: 2051 | AF31: 2052 | AG31: 2053 | AH31: 2054 | AI31: 2055 | AJ31: 2056 | AK31: 2057 | AL31: 2058 | AM31: 2059 | AN31: 2060
A32: Biomass Heat | B32: =Commercial!B32*Commercial!$B$30 -> 1447119.3 | C32: =Commercial!C32*Commercial!$B$30 -> 1541564.9 | D32: =Commercial!D32*Commercial!$B$30 -> 1642174.6 | E32: =Commercial!E32*Commercial!$B$30 -> 1749350.5 | F32: =Commercial!F32*Commercial!$B$30 -> 1863521.2 | G32: =Commercial!G32*Commercial!$B$30 -> 1985143.3 | H32: =Commercial!H32*Commercial!$B$30 -> 2114702.9 | I32: =Commercial!I32*Commercial!$B$30 -> 2252718.2 | ... AN32: =Commercial!AN32*Commercial!$B$30 -> 15991513
A33: Solar Heat | B33: =Commercial!B33*Commercial!$B$30 -> 883992.09 | C33: =Commercial!C33*Commercial!$B$30 -> 941685.5 | D33: =Commercial!D33*Commercial!$B$30 -> 1003144.3 | E33: =Commercial!E33*Commercial!$B$30 -> 1068614.1 | F33: =Commercial!F33*Commercial!$B$30 -> 1138356.8 | G33: =Commercial!G33*Commercial!$B$30 -> 1212651.2 | H33: =Commercial!H33*Commercial!$B$30 -> 1291794.4 | I33: =Commercial!I33*Commercial!$B$30 -> 1376102.9 | ... AN33: =Commercial!AN33*Commercial!$B$30 -> 9768628.9
A34: Gas Heat | B34: =Commercial!B34*Commercial!$B$30 -> 686424.21 | C34: =Commercial!C34*Commercial!$B$30 -> 731223.43 | D34: =Commercial!D34*Commercial!$B$30 -> 778946.45 | E34: =Commercial!E34*Commercial!$B$30 -> 829784.1 | F34: =Commercial!F34*Commercial!$B$30 -> 883939.65 | G34: =Commercial!G34*Commercial!$B$30 -> 941629.64 | H34: =Commercial!H34*Commercial!$B$30 -> 1003084.8 | I34: =Commercial!I34*Commercial!$B$30 -> 1068550.7 | ... AN34: =Commercial!AN34*Commercial!$B$30 -> 7585388.4
A35: Kerosene Heat | B35: =Commercial!B35*Commercial!$B$30 -> 48138.71 | C35: =Commercial!C35*Commercial!$B$30 -> 51280.464 | D35: =Commercial!D35*Commercial!$B$30 -> 54627.265 | E35: =Commercial!E35*Commercial!$B$30 -> 58192.493 | F35: =Commercial!F35*Commercial!$B$30 -> 61990.404 | G35: =Commercial!G35*Commercial!$B$30 -> 66036.185 | H35: =Commercial!H35*Commercial!$B$30 -> 70346.012 | I35: =Commercial!I35*Commercial!$B$30 -> 74937.118 | ... AN35: =Commercial!AN35*Commercial!$B$30 -> 531960.86
A36: Gasoil Generator | B36: =Commercial!B36*Commercial!$B$30 -> 36816.096 | C36: =Commercial!C36*Commercial!$B$30 -> 39218.885 | D36: =Commercial!D36*Commercial!$B$30 -> 41778.491 | E36: =Commercial!E36*Commercial!$B$30 -> 44505.149 | F36: =Commercial!F36*Commercial!$B$30 -> 47409.761 | G36: =Commercial!G36*Commercial!$B$30 -> 50503.941 | H36: =Commercial!H36*Commercial!$B$30 -> 53800.062 | I36: =Commercial!I36*Commercial!$B$30 -> 57311.303 | ... AN36: =Commercial!AN36*Commercial!$B$30 -> 406839.37
A37: Biogasoil Generator | B37: =Commercial!B37*Commercial!$B$30 -> 377426.76 | C37: =Commercial!C37*Commercial!$B$30 -> 402059.38 | D37: =Commercial!D37*Commercial!$B$30 -> 428299.63 | E37: =Commercial!E37*Commercial!$B$30 -> 456252.45 | F37: =Commercial!F37*Commercial!$B$30 -> 486029.59 | G37: =Commercial!G37*Commercial!$B$30 -> 517750.13 | H37: =Commercial!H37*Commercial!$B$30 -> 551540.9 | I37: =Commercial!I37*Commercial!$B$30 -> 587537.02 | ... AN37: =Commercial!AN37*Commercial!$B$30 -> 4170786.2
A38: MDF Generator | B38: =Commercial!B38*Commercial!$B$30 -> 327.81126 | C38: =Commercial!C38*Commercial!$B$30 -> 349.20574 | D38: =Commercial!D38*Commercial!$B$30 -> 371.99652 | E38: =Commercial!E38*Commercial!$B$30 -> 396.27473 | F38: =Commercial!F38*Commercial!$B$30 -> 422.13745 | G38: =Commercial!G38*Commercial!$B$30 -> 449.6881 | H38: =Commercial!H38*Commercial!$B$30 -> 479.03682 | I38: =Commercial!I38*Commercial!$B$30 -> 510.30098 | ... AN38: =Commercial!AN38*Commercial!$B$30 -> 3622.5058
A39: LPG Heat | B39: =Commercial!B39*Commercial!$B$30 -> 598559.8 | C39: =Commercial!C39*Commercial!$B$30 -> 637624.58 | D39: =Commercial!D39*Commercial!$B$30 -> 679238.91 | E39: =Commercial!E39*Commercial!$B$30 -> 723569.19 | F39: =Commercial!F39*Commercial!$B$30 -> 770792.66 | G39: =Commercial!G39*Commercial!$B$30 -> 821098.16 | H39: =Commercial!H39*Commercial!$B$30 -> 874686.82 | I39: =Commercial!I39*Commercial!$B$30 -> 931772.93 | ... AN39: =Commercial!AN39*Commercial!$B$30 -> 6614435.4
A41: Variable: Non Electricity Consumption: Total Final Energy Consumption (Gigajoule)
A42: Scenario: Business as Usual
A43: Branch: Demand\Commercial\Hotel\Three Star\Non Electricity Consumption\Biomass Heat
A44: Region: Indonesia
A46: Branch | B46: 2022 | C46: 2023 | D46: 2024 | E46: 2025 | F46: 2026 | G46: 2027 | H46: 2028 | I46: 2029 | J46: 2030 | K46: 2031 | L46: 2032 | M46: 2033 | N46: 2034 | O46: 2035 | P46: 2036 | Q46: 2037 | R46: 2038 | S46: 2039 | T46: 2040 | U46: 2041 | V46: 2042 | W46: 2043 | X46: 2044 | Y46: 2045 | Z46: 2046 | AA46: 2047 | AB46: 2048 | AC46: 2049 | AD46: 2050 | AE46: 2051 | AF46: 2052 | AG46: 2053 | AH46: 2054 | AI46: 2055 | AJ46: 2056 | AK46: 2057 | AL46: 2058 | AM46: 2059 | AN46: 2060
A47: Biomass Heat | B47: =Commercial!B47*Commercial!$B$30 -> 1086472.7 | C47: =Commercial!C47*Commercial!$B$30 -> 1157381 | D47: =Commercial!D47*Commercial!$B$30 -> 1232917 | E47: =Commercial!E47*Commercial!$B$30 -> 1313382.9 | F47: =Commercial!F47*Commercial!$B$30 -> 1399100.3 | G47: =Commercial!G47*Commercial!$B$30 -> 1490412.1 | H47: =Commercial!H47*Commercial!$B$30 -> 1587683.3 | I47: =Commercial!I47*Commercial!$B$30 -> 1691302.8 | ... AN47: =Commercial!AN47*Commercial!$B$30 -> 12006158
...

Sheet Electricity
A1: Variable: Electric Appliances: Total Final Energy Consumption (Million Gigajoule)
A2: Scenario: Business as Usual
A3: Branch: Demand\Commercial\Office\Conventional Office\Electric Appliances\Air Conditioner
A4: Region: Indonesia
A5: Million Gigajoule to Gigajoule | B5: 1000000
A6: Branch | B6: 2022 | C6: 2023 | D6: 2024 | E6: 2025 | F6: 2026 | G6: 2027 | H6: 2028 | I6: 2029 | J6: 2030 | K6: 2031 | L6: 2032 | M6: 2033 | N6: 2034 | O6: 2035 | P6: 2036 | Q6: 2037 | R6: 2038 | S6: 2039 | T6: 2040 | U6: 2041 | V6: 2042 | W6: 2043 | X6: 2044 | Y6: 2045 | Z6: 2046 | AA6: 2047 | AB6: 2048 | AC6: 2049 | AD6: 2050 | AE6: 2051 | AF6: 2052 | AG6: 2053 | AH6: 2054 | AI6: 2055 | AJ6: 2056 | AK6: 2057 | AL6: 2058 | AM6: 2059 | AN6: 2060
A7: Air Conditioner | B7: 45.305693 | C7: 47.574826 | D7: 48.03712 | E7: 48.501453 | F7: 49.244504 | G7: 49.993009 | H7: 50.746968 | I7: 51.506382 | J7: 52.271249 | K7: 52.968655 | L7: 53.670642 | M7: 54.37721 | N7: 55.088359 | O7: 55.804089 | P7: 56.448434 | Q7: 57.096477 | R7: 57.748217 | S7: 58.403656 | T7: 59.062792 | U7: 59.649168 | V7: 60.238379 | W7: 60.830423 | X7: 61.425301 | Y7: 62.023013 | Z7: 62.548129 | AA7: 63.075251 | AB7: 63.604377 | AC7: 64.135509 | AD7: 64.668646 | AE7: 65.016264 | AF7: 65.363882 | AG7: 65.7115 | AH7: 66.059118 | AI7: 66.406736 | AJ7: 66.754354 | AK7: 67.101972 | AL7: 67.44959 | AM7: 67.797207 | AN7: 68.144825
A8: Lighting and Electronics | B8: 17.669927 | C8: 18.554924 | D8: 18.735226 | E8: 18.916323 | F8: 19.206125 | G8: 19.498054 | H8: 19.792109 | I8: 20.088292 | J8: 20.386602 | K8: 20.658602 | L8: 20.932388 | M8: 21.20796 | N8: 21.485319 | O8: 21.764465 | P8: 22.01577 | Q8: 22.268517 | R8: 22.522706 | S8: 22.778337 | T8: 23.03541 | U8: 23.264106 | V8: 23.493907 | W8: 23.724814 | X8: 23.956826 | Y8: 24.189943 | Z8: 24.394746 | AA8: 24.600332 | AB8: 24.806699 | AC8: 25.013849 | AD8: 25.221781 | AE8: 25.357357 | AF8: 25.492934 | AG8: 25.62851 | AH8: 25.764087 | AI8: 25.899663 | AJ8: 26.035239 | AK8: 26.170816 | AL8: 26.306392 | AM8: 26.441969 | AN8: 26.577545
A9: Elevator or Escalator | B9: 4.8062202 | C9: 5.0469395 | D9: 5.0959815 | E9: 5.1452399 | F9: 5.2240659 | G9: 5.3034706 | H9: 5.3834537 | I9: 5.4640155 | J9: 5.5451559 | K9: 5.6191397 | L9: 5.6936095 | M9: 5.7685652 | N9: 5.8440069 | O9: 5.9199345 | P9: 5.9882894 | Q9: 6.0570365 | R9: 6.126176 | S9: 6.1957076 | T9: 6.2656316 | U9: 6.3278369 | V9: 6.3903428 | W9: 6.4531494 | X9: 6.5162566 | Y9: 6.5796644 | Z9: 6.635371 | AA9: 6.6912903 | AB9: 6.7474223 | AC9: 6.803767 | AD9: 6.8603244 | AE9: 6.8972012 | AF9: 6.934078 | AG9: 6.9709548 | AH9: 7.0078315 | AI9: 7.0447083 | AJ9: 7.0815851 | AK9: 7.1184619 | AL9: 7.1553387 | AM9: 7.1922155 | AN9: 7.2290922
A10: Other Electricity Use | B10: 2.8978681 | C10: 3.0430076 | D10: 3.0725771 | E10: 3.102277 | F10: 3.1498045 | G10: 3.1976808 | H10: 3.2459059 | I10: 3.2944799 | J10: 3.3434028 | K10: 3.3880107 | L10: 3.4329116 | M10: 3.4781055 | N10: 3.5235924 | O10: 3.5693723 | P10: 3.6105863 | Q10: 3.6520367 | R10: 3.6937237 | S10: 3.7356472 | T10: 3.7778073 | U10: 3.8153134 | V10: 3.8530008 | W10: 3.8908695 | X10: 3.9289194 | Y10: 3.9671506 | Z10: 4.0007384 | AA10: 4.0344544 | AB10: 4.0682987 | AC10: 4.1022713 | AD10: 4.1363721 | AE10: 4.1586066 | AF10: 4.1808411 | AG10: 4.2030757 | AH10: 4.2253102 | AI10: 4.2475447 | AJ10: 4.2697793 | AK10: 4.2920138 | AL10: 4.3142483 | AM10: 4.3364828 | AN10: 4.3587174
A12: Variable: Electric Appliances: Total Final Energy Consumption (Million Gigajoule)
A13: Scenario: Business as Usual
A14: Branch: Demand\Commercial\Hotel\Five Star\Electric Appliances\Air Conditioner
A15: Region: Indonesia
A16: Million Gigajoule to Gigajoule | B16: 1000000
A17: Branch | B17: 2022 | C17: 2023 | D17: 2024 | E17: 2025 | F17: 2026 | G17: 2027 | H17: 2028 | I17: 2029 | J17: 2030 | K17: 2031 | L17: 2032 | M17: 2033 | N17: 2034 | O17: 2035 | P17: 2036 | Q17: 2037 | R17: 2038 | S17: 2039 | T17: 2040 | U17: 2041 | V17: 2042 | W17: 2043 | X17: 2044 | Y17: 2045 | Z17: 2046 | AA17: 2047 | AB17: 2048 | AC17: 2049 | AD17: 2050 | AE17: 2051 | AF17: 2052 | AG17: 2053 | AH17: 2054 | AI17: 2055 | AJ17: 2056 | AK17: 2057 | AL17: 2058 | AM17: 2059 | AN17: 2060
A18: Air Conditioner | B18: 2.3983642 | C18: 2.5548925 | D18: 2.7216367 | E18: 2.8992633 | F18: 3.0884826 | G18: 3.2900512 | H18: 3.5047752 | I18: 3.7335131 | J18: 3.9771794 | K18: 4.2367485 | L18: 4.5132583 | M18: 4.8078145 | N18: 5.1215947 | O18: 5.4558537 | P18: 5.8119279 | Q18: 6.1912412 | R18: 6.5953103 | S18: 7.0257507 | T18: 7.4842837 | U18: 7.9727427 | V18: 8.4930808 | W18: 9.0473785 | X18: 9.6378523 | Y18: 10.266863 | Z18: 10.936926 | AA18: 11.650721 | AB18: 12.4111 | AC18: 13.221106 | AD18: 14.083977 | AE18: 15.003162 | AF18: 15.982338 | AG18: 17.02542 | AH18: 18.136577 | AI18: 19.320254 | AJ18: 20.581183 | AK18: 21.924407 | AL18: 23.355295 | AM18: 24.879569 | AN18: 26.503325
A19: Lighting and Electronics | B19: 0.74881054 | C19: 0.79768138 | D19: 0.84974176 | E19: 0.90519984 | F19: 0.96427737 | G19: 1.0272106 | H19: 1.0942511 | I19: 1.165667 | J19: 1.2417438 | K19: 1.3227857 | L19: 1.4091169 | M19: 1.5010823 | N19: 1.5990499 | O19: 1.7034113 | P19: 1.8145838 | Q19: 1.933012 | R19: 2.0591693 | S19: 2.1935602 | T19: 2.3367221 | U19: 2.4892274 | V19: 2.6516859 | W19: 2.8247471 | X19: 3.0091032 | Y19: 3.2054912 | Z19: 3.4146964 | AA19: 3.6375553 | AB19: 3.874959 | AC19: 4.1278567 | AD19: 4.3972598 | AE19: 4.6842453 | AF19: 4.9899608 | AG19: 5.3156287 | AH19: 5.6625513 | AI19: 6.0321156 | AJ19: 6.4257993 | AK19: 6.8451767 | AL19: 7.2919246 | AM19: 7.7678294 | AN19: 8.2747939
A20: Elevator or Escalator | B20: 0.22428142 | C20: 0.23891906 | D20: 0.25451202 | E20: 0.27112266 | F20: 0.28881738 | G20: 0.30766693 | H20: 0.3277467 | I20: 0.34913697 | J20: 0.37192326 | K20: 0.3961967 | L20: 0.42205432 | M20: 0.44959954 | N20: 0.47894249 | O20: 0.51020049 | P20: 0.54349854 | Q20: 0.57896977 | R20: 0.61675601 | S20: 0.65700836 | T20: 0.69988777 | U20: 0.74556568 | V20: 0.79422475 | W20: 0.84605953 | X20: 0.90127729 | Y20: 0.96009882 | Z20: 1.0227593 | AA20: 1.0895093 | AB20: 1.1606157 | AC20: 1.2363629 | AD20: 1.3170536 | AE20: 1.4030107 | AF20: 1.4945776 | AG20: 1.5921207 | AH20: 1.6960298 | AI20: 1.8067206 | AJ20: 1.9246355 | AK20: 2.0502462 | AL20: 2.1840547 | AM20: 2.3265962 | AN20: 2.4784407
A21: Other Electricity Use | B21: 0.24598607 | C21: 0.26204026 | D21: 0.27914222 | E21: 0.29736033 | F21: 0.31676744 | G21: 0.33744115 | H21: 0.35946412 | I21: 0.38292442 | J21: 0.40791584 | K21: 0.43453831 | L21: 0.46289829 | M21: 0.49310918 | N21: 0.52529176 | O21: 0.55957473 | P21: 0.59609517 | Q21: 0.6349991 | R21: 0.67644208 | S21: 0.72058982 | T21: 0.76761884 | U21: 0.8177172 | V21: 0.87108521 | W21: 0.92793626 | X21: 0.98849767 | Y21: 1.0530116 | Z21: 1.121736 | AA21: 1.1949457 | AB21: 1.2729334 | AC21: 1.3560109 | AD21: 1.4445105 | AE21: 1.5387859 | AF21: 1.6392142 | AG21: 1.7461969 | AH21: 1.8601618 | AI21: 1.9815645 | AJ21: 2.1108906 | AK21: 2.2486571 | AL21: 2.3954149 | AM21: 2.5517507 | AN21: 2.7182898
A23: Variable: Electric Appliances: Total Final Energy Consumption (Million Gigajoule)
A24: Scenario: Business as Usual
A25: Branch: Demand\Commercial\Hotel\Four Star\Electric Appliances\Air Conditioner
A26: Region: Indonesia
A27: Million Gigajoule to Gigajoule | B27: 1000000
A28: Branch | B28: 2022 | C28: 2023 | D28: 2024 | E28: 2025 | F28: 2026 | G28: 2027 | H28: 2028 | I28: 2029 | J28: 2030 | K28: 2031 | L28: 2032 | M28: 2033 | N28: 2034 | O28: 2035 | P28: 2036 | Q28: 2037 | R28: 2038 | S28: 2039 | T28: 2040 | U28: 2041 | V28: 2042 | W28: 2043 | X28: 2044 | Y28: 2045 | Z28: 2046 | AA28: 2047 | AB28: 2048 | AC28: 2049 | AD28: 2050 | AE28: 2051 | AF28: 2052 | AG28: 2053 | AH28: 2054 | AI28: 2055 | AJ28: 2056 | AK28: 2057 | AL28: 2058 | AM28: 2059 | AN28: 2060
A29: Air Conditioner | B29: 5.2568266 | C29: 5.5999114 | D29: 5.9653876 | E29: 6.3547164 | F29: 6.7694545 | G29: 7.2112605 | H29: 7.6819007 | I29: 8.1832571 | J29: 8.7173343 | K29: 9.2862679 | L29: 9.8923327 | M29: 10.537952 | N29: 11.225708 | O29: 11.958349 | P29: 12.738806 | Q29: 13.5702 | R29: 14.455854 | S29: 15.39931 | T29: 16.40434 | U29: 17.474963 | V29: 18.61546 | W29: 19.830391 | X29: 21.124614 | Y29: 22.503304 | Z29: 23.971974 | AA29: 25.536496 | AB29: 27.203126 | AC29: 28.978528 | AD29: 30.869801 | AE29: 32.884507 | AF29: 35.030702 | AG29: 37.316967 | AH29: 39.752445 | AI29: 42.346874 | AJ29: 45.110627 | AK29: 48.054755 | AL29: 51.191031 | AM29: 54.531994 | AN29: 58.091004
A30: Lighting and Electronics | B30: 1.6412717 | C30: 1.7483886 | D30: 1.8624966 | E30: 1.9840517 | F30: 2.1135401 | G30: 2.2514795 | H30: 2.3984215 | I30: 2.5549536 | J30: 2.7217017 | K30: 2.8993325 | L30: 3.0885564 | M30: 3.2901298 | N30: 3.5048589 | O30: 3.7336022 | P30: 3.9772744 | Q30: 4.2368497 | R30: 4.5133662 | S30: 4.8079293 | T30: 5.121717 | U30: 5.455984 | V30: 5.8120667 | W30: 6.1913891 | X30: 6.5954678 | Y30: 7.0259185 | Z30: 7.4844625 | AA30: 7.9729332 | AB30: 8.4932837 | AC30: 9.0475946 | AD30: 9.6380825 | AE30: 10.267108 | AF30: 10.937187 | AG30: 11.650999 | AH30: 12.411397 | AI30: 13.221422 | AJ30: 14.084313 | AK30: 15.003521 | AL30: 15.98272 | AM30: 17.025826 | AN30: 18.13701
A31: Elevator or Escalator | B31: 0.49158861 | C31: 0.52367196 | D31: 0.55784921 | E31: 0.59425703 | F31: 0.633041 | G31: 0.67435618 | H31: 0.71836779 | I31: 0.76525179 | J31: 0.81519567 | K31: 0.86839911 | L31: 0.92507485 | M31: 0.98544952 | N31: 1.0497645 | O31: 1.118277 | P31: 1.1912609 | Q31: 1.2690081 | R31: 1.3518295 | S31: 1.4400561 | T31: 1.5340408 | U31: 1.6341595 | V31: 1.7408123 | W31: 1.8544257 | X31: 1.9754541 | Y31: 2.1043814 | Z31: 2.2417231 | AA31: 2.3880283 | AB31: 2.5438821 | AC31: 2.7099076 | AD31: 2.8867687 | AE31: 3.0751726 | AF31: 3.2758726 | AG31: 3.4896712 | AH31: 3.7174232 | AI31: 3.9600395 | AJ31: 4.21849 | AK31: 4.4938082 | AL31: 4.7870949 | AM31: 5.0995228 | AN31: 5.4323413
A32: Other Electricity Use | B32: 0.5391617 | C32: 0.57434989 | D32: 0.61183462 | E32: 0.65176578 | F32: 0.69430303 | G32: 0.73961646 | H32: 0.78788725 | I32: 0.83930842 | J32: 0.89408557 | K32: 0.95243773 | L32: 1.0145982 | M32: 1.0808156 | N32: 1.1513546 | O32: 1.2264974 | P32: 1.3065442 | Q32: 1.3918154 | R32: 1.4826517 | S32: 1.5794164 | T32: 1.6824964 | U32: 1.7923039 | V32: 1.909278 | W32: 2.0338863 | X32: 2.1666271 | Y32: 2.3080312 | Z32: 2.458664 | AA32: 2.6191278 | AB32: 2.7900642 | AC32: 2.9721567 | AD32: 3.1661334 | AE32: 3.3727699 | AF32: 3.5928925 | AG32: 3.8273813 | AH32: 4.0771739 | AI32: 4.3432691 | AJ32: 4.6267309 | AK32: 4.9286928 | AL32: 5.2503621 | AM32: 5.593025 | AN32: 5.9580517
A34: Variable: Electric Appliances: Total Final Energy Consumption (Million Gigajoule)
A35: Scenario: Business as Usual
A36: Branch: Demand\Commercial\Hotel\Three Star\Electric Appliances\Air Conditioner
A37: Region: Indonesia
A38: Million Gigajoule to Gigajoule | B38: 1000000
A39: Branch | B39: 2022 | C39: 2023 | D39: 2024 | E39: 2025 | F39: 2026 | G39: 2027 | H39: 2028 | I39: 2029 | J39: 2030 | K39: 2031 | L39: 2032 | M39: 2033 | N39: 2034 | O39: 2035 | P39: 2036 | Q39: 2037 | R39: 2038 | S39: 2039 | T39: 2040 | U39: 2041 | V39: 2042 | W39: 2043 | X39: 2044 | Y39: 2045 | Z39: 2046 | AA39: 2047 | AB39: 2048 | AC39: 2049 | AD39: 2050 | AE39: 2051 | AF39: 2052 | AG39: 2053 | AH39: 2054 | AI39: 2055 | AJ39: 2056 | AK39: 2057 | AL39: 2058 | AM39: 2059 | AN39: 2060
A40: Air Conditioner | B40: 3.9467368 | C40: 4.2043191 | D40: 4.4787124 | E40: 4.7710139 | F40: 5.0823923 | G40: 5.4140928 | H40: 5.7674415 | I40: 6.1438514 | J40: 6.5448276 | K40: 6.9719733 | L40: 7.4269966 | M40: 7.9117167 | N40: 8.428072 | O40: 8.9781269 | P40: 9.564081 | Q40: 10.188277 | R40: 10.853211 | S40: 11.561542 | T40: 12.316102 | U40: 13.119908 | V40: 13.976174 | W40: 14.888323 | X40: 15.860004 | Y40: 16.895101 | Z40: 17.997754 | AA40: 19.172371 | AB40: 20.423648 | AC40: 21.75659 | AD40: 23.176526 | AE40: 24.689133 | AF40: 26.30046 | AG40: 28.01695 | AH40: 29.845466 | AI40: 31.793319 | AJ40: 33.868298 | AK40: 36.0787 | AL40: 38.433363 | AM40: 40.941702 | AN40: 43.613746
A41: Lighting and Electronics | B41: 1.2322391 | C41: 1.3126607 | D41: 1.398331 | E41: 1.4895926 | F41: 1.5868103 | G41: 1.6903729 | H41: 1.8006944 | I41: 1.9182161 | J41: 2.0434077 | K41: 2.1767699 | L41: 2.318836 | M41: 2.470174 | N41: 2.631389 | O41: 2.8031256 | P41: 2.9860705 | Q41: 3.1809553 | R41: 3.3885592 | S41: 3.6097122 | T41: 3.8452988 | U41: 4.0962608 | V41: 4.3636017 | W41: 4.6483905 | X41: 4.951766 | Y41: 5.2749412 | Z41: 5.6192082 | AA41: 5.9859438 | AB41: 6.3766141 | AC41: 6.7927815 | AD41: 7.2361098 | AE41: 7.7083718 | AF41: 8.2114559 | AG41: 8.7473735 | AH41: 9.3182675 | AI41: 9.9264208 | AJ41: 10.574265 | AK41: 11.26439 | AL41: 11.999557 | AM41: 12.782703 | AN41: 13.616962
A42: Elevator or Escalator | B42: 0.36907644 | C42: 0.39316408 | D42: 0.41882378 | E42: 0.44615816 | F42: 0.47527651 | G42: 0.50629525 | H42: 0.53933842 | I42: 0.57453814 | J42: 0.61203516 | K42: 0.65197941 | L42: 0.6945306 | M42: 0.73985888 | N42: 0.78814549 | O42: 0.83958351 | P42: 0.89437862 | Q42: 0.95274991 | R42: 1.0149308 | S42: 1.0811699 | T42: 1.151732 | U42: 1.2268994 | V42: 1.3069725 | W42: 1.3922716 | X42: 1.4831376 | Y42: 1.5799341 | Z42: 1.6830479 | AA42: 1.7928914 | AB42: 1.9099038 | AC42: 2.0345529 | AD42: 2.1673372 | AE42: 2.3087877 | AF42: 2.4594699 | AG42: 2.6199863 | AH42: 2.7909787 | AI42: 2.9731309 | AJ42: 3.1671711 | AK42: 3.3738754 | AL42: 3.5940701 | AM42: 3.8286357 | AN42: 4.0785102
A43: Other Electricity Use | B43: 0.40479351 | C43: 0.43121221 | D43: 0.45935512 | E43: 0.48933476 | F43: 0.52127101 | G43: 0.55529156 | H43: 0.59153246 | I43: 0.63013861 | J43: 0.67126437 | K43: 0.71507419 | L43: 0.76174324 | M43: 0.81145812 | N43: 0.86441764 | O43: 0.92083353 | P43: 0.98093139 | Q43: 1.0449515 | R43: 1.1131499 | S43: 1.1857992 | T43: 1.2631899 | U43: 1.3456316 | V43: 1.4334537 | W43: 1.5270075 | X43: 1.6266671 | Y43: 1.7328309 | Z43: 1.8459235 | AA43: 1.966397 | AB43: 2.0947331 | AC43: 2.2314451 | AD43: 2.3770796 | AE43: 2.5322188 | AF43: 2.6974831 | AG43: 2.8735333 | AH43: 3.0610734 | AI43: 3.2608532 | AJ43: 3.4736716 | AK43: 3.7003795 | AL43: 3.9418833 | AM43: 4.1991489 | AN43: 4.4732048
...

Sheet Electricity-Conversion
A1: Variable: Electric Appliances: Total Final Energy Consumption (Gigajoule)
A2: Scenario: Business as Usual
A3: Branch: Demand\Commercial\Office\Conventional Office\Electric Appliances\Air Conditioner
A4: Region: Indonesia
A6: Branch | B6: 2022 | C6: 2023 | D6: 2024 | E6: 2025 | F6: 2026 | G6: 2027 | H6: 2028 | I6: 2029 | J6: 2030 | K6: 2031 | L6: 2032 | M6: 2033 | N6: 2034 | O6: 2035 | P6: 2036 | Q6: 2037 | R6: 2038 | S6: 2039 | T6: 2040 | U6: 2041 | V6: 2042 | W6: 2043 | X6: 2044 | Y6: 2045 | Z6: 2046 | AA6: 2047 | AB6: 2048 | AC6: 2049 | AD6: 2050 | AE6: 2051 | AF6: 2052 | AG6: 2053 | AH6: 2054 | AI6: 2055 | AJ6: 2056 | AK6: 2057 | AL6: 2058 | AM6: 2059 | AN6: 2060
A7: Air Conditioner | B7: =Electricity!B7*Electricity!$B$5 -> 45305693 | C7: =Electricity!C7*Electricity!$B$5 -> 47574826 | D7: =Electricity!D7*Electricity!$B$5 -> 48037120 | E7: =Electricity!E7*Electricity!$B$5 -> 48501453 | F7: =Electricity!F7*Electricity!$B$5 -> 49244504 | G7: =Electricity!G7*Electricity!$B$5 -> 49993009 | H7: =Electricity!H7*Electricity!$B$5 -> 50746968 | I7: =Electricity!I7*Electricity!$B$5 -> 51506382 | ... AN7: =Electricity!AN7*Electricity!$B$5 -> 68144825
A8: Lighting and Electronics | B8: =Electricity!B8*Electricity!$B$5 -> 17669927 | C8: =Electricity!C8*Electricity!$B$5 -> 18554924 | D8: =Electricity!D8*Electricity!$B$5 -> 18735226 | E8: =Electricity!E8*Electricity!$B$5 -> 18916323 | F8: =Electricity!F8*Electricity!$B$5 -> 19206125 | G8: =Electricity!G8*Electricity!$B$5 -> 19498054 | H8: =Electricity!H8*Electricity!$B$5 -> 19792109 | I8: =Electricity!I8*Electricity!$B$5 -> 20088292 | ... AN8: =Electricity!AN8*Electricity!$B$5 -> 26577545
A9: Elevator or Escalator | B9: =Electricity!B9*Electricity!$B$5 -> 4806220.2 | C9: =Electricity!C9*Electricity!$B$5 -> 5046939.5 | D9: =Electricity!D9*Electricity!$B$5 -> 5095981.5 | E9: =Electricity!E9*Electricity!$B$5 -> 5145239.9 | F9: =Electricity!F9*Electricity!$B$5 -> 5224065.9 | G9: =Electricity!G9*Electricity!$B$5 -> 5303470.6 | H9: =Electricity!H9*Electricity!$B$5 -> 5383453.7 | I9: =Electricity!I9*Electricity!$B$5 -> 5464015.5 | ... AN9: =Electricity!AN9*Electricity!$B$5 -> 7229092.2
A10: Other Electricity Use | B10: =Electricity!B10*Electricity!$B$5 -> 2897868.1 | C10: =Electricity!C10*Electricity!$B$5 -> 3043007.6 | D10: =Electricity!D10*Electricity!$B$5 -> 3072577.1 | E10: =Electricity!E10*Electricity!$B$5 -> 3102277 | F10: =Electricity!F10*Electricity!$B$5 -> 3149804.5 | G10: =Electricity!G10*Electricity!$B$5 -> 3197680.8 | H10: =Electricity!H10*Electricity!$B$5 -> 3245905.9 | I10: =Electricity!I10*Electricity!$B$5 -> 3294479.9 | ... AN10: =Electricity!AN10*Electricity!$B$5 -> 4358717.4
A12: Variable: Electric Appliances: Total Final Energy Consumption (Gigajoule)
A13: Scenario: Business as Usual
A14: Branch: Demand\Commercial\Hotel\Five Star\Electric Appliances\Air Conditioner
A15: Region: Indonesia
A17: Branch | B17: 2022 | C17: 2023 | D17: 2024 | E17: 2025 | F17: 2026 | G17: 2027 | H17: 2028 | I17: 2029 | J17: 2030 | K17: 2031 | L17: 2032 | M17: 2033 | N17: 2034 | O17: 2035 | P17: 2036 | Q17: 2037 | R17: 2038 | S17: 2039 | T17: 2040 | U17: 2041 | V17: 2042 | W17: 2043 | X17: 2044 | Y17: 2045 | Z17: 2046 | AA17: 2047 | AB17: 2048 | AC17: 2049 | AD17: 2050 | AE17: 2051 | AF17: 2052 | AG17: 2053 | AH17: 2054 | AI17: 2055 | AJ17: 2056 | AK17: 2057 | AL17: 2058 | AM17: 2059 | AN17: 2060
A18: Air Conditioner | B18: =Electricity!B18*Electricity!$B$16 -> 2398364.2 | C18: =Electricity!C18*Electricity!$B$16 -> 2554892.5 | D18: =Electricity!D18*Electricity!$B$16 -> 2721636.7 | E18: =Electricity!E18*Electricity!$B$16 -> 2899263.3 | F18: =Electricity!F18*Electricity!$B$16 -> 3088482.6 | G18: =Electricity!G18*Electricity!$B$16 -> 3290051.2 | H18: =Electricity!H18*Electricity!$B$16 -> 3504775.2 | I18: =Electricity!I18*Electricity!$B$16 -> 3733513.1 | ... AN18: =Electricity!AN18*Electricity!$B$16 -> 26503325
A19: Lighting and Electronics | B19: =Electricity!B19*Electricity!$B$16 -> 748810.54 | C19: =Electricity!C19*Electricity!$B$16 -> 797681.38 | D19: =Electricity!D19*Electricity!$B$16 -> 849741.76 | E19: =Electricity!E19*Electricity!$B$16 -> 905199.84 | F19: =Electricity!F19*Electricity!$B$16 -> 964277.37 | G19: =Electricity!G19*Electricity!$B$16 -> 1027210.6 | H19: =Electricity!H19*Electricity!$B$16 -> 1094251.1 | I19: =Electricity!I19*Electricity!$B$16 -> 1165667 | ... AN19: =Electricity!AN19*Electricity!$B$16 -> 8274793.9
A20: Elevator or Escalator | B20: =Electricity!B20*Electricity!$B$16 -> 224281.42 | C20: =Electricity!C20*Electricity!$B$16 -> 238919.06 | D20: =Electricity!D20*Electricity!$B$16 -> 254512.02 | E20: =Electricity!E20*Electricity!$B$16 -> 271122.66 | F20: =Electricity!F20*Electricity!$B$16 -> 288817.38 | G20: =Electricity!G20*Electricity!$B$16 -> 307666.93 | H20: =Electricity!H20*Electricity!$B$16 -> 327746.7 | I20: =Electricity!I20*Electricity!$B$16 -> 349136.97 | ... AN20: =Electricity!AN20*Electricity!$B$16 -> 2478440.7
A21: Other Electricity Use | B21: =Electricity!B21*Electricity!$B$16 -> 245986.07 | C21: =Electricity!C21*Electricity!$B$16 -> 262040.26 | D21: =Electricity!D21*Electricity!$B$16 -> 279142.22 | E21: =Electricity!E21*Electricity!$B$16 -> 297360.33 | F21: =Electricity!F21*Electricity!$B$16 -> 316767.44 | G21: =Electricity!G21*Electricity!$B$16 -> 337441.15 | H21: =Electricity!H21*Electricity!$B$16 -> 359464.12 | I21: =Electricity!I21*Electricity!$B$16 -> 382924.42 | ... AN21: =Electricity!AN21*Electricity!$B$16 -> 2718289.8
A23: Variable: Electric Appliances: Total Final Energy Consumption (Gigajoule)
A24: Scenario: Business as Usual
A25: Branch: Demand\Commercial\Hotel\Four Star\Electric Appliances\Air Conditioner
A26: Region: Indonesia
A28: Branch | B28: 2022 | C28: 2023 | D28: 2024 | E28: 2025 | F28: 2026 | G28: 2027 | H28: 2028 | I28: 2029 | J28: 2030 | K28: 2031 | L28: 2032 | M28: 2033 | N28: 2034 | O28: 2035 | P28: 2036 | Q28: 2037 | R28: 2038 | S28: 2039 | T28: 2040 | U28: 2041 | V28: 2042 | W28: 2043 | X28: 2044 | Y28: 2045 | Z28: 2046 | AA28: 2047 | AB28: 2048 | AC28: 2049 | AD28: 2050 | AE28: 2051 | AF28: 2052 | AG28: 2053 | AH28: 2054 | AI28: 2055 | AJ28: 2056 | AK28: 2057 | AL28: 2058 | AM28: 2059 | AN28: 2060
A29: Air Conditioner | B29: =Electricity!B29*Electricity!$B$27 -> 5256826.6 | C29: =Electricity!C29*Electricity!$B$27 -> 5599911.4 | D29: =Electricity!D29*Electricity!$B$27 -> 5965387.6 | E29: =Electricity!E29*Electricity!$B$27 -> 6354716.4 | F29: =Electricity!F29*Electricity!$B$27 -> 6769454.5 | G29: =Electricity!G29*Electricity!$B$27 -> 7211260.5 | H29: =Electricity!H29*Electricity!$B$27 -> 7681900.7 | I29: =Electricity!I29*Electricity!$B$27 -> 8183257.1 | ... AN29: =Electricity!AN29*Electricity!$B$27 -> 58091004
A30: Lighting and Electronics | B30: =Electricity!B30*Electricity!$B$27 -> 1641271.7 | C30: =Electricity!C30*Electricity!$B$27 -> 1748388.6 | D30: =Electricity!D30*Electricity!$B$27 -> 1862496.6 | E30: =Electricity!E30*Electricity!$B$27 -> 1984051.7 | F30: =Electricity!F30*Electricity!$B$27 -> 2113540.1 | G30: =Electricity!G30*Electricity!$B$27 -> 2251479.5 | H30: =Electricity!H30*Electricity!$B$27 -> 2398421.5 | I30: =Electricity!I30*Electricity!$B$27 -> 2554953.6 | ... AN30: =Electricity!AN30*Electricity!$B$27 -> 18137010
A31: Elevator or Escalator | B31: =Electricity!B31*Electricity!$B$27 -> 491588.61 | C31: =Electricity!C31*Electricity!$B$27 -> 523671.96 | D31: =Electricity!D31*Electricity!$B$27 -> 557849.21 | E31: =Electricity!E31*Electricity!$B$27 -> 594257.03 | F31: =Electricity!F31*Electricity!$B$27 -> 633041 | G31: =Electricity!G31*Electricity!$B$27 -> 674356.18 | H31: =Electricity!H31*Electricity!$B$27 -> 718367.79 | I31: =Electricity!I31*Electricity!$B$27 -> 765251.79 | ... AN31: =Electricity!AN31*Electricity!$B$27 -> 5432341.3
A32: Other Electricity Use | B32: =Electricity!B32*Electricity!$B$27 -> 539161.7 | C32: =Electricity!C32*Electricity!$B$27 -> 574349.89 | D32: =Electricity!D32*Electricity!$B$27 -> 611834.62 | E32: =Electricity!E32*Electricity!$B$27 -> 651765.78 | F32: =Electricity!F32*Electricity!$B$27 -> 694303.03 | G32: =Electricity!G32*Electricity!$B$27 -> 739616.46 | H32: =Electricity!H32*Electricity!$B$27 -> 787887.25 | I32: =Electricity!I32*Electricity!$B$27 -> 839308.42 | ... AN32: =Electricity!AN32*Electricity!$B$27 -> 5958051.7
A34: Variable: Electric Appliances: Total Final Energy Consumption (Gigajoule)
A35: Scenario: Business as Usual
A36: Branch: Demand\Commercial\Hotel\Three Star\Electric Appliances\Air Conditioner
A37: Region: Indonesia
A39: Branch | B39: 2022 | C39: 2023 | D39: 2024 | E39: 2025 | F39: 2026 | G39: 2027 | H39: 2028 | I39: 2029 | J39: 2030 | K39: 2031 | L39: 2032 | M39: 2033 | N39: 2034 | O39: 2035 | P39: 2036 | Q39: 2037 | R39: 2038 | S39: 2039 | T39: 2040 | U39: 2041 | V39: 2042 | W39: 2043 | X39: 2044 | Y39: 2045 | Z39: 2046 | AA39: 2047 | AB39: 2048 | AC39: 2049 | AD39: 2050 | AE39: 2051 | AF39: 2052 | AG39: 2053 | AH39: 2054 | AI39: 2055 | AJ39: 2056 | AK39: 2057 | AL39: 2058 | AM39: 2059 | AN39: 2060
A40: Air Conditioner | B40: =Electricity!B40*Electricity!$B$38 -> 3946736.8 | C40: =Electricity!C40*Electricity!$B$38 -> 4204319.1 | D40: =Electricity!D40*Electricity!$B$38 -> 4478712.4 | E40: =Electricity!E40*Electricity!$B$38 -> 4771013.9 | F40: =Electricity!F40*Electricity!$B$38 -> 5082392.3 | G40: =Electricity!G40*Electricity!$B$38 -> 5414092.8 | H40: =Electricity!H40*Electricity!$B$38 -> 5767441.5 | I40: =Electricity!I40*Electricity!$B$38 -> 6143851.4 | ... AN40: =Electricity!AN40*Electricity!$B$38 -> 43613746
A41: Lighting and Electronics | B41: =Electricity!B41*Electricity!$B$38 -> 1232239.1 | C41: =Electricity!C41*Electricity!$B$38 -> 1312660.7 | D41: =Electricity!D41*Electricity!$B$38 -> 1398331 | E41: =Electricity!E41*Electricity!$B$38 -> 1489592.6 | F41: =Electricity!F41*Electricity!$B$38 -> 1586810.3 | G41: =Electricity!G41*Electricity!$B$38 -> 1690372.9 | H41: =Electricity!H41*Electricity!$B$38 -> 1800694.4 | I41: =Electricity!I41*Electricity!$B$38 -> 1918216.1 | ... AN41: =Electricity!AN41*Electricity!$B$38 -> 13616962
A42: Elevator or Escalator | B42: =Electricity!B42*Electricity!$B$38 -> 369076.44 | C42: =Electricity!C42*Electricity!$B$38 -> 393164.08 | D42: =Electricity!D42*Electricity!$B$38 -> 418823.78 | E42: =Electricity!E42*Electricity!$B$38 -> 446158.16 | F42: =Electricity!F42*Electricity!$B$38 -> 475276.51 | G42: =Electricity!G42*Electricity!$B$38 -> 506295.25 | H42: =Electricity!H42*Electricity!$B$38 -> 539338.42 | I42: =Electricity!I42*Electricity!$B$38 -> 574538.14 | ... AN42: =Electricity!AN42*Electricity!$B$38 -> 4078510.2
A43: Other Electricity Use | B43: =Electricity!B43*Electricity!$B$38 -> 404793.51 | C43: =Electricity!C43*Electricity!$B$38 -> 431212.21 | D43: =Electricity!D43*Electricity!$B$38 -> 459355.12 | E43: =Electricity!E43*Electricity!$B$38 -> 489334.76 | F43: =Electricity!F43*Electricity!$B$38 -> 521271.01 | G43: =Electricity!G43*Electricity!$B$38 -> 555291.56 | H43: =Electricity!H43*Electricity!$B$38 -> 591532.46 | I43: =Electricity!I43*Electricity!$B$38 -> 630138.61 | ... AN43: =Electricity!AN43*Electricity!$B$38 -> 4473204.8
A45: Variable: Electric Appliances: Total Final Energy Consumption (Gigajoule)
A46: Scenario: Business as Usual
A47: Branch: Demand\Commercial\Hotel\Budget\Electric Appliances\Air Conditioner
A48: Region: Indonesia
...

Sheet Total Other Sectors
A1: Year | B1: 2022 | C1: 2023 | D1: 2024 | E1: 2025 | F1: 2026 | G1: 2027 | H1: 2028 | I1: 2029 | J1: 2030 | K1: 2031 | L1: 2032 | M1: 2033 | N1: 2034 | O1: 2035 | P1: 2036 | Q1: 2037 | R1: 2038 | S1: 2039 | T1: 2040 | U1: 2041 | V1: 2042 | W1: 2043 | X1: 2044 | Y1: 2045 | Z1: 2046 | AA1: 2047 | AB1: 2048 | AC1: 2049 | AD1: 2050 | AE1: 2051 | AF1: 2052 | AG1: 2053 | AH1: 2054 | AI1: 2055 | AJ1: 2056 | AK1: 2057 | AL1: 2058 | AM1: 2059 | AN1: 2060
A2: Biomass Heat | B2: ='Commercial-Conversion'!B17+'Commercial-Conversion'!B32+'Commercial-Conversion'!B47+'Commercial-Conversion'!B62+'Commercial-Conversion'!B77+'Commercial-Conversion'!B92+'Commercial-Conversion'!B122+'Commercial-Conversion'!B152 -> 7420588.2 | C2: ='Commercial-Conversion'!C17+'Commercial-Conversion'!C32+'Commercial-Conversion'!C47+'Commercial-Conversion'!C62+'Commercial-Conversion'!C77+'Commercial-Conversion'!C92+'Commercial-Conversion'!C122+'Commercial-Conversion'!C152 -> 7755874.3 | D2: ='Commercial-Conversion'!D17+'Commercial-Conversion'!D32+'Commercial-Conversion'!D47+'Commercial-Conversion'!D62+'Commercial-Conversion'!D77+'Commercial-Conversion'!D92+'Commercial-Conversion'!D122+'Commercial-Conversion'!D152 -> 8112505 | E2: ='Commercial-Conversion'!E17+'Commercial-Conversion'!E32+'Commercial-Conversion'!E47+'Commercial-Conversion'!E62+'Commercial-Conversion'!E77+'Commercial-Conversion'!E92+'Commercial-Conversion'!E122+'Commercial-Conversion'!E152 -> 8491873.3 | F2: ='Commercial-Conversion'!F17+'Commercial-Conversion'!F32+'Commercial-Conversion'!F47+'Commercial-Conversion'!F62+'Commercial-Conversion'!F77+'Commercial-Conversion'!F92+'Commercial-Conversion'!F122+'Commercial-Conversion'!F152 -> 8909263.7 | G2: ='Commercial-Conversion'!G17+'Commercial-Conversion'!G32+'Commercial-Conversion'!G47+'Commercial-Conversion'!G62+'Commercial-Conversion'!G77+'Commercial-Conversion'!G92+'Commercial-Conversion'!G122+'Commercial-Conversion'!G152 -> 9352456.6 | H2: ='Commercial-Conversion'!H17+'Commercial-Conversion'!H32+'Commercial-Conversion'!H47+'Commercial-Conversion'!H62+'Commercial-Conversion'!H77+'Commercial-Conversion'!H92+'Commercial-Conversion'!H122+'Commercial-Conversion'!H152 -> 9823135.8 | I2: ='Commercial-Conversion'!I17+'Commercial-Conversion'!I32+'Commercial-Conversion'!I47+'Commercial-Conversion'!I62+'Commercial-Conversion'!I77+'Commercial-Conversion'!I92+'Commercial-Conversion'!I122+'Commercial-Conversion'!I152 -> 10323095 | ... AN2: ='Commercial-Conversion'!AN17+'Commercial-Conversion'!AN32+'Commercial-Conversion'!AN47+'Commercial-Conversion'!AN62+'Commercial-Conversion'!AN77+'Commercial-Conversion'!AN92+'Commercial-Conversion'!AN122+'Commercial-Conversion'!AN152 -> 58184941
