Workbook
Name asdf: [1]About!$A$113
Name cpi_2010to2012: [2]About!#REF!
Name cpi_2014to2012: [2]About!#REF!
Name cpi_2017to2012: [2]About!$A$120
Name cpi_2018to2012: [2]About!$A$121
Name cpi_2019to2012: [2]About!$A$122
Name cpi_2020to2012: [2]About!$A$123
Name cpi_2021to2012: [2]About!$A$124
Name cpi_2022to2012: [2]About!$A$125
Name H2_kg_to_MMBtu: [3]Constants!$D$7
Name kWh_to_Btu: [3]Constants!$D$4

Sheet About
A1: SYBCbVT Start Year Battery Capacity by Vehicle Type
A3: Sources: | B3: motorbikes (2- and 3-wheelers)
B4: IRENA
B5: 2017
B6: Electricity Storage and Renewables: Costs and Markets to 2030
B7: http://www.irena.org/publications/2017/Oct/Electricity-storage-and-renewables-costs-and-markets
B8: Page 104
B10: All others
B11: Lindon, Henry (CleanTechnica)
B12: 2016
B13: Electric Bus Batteries Could Soon Overtake Consumer Electronic Batteries
B14: https://cleantechnica.com/2016/03/12/electric-bus-batteries-could-soon-overtake-consumer-electronic-batteries/
B15: Paragraph 2
B17: ICCT
B18: (Data on Request)
B19: 2022
B20: Estimated vehicle costs, battery sizes, and fleet distance traveled
B22: Breakdown by class 6/7
B23: Energy Information Administration (Data on Request)
B24: 2024
B25: Estimated freight vehicle miles traveled by vehicle class

Sheet Data
A1: 2- and 3-wheelers
A2: 0.7 | B2: kWh/vehicle
A3: =A2/10^3 -> 0.0007 | B3: MWh/vehicle
A5: buses
A6: 75 | B6: kWh/veh (low end of range)
A7: 300 | B7: kWh/veh (high end of range)
A8: =AVERAGE(A6:A7) -> 187.5 | B8: kWh/veh (avg)
A9: =A8/10^3 -> 0.1875 | B9: MWh/veh
A11: freight trucks
A12: 212 | B12: kWh/vehicle
A13: =A12/10^3 -> 0.212 | B13: MWh/vehicle
A15: battery electric passenger LDVs
A16: 70 | B16: kWh/veh (Tesla Model S, low end)
A17: 90 | B17: kWh/veh (Tesla Model S, high end)
A18: 60 | B18: kWh/veh (Chevy Bolt)
A19: =AVERAGE(A16:A18) -> 73.333333 | B19: kWh/veh (avg)
A20: =A19/10^3 -> 0.073333333 | B20: MWh/vehicle
A22: plug-in hybrid passenger LDVs
A23: 18.4 | B23: kWh/veh (Chevy Volt)
A24: 8.8 | B24: kWh/veh (Toyota Prius Prime)
A25: =AVERAGE(A23:A24) -> 13.6 | B25: kWh/veh (avg)
A26: =A25/10^3 -> 0.0136 | B26: MWh/vehicle

Sheet Pass LDVs
A1: ICE Sales Shares (from the report above, page 14, paragraph 2) | D1: Data here and below from an earlier ICCT 2017 report
A2: car | B2: 0.26967961 | D2: Source: Figure 4, Lutsey & Nicholas (2018) "Electric Vehicle Costs and Consumer Benefits in Colorado in the 2020-2030 Time Frame," International Council on Clean Transportation, https://theicct.org/wp-content/uploads/2021/06/ev_Colorado_cost_2020_20190613.pdf
A3: crossover | B3: 0.35313092
A4: SUV | B4: 0.230751
A5: pickup | B5: 0.14643847
A7: Annual US BEV sales by vehicle class and range
A8: Vehicle Type | B8: 2018 | C8: 2019 | D8: 2020 | E8: 2021 | F8: 2030
A9: Electric car (150 mile) | B9: 14775 | C9: 12365 | D9: 9564 | E9: 14239 | F9: 0
A10: Electric car (200 mile) | B10: 18019 | C10: 16550 | D10: 25173 | E10: 37438 | F10: 0
A11: Electric car (250 mile) | B11: 0 | C11: 0 | D11: 3 | E11: 27140 | F11: 0
A12: Electric car (300 mile) | B12: 164220 | C12: 158253 | D12: 109589 | E12: 164966 | F12: =B2*100 -> 26.967961
A13: Electric car (350 mile) | B13: 0 | C13: 0 | D13: 0 | E13: 0 | F13: 0
A14: Electric car (400 mile) | B14: 0 | C14: 0 | D14: 0 | E14: 125 | F14: 0
A15: Crossover (150 mile) | B15: 0 | C15: 2508 | D15: 2848 | E15: 8717 | F15: 0
A16: Crossover (200 mile) | B16: 0 | C16: 3603 | D16: 3116 | E16: 15328 | F16: 0
A17: Crossover (250 mile) | B17: 0 | C17: 0 | D17: 75400 | E17: 188400 | F17: 0
A18: Crossover (300 mile) | B18: 0 | C18: 0 | D18: 0 | E18: 0 | F18: =B3*100 -> 35.313092
A19: Crossover (350 mile) | B19: 0 | C19: 0 | D19: 0 | E19: 0 | F19: 0
A20: Crossover (400 mile) | B20: 0 | C20: 0 | D20: 0 | E20: 0 | F20: 0
A21: Sport utilty vehicle (150 mile) | B21: 0 | C21: 0 | D21: 0 | E21: 0 | F21: 0
A22: Sport utility vehicle (200 mile) | B22: 393 | C22: 7966 | D22: 8860 | E22: 27388 | F22: 0
A23: Sport utility vehicle (250 mile) | B23: 0 | C23: 0 | D23: 0 | E23: 0 | F23: 0
A24: Sport utility vehicle (300 mile) | B24: 24650 | C24: 18442 | D24: 16650 | E24: 1015 | F24: =B4*100 -> 23.0751
A25: Sport utility vehicle (350 mile) | B25: 0 | C25: 0 | D25: 0 | E25: 0 | F25: 0
A26: Sport utility vehicle (400 mile) | B26: 0 | C26: 0 | D26: 0 | E26: 0 | F26: 0
A27: Pickup (150 mile) | B27: 0 | C27: 0 | D27: 0 | E27: 0 | F27: 0
A28: Pickup (200 mile) | B28: 0 | C28: 0 | D28: 0 | E28: 76 | F28: 0
A29: Pickup (250 mile) | B29: 0 | C29: 0 | D29: 0 | E29: 0 | F29: 0
A30: Pickup (300 mile) | B30: 0 | C30: 0 | D30: 0 | E30: 913 | F30: =B5*100 -> 14.643847
A31: Pickup (350 mile) | B31: 0 | C31: 0 | D31: 0 | E31: 0 | F31: 0
A32: Pickup (400 mile) | B32: 0 | C32: 0 | D32: 0 | E32: 0 | F32: 0
A35: Annual US PHEV sales by vehicle class and range | B35: 2018 | C35: 2019 | D35: 2020 | E35: 2021 | F35: 2030
A36: PHEV car (20 mile) | B36: 51806 | C36: 39780 | D36: 25570 | E36: 39782 | F36: 0
A37: PHEV car (30 mile) | B37: 261 | C37: 42 | D37: 10 | E37: 18 | F37: 0
A38: PHEV car (40 mile) | B38: 18602 | C38: 10758 | D38: 7140 | E38: 30021 | F38: 0
A39: PHEV car (50 mile) | B39: 18306 | C39: 4493 | D39: 43 | E39: 16 | F39: =B2*100 -> 26.967961
A40: PHEV car (60 mile) | B40: 0 | C40: 0 | D40: 0 | E40: 99 | F40: 0
A41: PHEV car (70 mile) | B41: 0 | C41: 0 | D41: 0 | E41: 0 | F41: 0
A42: PHEV crossover (20 mile) | B42: 7892 | C42: 6846 | D42: 8713 | E42: 45098 | F42: 0
A43: PHEV crossover (30 mile) | B43: 0 | C43: 0 | D43: 27 | E43: 7201 | F43: 0
...

Sheet AEO by Class
A1: Total VMT by Class
B2: 2021 | C2: 2022 | D2: 2023 | E2: 2024 | F2: 2025 | G2: 2026 | H2: 2027 | I2: 2028 | J2: 2029 | K2: 2030 | L2: 2031 | M2: 2032 | N2: 2033 | O2: 2034 | P2: 2035 | Q2: 2036 | R2: 2037 | S2: 2038 | T2: 2039 | U2: 2040 | V2: 2041 | W2: 2042 | X2: 2043 | Y2: 2044 | Z2: 2045 | AA2: 2046 | AB2: 2047 | AC2: 2048 | AD2: 2049 | AE2: 2050
A3: 2b | B3: =SUMIFS($E$22:$E$372,$B$22:$B$372,B$2)+SUMIFS($F$22:$F$372,$B$22:$B$372,B$2) -> 89367047258 | C3: =SUMIFS($E$22:$E$372,$B$22:$B$372,C$2)+SUMIFS($F$22:$F$372,$B$22:$B$372,C$2) -> 95977015103 | D3: =SUMIFS($E$22:$E$372,$B$22:$B$372,D$2)+SUMIFS($F$22:$F$372,$B$22:$B$372,D$2) -> 98812825093 | E3: =SUMIFS($E$22:$E$372,$B$22:$B$372,E$2)+SUMIFS($F$22:$F$372,$B$22:$B$372,E$2) -> 100094998262 | F3: =SUMIFS($E$22:$E$372,$B$22:$B$372,F$2)+SUMIFS($F$22:$F$372,$B$22:$B$372,F$2) -> 100480428369 | G3: =SUMIFS($E$22:$E$372,$B$22:$B$372,G$2)+SUMIFS($F$22:$F$372,$B$22:$B$372,G$2) -> 101424489851 | H3: =SUMIFS($E$22:$E$372,$B$22:$B$372,H$2)+SUMIFS($F$22:$F$372,$B$22:$B$372,H$2) -> 102816579379 | I3: =SUMIFS($E$22:$E$372,$B$22:$B$372,I$2)+SUMIFS($F$22:$F$372,$B$22:$B$372,I$2) -> 104230371474 | ... AE3: =SUMIFS($E$22:$E$372,$B$22:$B$372,AE$2)+SUMIFS($F$22:$F$372,$B$22:$B$372,AE$2) -> 130641797616
A4: 3 | B4: =SUMIFS($G$22:$G$372,$B$22:$B$372,B$2)+SUMIFS($H$22:$H$372,$B$22:$B$372,B$2) -> 73491209528 | C4: =SUMIFS($G$22:$G$372,$B$22:$B$372,C$2)+SUMIFS($H$22:$H$372,$B$22:$B$372,C$2) -> 75058850216 | D4: =SUMIFS($G$22:$G$372,$B$22:$B$372,D$2)+SUMIFS($H$22:$H$372,$B$22:$B$372,D$2) -> 74732068170 | E4: =SUMIFS($G$22:$G$372,$B$22:$B$372,E$2)+SUMIFS($H$22:$H$372,$B$22:$B$372,E$2) -> 75056362035 | F4: =SUMIFS($G$22:$G$372,$B$22:$B$372,F$2)+SUMIFS($H$22:$H$372,$B$22:$B$372,F$2) -> 76161660589 | G4: =SUMIFS($G$22:$G$372,$B$22:$B$372,G$2)+SUMIFS($H$22:$H$372,$B$22:$B$372,G$2) -> 77621935152 | H4: =SUMIFS($G$22:$G$372,$B$22:$B$372,H$2)+SUMIFS($H$22:$H$372,$B$22:$B$372,H$2) -> 78824143867 | I4: =SUMIFS($G$22:$G$372,$B$22:$B$372,I$2)+SUMIFS($H$22:$H$372,$B$22:$B$372,I$2) -> 79954302377 | ... AE4: =SUMIFS($G$22:$G$372,$B$22:$B$372,AE$2)+SUMIFS($H$22:$H$372,$B$22:$B$372,AE$2) -> 123324758518
A5: 4 | B5: =SUMIFS($I$22:$I$372,$B$22:$B$372,B$2) -> 16520378018 | C5: =SUMIFS($I$22:$I$372,$B$22:$B$372,C$2) -> 16751666086 | D5: =SUMIFS($I$22:$I$372,$B$22:$B$372,D$2) -> 16583323470 | E5: =SUMIFS($I$22:$I$372,$B$22:$B$372,E$2) -> 16511942220 | F5: =SUMIFS($I$22:$I$372,$B$22:$B$372,F$2) -> 16557685158 | G5: =SUMIFS($I$22:$I$372,$B$22:$B$372,G$2) -> 16722257362 | H5: =SUMIFS($I$22:$I$372,$B$22:$B$372,H$2) -> 16890767928 | I5: =SUMIFS($I$22:$I$372,$B$22:$B$372,I$2) -> 17088339593 | ... AE5: =SUMIFS($I$22:$I$372,$B$22:$B$372,AE$2) -> 22481978241
A6: 5 | B6: =SUMIFS($J$22:$J$372,$B$22:$B$372,B$2) -> 21162307201 | C6: =SUMIFS($J$22:$J$372,$B$22:$B$372,C$2) -> 21781207474 | D6: =SUMIFS($J$22:$J$372,$B$22:$B$372,D$2) -> 21876699449 | E6: =SUMIFS($J$22:$J$372,$B$22:$B$372,E$2) -> 22056979412 | F6: =SUMIFS($J$22:$J$372,$B$22:$B$372,F$2) -> 22392723421 | G6: =SUMIFS($J$22:$J$372,$B$22:$B$372,G$2) -> 22851304902 | H6: =SUMIFS($J$22:$J$372,$B$22:$B$372,H$2) -> 23305101083 | I6: =SUMIFS($J$22:$J$372,$B$22:$B$372,I$2) -> 23762269052 | ... AE6: =SUMIFS($J$22:$J$372,$B$22:$B$372,AE$2) -> 34590984593
A7: 6 | B7: =SUMIFS($K$22:$K$372,$B$22:$B$372,B$2) -> 21091781567 | C7: =SUMIFS($K$22:$K$372,$B$22:$B$372,C$2) -> 21163519149 | D7: =SUMIFS($K$22:$K$372,$B$22:$B$372,D$2) -> 20772978430 | E7: =SUMIFS($K$22:$K$372,$B$22:$B$372,E$2) -> 20535995156 | F7: =SUMIFS($K$22:$K$372,$B$22:$B$372,F$2) -> 20494574836 | G7: =SUMIFS($K$22:$K$372,$B$22:$B$372,G$2) -> 20605713318 | H7: =SUMIFS($K$22:$K$372,$B$22:$B$372,H$2) -> 20747433204 | I7: =SUMIFS($K$22:$K$372,$B$22:$B$372,I$2) -> 20918246976 | ... AE7: =SUMIFS($K$22:$K$372,$B$22:$B$372,AE$2) -> 27570635908
A8: 7 | B8: =SUMIFS($M$22:$M$372,$B$22:$B$372,B$2)+SUMIFS($N$22:$N$372,$B$22:$B$372,B$2)+SUMIFS($O$22:$O$372,$B$22:$B$372,B$2)+SUMIFS($L$22:$L$372,$B$22:$B$372,B$2) -> 21507671116 | C8: =SUMIFS($M$22:$M$372,$B$22:$B$372,C$2)+SUMIFS($N$22:$N$372,$B$22:$B$372,C$2)+SUMIFS($O$22:$O$372,$B$22:$B$372,C$2)+SUMIFS($L$22:$L$372,$B$22:$B$372,C$2) -> 21357975768 | D8: =SUMIFS($M$22:$M$372,$B$22:$B$372,D$2)+SUMIFS($N$22:$N$372,$B$22:$B$372,D$2)+SUMIFS($O$22:$O$372,$B$22:$B$372,D$2)+SUMIFS($L$22:$L$372,$B$22:$B$372,D$2) -> 20783058567 | E8: =SUMIFS($M$22:$M$372,$B$22:$B$372,E$2)+SUMIFS($N$22:$N$372,$B$22:$B$372,E$2)+SUMIFS($O$22:$O$372,$B$22:$B$372,E$2)+SUMIFS($L$22:$L$372,$B$22:$B$372,E$2) -> 20374639585 | F8: =SUMIFS($M$22:$M$372,$B$22:$B$372,F$2)+SUMIFS($N$22:$N$372,$B$22:$B$372,F$2)+SUMIFS($O$22:$O$372,$B$22:$B$372,F$2)+SUMIFS($L$22:$L$372,$B$22:$B$372,F$2) -> 20181540051 | G8: =SUMIFS($M$22:$M$372,$B$22:$B$372,G$2)+SUMIFS($N$22:$N$372,$B$22:$B$372,G$2)+SUMIFS($O$22:$O$372,$B$22:$B$372,G$2)+SUMIFS($L$22:$L$372,$B$22:$B$372,G$2) -> 20133620176 | H8: =SUMIFS($M$22:$M$372,$B$22:$B$372,H$2)+SUMIFS($N$22:$N$372,$B$22:$B$372,H$2)+SUMIFS($O$22:$O$372,$B$22:$B$372,H$2)+SUMIFS($L$22:$L$372,$B$22:$B$372,H$2) -> 20087106886 | I8: =SUMIFS($M$22:$M$372,$B$22:$B$372,I$2)+SUMIFS($N$22:$N$372,$B$22:$B$372,I$2)+SUMIFS($O$22:$O$372,$B$22:$B$372,I$2)+SUMIFS($L$22:$L$372,$B$22:$B$372,I$2) -> 20038635908 | ... AE8: =SUMIFS($M$22:$M$372,$B$22:$B$372,AE$2)+SUMIFS($N$22:$N$372,$B$22:$B$372,AE$2)+SUMIFS($O$22:$O$372,$B$22:$B$372,AE$2)+SUMIFS($L$22:$L$372,$B$22:$B$372,AE$2) -> 19474802616
A9: 8 | B9: =SUMIFS($P$22:$P$372,$B$22:$B$372,B$2)+SUMIFS($Q$22:$Q$372,$B$22:$B$372,B$2)+SUMIFS($R$22:$R$372,$B$22:$B$372,B$2)+SUMIFS($S$22:$S$372,$B$22:$B$372,B$2)+SUMIFS($T$22:$T$372,$B$22:$B$372,B$2)+SUMIFS($U$22:$U$372,$B$22:$B$372,B$2)+SUMIFS($V$22:$V$372,$B$22:$B$372,B$2)+SUMIFS($W$22:$W$372,$B$22:$B$372,B$2) -> 161513165543 | C9: =SUMIFS($P$22:$P$372,$B$22:$B$372,C$2)+SUMIFS($Q$22:$Q$372,$B$22:$B$372,C$2)+SUMIFS($R$22:$R$372,$B$22:$B$372,C$2)+SUMIFS($S$22:$S$372,$B$22:$B$372,C$2)+SUMIFS($T$22:$T$372,$B$22:$B$372,C$2)+SUMIFS($U$22:$U$372,$B$22:$B$372,C$2)+SUMIFS($V$22:$V$372,$B$22:$B$372,C$2)+SUMIFS($W$22:$W$372,$B$22:$B$372,C$2) -> 165833835900 | D9: =SUMIFS($P$22:$P$372,$B$22:$B$372,D$2)+SUMIFS($Q$22:$Q$372,$B$22:$B$372,D$2)+SUMIFS($R$22:$R$372,$B$22:$B$372,D$2)+SUMIFS($S$22:$S$372,$B$22:$B$372,D$2)+SUMIFS($T$22:$T$372,$B$22:$B$372,D$2)+SUMIFS($U$22:$U$372,$B$22:$B$372,D$2)+SUMIFS($V$22:$V$372,$B$22:$B$372,D$2)+SUMIFS($W$22:$W$372,$B$22:$B$372,D$2) -> 165951663770 | E9: =SUMIFS($P$22:$P$372,$B$22:$B$372,E$2)+SUMIFS($Q$22:$Q$372,$B$22:$B$372,E$2)+SUMIFS($R$22:$R$372,$B$22:$B$372,E$2)+SUMIFS($S$22:$S$372,$B$22:$B$372,E$2)+SUMIFS($T$22:$T$372,$B$22:$B$372,E$2)+SUMIFS($U$22:$U$372,$B$22:$B$372,E$2)+SUMIFS($V$22:$V$372,$B$22:$B$372,E$2)+SUMIFS($W$22:$W$372,$B$22:$B$372,E$2) -> 166563777972 | F9: =SUMIFS($P$22:$P$372,$B$22:$B$372,F$2)+SUMIFS($Q$22:$Q$372,$B$22:$B$372,F$2)+SUMIFS($R$22:$R$372,$B$22:$B$372,F$2)+SUMIFS($S$22:$S$372,$B$22:$B$372,F$2)+SUMIFS($T$22:$T$372,$B$22:$B$372,F$2)+SUMIFS($U$22:$U$372,$B$22:$B$372,F$2)+SUMIFS($V$22:$V$372,$B$22:$B$372,F$2)+SUMIFS($W$22:$W$372,$B$22:$B$372,F$2) -> 168228600747 | G9: =SUMIFS($P$22:$P$372,$B$22:$B$372,G$2)+SUMIFS($Q$22:$Q$372,$B$22:$B$372,G$2)+SUMIFS($R$22:$R$372,$B$22:$B$372,G$2)+SUMIFS($S$22:$S$372,$B$22:$B$372,G$2)+SUMIFS($T$22:$T$372,$B$22:$B$372,G$2)+SUMIFS($U$22:$U$372,$B$22:$B$372,G$2)+SUMIFS($V$22:$V$372,$B$22:$B$372,G$2)+SUMIFS($W$22:$W$372,$B$22:$B$372,G$2) -> 170541530605 | H9: =SUMIFS($P$22:$P$372,$B$22:$B$372,H$2)+SUMIFS($Q$22:$Q$372,$B$22:$B$372,H$2)+SUMIFS($R$22:$R$372,$B$22:$B$372,H$2)+SUMIFS($S$22:$S$372,$B$22:$B$372,H$2)+SUMIFS($T$22:$T$372,$B$22:$B$372,H$2)+SUMIFS($U$22:$U$372,$B$22:$B$372,H$2)+SUMIFS($V$22:$V$372,$B$22:$B$372,H$2)+SUMIFS($W$22:$W$372,$B$22:$B$372,H$2) -> 172436733111 | I9: =SUMIFS($P$22:$P$372,$B$22:$B$372,I$2)+SUMIFS($Q$22:$Q$372,$B$22:$B$372,I$2)+SUMIFS($R$22:$R$372,$B$22:$B$372,I$2)+SUMIFS($S$22:$S$372,$B$22:$B$372,I$2)+SUMIFS($T$22:$T$372,$B$22:$B$372,I$2)+SUMIFS($U$22:$U$372,$B$22:$B$372,I$2)+SUMIFS($V$22:$V$372,$B$22:$B$372,I$2)+SUMIFS($W$22:$W$372,$B$22:$B$372,I$2) -> 173990397454 | ... AE9: =SUMIFS($P$22:$P$372,$B$22:$B$372,AE$2)+SUMIFS($Q$22:$Q$372,$B$22:$B$372,AE$2)+SUMIFS($R$22:$R$372,$B$22:$B$372,AE$2)+SUMIFS($S$22:$S$372,$B$22:$B$372,AE$2)+SUMIFS($T$22:$T$372,$B$22:$B$372,AE$2)+SUMIFS($U$22:$U$372,$B$22:$B$372,AE$2)+SUMIFS($V$22:$V$372,$B$22:$B$372,AE$2)+SUMIFS($W$22:$W$372,$B$22:$B$372,AE$2) -> 185700776885
A11: Total VMT by Class
B12: 2021 | C12: 2022 | D12: 2023 | E12: 2024 | F12: 2025 | G12: 2026 | H12: 2027 | I12: 2028 | J12: 2029 | K12: 2030 | L12: 2031 | M12: 2032 | N12: 2033 | O12: 2034 | P12: 2035 | Q12: 2036 | R12: 2037 | S12: 2038 | T12: 2039 | U12: 2040 | V12: 2041 | W12: 2042 | X12: 2043 | Y12: 2044 | Z12: 2045 | AA12: 2046 | AB12: 2047 | AC12: 2048 | AD12: 2049 | AE12: 2050
A13: Percentage of class 6/7 VMT from class 6 | B13: =B7/SUM(B7:B8) -> 0.4951186 | C13: =C7/SUM(C7:C8) -> 0.49771343 | D13: =D7/SUM(D7:D8) -> 0.49987872 | E13: =E7/SUM(E7:E8) -> 0.50197205 | F13: =F7/SUM(F7:F8) -> 0.50384789 | G13: =G7/SUM(G7:G8) -> 0.50579407 | H13: =H7/SUM(H7:H8) -> 0.50808539 | I13: =I7/SUM(I7:I8) -> 0.51073826 | ... AE13: =AE7/SUM(AE7:AE8) -> 0.5860427
A14: Percentage of AEO HDV from class 7 | B14: =B8/SUM(B$8:B$9) -> 0.11751488 | C14: =C8/SUM(C$8:C$9) -> 0.11409674 | D14: =D8/SUM(D$8:D$9) -> 0.11129724 | E14: =E8/SUM(E$8:E$9) -> 0.10899118 | F14: =F8/SUM(F$8:F$9) -> 0.10711494 | G14: =G8/SUM(G$8:G$9) -> 0.10559121 | H14: =H8/SUM(H$8:H$9) -> 0.10433569 | I14: =I8/SUM(I$8:I$9) -> 0.10327648 | ... AE14: =AE8/SUM(AE$8:AE$9) -> 0.094917741
A15: Percentage of AEO HDV from class 8 | B15: =B9/SUM(B$8:B$9) -> 0.88248512 | C15: =C9/SUM(C$8:C$9) -> 0.88590326 | D15: =D9/SUM(D$8:D$9) -> 0.88870276 | E15: =E9/SUM(E$8:E$9) -> 0.89100882 | F15: =F9/SUM(F$8:F$9) -> 0.89288506 | G15: =G9/SUM(G$8:G$9) -> 0.89440879 | H15: =H9/SUM(H$8:H$9) -> 0.89566431 | I15: =I9/SUM(I$8:I$9) -> 0.89672352 | ... AE15: =AE9/SUM(AE$8:AE$9) -> 0.90508226
A17: Freight truck VMT (Class 2b-8) by fuel and market class
A18: AEO2023 Reference case
H20: Vocational | M20: Class 7 tractor | P20: Class 8
B21: Year | D21: Powertrain | E21: Class 2 pickup and van | F21: Class 2 vocational | G21: Class 3 pickup and van | H21: 3 | I21: 4 | J21: 5 | K21: 6 | L21: 7 | M21: Day low | N21: day mid | O21: day high | P21: voc | Q21: day low | R21: day mid | S21: day high | T21: sleeper low | U21: sleeper mid | V21: sleeper high | W21: heavy-haul | AA21: Light-Medium | AB21: Medium-Heavy | AC21: Heavy-heavy
B22: 2012 | C22: Diesel | D22: 1 | E22: 1440254464 | F22: 5322017 | G22: 35961749504 | H22: 3098777600 | I22: 10600532992 | J22: 10702599168 | K22: 16254921728 | L22: 16212148224 | M22: 1825904512 | N22: 1825904512 | O22: 5477713920 | P22: 22833444864 | Q22: 10201739264 | R22: 10201739264 | S22: 30717327360 | T22: 12219665408 | U22: 12219665408 | V22: 36546887680 | W22: 2016466 | Z22: 2012 | AA22: {=SUM(($G$22:$H$372)*($B$22:$B$372=$Z22))/1000000} -> 53357.496 | AB22: {=SUM(($I$22:$K$372)*($B$22:$B$372=$Z22))/1000000} -> 54962.399 | AC22: {=SUM(($L$22:$W$372)*($B$22:$B$372=$Z22))/1000000} -> 160885.03 | AD22: =SUM(AA22:AC22) -> 269204.93
B23: 2012 | C23: Gasoline | D23: 2 | E23: 2212064768 | F23: 595231552 | G23: 7394046976 | H23: 5169382400 | I23: 8645104640 | J23: 3212722688 | K23: 5412267008 | L23: 339667136 | M23: 0 | N23: 0 | O23: 0 | P23: 38699320 | Q23: 0 | R23: 0 | S23: 0 | T23: 0 | U23: 0 | V23: 0 | W23: 0 | Z23: 2013 | AA23: {=SUM(($G$22:$H$372)*($B$22:$B$372=$Z23))/1000000} -> 54849.001 | AB23: {=SUM(($I$22:$K$372)*($B$22:$B$372=$Z23))/1000000} -> 55016.168 | AC23: {=SUM(($L$22:$W$372)*($B$22:$B$372=$Z23))/1000000} -> 165149.1 | AD23: =SUM(AA23:AC23) -> 275014.27
B24: 2012 | C24: LPG | D24: 3 | E24: 0 | F24: 0 | G24: 2868664 | H24: 1669 | I24: 4813934 | J24: 3126864 | K24: 14819426 | L24: 17589540 | M24: 0 | N24: 0 | O24: 0 | P24: 166131 | Q24: 0 | R24: 0 | S24: 0 | T24: 0 | U24: 0 | V24: 0 | W24: 0 | Z24: 2014 | AA24: {=SUM(($G$22:$H$372)*($B$22:$B$372=$Z24))/1000000} -> 56369.293 | AB24: {=SUM(($I$22:$K$372)*($B$22:$B$372=$Z24))/1000000} -> 54763.222 | AC24: {=SUM(($L$22:$W$372)*($B$22:$B$372=$Z24))/1000000} -> 167996.19 | AD24: =SUM(AA24:AC24) -> 279128.7
B25: 2012 | C25: CNG | D25: 4 | E25: 1938696 | F25: 496 | G25: 0 | H25: 0 | I25: 16868926 | J25: 1779335 | K25: 20459338 | L25: 3961454 | M25: 646493 | N25: 646493 | O25: 1939480 | P25: 128548256 | Q25: 6280110 | R25: 6280110 | S25: 18909346 | T25: 7522331 | U25: 7522331 | V25: 22497980 | W25: 0 | Z25: 2015 | AA25: {=SUM(($G$22:$H$372)*($B$22:$B$372=$Z25))/1000000} -> 58042.053 | AB25: {=SUM(($I$22:$K$372)*($B$22:$B$372=$Z25))/1000000} -> 54072.603 | AC25: {=SUM(($L$22:$W$372)*($B$22:$B$372=$Z25))/1000000} -> 167723.9 | AD25: =SUM(AA25:AC25) -> 279838.55
B26: 2012 | C26: Flex | D26: 5 | E26: 1526867200 | F26: 15506088 | G26: 1261574912 | H26: 467267328 | I26: 72383440 | J26: 0 | K26: 0 | L26: 0 | M26: 0 | N26: 0 | O26: 0 | P26: 0 | Q26: 0 | R26: 0 | S26: 0 | T26: 0 | U26: 0 | V26: 0 | W26: 0 | Z26: 2016 | AA26: {=SUM(($G$22:$H$372)*($B$22:$B$372=$Z26))/1000000} -> 59349.005 | AB26: {=SUM(($I$22:$K$372)*($B$22:$B$372=$Z26))/1000000} -> 54712.408 | AC26: {=SUM(($L$22:$W$372)*($B$22:$B$372=$Z26))/1000000} -> 173828.55 | AD26: =SUM(AA26:AC26) -> 287889.96
B27: 2012 | C27: BEV | D27: 6 | E27: 0 | F27: 0 | G27: 0 | H27: 1827002 | I27: 0 | J27: 0 | K27: 0 | L27: 0 | M27: 0 | N27: 0 | O27: 0 | P27: 0 | Q27: 0 | R27: 0 | S27: 0 | T27: 0 | U27: 0 | V27: 0 | W27: 0 | Z27: 2017 | AA27: {=SUM(($G$22:$H$372)*($B$22:$B$372=$Z27))/1000000} -> 63513.358 | AB27: {=SUM(($I$22:$K$372)*($B$22:$B$372=$Z27))/1000000} -> 57567.424 | AC27: {=SUM(($L$22:$W$372)*($B$22:$B$372=$Z27))/1000000} -> 176504.52 | AD27: =SUM(AA27:AC27) -> 297585.3
B28: 2012 | C28: PHEV diesel | D28: 7 | E28: 0 | F28: 0 | G28: 0 | H28: 0 | I28: 0 | J28: 0 | K28: 0 | L28: 0 | M28: 0 | N28: 0 | O28: 0 | P28: 0 | Q28: 0 | R28: 0 | S28: 0 | T28: 0 | U28: 0 | V28: 0 | W28: 0 | Z28: 2018 | AA28: {=SUM(($G$22:$H$372)*($B$22:$B$372=$Z28))/1000000} -> 65749.611 | AB28: {=SUM(($I$22:$K$372)*($B$22:$B$372=$Z28))/1000000} -> 58713.445 | AC28: {=SUM(($L$22:$W$372)*($B$22:$B$372=$Z28))/1000000} -> 180393.99 | AD28: =SUM(AA28:AC28) -> 304857.04
B29: 2012 | C29: PHEV gasoline | D29: 8 | E29: 0 | F29: 0 | G29: 0 | H29: 0 | I29: 0 | J29: 0 | K29: 0 | L29: 0 | M29: 0 | N29: 0 | O29: 0 | P29: 0 | Q29: 0 | R29: 0 | S29: 0 | T29: 0 | U29: 0 | V29: 0 | W29: 0 | Z29: 2019 | AA29: {=SUM(($G$22:$H$372)*($B$22:$B$372=$Z29))/1000000} -> 64032.876 | AB29: {=SUM(($I$22:$K$372)*($B$22:$B$372=$Z29))/1000000} -> 57753.082 | AC29: {=SUM(($L$22:$W$372)*($B$22:$B$372=$Z29))/1000000} -> 178258.79 | AD29: =SUM(AA29:AC29) -> 300044.75
B30: 2012 | C30: Fuel cell | D30: 9 | E30: 0 | F30: 0 | G30: 0 | H30: 0 | I30: 0 | J30: 0 | K30: 0 | L30: 0 | M30: 0 | N30: 0 | O30: 0 | P30: 0 | Q30: 0 | R30: 0 | S30: 0 | T30: 0 | U30: 0 | V30: 0 | W30: 0 | Z30: 2020 | AA30: {=SUM(($G$22:$H$372)*($B$22:$B$372=$Z30))/1000000} -> 66392.729 | AB30: {=SUM(($I$22:$K$372)*($B$22:$B$372=$Z30))/1000000} -> 56565.216 | AC30: {=SUM(($L$22:$W$372)*($B$22:$B$372=$Z30))/1000000} -> 179177.29 | AD30: =SUM(AA30:AC30) -> 302135.24
B31: 2013 | C31: =C22 -> Diesel | D31: 1 | E31: 30803937280 | F31: 113826472 | G31: 37116588032 | H31: 2996025344 | I31: 10001015808 | J31: 11095851008 | K31: 16266354688 | L31: 15772302336 | M31: 1837885568 | N31: 1837885568 | O31: 5513656832 | P31: 22739668992 | Q31: 10591882240 | R31: 10591882240 | S31: 31892043776 | T31: 12686980096 | U31: 12686980096 | V31: 37944545280 | W31: 2940154 | Z31: 2021 | AA31: {=SUM(($G$22:$H$372)*($B$22:$B$372=$Z31))/1000000} -> 73491.21 | AB31: {=SUM(($I$22:$K$372)*($B$22:$B$372=$Z31))/1000000} -> 58774.467 | AC31: {=SUM(($L$22:$W$372)*($B$22:$B$372=$Z31))/1000000} -> 183020.84 | AD31: =SUM(AA31:AC31) -> 315286.51
B32: 2013 | C32: =C23 -> Gasoline | D32: 2 | E32: 40669630464 | F32: 10943552512 | G32: 7747261440 | H32: 5148895232 | I32: 8775163904 | J32: 3338966272 | K32: 5325068288 | L32: 316361344 | M32: 0 | N32: 0 | O32: 0 | P32: 37404796 | Q32: 0 | R32: 0 | S32: 0 | T32: 0 | U32: 0 | V32: 0 | W32: 0 | Z32: 2022 | AA32: {=SUM(($G$22:$H$372)*($B$22:$B$372=$Z32))/1000000} -> 75058.85 | AB32: {=SUM(($I$22:$K$372)*($B$22:$B$372=$Z32))/1000000} -> 59696.393 | AC32: {=SUM(($L$22:$W$372)*($B$22:$B$372=$Z32))/1000000} -> 187191.81 | AD32: =SUM(AA32:AC32) -> 321947.05
B33: 2013 | C33: =C24 -> LPG | D33: 3 | E33: 185391 | F33: 24 | G33: 2577511 | H33: 1674 | I33: 4126762 | J33: 2774236 | K33: 13745288 | L33: 14937902 | M33: 0 | N33: 0 | O33: 0 | P33: 205250 | Q33: 0 | R33: 0 | S33: 0 | T33: 0 | U33: 0 | V33: 0 | W33: 0 | Z33: 2023 | AA33: {=SUM(($G$22:$H$372)*($B$22:$B$372=$Z33))/1000000} -> 74732.068 | AB33: {=SUM(($I$22:$K$372)*($B$22:$B$372=$Z33))/1000000} -> 59233.001 | AC33: {=SUM(($L$22:$W$372)*($B$22:$B$372=$Z33))/1000000} -> 186734.72 | AD33: =SUM(AA33:AC33) -> 320699.79
B34: 2013 | C34: =C25 -> CNG | D34: 4 | E34: 52313188 | F34: 7134 | G34: 0 | H34: 0 | I34: 20689670 | J34: 1538102 | K34: 19159026 | L34: 12698769 | M34: 2153647 | N34: 2153647 | O34: 6460942 | P34: 424092032 | Q34: 21292082 | R34: 21292082 | S34: 64110228 | T34: 25503706 | U34: 25503706 | V34: 76277136 | W34: 0 | Z34: 2024 | AA34: {=SUM(($G$22:$H$372)*($B$22:$B$372=$Z34))/1000000} -> 75056.362 | AB34: {=SUM(($I$22:$K$372)*($B$22:$B$372=$Z34))/1000000} -> 59104.917 | AC34: {=SUM(($L$22:$W$372)*($B$22:$B$372=$Z34))/1000000} -> 186938.42 | AD34: =SUM(AA34:AC34) -> 321099.7
B35: 2013 | C35: =C26 -> Flex | D35: 5 | E35: 5602993664 | F35: 77389656 | G35: 1203051136 | H35: 632725120 | I35: 128952440 | J35: 0 | K35: 22762426 | L35: 0 | M35: 0 | N35: 0 | O35: 0 | P35: 0 | Q35: 0 | R35: 0 | S35: 0 | T35: 0 | U35: 0 | V35: 0 | W35: 0 | Z35: 2025 | AA35: {=SUM(($G$22:$H$372)*($B$22:$B$372=$Z35))/1000000} -> 76161.661 | AB35: {=SUM(($I$22:$K$372)*($B$22:$B$372=$Z35))/1000000} -> 59444.983 | AC35: {=SUM(($L$22:$W$372)*($B$22:$B$372=$Z35))/1000000} -> 188410.14 | AD35: =SUM(AA35:AC35) -> 324016.78
B36: 2013 | C36: =C27 -> BEV | D36: 6 | E36: 0 | F36: 0 | G36: 0 | H36: 1875744 | I36: 0 | J36: 0 | K36: 0 | L36: 0 | M36: 0 | N36: 0 | O36: 0 | P36: 0 | Q36: 0 | R36: 0 | S36: 0 | T36: 0 | U36: 0 | V36: 0 | W36: 0 | Z36: 2026 | AA36: {=SUM(($G$22:$H$372)*($B$22:$B$372=$Z36))/1000000} -> 77621.935 | AB36: {=SUM(($I$22:$K$372)*($B$22:$B$372=$Z36))/1000000} -> 60179.276 | AC36: {=SUM(($L$22:$W$372)*($B$22:$B$372=$Z36))/1000000} -> 190675.15 | AD36: =SUM(AA36:AC36) -> 328476.36
B37: 2013 | C37: =C28 -> PHEV diesel | D37: 7 | E37: 0 | F37: 0 | G37: 0 | H37: 0 | I37: 0 | J37: 0 | K37: 0 | L37: 0 | M37: 0 | N37: 0 | O37: 0 | P37: 0 | Q37: 0 | R37: 0 | S37: 0 | T37: 0 | U37: 0 | V37: 0 | W37: 0 | Z37: 2027 | AA37: {=SUM(($G$22:$H$372)*($B$22:$B$372=$Z37))/1000000} -> 78824.144 | AB37: {=SUM(($I$22:$K$372)*($B$22:$B$372=$Z37))/1000000} -> 60943.302 | AC37: {=SUM(($L$22:$W$372)*($B$22:$B$372=$Z37))/1000000} -> 192523.84 | AD37: =SUM(AA37:AC37) -> 332291.29
B38: 2013 | C38: =C29 -> PHEV gasoline | D38: 8 | E38: 0 | F38: 0 | G38: 0 | H38: 0 | I38: 0 | J38: 0 | K38: 0 | L38: 0 | M38: 0 | N38: 0 | O38: 0 | P38: 0 | Q38: 0 | R38: 0 | S38: 0 | T38: 0 | U38: 0 | V38: 0 | W38: 0 | Z38: 2028 | AA38: {=SUM(($G$22:$H$372)*($B$22:$B$372=$Z38))/1000000} -> 79954.302 | AB38: {=SUM(($I$22:$K$372)*($B$22:$B$372=$Z38))/1000000} -> 61768.856 | AC38: {=SUM(($L$22:$W$372)*($B$22:$B$372=$Z38))/1000000} -> 194029.03 | AD38: =SUM(AA38:AC38) -> 335752.19
B39: 2013 | C39: =C30 -> Fuel cell | D39: 9 | E39: 0 | F39: 0 | G39: 0 | H39: 0 | I39: 0 | J39: 0 | K39: 0 | L39: 0 | M39: 0 | N39: 0 | O39: 0 | P39: 0 | Q39: 0 | R39: 0 | S39: 0 | T39: 0 | U39: 0 | V39: 0 | W39: 0 | Z39: 2029 | AA39: {=SUM(($G$22:$H$372)*($B$22:$B$372=$Z39))/1000000} -> 81126.438 | AB39: {=SUM(($I$22:$K$372)*($B$22:$B$372=$Z39))/1000000} -> 62522.915 | AC39: {=SUM(($L$22:$W$372)*($B$22:$B$372=$Z39))/1000000} -> 194919.58 | AD39: =SUM(AA39:AC39) -> 338568.93
B40: 2014 | C40: =C31 -> Diesel | D40: 1 | E40: 31470921728 | F40: 73441176 | G40: 37866586112 | H40: 2775675904 | I40: 9478882304 | J40: 11652484096 | K40: 15905961984 | L40: 15311998976 | M40: 1816530688 | N40: 1816530688 | O40: 5449592320 | P40: 22719107072 | Q40: 10872541184 | R40: 10872541184 | S40: 32737095680 | T40: 13023152128 | U40: 13023152128 | V40: 38949990400 | W40: 3021042 | Z40: 2030 | AA40: {=SUM(($G$22:$H$372)*($B$22:$B$372=$Z40))/1000000} -> 82515.568 | AB40: {=SUM(($I$22:$K$372)*($B$22:$B$372=$Z40))/1000000} -> 63231.207 | AC40: {=SUM(($L$22:$W$372)*($B$22:$B$372=$Z40))/1000000} -> 195347.26 | AD40: =SUM(AA40:AC40) -> 341094.03
B41: 2014 | C41: =C32 -> Gasoline | D41: 2 | E41: 50104815616 | F41: 1981181184 | G41: 8467652608 | H41: 5142343680 | I41: 8770002944 | J41: 3432117504 | K41: 5204172800 | L41: 292320064 | M41: 0 | N41: 0 | O41: 0 | P41: 37042424 | Q41: 0 | R41: 0 | S41: 0 | T41: 0 | U41: 0 | V41: 0 | W41: 0 | Z41: 2031 | AA41: {=SUM(($G$22:$H$372)*($B$22:$B$372=$Z41))/1000000} -> 84225.81 | AB41: {=SUM(($I$22:$K$372)*($B$22:$B$372=$Z41))/1000000} -> 64039.528 | AC41: {=SUM(($L$22:$W$372)*($B$22:$B$372=$Z41))/1000000} -> 195864.9 | AD41: =SUM(AA41:AC41) -> 344130.23
B42: 2014 | C42: =C33 -> LPG | D42: 3 | E42: 190928 | F42: 318 | G42: 2210096 | H42: 0 | I42: 3378688 | J42: 2267157 | K42: 11943307 | L42: 13006248 | M42: 0 | N42: 0 | O42: 0 | P42: 148184 | Q42: 0 | R42: 0 | S42: 0 | T42: 0 | U42: 0 | V42: 0 | W42: 0 | Z42: 2032 | AA42: {=SUM(($G$22:$H$372)*($B$22:$B$372=$Z42))/1000000} -> 86247.875 | AB42: {=SUM(($I$22:$K$372)*($B$22:$B$372=$Z42))/1000000} -> 65124.282 | AC42: {=SUM(($L$22:$W$372)*($B$22:$B$372=$Z42))/1000000} -> 196870.93 | AD42: =SUM(AA42:AC42) -> 348243.09
... B60: 2016 | C60: =C51 -> LPG | D60: 3 | E60: 154088 | F60: 322 | G60: 1419799 | H60: 0 | I60: 6546392 | J60: 22589896 | K60: 22562494 | L60: 21641836 | M60: 0 | N60: 0 | O60: 0 | P60: 219438 | Q60: 0 | R60: 0 | S60: 0 | T60: 0 | U60: 0 | V60: 0 | W60: 0 | Z60: 2050 | AA60: {=SUM(($G$22:$H$372)*($B$22:$B$372=$Z60))/1000000} -> 123324.76 | AB60: {=SUM(($I$22:$K$372)*($B$22:$B$372=$Z60))/1000000} -> 84643.599 | AC60: {=SUM(($L$22:$W$372)*($B$22:$B$372=$Z60))/1000000} -> 205175.58 | AD60: =SUM(AA60:AC60) -> 413143.94
...

Sheet Freight LDVs + HDVs
A1: Average Battery Pack Size | B1: 2020 | C1: 2021 | D1: 2022 | E1: 2023 | F1: 2024 | G1: 2025 | H1: 2026 | I1: 2027 | J1: 2028 | K1: 2029 | L1: 2030 | M1: 2031 | N1: 2032 | O1: 2033 | P1: 2034 | Q1: 2035 | R1: 2036 | S1: 2037 | T1: 2038 | U1: 2039 | V1: 2040 | W1: 2041 | X1: 2042 | Y1: 2043 | Z1: 2044 | AA1: 2045 | AB1: 2046 | AC1: 2047 | AD1: 2048 | AE1: 2049 | AF1: 2050
A2: Rigid truck, 4-5 | B2: {=TREND($D2:$H2,$D$1:$H$1,B$1)} -> 140.5 | C2: {=TREND($D2:$H2,$D$1:$H$1,C$1)} -> 137.75 | D2: 135 | E2: 132.25 | F2: 129.5 | G2: 126.75 | H2: 124 | I2: 121.25 | J2: 118.5 | K2: 115.75 | L2: 113 | M2: 113 | N2: 113 | O2: 113 | P2: 113 | Q2: 113 | R2: 113 | S2: 113 | T2: 113 | U2: 113 | V2: 113 | W2: 113 | X2: 113 | Y2: 113 | Z2: 113 | AA2: 113 | AB2: 113 | AC2: 113 | AD2: 113 | AE2: 113 | AF2: 113
A3: Rigid truck, 6-7 | B3: {=TREND($D3:$H3,$D$1:$H$1,B$1)} -> 213.5 | C3: {=TREND($D3:$H3,$D$1:$H$1,C$1)} -> 209.25 | D3: 205 | E3: 200.75 | F3: 196.5 | G3: 192.25 | H3: 188 | I3: 183.75 | J3: 179.5 | K3: 175.25 | L3: 171 | M3: 171 | N3: 171 | O3: 171 | P3: 171 | Q3: 171 | R3: 171 | S3: 171 | T3: 171 | U3: 171 | V3: 171 | W3: 171 | X3: 171 | Y3: 171 | Z3: 171 | AA3: 171 | AB3: 171 | AC3: 171 | AD3: 171 | AE3: 171 | AF3: 171
A4: Rigid truck, 8 | B4: {=TREND($D4:$H4,$D$1:$H$1,B$1)} -> 425 | C4: {=TREND($D4:$H4,$D$1:$H$1,C$1)} -> 412.5 | D4: 400 | E4: 387.5 | F4: 375 | G4: 362.5 | H4: 350 | I4: 337.5 | J4: 325 | K4: 312.5 | L4: 300 | M4: 300 | N4: 300 | O4: 300 | P4: 300 | Q4: 300 | R4: 300 | S4: 300 | T4: 300 | U4: 300 | V4: 300 | W4: 300 | X4: 300 | Y4: 300 | Z4: 300 | AA4: 300 | AB4: 300 | AC4: 300 | AD4: 300 | AE4: 300 | AF4: 300
A5: Tractor truck, short-haul | B5: {=TREND($D5:$H5,$D$1:$H$1,B$1)} -> 485.5 | C5: {=TREND($D5:$H5,$D$1:$H$1,C$1)} -> 470.25 | D5: 455 | E5: 439.75 | F5: 424.5 | G5: 409.25 | H5: 394 | I5: 378.75 | J5: 363.5 | K5: 348.25 | L5: 333 | M5: 333 | N5: 333 | O5: 333 | P5: 333 | Q5: 333 | R5: 333 | S5: 333 | T5: 333 | U5: 333 | V5: 333 | W5: 333 | X5: 333 | Y5: 333 | Z5: 333 | AA5: 333 | AB5: 333 | AC5: 333 | AD5: 333 | AE5: 333 | AF5: 333
A6: Tractor truck, long-haul | B6: {=TREND($D6:$H6,$D$1:$H$1,B$1)} -> 984.25 | C6: {=TREND($D6:$H6,$D$1:$H$1,C$1)} -> 952.125 | D6: 920 | E6: 887.875 | F6: 855.75 | G6: 823.625 | H6: 791.5 | I6: 759.375 | J6: 727.25 | K6: 695.125 | L6: 663 | M6: 663 | N6: 663 | O6: 663 | P6: 663 | Q6: 663 | R6: 663 | S6: 663 | T6: 663 | U6: 663 | V6: 663 | W6: 663 | X6: 663 | Y6: 663 | Z6: 663 | AA6: 663 | AB6: 663 | AC6: 663 | AD6: 663 | AE6: 663 | AF6: 663
A7: Refuse truck | B7: {=TREND($D7:$H7,$D$1:$H$1,B$1)} -> 428.25 | C7: {=TREND($D7:$H7,$D$1:$H$1,C$1)} -> 416.625 | D7: 405 | E7: 393.375 | F7: 381.75 | G7: 370.125 | H7: 358.5 | I7: 346.875 | J7: 335.25 | K7: 323.625 | L7: 312 | M7: 312 | N7: 312 | O7: 312 | P7: 312 | Q7: 312 | R7: 312 | S7: 312 | T7: 312 | U7: 312 | V7: 312 | W7: 312 | X7: 312 | Y7: 312 | Z7: 312 | AA7: 312 | AB7: 312 | AC7: 312 | AD7: 312 | AE7: 312 | AF7: 312
A8: Small bus, 4-5 | B8: {=TREND($D8:$H8,$D$1:$H$1,B$1)} -> 121.25 | C8: {=TREND($D8:$H8,$D$1:$H$1,C$1)} -> 120.625 | D8: 120 | E8: 119.375 | F8: 118.75 | G8: 118.125 | H8: 117.5 | I8: 116.875 | J8: 116.25 | K8: 115.625 | L8: 115 | M8: 115 | N8: 115 | O8: 115 | P8: 115 | Q8: 115 | R8: 115 | S8: 115 | T8: 115 | U8: 115 | V8: 115 | W8: 115 | X8: 115 | Y8: 115 | Z8: 115 | AA8: 115 | AB8: 115 | AC8: 115 | AD8: 115 | AE8: 115 | AF8: 115
A9: Transit bus, 6-8 | B9: {=TREND($D9:$H9,$D$1:$H$1,B$1)} -> 455 | C9: {=TREND($D9:$H9,$D$1:$H$1,C$1)} -> 452.5 | D9: 450 | E9: 447.5 | F9: 445 | G9: 442.5 | H9: 440 | I9: 437.5 | J9: 435 | K9: 432.5 | L9: 430 | M9: 430 | N9: 430 | O9: 430 | P9: 430 | Q9: 430 | R9: 430 | S9: 430 | T9: 430 | U9: 430 | V9: 430 | W9: 430 | X9: 430 | Y9: 430 | Z9: 430 | AA9: 430 | AB9: 430 | AC9: 430 | AD9: 430 | AE9: 430 | AF9: 430
A10: School bus, 6-8 | B10: {=TREND($D10:$H10,$D$1:$H$1,B$1)} -> 182 | C10: {=TREND($D10:$H10,$D$1:$H$1,C$1)} -> 181 | D10: 180 | E10: 179 | F10: 178 | G10: 177 | H10: 176 | I10: 175 | J10: 174 | K10: 173 | L10: 172 | M10: 172 | N10: 172 | O10: 172 | P10: 172 | Q10: 172 | R10: 172 | S10: 172 | T10: 172 | U10: 172 | V10: 172 | W10: 172 | X10: 172 | Y10: 172 | Z10: 172 | AA10: 172 | AB10: 172 | AC10: 172 | AD10: 172 | AE10: 172 | AF10: 172
A11: Other bus, 6-8 | B11: {=TREND($D11:$H11,$D$1:$H$1,B$1)} -> 683.5 | C11: {=TREND($D11:$H11,$D$1:$H$1,C$1)} -> 679.75 | D11: 676 | E11: 672.25 | F11: 668.5 | G11: 664.75 | H11: 661 | I11: 657.25 | J11: 653.5 | K11: 649.75 | L11: 646 | M11: 646 | N11: 646 | O11: 646 | P11: 646 | Q11: 646 | R11: 646 | S11: 646 | T11: 646 | U11: 646 | V11: 646 | W11: 646 | X11: 646 | Y11: 646 | Z11: 646 | AA11: 646 | AB11: 646 | AC11: 646 | AD11: 646 | AE11: 646 | AF11: 646
A14: Total vehicle sales - historical data and projections
B15: 2020 | C15: 2021 | D15: 2022 | E15: 2023 | F15: 2024 | G15: 2025 | H15: 2026 | I15: 2027 | J15: 2028 | K15: 2029 | L15: 2030 | M15: 2031 | N15: 2032 | O15: 2033 | P15: 2034 | Q15: 2035 | R15: 2036 | S15: 2037 | T15: 2038 | U15: 2039 | V15: 2040 | W15: 2041 | X15: 2042 | Y15: 2043 | Z15: 2044 | AA15: 2045 | AB15: 2046 | AC15: 2047 | AD15: 2048 | AE15: 2049 | AF15: 2050 | AG15: 2051 | AH15: 2052 | AI15: 2053 | AJ15: EPS Category
A16: Annual sales
A17: Rigid truck, 4-5 | B17: 116537.59 | C17: =($G17-$B17)/5+B17 -> 117344.41 | D17: =($G17-$B17)/5+C17 -> 118151.24 | E17: =($G17-$B17)/5+D17 -> 118958.06 | F17: =($G17-$B17)/5+E17 -> 119764.89 | G17: 120571.71 | H17: =($L17-$G17)/5+G17 -> 122325.78 | I17: =($L17-$G17)/5+H17 -> 124079.86 | J17: =($L17-$G17)/5+I17 -> 125833.93 | K17: =($L17-$G17)/5+J17 -> 127588.01 | L17: 129342.08 | M17: =($Q17-$L17)/5+L17 -> 132498.09 | N17: =($Q17-$L17)/5+M17 -> 135654.1 | O17: =($Q17-$L17)/5+N17 -> 138810.12 | P17: =($Q17-$L17)/5+O17 -> 141966.13 | Q17: 145122.14 | R17: =($V17-$Q17)/5+Q17 -> 148198.99 | S17: =($V17-$Q17)/5+R17 -> 151275.84 | T17: =($V17-$Q17)/5+S17 -> 154352.7 | U17: =($V17-$Q17)/5+T17 -> 157429.55 | V17: 160506.4 | W17: {=TREND($M17:$V17,$M$15:$V$15,W$15)} -> 163688.8 | X17: {=TREND($M17:$V17,$M$15:$V$15,X$15)} -> 166799.23 | Y17: {=TREND($M17:$V17,$M$15:$V$15,Y$15)} -> 169909.67 | Z17: {=TREND($M17:$V17,$M$15:$V$15,Z$15)} -> 173020.1 | AA17: {=TREND($M17:$V17,$M$15:$V$15,AA$15)} -> 176130.54 | AB17: {=TREND($M17:$V17,$M$15:$V$15,AB$15)} -> 179240.97 | AC17: {=TREND($M17:$V17,$M$15:$V$15,AC$15)} -> 182351.41 | AD17: {=TREND($M17:$V17,$M$15:$V$15,AD$15)} -> 185461.84 | ... AI17: {=TREND($M17:$V17,$M$15:$V$15,AI$15)} -> 201014.02 | AJ17: Freight LDV
A18: Rigid truck, 6-7 | B18: 118399.01 | C18: =($G18-$B18)/5+B18 -> 119218.7 | D18: =($G18-$B18)/5+C18 -> 120038.39 | E18: =($G18-$B18)/5+D18 -> 120858.07 | F18: =($G18-$B18)/5+E18 -> 121677.76 | G18: 122497.45 | H18: =($L18-$G18)/5+G18 -> 124279.49 | I18: =($L18-$G18)/5+H18 -> 126061.52 | J18: =($L18-$G18)/5+I18 -> 127843.56 | K18: =($L18-$G18)/5+J18 -> 129625.6 | L18: 131407.63 | M18: =($Q18-$L18)/5+L18 -> 134614.11 | N18: =($Q18-$L18)/5+M18 -> 137820.6 | O18: =($Q18-$L18)/5+N18 -> 141027.08 | P18: =($Q18-$L18)/5+O18 -> 144233.56 | Q18: 147440.04 | R18: =($V18-$Q18)/5+Q18 -> 150566.05 | S18: =($V18-$Q18)/5+R18 -> 153692.05 | T18: =($V18-$Q18)/5+S18 -> 156818.06 | U18: =($V18-$Q18)/5+T18 -> 159944.06 | V18: 163070.07 | W18: {=TREND($M18:$V18,$M$15:$V$15,W$15)} -> 166303.38 | X18: {=TREND($M18:$V18,$M$15:$V$15,X$15)} -> 169463.52 | Y18: {=TREND($M18:$V18,$M$15:$V$15,Y$15)} -> 172623.67 | Z18: {=TREND($M18:$V18,$M$15:$V$15,Z$15)} -> 175783.82 | AA18: {=TREND($M18:$V18,$M$15:$V$15,AA$15)} -> 178943.97 | AB18: {=TREND($M18:$V18,$M$15:$V$15,AB$15)} -> 182104.11 | AC18: {=TREND($M18:$V18,$M$15:$V$15,AC$15)} -> 185264.26 | AD18: {=TREND($M18:$V18,$M$15:$V$15,AD$15)} -> 188424.41 | ... AI18: {=TREND($M18:$V18,$M$15:$V$15,AI$15)} -> 204225.14 | AJ18: Freight LDV
A19: Rigid truck, 8 | B19: 95647.28 | C19: =($G19-$B19)/5+B19 -> 96309.492 | D19: =($G19-$B19)/5+C19 -> 96971.704 | E19: =($G19-$B19)/5+D19 -> 97633.915 | F19: =($G19-$B19)/5+E19 -> 98296.127 | G19: 98958.339 | H19: =($L19-$G19)/5+G19 -> 100397.96 | I19: =($L19-$G19)/5+H19 -> 101837.59 | J19: =($L19-$G19)/5+I19 -> 103277.21 | K19: =($L19-$G19)/5+J19 -> 104716.83 | L19: 106156.46 | M19: =($Q19-$L19)/5+L19 -> 108746.77 | N19: =($Q19-$L19)/5+M19 -> 111337.08 | O19: =($Q19-$L19)/5+N19 -> 113927.39 | P19: =($Q19-$L19)/5+O19 -> 116517.71 | Q19: 119108.02 | R19: =($V19-$Q19)/5+Q19 -> 121633.36 | S19: =($V19-$Q19)/5+R19 -> 124158.69 | T19: =($V19-$Q19)/5+S19 -> 126684.03 | U19: =($V19-$Q19)/5+T19 -> 129209.37 | V19: 131734.7 | W19: {=TREND($M19:$V19,$M$15:$V$15,W$15)} -> 134346.68 | X19: {=TREND($M19:$V19,$M$15:$V$15,X$15)} -> 136899.58 | Y19: {=TREND($M19:$V19,$M$15:$V$15,Y$15)} -> 139452.48 | Z19: {=TREND($M19:$V19,$M$15:$V$15,Z$15)} -> 142005.38 | AA19: {=TREND($M19:$V19,$M$15:$V$15,AA$15)} -> 144558.29 | AB19: {=TREND($M19:$V19,$M$15:$V$15,AB$15)} -> 147111.19 | AC19: {=TREND($M19:$V19,$M$15:$V$15,AC$15)} -> 149664.09 | AD19: {=TREND($M19:$V19,$M$15:$V$15,AD$15)} -> 152216.99 | ... AI19: {=TREND($M19:$V19,$M$15:$V$15,AI$15)} -> 164981.51 | AJ19: Freight HDV
A20: Tractor truck, short-haul | B20: 55945.25 | C20: =($G20-$B20)/5+B20 -> 55322.91 | D20: =($G20-$B20)/5+C20 -> 54700.57 | E20: =($G20-$B20)/5+D20 -> 54078.23 | F20: =($G20-$B20)/5+E20 -> 53455.89 | G20: 52833.55 | H20: =($L20-$G20)/5+G20 -> 52462.84 | I20: =($L20-$G20)/5+H20 -> 52092.13 | J20: =($L20-$G20)/5+I20 -> 51721.42 | K20: =($L20-$G20)/5+J20 -> 51350.71 | L20: 50980 | M20: =($Q20-$L20)/5+L20 -> 51194.304 | N20: =($Q20-$L20)/5+M20 -> 51408.608 | O20: =($Q20-$L20)/5+N20 -> 51622.912 | P20: =($Q20-$L20)/5+O20 -> 51837.216 | Q20: 52051.52 | R20: =($V20-$Q20)/5+Q20 -> 52259.394 | S20: =($V20-$Q20)/5+R20 -> 52467.268 | T20: =($V20-$Q20)/5+S20 -> 52675.142 | U20: =($V20-$Q20)/5+T20 -> 52883.016 | V20: 53090.89 | W20: {=TREND($M20:$V20,$M$15:$V$15,W$15)} -> 53307.337 | X20: {=TREND($M20:$V20,$M$15:$V$15,X$15)} -> 53517.939 | Y20: {=TREND($M20:$V20,$M$15:$V$15,Y$15)} -> 53728.541 | Z20: {=TREND($M20:$V20,$M$15:$V$15,Z$15)} -> 53939.143 | AA20: {=TREND($M20:$V20,$M$15:$V$15,AA$15)} -> 54149.745 | AB20: {=TREND($M20:$V20,$M$15:$V$15,AB$15)} -> 54360.347 | AC20: {=TREND($M20:$V20,$M$15:$V$15,AC$15)} -> 54570.949 | AD20: {=TREND($M20:$V20,$M$15:$V$15,AD$15)} -> 54781.55 | ... AI20: {=TREND($M20:$V20,$M$15:$V$15,AI$15)} -> 55834.56 | AJ20: Freight HDV
A21: Tractor truck, long-haul | B21: 92843.9 | C21: =($G21-$B21)/5+B21 -> 91811.12 | D21: =($G21-$B21)/5+C21 -> 90778.34 | E21: =($G21-$B21)/5+D21 -> 89745.56 | F21: =($G21-$B21)/5+E21 -> 88712.78 | G21: 87680 | H21: =($L21-$G21)/5+G21 -> 87064.76 | I21: =($L21-$G21)/5+H21 -> 86449.52 | J21: =($L21-$G21)/5+I21 -> 85834.28 | K21: =($L21-$G21)/5+J21 -> 85219.04 | L21: 84603.8 | M21: =($Q21-$L21)/5+L21 -> 84959.44 | N21: =($Q21-$L21)/5+M21 -> 85315.08 | O21: =($Q21-$L21)/5+N21 -> 85670.72 | P21: =($Q21-$L21)/5+O21 -> 86026.36 | Q21: 86382 | R21: =($V21-$Q21)/5+Q21 -> 86726.98 | S21: =($V21-$Q21)/5+R21 -> 87071.96 | T21: =($V21-$Q21)/5+S21 -> 87416.94 | U21: =($V21-$Q21)/5+T21 -> 87761.92 | V21: 88106.9 | W21: {=TREND($M21:$V21,$M$15:$V$15,W$15)} -> 88466.093 | X21: {=TREND($M21:$V21,$M$15:$V$15,X$15)} -> 88815.596 | Y21: {=TREND($M21:$V21,$M$15:$V$15,Y$15)} -> 89165.098 | Z21: {=TREND($M21:$V21,$M$15:$V$15,Z$15)} -> 89514.601 | AA21: {=TREND($M21:$V21,$M$15:$V$15,AA$15)} -> 89864.103 | AB21: {=TREND($M21:$V21,$M$15:$V$15,AB$15)} -> 90213.605 | AC21: {=TREND($M21:$V21,$M$15:$V$15,AC$15)} -> 90563.108 | AD21: {=TREND($M21:$V21,$M$15:$V$15,AD$15)} -> 90912.61 | ... AI21: {=TREND($M21:$V21,$M$15:$V$15,AI$15)} -> 92660.122 | AJ21: Freight HDV
A22: Refuse truck | B22: 3614 | C22: =($G22-$B22)/5+B22 -> 3639 | D22: =($G22-$B22)/5+C22 -> 3664 | E22: =($G22-$B22)/5+D22 -> 3689 | F22: =($G22-$B22)/5+E22 -> 3714 | G22: 3739 | H22: =($L22-$G22)/5+G22 -> 3793.4 | I22: =($L22-$G22)/5+H22 -> 3847.8 | J22: =($L22-$G22)/5+I22 -> 3902.2 | K22: =($L22-$G22)/5+J22 -> 3956.6 | L22: 4011 | M22: =($Q22-$L22)/5+L22 -> 4108.8 | N22: =($Q22-$L22)/5+M22 -> 4206.6 | O22: =($Q22-$L22)/5+N22 -> 4304.4 | P22: =($Q22-$L22)/5+O22 -> 4402.2 | Q22: 4500 | R22: =($V22-$Q22)/5+Q22 -> 4595.4 | S22: =($V22-$Q22)/5+R22 -> 4690.8 | T22: =($V22-$Q22)/5+S22 -> 4786.2 | U22: =($V22-$Q22)/5+T22 -> 4881.6 | V22: 4977 | W22: {=TREND($M22:$V22,$M$15:$V$15,W$15)} -> 5075.6 | X22: {=TREND($M22:$V22,$M$15:$V$15,X$15)} -> 5172.0182 | Y22: {=TREND($M22:$V22,$M$15:$V$15,Y$15)} -> 5268.4364 | Z22: {=TREND($M22:$V22,$M$15:$V$15,Z$15)} -> 5364.8545 | AA22: {=TREND($M22:$V22,$M$15:$V$15,AA$15)} -> 5461.2727 | AB22: {=TREND($M22:$V22,$M$15:$V$15,AB$15)} -> 5557.6909 | AC22: {=TREND($M22:$V22,$M$15:$V$15,AC$15)} -> 5654.1091 | AD22: {=TREND($M22:$V22,$M$15:$V$15,AD$15)} -> 5750.5273 | ... AI22: {=TREND($M22:$V22,$M$15:$V$15,AI$15)} -> 6232.6182 | AJ22: Freight HDV
A23: Overall HDT | B23: =SUM(B17:B22) -> 482987.03 | G23: =SUM(G17:G22) -> 486280.05 | L23: =SUM(L17:L22) -> 506500.97 | Q23: =SUM(Q17:Q22) -> 554603.72 | V23: =SUM(V17:V22) -> 601485.96
A24: Small bus, 4-5 | B24: 4754.011 | C24: =($G24-$B24)/5+B24 -> 4754.1696 | D24: =($G24-$B24)/5+C24 -> 4754.3282 | E24: =($G24-$B24)/5+D24 -> 4754.4868 | F24: =($G24-$B24)/5+E24 -> 4754.6454 | G24: 4754.804 | H24: =($L24-$G24)/5+G24 -> 4784.2998 | I24: =($L24-$G24)/5+H24 -> 4813.7956 | J24: =($L24-$G24)/5+I24 -> 4843.2914 | K24: =($L24-$G24)/5+J24 -> 4872.7872 | L24: 4902.283 | M24: =($Q24-$L24)/5+L24 -> 4986.5684 | N24: =($Q24-$L24)/5+M24 -> 5070.8538 | O24: =($Q24-$L24)/5+N24 -> 5155.1392 | P24: =($Q24-$L24)/5+O24 -> 5239.4246 | Q24: 5323.71 | R24: =($V24-$Q24)/5+Q24 -> 5405.7774 | S24: =($V24-$Q24)/5+R24 -> 5487.8448 | T24: =($V24-$Q24)/5+S24 -> 5569.9122 | U24: =($V24-$Q24)/5+T24 -> 5651.9796 | V24: 5734.047 | W24: {=TREND($M24:$V24,$M$15:$V$15,W$15)} -> 5819.0717 | X24: {=TREND($M24:$V24,$M$15:$V$15,X$15)} -> 5902.0801 | Y24: {=TREND($M24:$V24,$M$15:$V$15,Y$15)} -> 5985.0885 | Z24: {=TREND($M24:$V24,$M$15:$V$15,Z$15)} -> 6068.0968 | AA24: {=TREND($M24:$V24,$M$15:$V$15,AA$15)} -> 6151.1052 | AB24: {=TREND($M24:$V24,$M$15:$V$15,AB$15)} -> 6234.1136 | AC24: {=TREND($M24:$V24,$M$15:$V$15,AC$15)} -> 6317.122 | AD24: {=TREND($M24:$V24,$M$15:$V$15,AD$15)} -> 6400.1303 | ... AI24: {=TREND($M24:$V24,$M$15:$V$15,AI$15)} -> 6815.1722 | AJ24: Passenger HDV
A25: Transit bus, 6-8 | B25: 5282.984 | C25: =($G25-$B25)/5+B25 -> 5283.158 | D25: =($G25-$B25)/5+C25 -> 5283.332 | E25: =($G25-$B25)/5+D25 -> 5283.506 | F25: =($G25-$B25)/5+E25 -> 5283.68 | G25: 5283.854 | H25: =($L25-$G25)/5+G25 -> 5316.6318 | I25: =($L25-$G25)/5+H25 -> 5349.4096 | J25: =($L25-$G25)/5+I25 -> 5382.1874 | K25: =($L25-$G25)/5+J25 -> 5414.9652 | L25: 5447.743 | M25: =($Q25-$L25)/5+L25 -> 5541.4026 | N25: =($Q25-$L25)/5+M25 -> 5635.0622 | O25: =($Q25-$L25)/5+N25 -> 5728.7218 | P25: =($Q25-$L25)/5+O25 -> 5822.3814 | Q25: 5916.041 | R25: =($V25-$Q25)/5+Q25 -> 6007.242 | S25: =($V25-$Q25)/5+R25 -> 6098.443 | T25: =($V25-$Q25)/5+S25 -> 6189.644 | U25: =($V25-$Q25)/5+T25 -> 6280.845 | V25: 6372.046 | W25: {=TREND($M25:$V25,$M$15:$V$15,W$15)} -> 6466.5251 | X25: {=TREND($M25:$V25,$M$15:$V$15,X$15)} -> 6558.7692 | Y25: {=TREND($M25:$V25,$M$15:$V$15,Y$15)} -> 6651.0132 | Z25: {=TREND($M25:$V25,$M$15:$V$15,Z$15)} -> 6743.2573 | AA25: {=TREND($M25:$V25,$M$15:$V$15,AA$15)} -> 6835.5013 | AB25: {=TREND($M25:$V25,$M$15:$V$15,AB$15)} -> 6927.7453 | AC25: {=TREND($M25:$V25,$M$15:$V$15,AC$15)} -> 7019.9894 | AD25: {=TREND($M25:$V25,$M$15:$V$15,AD$15)} -> 7112.2334 | ... AI25: {=TREND($M25:$V25,$M$15:$V$15,AI$15)} -> 7573.4536 | AJ25: Passenger HDV
A26: School bus, 6-8 | B26: 27044.907 | C26: =($G26-$B26)/5+B26 -> 27045.802 | D26: =($G26-$B26)/5+C26 -> 27046.698 | E26: =($G26-$B26)/5+D26 -> 27047.593 | F26: =($G26-$B26)/5+E26 -> 27048.489 | G26: 27049.384 | H26: =($L26-$G26)/5+G26 -> 27217.202 | I26: =($L26-$G26)/5+H26 -> 27385.02 | J26: =($L26-$G26)/5+I26 -> 27552.837 | K26: =($L26-$G26)/5+J26 -> 27720.655 | L26: 27888.473 | M26: =($Q26-$L26)/5+L26 -> 28367.96 | N26: =($Q26-$L26)/5+M26 -> 28847.447 | O26: =($Q26-$L26)/5+N26 -> 29326.934 | P26: =($Q26-$L26)/5+O26 -> 29806.421 | Q26: 30285.908 | R26: =($V26-$Q26)/5+Q26 -> 30752.794 | S26: =($V26-$Q26)/5+R26 -> 31219.68 | T26: =($V26-$Q26)/5+S26 -> 31686.566 | U26: =($V26-$Q26)/5+T26 -> 32153.452 | V26: 32620.338 | W26: {=TREND($M26:$V26,$M$15:$V$15,W$15)} -> 33104.025 | X26: {=TREND($M26:$V26,$M$15:$V$15,X$15)} -> 33576.257 | Y26: {=TREND($M26:$V26,$M$15:$V$15,Y$15)} -> 34048.489 | Z26: {=TREND($M26:$V26,$M$15:$V$15,Z$15)} -> 34520.721 | AA26: {=TREND($M26:$V26,$M$15:$V$15,AA$15)} -> 34992.953 | AB26: {=TREND($M26:$V26,$M$15:$V$15,AB$15)} -> 35465.185 | AC26: {=TREND($M26:$V26,$M$15:$V$15,AC$15)} -> 35937.417 | AD26: {=TREND($M26:$V26,$M$15:$V$15,AD$15)} -> 36409.648 | ... AI26: {=TREND($M26:$V26,$M$15:$V$15,AI$15)} -> 38770.808 | AJ26: Passenger HDV
A27: Other bus, 6-8 | B27: 16228.913 | C27: =($G27-$B27)/5+B27 -> 16229.455 | D27: =($G27-$B27)/5+C27 -> 16229.997 | E27: =($G27-$B27)/5+D27 -> 16230.539 | F27: =($G27-$B27)/5+E27 -> 16231.081 | G27: 16231.623 | H27: =($L27-$G27)/5+G27 -> 16332.309 | I27: =($L27-$G27)/5+H27 -> 16432.996 | J27: =($L27-$G27)/5+I27 -> 16533.682 | K27: =($L27-$G27)/5+J27 -> 16634.369 | L27: 16735.055 | M27: =($Q27-$L27)/5+L27 -> 17022.792 | N27: =($Q27-$L27)/5+M27 -> 17310.528 | O27: =($Q27-$L27)/5+N27 -> 17598.265 | P27: =($Q27-$L27)/5+O27 -> 17886.001 | Q27: 18173.738 | R27: =($V27-$Q27)/5+Q27 -> 18453.896 | S27: =($V27-$Q27)/5+R27 -> 18734.054 | T27: =($V27-$Q27)/5+S27 -> 19014.212 | U27: =($V27-$Q27)/5+T27 -> 19294.37 | V27: 19574.528 | W27: {=TREND($M27:$V27,$M$15:$V$15,W$15)} -> 19864.791 | X27: {=TREND($M27:$V27,$M$15:$V$15,X$15)} -> 20148.164 | Y27: {=TREND($M27:$V27,$M$15:$V$15,Y$15)} -> 20431.537 | Z27: {=TREND($M27:$V27,$M$15:$V$15,Z$15)} -> 20714.91 | AA27: {=TREND($M27:$V27,$M$15:$V$15,AA$15)} -> 20998.283 | AB27: {=TREND($M27:$V27,$M$15:$V$15,AB$15)} -> 21281.657 | AC27: {=TREND($M27:$V27,$M$15:$V$15,AC$15)} -> 21565.03 | AD27: {=TREND($M27:$V27,$M$15:$V$15,AD$15)} -> 21848.403 | ... AI27: {=TREND($M27:$V27,$M$15:$V$15,AI$15)} -> 23265.269 | AJ27: Passenger HDV
A28: Overall Bus | B28: =SUM(B24:B27) -> 53310.815 | G28: =SUM(G24:G27) -> 53319.665 | L28: =SUM(L24:L27) -> 54973.554 | Q28: =SUM(Q24:Q27) -> 59699.397 | V28: =SUM(V24:V27) -> 64300.959
B31: VKT per vehicle
B32: Average of VKTpVeh
B33: Row Labels | C33: 2020 | D33: 2021 | E33: 2022 | F33: 2023 | G33: 2024 | H33: 2025 | I33: 2026 | J33: 2027 | K33: 2028 | L33: 2029 | M33: 2030 | N33: 2031 | O33: 2032 | P33: 2033 | Q33: 2034 | R33: 2035 | S33: 2036 | T33: 2037 | U33: 2038 | V33: 2039 | W33: 2040 | X33: 2041 | Y33: 2042 | Z33: 2043 | AA33: 2044 | AB33: 2045 | AC33: 2046 | AD33: 2047 | AE33: 2048 | AF33: 2049 | AG33: 2050 | AH33: 2051 | AI33: 2052 | AJ33: 2053 | AK33: 2054 | AL33: 2055 | AM33: 2056 | AN33: 2057 | AO33: 2058 | AP33: 2059 | AQ33: 2060 | AR33: 2061 | AS33: 2062 | AT33: 2063 | AU33: 2064 | AV33: 2065 | AW33: 2066 | AX33: 2067 | AY33: 2068 | AZ33: 2069 | BA33: 2070 | BB33: (blank) | BC33: Grand Total
A34: bus | B34: Motor Home_4_5 | C34: 7282.1417 | D34: 7350.0019 | E34: 7417.8622 | F34: 7485.7225 | G34: 7553.5827 | H34: 7621.443 | I34: 7849.9524 | J34: 8078.4619 | K34: 8306.9713 | L34: 8535.4807 | M34: 8763.9902 | N34: 8847.3833 | O34: 8930.7764 | P34: 9014.1695 | Q34: 9097.5626 | R34: 9180.9557 | S34: 9222.1208 | T34: 9263.2859 | U34: 9304.451 | V34: 9345.6161 | W34: 9386.7812 | X34: 9369.1215 | Y34: 9351.4619 | Z34: 9333.8022 | AA34: 9316.1426 | AB34: 9298.4829 | AC34: 9319.9004 | AD34: 9341.3179 | AE34: 9362.7354 | AF34: 9384.1529 | AG34: 9405.5704 | AH34: 9452.4188 | AI34: 9499.2673 | AJ34: 9546.1157 | AK34: 9592.9642 | AL34: 9639.8126 | AM34: 9681.9088 | AN34: 9724.0049 | AO34: 9766.1011 | AP34: 9808.1972 | AQ34: 9850.2934 | AR34: 9850.2934 | AS34: 9850.2934 | AT34: 9850.2934 | AU34: 9850.2934 | AV34: 9850.2934 | AW34: 9850.2934 | AX34: 9850.2934 | AY34: 9850.2934 | AZ34: 9850.2934 | BA34: 9850.2934 | BC34: 8941.1253
A35: bus | B35: Motor Home_6_7 | C35: 8136.7393 | D35: 8129.8981 | E35: 8123.057 | F35: 8116.2159 | G35: 8109.3747 | H35: 8102.5336 | I35: 8172.6773 | J35: 8242.821 | K35: 8312.9647 | L35: 8383.1085 | M35: 8453.2522 | N35: 8557.9387 | O35: 8662.6252 | P35: 8767.3116 | Q35: 8871.9981 | R35: 8976.6846 | S35: 9033.8404 | T35: 9090.9962 | U35: 9148.1519 | V35: 9205.3077 | W35: 9262.4635 | X35: 9269.6668 | Y35: 9276.8702 | Z35: 9284.0736 | AA35: 9291.2769 | AB35: 9298.4803 | AC35: 9319.8974 | AD35: 9341.3146 | AE35: 9362.7317 | AF35: 9384.1488 | AG35: 9405.5659 | AH35: 9452.4154 | AI35: 9499.2649 | AJ35: 9546.1145 | AK35: 9592.964 | AL35: 9639.8135 | AM35: 9681.9107 | AN35: 9724.0079 | AO35: 9766.1051 | AP35: 9808.2023 | AQ35: 9850.2995 | AR35: 9850.2995 | AS35: 9850.2995 | AT35: 9850.2995 | AU35: 9850.2995 | AV35: 9850.2995 | AW35: 9850.2995 | AX35: 9850.2995 | AY35: 9850.2995 | AZ35: 9850.2995 | BA35: 9850.2995 | BC35: 9335.2229
A36: bus | B36: Motor Home_8 | C36: 8719.9367 | D36: 8710.9262 | E36: 8701.9157 | F36: 8692.9052 | G36: 8683.8947 | H36: 8674.8843 | I36: 8710.6316 | J36: 8746.3789 | K36: 8782.1261 | L36: 8817.8734 | M36: 8853.6207 | N36: 8903.4736 | O36: 8953.3264 | P36: 9003.1792 | Q36: 9053.032 | R36: 9102.8849 | S36: 9139.2061 | T36: 9175.5272 | U36: 9211.8484 | V36: 9248.1696 | W36: 9284.4908 | X36: 9287.2934 | Y36: 9290.0959 | Z36: 9292.8985 | AA36: 9295.701 | AB36: 9298.5036 | AC36: 9319.9193 | AD36: 9341.335 | AE36: 9362.7507 | AF36: 9384.1664 | AG36: 9405.582 | AH36: 9452.4314 | AI36: 9499.2808 | AJ36: 9546.1301 | AK36: 9592.9795 | AL36: 9639.8288 | AM36: 9681.927 | AN36: 9724.0251 | AO36: 9766.1233 | AP36: 9808.2214 | AQ36: 9850.3195 | AR36: 9850.3195 | AS36: 9850.3195 | AT36: 9850.3195 | AU36: 9850.3195 | AV36: 9850.3195 | AW36: 9850.3195 | AX36: 9850.3195 | AY36: 9850.3195 | AZ36: 9850.3195 | BA36: 9850.3195 | BC36: 9449.9949
A37: bus | B37: Other Buses_4_5 | C37: 47403.343 | D37: 47370.819 | E37: 47338.296 | F37: 47305.773 | G37: 47273.25 | H37: 47240.726 | I37: 47313.685 | J37: 47386.644 | K37: 47459.602 | L37: 47532.561 | M37: 47605.52 | N37: 47813.84 | O37: 48022.161 | P37: 48230.482 | Q37: 48438.802 | R37: 48647.123 | S37: 49000.983 | T37: 49354.842 | U37: 49708.702 | V37: 50062.561 | W37: 50416.421 | X37: 50436.532 | Y37: 50456.643 | Z37: 50476.753 | AA37: 50496.864 | AB37: 50516.975 | AC37: 50482.109 | AD37: 50447.243 | AE37: 50412.377 | AF37: 50377.511 | AG37: 50342.645 | AH37: 50354.082 | AI37: 50365.519 | AJ37: 50376.956 | AK37: 50388.393 | AL37: 50399.83 | AM37: 50409.758 | AN37: 50419.687 | AO37: 50429.615 | AP37: 50439.543 | AQ37: 50449.472 | AR37: 50449.472 | AS37: 50449.472 | AT37: 50449.472 | AU37: 50449.472 | AV37: 50449.472 | AW37: 50449.472 | AX37: 50449.472 | AY37: 50449.472 | AZ37: 50449.472 | BA37: 50449.472 | BC37: 49876.036
A38: Other bus, 6-8 | B38: Other Buses_6_7 | C38: 46342.195 | D38: 46524.8 | E38: 46707.405 | F38: 46890.011 | G38: 47072.616 | H38: 47255.221 | I38: 47488.017 | J38: 47720.814 | K38: 47953.61 | L38: 48186.406 | M38: 48419.202 | N38: 48697.121 | O38: 48975.039 | P38: 49252.958 | Q38: 49530.877 | R38: 49808.796 | S38: 50037.092 | T38: 50265.388 | U38: 50493.684 | V38: 50721.98 | W38: 50950.276 | X38: 50863.641 | Y38: 50777.005 | Z38: 50690.369 | AA38: 50603.734 | AB38: 50517.098 | AC38: 50482.235 | AD38: 50447.372 | AE38: 50412.509 | AF38: 50377.646 | AG38: 50342.783 | AH38: 50354.218 | AI38: 50365.652 | AJ38: 50377.086 | AK38: 50388.521 | AL38: 50399.955 | AM38: 50409.891 | AN38: 50419.827 | AO38: 50429.764 | AP38: 50439.7 | AQ38: 50449.636 | AR38: 50449.636 | AS38: 50449.636 | AT38: 50449.636 | AU38: 50449.636 | AV38: 50449.636 | AW38: 50449.636 | AX38: 50449.636 | AY38: 50449.636 | AZ38: 50449.636 | BA38: 50449.636 | BC38: 48998.777
A39: Other bus, 6-8 | B39: Other Buses_8 | C39: 47278.158 | D39: 47569.074 | E39: 47859.99 | F39: 48150.905 | G39: 48441.821 | H39: 48732.737 | I39: 48956.527 | J39: 49180.316 | K39: 49404.106 | L39: 49627.896 | M39: 49851.686 | N39: 49992.598 | O39: 50133.51 | P39: 50274.421 | Q39: 50415.333 | R39: 50556.245 | S39: 50632.373 | T39: 50708.5 | U39: 50784.627 | V39: 50860.755 | W39: 50936.882 | X39: 50852.921 | Y39: 50768.96 | Z39: 50684.999 | AA39: 50601.038 | AB39: 50517.077 | AC39: 50482.206 | AD39: 50447.336 | AE39: 50412.466 | AF39: 50377.595 | AG39: 50342.725 | AH39: 50354.163 | AI39: 50365.601 | AJ39: 50377.038 | AK39: 50388.476 | AL39: 50399.914 | AM39: 50409.856 | AN39: 50419.798 | AO39: 50429.739 | AP39: 50439.681 | AQ39: 50449.623 | AR39: 50449.623 | AS39: 50449.623 | AT39: 50449.623 | AU39: 50449.623 | AV39: 50449.623 | AW39: 50449.623 | AX39: 50449.623 | AY39: 50449.623 | AZ39: 50449.623 | BA39: 50449.623 | BC39: 48193.856
A40: Small bus, 4-5 | B40: School Bus_4_5 | C40: 16553.996 | D40: 16490.021 | E40: 16426.045 | F40: 16362.07 | G40: 16298.094 | H40: 16234.119 | I40: 16231.142 | J40: 16228.165 | K40: 16225.188 | L40: 16222.21 | M40: 16219.233 | N40: 16279.774 | O40: 16340.315 | P40: 16400.857 | Q40: 16461.398 | R40: 16521.939 | S40: 16649.081 | T40: 16776.224 | U40: 16903.366 | V40: 17030.509 | W40: 17157.652 | X40: 17212.593 | Y40: 17267.535 | Z40: 17322.477 | AA40: 17377.419 | AB40: 17432.361 | AC40: 17419.188 | AD40: 17406.014 | AE40: 17392.841 | AF40: 17379.668 | AG40: 17366.495 | AH40: 17369.149 | AI40: 17371.803 | AJ40: 17374.456 | AK40: 17377.11 | AL40: 17379.764 | AM40: 17382.863 | AN40: 17385.963 | AO40: 17389.062 | AP40: 17392.161 | AQ40: 17395.26 | AR40: 17395.26 | AS40: 17395.26 | AT40: 17395.26 | AU40: 17395.26 | AV40: 17395.26 | AW40: 17395.26 | AX40: 17395.26 | AY40: 17395.26 | AZ40: 17395.26 | BA40: 17395.26 | BC40: 16842.3
A41: School bus, 6-8 | B41: School Bus_6_7 | C41: 16570.755 | D41: 16622.415 | E41: 16674.076 | F41: 16725.737 | G41: 16777.397 | H41: 16829.058 | I41: 16868.764 | J41: 16908.47 | K41: 16948.176 | L41: 16987.882 | M41: 17027.588 | N41: 17080.18 | O41: 17132.772 | P41: 17185.364 | Q41: 17237.957 | R41: 17290.549 | S41: 17338.471 | T41: 17386.392 | U41: 17434.314 | V41: 17482.236 | W41: 17530.157 | X41: 17510.594 | Y41: 17491.03 | Z41: 17471.466 | AA41: 17451.902 | AB41: 17432.339 | AC41: 17419.165 | AD41: 17405.992 | AE41: 17392.818 | AF41: 17379.645 | AG41: 17366.472 | AH41: 17369.128 | AI41: 17371.784 | AJ41: 17374.441 | AK41: 17377.097 | AL41: 17379.754 | AM41: 17382.852 | AN41: 17385.951 | AO41: 17389.049 | AP41: 17392.148 | AQ41: 17395.246 | AR41: 17395.246 | AS41: 17395.246 | AT41: 17395.246 | AU41: 17395.246 | AV41: 17395.246 | AW41: 17395.246 | AX41: 17395.246 | AY41: 17395.246 | AZ41: 17395.246 | BA41: 17395.246 | BC41: 16665.306
A42: School bus, 6-8 | B42: School Bus_8 | C42: 16704.542 | D42: 16744.325 | E42: 16784.109 | F42: 16823.892 | G42: 16863.675 | H42: 16903.458 | I42: 16930.018 | J42: 16956.578 | K42: 16983.137 | L42: 17009.697 | M42: 17036.256 | N42: 17092.803 | O42: 17149.349 | P42: 17205.895 | Q42: 17262.441 | R42: 17318.987 | S42: 17364.258 | T42: 17409.529 | U42: 17454.8 | V42: 17500.072 | W42: 17545.343 | X42: 17522.743 | Y42: 17500.144 | Z42: 17477.544 | AA42: 17454.944 | AB42: 17432.345 | AC42: 17419.171 | AD42: 17405.996 | AE42: 17392.822 | AF42: 17379.648 | AG42: 17366.474 | AH42: 17369.128 | AI42: 17371.782 | AJ42: 17374.436 | AK42: 17377.091 | AL42: 17379.745 | AM42: 17382.843 | AN42: 17385.941 | AO42: 17389.038 | AP42: 17392.136 | AQ42: 17395.234 | AR42: 17395.234 | AS42: 17395.234 | AT42: 17395.234 | AU42: 17395.234 | AV42: 17395.234 | AW42: 17395.234 | AX42: 17395.234 | AY42: 17395.234 | AZ42: 17395.234 | BA42: 17395.234 | BC42: 16757.077
A43: Small bus, 4-5 | B43: Transit Bus_4_5 | C43: 48680.059 | D43: 48531.565 | E43: 48383.072 | F43: 48234.578 | G43: 48086.084 | H43: 47937.59 | I43: 47927.116 | J43: 47916.641 | K43: 47906.167 | L43: 47895.692 | M43: 47885.217 | N43: 47968.701 | O43: 48052.184 | P43: 48135.667 | Q43: 48219.151 | R43: 48302.634 | S43: 48572.494 | T43: 48842.354 | U43: 49112.213 | V43: 49382.073 | W43: 49651.933 | X43: 49714.263 | Y43: 49776.593 | Z43: 49838.923 | AA43: 49901.253 | AB43: 49963.584 | AC43: 49892.911 | AD43: 49822.238 | AE43: 49751.565 | AF43: 49680.892 | AG43: 49610.219 | AH43: 49619.684 | AI43: 49629.149 | AJ43: 49638.614 | AK43: 49648.078 | AL43: 49657.543 | AM43: 49669.802 | AN43: 49682.062 | AO43: 49694.321 | AP43: 49706.58 | AQ43: 49718.84 | AR43: 49718.84 | AS43: 49718.84 | AT43: 49718.84 | AU43: 49718.84 | AV43: 49718.84 | AW43: 49718.84 | AX43: 49718.84 | AY43: 49718.84 | AZ43: 49718.84 | BA43: 49718.84 | BC43: 49997.894
A44: Transit bus, 6-8 | B44: Transit Bus_6_7 | C44: 48928.255 | D44: 48905.951 | E44: 48883.647 | F44: 48861.343 | G44: 48839.039 | H44: 48816.735 | I44: 48853.19 | J44: 48889.644 | K44: 48926.098 | L44: 48962.553 | M44: 48999.007 | N44: 49142.052 | O44: 49285.097 | P44: 49428.142 | Q44: 49571.187 | R44: 49714.232 | S44: 49870.382 | T44: 50026.531 | U44: 50182.68 | V44: 50338.829 | W44: 50494.979 | X44: 50388.725 | Y44: 50282.472 | Z44: 50176.219 | AA44: 50069.966 | AB44: 49963.713 | AC44: 49893.036 | AD44: 49822.36 | AE44: 49751.684 | AF44: 49681.007 | AG44: 49610.331 | AH44: 49619.804 | AI44: 49629.276 | AJ44: 49638.749 | AK44: 49648.222 | AL44: 49657.695 | AM44: 49669.953 | AN44: 49682.211 | AO44: 49694.469 | AP44: 49706.726 | AQ44: 49718.984 | AR44: 49718.984 | AS44: 49718.984 | AT44: 49718.984 | AU44: 49718.984 | AV44: 49718.984 | AW44: 49718.984 | AX44: 49718.984 | AY44: 49718.984 | AZ44: 49718.984 | BA44: 49718.984 | BC44: 49806.33
...

Sheet SYBCbVT-passenger
A1: Battery Capacity (MW*hr/vehicle | B1: battery electric vehicle | C1: natural gas vehicle | D1: gasoline vehicle | E1: diesel vehicle | F1: plugin hybrid vehicle | G1: LPG vehicle | H1: hydrogen vehicle | I1: nonroad vehicle
A2: LDVs | B2: ='Pass LDVs'!B181/1000 -> 0.095525493 | C2: 0 | D2: 0 | E2: 0 | F2: ='Pass LDVs'!B182/1000 -> 0.016635207 | G2: 0 | H2: 0 | I2: 0
A3: HDVs | B3: ='Freight LDVs + HDVs'!C132/1000 -> 0.4467612 | C3: 0 | D3: 0 | E3: 0 | F3: 0 | G3: 0 | H3: 0 | I3: 0
A4: aircraft | B4: 0 | C4: 0 | D4: 0 | E4: 0 | F4: 0 | G4: 0 | H4: 0 | I4: 0
A5: rail | B5: 0 | C5: 0 | D5: 0 | E5: 0 | F5: 0 | G5: 0 | H5: 0 | I5: 0
A6: ships | B6: 0 | C6: 0 | D6: 0 | E6: 0 | F6: 0 | G6: 0 | H6: 0 | I6: 0
A7: motorbikes | B7: =Data!A3 -> 0.0007 | C7: 0 | D7: 0 | E7: 0 | F7: 0 | G7: 0 | H7: 0 | I7: 0

Sheet SYBCbVT-freight
A1: Battery Capacity (MW*hr/vehicle | B1: battery electric vehicle | C1: natural gas vehicle | D1: gasoline vehicle | E1: diesel vehicle | F1: plugin hybrid vehicle | G1: LPG vehicle | H1: hydrogen vehicle | I1: nonroad vehicle
A2: LDVs | B2: ='Freight LDVs + HDVs'!C130/1000 -> 0.12295576 | C2: 0 | D2: 0 | E2: 0 | F2: ='SYBCbVT-passenger'!F2*B2/'SYBCbVT-passenger'!B2 -> 0.021412028 | G2: 0 | H2: 0 | I2: 0
A3: HDVs | B3: ='Freight LDVs + HDVs'!C131/1000 -> 0.86592241 | C3: 0 | D3: 0 | E3: 0 | F3: 0 | G3: 0 | H3: 0 | I3: 0
A4: aircraft | B4: 0 | C4: 0 | D4: 0 | E4: 0 | F4: 0 | G4: 0 | H4: 0 | I4: 0
A5: rail | B5: 0 | C5: 0 | D5: 0 | E5: 0 | F5: 0 | G5: 0 | H5: 0 | I5: 0
A6: ships | B6: 0 | C6: 0 | D6: 0 | E6: 0 | F6: 0 | G6: 0 | H6: 0 | I6: 0
A7: motorbikes | B7: =Data!A3 -> 0.0007 | C7: 0 | D7: 0 | E7: 0 | F7: 0 | G7: 0 | H7: 0 | I7: 0
